[2025-04-16T20:01:31.977+0000] {local_task_job_runner.py:123} INFO - ::group::Pre task execution logs
[2025-04-16T20:01:32.033+0000] {taskinstance.py:2614} INFO - Dependencies all met for dep_context=non-requeueable deps ti=<TaskInstance: BinanceCryptoAPI.TestConnectionDB manual__2025-04-16T20:01:30.000590+00:00 [queued]>
[2025-04-16T20:01:32.044+0000] {taskinstance.py:2614} INFO - Dependencies all met for dep_context=requeueable deps ti=<TaskInstance: BinanceCryptoAPI.TestConnectionDB manual__2025-04-16T20:01:30.000590+00:00 [queued]>
[2025-04-16T20:01:32.045+0000] {taskinstance.py:2867} INFO - Starting attempt 1 of 1
[2025-04-16T20:01:32.063+0000] {taskinstance.py:2890} INFO - Executing <Task(PythonOperator): TestConnectionDB> on 2025-04-16 20:01:30.000590+00:00
[2025-04-16T20:01:32.071+0000] {warnings.py:112} WARNING - /home/***/.local/lib/python3.12/site-packages/***/task/task_runner/standard_task_runner.py:70: DeprecationWarning: This process (pid=537) is multi-threaded, use of fork() may lead to deadlocks in the child.
  pid = os.fork()

[2025-04-16T20:01:32.074+0000] {standard_task_runner.py:72} INFO - Started process 539 to run task
[2025-04-16T20:01:32.075+0000] {standard_task_runner.py:104} INFO - Running: ['***', 'tasks', 'run', 'BinanceCryptoAPI', 'TestConnectionDB', 'manual__2025-04-16T20:01:30.000590+00:00', '--job-id', '16', '--raw', '--subdir', 'DAGS_FOLDER/ETL/BinanceETL.py', '--cfg-path', '/tmp/tmp8gqms6ra']
[2025-04-16T20:01:32.078+0000] {standard_task_runner.py:105} INFO - Job 16: Subtask TestConnectionDB
[2025-04-16T20:01:32.756+0000] {task_command.py:467} INFO - Running <TaskInstance: BinanceCryptoAPI.TestConnectionDB manual__2025-04-16T20:01:30.000590+00:00 [running]> on host 2903c312f900
[2025-04-16T20:01:33.221+0000] {taskinstance.py:3134} INFO - Exporting env vars: AIRFLOW_CTX_DAG_OWNER='***' AIRFLOW_CTX_DAG_ID='BinanceCryptoAPI' AIRFLOW_CTX_TASK_ID='TestConnectionDB' AIRFLOW_CTX_EXECUTION_DATE='2025-04-16T20:01:30.000590+00:00' AIRFLOW_CTX_TRY_NUMBER='1' AIRFLOW_CTX_DAG_RUN_ID='manual__2025-04-16T20:01:30.000590+00:00'
[2025-04-16T20:01:33.223+0000] {taskinstance.py:732} INFO - ::endgroup::
[2025-04-16T20:01:33.331+0000] {base.py:84} INFO - Retrieving connection 'MY_DB'
[2025-04-16T20:01:33.356+0000] {logging_mixin.py:190} INFO - Connection to database successful
[2025-04-16T20:01:33.386+0000] {sql.py:511} INFO - Running statement: SELECT * FROM cryptoInfo, parameters: None
[2025-04-16T20:01:33.392+0000] {logging_mixin.py:190} INFO - Failed to connect to database: relation "cryptoinfo" does not exist
LINE 1: SELECT * FROM cryptoInfo
                      ^
[2025-04-16T20:01:33.394+0000] {taskinstance.py:3313} ERROR - Task failed with exception
Traceback (most recent call last):
  File "/home/airflow/.local/lib/python3.12/site-packages/airflow/models/taskinstance.py", line 768, in _execute_task
    result = _execute_callable(context=context, **execute_callable_kwargs)
             ^^^^^^^^^^^^^^^^^^^^^^^^^^^^^^^^^^^^^^^^^^^^^^^^^^^^^^^^^^^^^
  File "/home/airflow/.local/lib/python3.12/site-packages/airflow/models/taskinstance.py", line 734, in _execute_callable
    return ExecutionCallableRunner(
           ^^^^^^^^^^^^^^^^^^^^^^^^
  File "/home/airflow/.local/lib/python3.12/site-packages/airflow/utils/operator_helpers.py", line 252, in run
    return self.func(*args, **kwargs)
           ^^^^^^^^^^^^^^^^^^^^^^^^^^
  File "/home/airflow/.local/lib/python3.12/site-packages/airflow/models/baseoperator.py", line 424, in wrapper
    return func(self, *args, **kwargs)
           ^^^^^^^^^^^^^^^^^^^^^^^^^^^
  File "/home/airflow/.local/lib/python3.12/site-packages/airflow/operators/python.py", line 238, in execute
    return_value = self.execute_callable()
                   ^^^^^^^^^^^^^^^^^^^^^^^
  File "/home/airflow/.local/lib/python3.12/site-packages/airflow/operators/python.py", line 256, in execute_callable
    return runner.run(*self.op_args, **self.op_kwargs)
           ^^^^^^^^^^^^^^^^^^^^^^^^^^^^^^^^^^^^^^^^^^^
  File "/home/airflow/.local/lib/python3.12/site-packages/airflow/utils/operator_helpers.py", line 252, in run
    return self.func(*args, **kwargs)
           ^^^^^^^^^^^^^^^^^^^^^^^^^^
  File "/opt/airflow/dags/ETL/BinanceETL.py", line 28, in connect_to_db
    pg_hook.run(sqlQuery)
  File "/home/airflow/.local/lib/python3.12/site-packages/airflow/providers/common/sql/hooks/sql.py", line 467, in run
    self._run_command(cur, sql_statement, parameters)
  File "/home/airflow/.local/lib/python3.12/site-packages/airflow/providers/common/sql/hooks/sql.py", line 516, in _run_command
    cur.execute(sql_statement)
psycopg2.errors.UndefinedTable: relation "cryptoinfo" does not exist
LINE 1: SELECT * FROM cryptoInfo
                      ^

[2025-04-16T20:01:33.438+0000] {taskinstance.py:1226} INFO - Marking task as FAILED. dag_id=BinanceCryptoAPI, task_id=TestConnectionDB, run_id=manual__2025-04-16T20:01:30.000590+00:00, execution_date=20250416T200130, start_date=20250416T200132, end_date=20250416T200133
[2025-04-16T20:01:33.636+0000] {taskinstance.py:341} INFO - ::group::Post task execution logs
[2025-04-16T20:01:33.637+0000] {standard_task_runner.py:124} ERROR - Failed to execute job 16 for task TestConnectionDB (relation "cryptoinfo" does not exist
LINE 1: SELECT * FROM cryptoInfo
                      ^
; 539)
Traceback (most recent call last):
  File "/home/airflow/.local/lib/python3.12/site-packages/airflow/task/task_runner/standard_task_runner.py", line 117, in _start_by_fork
    ret = args.func(args, dag=self.dag)
          ^^^^^^^^^^^^^^^^^^^^^^^^^^^^^
  File "/home/airflow/.local/lib/python3.12/site-packages/airflow/cli/cli_config.py", line 49, in command
    return func(*args, **kwargs)
           ^^^^^^^^^^^^^^^^^^^^^
  File "/home/airflow/.local/lib/python3.12/site-packages/airflow/utils/cli.py", line 116, in wrapper
    return f(*args, **kwargs)
           ^^^^^^^^^^^^^^^^^^
  File "/home/airflow/.local/lib/python3.12/site-packages/airflow/cli/commands/task_command.py", line 483, in task_run
    task_return_code = _run_task_by_selected_method(args, _dag, ti)
                       ^^^^^^^^^^^^^^^^^^^^^^^^^^^^^^^^^^^^^^^^^^^^
  File "/home/airflow/.local/lib/python3.12/site-packages/airflow/cli/commands/task_command.py", line 256, in _run_task_by_selected_method
    return _run_raw_task(args, ti)
           ^^^^^^^^^^^^^^^^^^^^^^^
  File "/home/airflow/.local/lib/python3.12/site-packages/airflow/cli/commands/task_command.py", line 341, in _run_raw_task
    return ti._run_raw_task(
           ^^^^^^^^^^^^^^^^^
  File "/home/airflow/.local/lib/python3.12/site-packages/airflow/utils/session.py", line 97, in wrapper
    return func(*args, session=session, **kwargs)
           ^^^^^^^^^^^^^^^^^^^^^^^^^^^^^^^^^^^^^^
  File "/home/airflow/.local/lib/python3.12/site-packages/airflow/models/taskinstance.py", line 3006, in _run_raw_task
    return _run_raw_task(
           ^^^^^^^^^^^^^^
  File "/home/airflow/.local/lib/python3.12/site-packages/airflow/models/taskinstance.py", line 274, in _run_raw_task
    TaskInstance._execute_task_with_callbacks(
  File "/home/airflow/.local/lib/python3.12/site-packages/airflow/models/taskinstance.py", line 3161, in _execute_task_with_callbacks
    result = self._execute_task(context, task_orig)
             ^^^^^^^^^^^^^^^^^^^^^^^^^^^^^^^^^^^^^^
  File "/home/airflow/.local/lib/python3.12/site-packages/airflow/models/taskinstance.py", line 3185, in _execute_task
    return _execute_task(self, context, task_orig)
           ^^^^^^^^^^^^^^^^^^^^^^^^^^^^^^^^^^^^^^^
  File "/home/airflow/.local/lib/python3.12/site-packages/airflow/models/taskinstance.py", line 768, in _execute_task
    result = _execute_callable(context=context, **execute_callable_kwargs)
             ^^^^^^^^^^^^^^^^^^^^^^^^^^^^^^^^^^^^^^^^^^^^^^^^^^^^^^^^^^^^^
  File "/home/airflow/.local/lib/python3.12/site-packages/airflow/models/taskinstance.py", line 734, in _execute_callable
    return ExecutionCallableRunner(
           ^^^^^^^^^^^^^^^^^^^^^^^^
  File "/home/airflow/.local/lib/python3.12/site-packages/airflow/utils/operator_helpers.py", line 252, in run
    return self.func(*args, **kwargs)
           ^^^^^^^^^^^^^^^^^^^^^^^^^^
  File "/home/airflow/.local/lib/python3.12/site-packages/airflow/models/baseoperator.py", line 424, in wrapper
    return func(self, *args, **kwargs)
           ^^^^^^^^^^^^^^^^^^^^^^^^^^^
  File "/home/airflow/.local/lib/python3.12/site-packages/airflow/operators/python.py", line 238, in execute
    return_value = self.execute_callable()
                   ^^^^^^^^^^^^^^^^^^^^^^^
  File "/home/airflow/.local/lib/python3.12/site-packages/airflow/operators/python.py", line 256, in execute_callable
    return runner.run(*self.op_args, **self.op_kwargs)
           ^^^^^^^^^^^^^^^^^^^^^^^^^^^^^^^^^^^^^^^^^^^
  File "/home/airflow/.local/lib/python3.12/site-packages/airflow/utils/operator_helpers.py", line 252, in run
    return self.func(*args, **kwargs)
           ^^^^^^^^^^^^^^^^^^^^^^^^^^
  File "/opt/airflow/dags/ETL/BinanceETL.py", line 28, in connect_to_db
    pg_hook.run(sqlQuery)
  File "/home/airflow/.local/lib/python3.12/site-packages/airflow/providers/common/sql/hooks/sql.py", line 467, in run
    self._run_command(cur, sql_statement, parameters)
  File "/home/airflow/.local/lib/python3.12/site-packages/airflow/providers/common/sql/hooks/sql.py", line 516, in _run_command
    cur.execute(sql_statement)
psycopg2.errors.UndefinedTable: relation "cryptoinfo" does not exist
LINE 1: SELECT * FROM cryptoInfo
                      ^

[2025-04-16T20:01:33.661+0000] {local_task_job_runner.py:266} INFO - Task exited with return code 1
[2025-04-16T20:01:33.922+0000] {taskinstance.py:3901} INFO - 0 downstream tasks scheduled from follow-on schedule check
[2025-04-16T20:01:33.928+0000] {local_task_job_runner.py:245} INFO - ::endgroup::
