[2025-04-23T20:20:15.281+0000] {processor.py:186} INFO - Started process (PID=560) to work on /opt/airflow/dags/ML/ML1.py
[2025-04-23T20:20:15.283+0000] {processor.py:914} INFO - Processing file /opt/airflow/dags/ML/ML1.py for tasks to queue
[2025-04-23T20:20:15.286+0000] {logging_mixin.py:190} INFO - [2025-04-23T20:20:15.286+0000] {dagbag.py:588} INFO - Filling up the DagBag from /opt/airflow/dags/ML/ML1.py
[2025-04-23T20:20:15.860+0000] {processor.py:925} INFO - DAG(s) 'YourDagNameHere' retrieved from /opt/airflow/dags/ML/ML1.py
[2025-04-23T20:20:16.301+0000] {logging_mixin.py:190} INFO - [2025-04-23T20:20:16.300+0000] {override.py:1820} ERROR - Add View Menu Error: (psycopg2.errors.UniqueViolation) duplicate key value violates unique constraint "serialized_dag_pkey"
DETAIL:  Key (dag_id)=(YourDagNameHere) already exists.

[SQL: INSERT INTO serialized_dag (dag_id, fileloc, fileloc_hash, data, data_compressed, last_updated, dag_hash, processor_subdir) VALUES (%(dag_id)s, %(fileloc)s, %(fileloc_hash)s, %(data)s, %(data_compressed)s, %(last_updated)s, %(dag_hash)s, %(processor_subdir)s)]
[parameters: {'dag_id': 'YourDagNameHere', 'fileloc': '/opt/airflow/dags/ML/ML1.py', 'fileloc_hash': 44895232645584036, 'data': '{"__version": 1, "dag": {"edge_info": {}, "timezone": "UTC", "_task_group": {"_group_id": null, "prefix_group_id": true, "tooltip": "", "ui_color": " ... (302 characters truncated) ... folio"], "fileloc": "/opt/airflow/dags/ML/ML1.py", "_processor_dags_folder": "/opt/airflow/dags", "tasks": [], "dag_dependencies": [], "params": []}}', 'data_compressed': None, 'last_updated': datetime.datetime(2025, 4, 23, 20, 20, 15, 900001, tzinfo=Timezone('UTC')), 'dag_hash': '55f740fc724807b6879e9e33e9e39dd9', 'processor_subdir': '/opt/airflow/dags'}]
(Background on this error at: https://sqlalche.me/e/14/gkpj)
[2025-04-23T20:20:16.399+0000] {logging_mixin.py:190} INFO - [2025-04-23T20:20:16.398+0000] {override.py:1912} INFO - Created Permission View: can read on None
[2025-04-23T20:20:16.436+0000] {logging_mixin.py:190} INFO - [2025-04-23T20:20:16.436+0000] {override.py:1915} ERROR - Creation of Permission View Error: (psycopg2.errors.UniqueViolation) duplicate key value violates unique constraint "ab_permission_view_permission_id_view_menu_id_uq"
DETAIL:  Key (permission_id, view_menu_id)=(4, 76) already exists.

[SQL: INSERT INTO ab_permission_view (permission_id, view_menu_id) VALUES (%(permission_id)s, %(view_menu_id)s) RETURNING ab_permission_view.id]
[parameters: {'permission_id': 4, 'view_menu_id': 76}]
(Background on this error at: https://sqlalche.me/e/14/gkpj)
[2025-04-23T20:20:16.444+0000] {logging_mixin.py:190} INFO - [2025-04-23T20:20:16.443+0000] {override.py:1915} ERROR - Creation of Permission View Error: (psycopg2.errors.UniqueViolation) duplicate key value violates unique constraint "ab_permission_view_permission_id_view_menu_id_uq"
DETAIL:  Key (permission_id, view_menu_id)=(1, 76) already exists.

[SQL: INSERT INTO ab_permission_view (permission_id, view_menu_id) VALUES (%(permission_id)s, %(view_menu_id)s) RETURNING ab_permission_view.id]
[parameters: {'permission_id': 1, 'view_menu_id': 76}]
(Background on this error at: https://sqlalche.me/e/14/gkpj)
[2025-04-23T20:20:16.449+0000] {logging_mixin.py:190} INFO - [2025-04-23T20:20:16.449+0000] {override.py:1820} ERROR - Add View Menu Error: (psycopg2.errors.UniqueViolation) duplicate key value violates unique constraint "ab_view_menu_name_uq"
DETAIL:  Key (name)=(DAG Run:YourDagNameHere) already exists.

[SQL: INSERT INTO ab_view_menu (name) VALUES (%(name)s) RETURNING ab_view_menu.id]
[parameters: {'name': 'DAG Run:YourDagNameHere'}]
(Background on this error at: https://sqlalche.me/e/14/gkpj)
[2025-04-23T20:20:16.454+0000] {logging_mixin.py:190} INFO - [2025-04-23T20:20:16.453+0000] {override.py:1912} INFO - Created Permission View: can read on None
[2025-04-23T20:20:16.460+0000] {logging_mixin.py:190} INFO - [2025-04-23T20:20:16.460+0000] {override.py:1915} ERROR - Creation of Permission View Error: (psycopg2.errors.UniqueViolation) duplicate key value violates unique constraint "ab_permission_view_permission_id_view_menu_id_uq"
DETAIL:  Key (permission_id, view_menu_id)=(4, 77) already exists.

[SQL: INSERT INTO ab_permission_view (permission_id, view_menu_id) VALUES (%(permission_id)s, %(view_menu_id)s) RETURNING ab_permission_view.id]
[parameters: {'permission_id': 4, 'view_menu_id': 77}]
(Background on this error at: https://sqlalche.me/e/14/gkpj)
[2025-04-23T20:20:16.471+0000] {logging_mixin.py:190} INFO - [2025-04-23T20:20:16.471+0000] {override.py:1915} ERROR - Creation of Permission View Error: (psycopg2.errors.UniqueViolation) duplicate key value violates unique constraint "ab_permission_view_permission_id_view_menu_id_uq"
DETAIL:  Key (permission_id, view_menu_id)=(5, 77) already exists.

[SQL: INSERT INTO ab_permission_view (permission_id, view_menu_id) VALUES (%(permission_id)s, %(view_menu_id)s) RETURNING ab_permission_view.id]
[parameters: {'permission_id': 5, 'view_menu_id': 77}]
(Background on this error at: https://sqlalche.me/e/14/gkpj)
[2025-04-23T20:20:16.481+0000] {logging_mixin.py:190} INFO - [2025-04-23T20:20:16.481+0000] {override.py:1915} ERROR - Creation of Permission View Error: (psycopg2.errors.UniqueViolation) duplicate key value violates unique constraint "ab_permission_view_permission_id_view_menu_id_uq"
DETAIL:  Key (permission_id, view_menu_id)=(3, 77) already exists.

[SQL: INSERT INTO ab_permission_view (permission_id, view_menu_id) VALUES (%(permission_id)s, %(view_menu_id)s) RETURNING ab_permission_view.id]
[parameters: {'permission_id': 3, 'view_menu_id': 77}]
(Background on this error at: https://sqlalche.me/e/14/gkpj)
[2025-04-23T20:20:16.483+0000] {logging_mixin.py:190} INFO - [2025-04-23T20:20:16.482+0000] {dag.py:3239} INFO - Sync 1 DAGs
[2025-04-23T20:20:16.523+0000] {logging_mixin.py:190} INFO - [2025-04-23T20:20:16.522+0000] {dag.py:3262} INFO - Creating ORM DAG for YourDagNameHere
[2025-04-23T20:20:16.524+0000] {logging_mixin.py:190} INFO - [2025-04-23T20:20:16.524+0000] {dag.py:4180} INFO - Setting next_dagrun for YourDagNameHere to None, run_after=None
[2025-04-23T20:20:17.071+0000] {logging_mixin.py:190} INFO - [2025-04-23T20:20:17.062+0000] {dagbag.py:698} ERROR - Failed to write serialized DAG: /opt/airflow/dags/ML/ML1.py
Traceback (most recent call last):
  File "/home/airflow/.local/lib/python3.12/site-packages/airflow/models/dagbag.py", line 686, in _serialize_dag_capturing_errors
    dag_was_updated = SerializedDagModel.write_dag(
                      ^^^^^^^^^^^^^^^^^^^^^^^^^^^^^
  File "/home/airflow/.local/lib/python3.12/site-packages/airflow/utils/session.py", line 94, in wrapper
    return func(*args, **kwargs)
           ^^^^^^^^^^^^^^^^^^^^^
  File "/home/airflow/.local/lib/python3.12/site-packages/airflow/models/serialized_dag.py", line 160, in write_dag
    if session.scalar(
       ^^^^^^^^^^^^^^^
  File "/home/airflow/.local/lib/python3.12/site-packages/sqlalchemy/orm/session.py", line 1747, in scalar
    return self.execute(
           ^^^^^^^^^^^^^
  File "/home/airflow/.local/lib/python3.12/site-packages/sqlalchemy/orm/session.py", line 1716, in execute
    conn = self._connection_for_bind(bind)
           ^^^^^^^^^^^^^^^^^^^^^^^^^^^^^^^
  File "/home/airflow/.local/lib/python3.12/site-packages/sqlalchemy/orm/session.py", line 1555, in _connection_for_bind
    return self._transaction._connection_for_bind(
           ^^^^^^^^^^^^^^^^^^^^^^^^^^^^^^^^^^^^^^^
  File "/home/airflow/.local/lib/python3.12/site-packages/sqlalchemy/orm/session.py", line 724, in _connection_for_bind
    self._assert_active()
  File "/home/airflow/.local/lib/python3.12/site-packages/sqlalchemy/orm/session.py", line 604, in _assert_active
    raise sa_exc.PendingRollbackError(
sqlalchemy.exc.PendingRollbackError: This Session's transaction has been rolled back due to a previous exception during flush. To begin a new transaction with this Session, first issue Session.rollback(). Original exception was: (psycopg2.errors.UniqueViolation) duplicate key value violates unique constraint "dag_pkey"
DETAIL:  Key (dag_id)=(YourDagNameHere) already exists.

[SQL: INSERT INTO dag (dag_id, root_dag_id, is_paused, is_subdag, is_active, last_parsed_time, last_pickled, last_expired, scheduler_lock, pickle_id, fileloc, processor_subdir, owners, dag_display_name, description, default_view, schedule_interval, timetable_description, dataset_expression, max_active_tasks, max_active_runs, max_consecutive_failed_dag_runs, has_task_concurrency_limits, has_import_errors, next_dagrun, next_dagrun_data_interval_start, next_dagrun_data_interval_end, next_dagrun_create_after) VALUES (%(dag_id)s, %(root_dag_id)s, %(is_paused)s, %(is_subdag)s, %(is_active)s, %(last_parsed_time)s, %(last_pickled)s, %(last_expired)s, %(scheduler_lock)s, %(pickle_id)s, %(fileloc)s, %(processor_subdir)s, %(owners)s, %(dag_display_name)s, %(description)s, %(default_view)s, %(schedule_interval)s, %(timetable_description)s, %(dataset_expression)s, %(max_active_tasks)s, %(max_active_runs)s, %(max_consecutive_failed_dag_runs)s, %(has_task_concurrency_limits)s, %(has_import_errors)s, %(next_dagrun)s, %(next_dagrun_data_interval_start)s, %(next_dagrun_data_interval_end)s, %(next_dagrun_create_after)s)]
[parameters: {'dag_id': 'YourDagNameHere', 'root_dag_id': None, 'is_paused': True, 'is_subdag': False, 'is_active': True, 'last_parsed_time': datetime.datetime(2025, 4, 23, 20, 20, 16, 524055, tzinfo=Timezone('UTC')), 'last_pickled': None, 'last_expired': None, 'scheduler_lock': None, 'pickle_id': None, 'fileloc': '/opt/airflow/dags/ML/ML1.py', 'processor_subdir': '/opt/airflow/dags', 'owners': '', 'dag_display_name': None, 'description': None, 'default_view': 'grid', 'schedule_interval': 'null', 'timetable_description': 'Never, external triggers only', 'dataset_expression': 'null', 'max_active_tasks': 16, 'max_active_runs': 16, 'max_consecutive_failed_dag_runs': 0, 'has_task_concurrency_limits': False, 'has_import_errors': False, 'next_dagrun': None, 'next_dagrun_data_interval_start': None, 'next_dagrun_data_interval_end': None, 'next_dagrun_create_after': None}]
(Background on this error at: https://sqlalche.me/e/14/gkpj) (Background on this error at: https://sqlalche.me/e/14/7s2a)
[2025-04-23T20:20:17.073+0000] {logging_mixin.py:190} INFO - [2025-04-23T20:20:17.073+0000] {dag.py:3239} INFO - Sync 1 DAGs
[2025-04-23T20:20:17.074+0000] {processor.py:211} ERROR - Got an exception! Propagating...
Traceback (most recent call last):
  File "/home/airflow/.local/lib/python3.12/site-packages/airflow/dag_processing/processor.py", line 207, in _run_file_processor
    _handle_dag_file_processing()
  File "/home/airflow/.local/lib/python3.12/site-packages/airflow/dag_processing/processor.py", line 188, in _handle_dag_file_processing
    result: tuple[int, int, int] = dag_file_processor.process_file(
                                   ^^^^^^^^^^^^^^^^^^^^^^^^^^^^^^^^
  File "/home/airflow/.local/lib/python3.12/site-packages/airflow/utils/session.py", line 97, in wrapper
    return func(*args, session=session, **kwargs)
           ^^^^^^^^^^^^^^^^^^^^^^^^^^^^^^^^^^^^^^
  File "/home/airflow/.local/lib/python3.12/site-packages/airflow/dag_processing/processor.py", line 942, in process_file
    serialize_errors = DagFileProcessor.save_dag_to_db(
                       ^^^^^^^^^^^^^^^^^^^^^^^^^^^^^^^^
  File "/home/airflow/.local/lib/python3.12/site-packages/airflow/api_internal/internal_api_call.py", line 166, in wrapper
    return func(*args, **kwargs)
           ^^^^^^^^^^^^^^^^^^^^^
  File "/home/airflow/.local/lib/python3.12/site-packages/airflow/utils/session.py", line 97, in wrapper
    return func(*args, session=session, **kwargs)
           ^^^^^^^^^^^^^^^^^^^^^^^^^^^^^^^^^^^^^^
  File "/home/airflow/.local/lib/python3.12/site-packages/airflow/dag_processing/processor.py", line 982, in save_dag_to_db
    import_errors = DagBag._sync_to_db(dags=dags, processor_subdir=dag_directory, session=session)
                    ^^^^^^^^^^^^^^^^^^^^^^^^^^^^^^^^^^^^^^^^^^^^^^^^^^^^^^^^^^^^^^^^^^^^^^^^^^^^^^
  File "/home/airflow/.local/lib/python3.12/site-packages/airflow/utils/session.py", line 94, in wrapper
    return func(*args, **kwargs)
           ^^^^^^^^^^^^^^^^^^^^^
  File "/home/airflow/.local/lib/python3.12/site-packages/airflow/models/dagbag.py", line 708, in _sync_to_db
    for attempt in run_with_db_retries(logger=log):
                   ^^^^^^^^^^^^^^^^^^^^^^^^^^^^^^^
  File "/home/airflow/.local/lib/python3.12/site-packages/tenacity/__init__.py", line 443, in __iter__
    do = self.iter(retry_state=retry_state)
         ^^^^^^^^^^^^^^^^^^^^^^^^^^^^^^^^^^
  File "/home/airflow/.local/lib/python3.12/site-packages/tenacity/__init__.py", line 376, in iter
    result = action(retry_state)
             ^^^^^^^^^^^^^^^^^^^
  File "/home/airflow/.local/lib/python3.12/site-packages/tenacity/__init__.py", line 398, in <lambda>
    self._add_action_func(lambda rs: rs.outcome.result())
                                     ^^^^^^^^^^^^^^^^^^^
  File "/usr/local/lib/python3.12/concurrent/futures/_base.py", line 449, in result
    return self.__get_result()
           ^^^^^^^^^^^^^^^^^^^
  File "/usr/local/lib/python3.12/concurrent/futures/_base.py", line 401, in __get_result
    raise self._exception
  File "/home/airflow/.local/lib/python3.12/site-packages/airflow/models/dagbag.py", line 724, in _sync_to_db
    DAG.bulk_write_to_db(dags.values(), processor_subdir=processor_subdir, session=session)
  File "/home/airflow/.local/lib/python3.12/site-packages/airflow/utils/session.py", line 94, in wrapper
    return func(*args, **kwargs)
           ^^^^^^^^^^^^^^^^^^^^^
  File "/home/airflow/.local/lib/python3.12/site-packages/airflow/models/dag.py", line 3252, in bulk_write_to_db
    orm_dags: list[DagModel] = session.scalars(query).unique().all()
                               ^^^^^^^^^^^^^^^^^^^^^^
  File "/home/airflow/.local/lib/python3.12/site-packages/sqlalchemy/orm/session.py", line 1778, in scalars
    return self.execute(
           ^^^^^^^^^^^^^
  File "/home/airflow/.local/lib/python3.12/site-packages/sqlalchemy/orm/session.py", line 1716, in execute
    conn = self._connection_for_bind(bind)
           ^^^^^^^^^^^^^^^^^^^^^^^^^^^^^^^
  File "/home/airflow/.local/lib/python3.12/site-packages/sqlalchemy/orm/session.py", line 1555, in _connection_for_bind
    return self._transaction._connection_for_bind(
           ^^^^^^^^^^^^^^^^^^^^^^^^^^^^^^^^^^^^^^^
  File "/home/airflow/.local/lib/python3.12/site-packages/sqlalchemy/orm/session.py", line 724, in _connection_for_bind
    self._assert_active()
  File "/home/airflow/.local/lib/python3.12/site-packages/sqlalchemy/orm/session.py", line 604, in _assert_active
    raise sa_exc.PendingRollbackError(
sqlalchemy.exc.PendingRollbackError: This Session's transaction has been rolled back due to a previous exception during flush. To begin a new transaction with this Session, first issue Session.rollback(). Original exception was: (psycopg2.errors.UniqueViolation) duplicate key value violates unique constraint "dag_pkey"
DETAIL:  Key (dag_id)=(YourDagNameHere) already exists.

[SQL: INSERT INTO dag (dag_id, root_dag_id, is_paused, is_subdag, is_active, last_parsed_time, last_pickled, last_expired, scheduler_lock, pickle_id, fileloc, processor_subdir, owners, dag_display_name, description, default_view, schedule_interval, timetable_description, dataset_expression, max_active_tasks, max_active_runs, max_consecutive_failed_dag_runs, has_task_concurrency_limits, has_import_errors, next_dagrun, next_dagrun_data_interval_start, next_dagrun_data_interval_end, next_dagrun_create_after) VALUES (%(dag_id)s, %(root_dag_id)s, %(is_paused)s, %(is_subdag)s, %(is_active)s, %(last_parsed_time)s, %(last_pickled)s, %(last_expired)s, %(scheduler_lock)s, %(pickle_id)s, %(fileloc)s, %(processor_subdir)s, %(owners)s, %(dag_display_name)s, %(description)s, %(default_view)s, %(schedule_interval)s, %(timetable_description)s, %(dataset_expression)s, %(max_active_tasks)s, %(max_active_runs)s, %(max_consecutive_failed_dag_runs)s, %(has_task_concurrency_limits)s, %(has_import_errors)s, %(next_dagrun)s, %(next_dagrun_data_interval_start)s, %(next_dagrun_data_interval_end)s, %(next_dagrun_create_after)s)]
[parameters: {'dag_id': 'YourDagNameHere', 'root_dag_id': None, 'is_paused': True, 'is_subdag': False, 'is_active': True, 'last_parsed_time': datetime.datetime(2025, 4, 23, 20, 20, 16, 524055, tzinfo=Timezone('UTC')), 'last_pickled': None, 'last_expired': None, 'scheduler_lock': None, 'pickle_id': None, 'fileloc': '/opt/airflow/dags/ML/ML1.py', 'processor_subdir': '/opt/airflow/dags', 'owners': '', 'dag_display_name': None, 'description': None, 'default_view': 'grid', 'schedule_interval': 'null', 'timetable_description': 'Never, external triggers only', 'dataset_expression': 'null', 'max_active_tasks': 16, 'max_active_runs': 16, 'max_consecutive_failed_dag_runs': 0, 'has_task_concurrency_limits': False, 'has_import_errors': False, 'next_dagrun': None, 'next_dagrun_data_interval_start': None, 'next_dagrun_data_interval_end': None, 'next_dagrun_create_after': None}]
(Background on this error at: https://sqlalche.me/e/14/gkpj) (Background on this error at: https://sqlalche.me/e/14/7s2a)
[2025-04-23T20:20:47.361+0000] {processor.py:186} INFO - Started process (PID=589) to work on /opt/airflow/dags/ML/ML1.py
[2025-04-23T20:20:47.364+0000] {processor.py:914} INFO - Processing file /opt/airflow/dags/ML/ML1.py for tasks to queue
[2025-04-23T20:20:47.368+0000] {logging_mixin.py:190} INFO - [2025-04-23T20:20:47.368+0000] {dagbag.py:588} INFO - Filling up the DagBag from /opt/airflow/dags/ML/ML1.py
[2025-04-23T20:20:47.877+0000] {processor.py:925} INFO - DAG(s) 'YourDagNameHere' retrieved from /opt/airflow/dags/ML/ML1.py
[2025-04-23T20:20:48.010+0000] {logging_mixin.py:190} INFO - [2025-04-23T20:20:48.010+0000] {dag.py:3239} INFO - Sync 1 DAGs
[2025-04-23T20:20:48.042+0000] {logging_mixin.py:190} INFO - [2025-04-23T20:20:48.041+0000] {dag.py:4180} INFO - Setting next_dagrun for YourDagNameHere to None, run_after=None
[2025-04-23T20:20:48.106+0000] {processor.py:208} INFO - Processing /opt/airflow/dags/ML/ML1.py took 0.752 seconds
[2025-04-23T20:21:10.691+0000] {processor.py:186} INFO - Started process (PID=604) to work on /opt/airflow/dags/ML/ML1.py
[2025-04-23T20:21:10.692+0000] {processor.py:914} INFO - Processing file /opt/airflow/dags/ML/ML1.py for tasks to queue
[2025-04-23T20:21:10.694+0000] {logging_mixin.py:190} INFO - [2025-04-23T20:21:10.694+0000] {dagbag.py:588} INFO - Filling up the DagBag from /opt/airflow/dags/ML/ML1.py
[2025-04-23T20:21:11.175+0000] {logging_mixin.py:190} INFO - [2025-04-23T20:21:11.162+0000] {dagbag.py:387} ERROR - Failed to import: /opt/airflow/dags/ML/ML1.py
Traceback (most recent call last):
  File "/home/airflow/.local/lib/python3.12/site-packages/airflow/models/dagbag.py", line 383, in parse
    loader.exec_module(new_module)
  File "<frozen importlib._bootstrap_external>", line 999, in exec_module
  File "<frozen importlib._bootstrap>", line 488, in _call_with_frames_removed
  File "/opt/airflow/dags/ML/ML1.py", line 17, in <module>
    with DAG(
         ^^^^
  File "/home/airflow/.local/lib/python3.12/site-packages/airflow/models/dag.py", line 593, in __init__
    validate_key(dag_id)
  File "/home/airflow/.local/lib/python3.12/site-packages/airflow/utils/helpers.py", line 57, in validate_key
    raise AirflowException(
airflow.exceptions.AirflowException: The key 'ML 1' has to be made of alphanumeric characters, dashes, dots and underscores exclusively
[2025-04-23T20:21:11.176+0000] {processor.py:927} WARNING - No viable dags retrieved from /opt/airflow/dags/ML/ML1.py
[2025-04-23T20:21:11.266+0000] {processor.py:208} INFO - Processing /opt/airflow/dags/ML/ML1.py took 0.581 seconds
[2025-04-23T20:21:42.319+0000] {processor.py:186} INFO - Started process (PID=633) to work on /opt/airflow/dags/ML/ML1.py
[2025-04-23T20:21:42.320+0000] {processor.py:914} INFO - Processing file /opt/airflow/dags/ML/ML1.py for tasks to queue
[2025-04-23T20:21:42.324+0000] {logging_mixin.py:190} INFO - [2025-04-23T20:21:42.323+0000] {dagbag.py:588} INFO - Filling up the DagBag from /opt/airflow/dags/ML/ML1.py
[2025-04-23T20:21:42.805+0000] {logging_mixin.py:190} INFO - [2025-04-23T20:21:42.795+0000] {dagbag.py:387} ERROR - Failed to import: /opt/airflow/dags/ML/ML1.py
Traceback (most recent call last):
  File "/home/airflow/.local/lib/python3.12/site-packages/airflow/models/dagbag.py", line 383, in parse
    loader.exec_module(new_module)
  File "<frozen importlib._bootstrap_external>", line 999, in exec_module
  File "<frozen importlib._bootstrap>", line 488, in _call_with_frames_removed
  File "/opt/airflow/dags/ML/ML1.py", line 17, in <module>
    with DAG(
         ^^^^
  File "/home/airflow/.local/lib/python3.12/site-packages/airflow/models/dag.py", line 593, in __init__
    validate_key(dag_id)
  File "/home/airflow/.local/lib/python3.12/site-packages/airflow/utils/helpers.py", line 57, in validate_key
    raise AirflowException(
airflow.exceptions.AirflowException: The key 'ML 1' has to be made of alphanumeric characters, dashes, dots and underscores exclusively
[2025-04-23T20:21:42.807+0000] {processor.py:927} WARNING - No viable dags retrieved from /opt/airflow/dags/ML/ML1.py
[2025-04-23T20:21:42.893+0000] {processor.py:208} INFO - Processing /opt/airflow/dags/ML/ML1.py took 0.583 seconds
[2025-04-23T20:22:13.734+0000] {processor.py:186} INFO - Started process (PID=662) to work on /opt/airflow/dags/ML/ML1.py
[2025-04-23T20:22:13.735+0000] {processor.py:914} INFO - Processing file /opt/airflow/dags/ML/ML1.py for tasks to queue
[2025-04-23T20:22:13.739+0000] {logging_mixin.py:190} INFO - [2025-04-23T20:22:13.738+0000] {dagbag.py:588} INFO - Filling up the DagBag from /opt/airflow/dags/ML/ML1.py
[2025-04-23T20:22:14.167+0000] {logging_mixin.py:190} INFO - [2025-04-23T20:22:14.156+0000] {dagbag.py:387} ERROR - Failed to import: /opt/airflow/dags/ML/ML1.py
Traceback (most recent call last):
  File "/home/airflow/.local/lib/python3.12/site-packages/airflow/models/dagbag.py", line 383, in parse
    loader.exec_module(new_module)
  File "<frozen importlib._bootstrap_external>", line 999, in exec_module
  File "<frozen importlib._bootstrap>", line 488, in _call_with_frames_removed
  File "/opt/airflow/dags/ML/ML1.py", line 17, in <module>
    with DAG(
         ^^^^
  File "/home/airflow/.local/lib/python3.12/site-packages/airflow/models/dag.py", line 593, in __init__
    validate_key(dag_id)
  File "/home/airflow/.local/lib/python3.12/site-packages/airflow/utils/helpers.py", line 57, in validate_key
    raise AirflowException(
airflow.exceptions.AirflowException: The key 'ML 1' has to be made of alphanumeric characters, dashes, dots and underscores exclusively
[2025-04-23T20:22:14.168+0000] {processor.py:927} WARNING - No viable dags retrieved from /opt/airflow/dags/ML/ML1.py
[2025-04-23T20:22:14.230+0000] {processor.py:208} INFO - Processing /opt/airflow/dags/ML/ML1.py took 0.501 seconds
[2025-04-23T20:22:44.598+0000] {processor.py:186} INFO - Started process (PID=691) to work on /opt/airflow/dags/ML/ML1.py
[2025-04-23T20:22:44.600+0000] {processor.py:914} INFO - Processing file /opt/airflow/dags/ML/ML1.py for tasks to queue
[2025-04-23T20:22:44.602+0000] {logging_mixin.py:190} INFO - [2025-04-23T20:22:44.602+0000] {dagbag.py:588} INFO - Filling up the DagBag from /opt/airflow/dags/ML/ML1.py
[2025-04-23T20:22:45.073+0000] {logging_mixin.py:190} INFO - [2025-04-23T20:22:45.064+0000] {dagbag.py:387} ERROR - Failed to import: /opt/airflow/dags/ML/ML1.py
Traceback (most recent call last):
  File "/home/airflow/.local/lib/python3.12/site-packages/airflow/models/dagbag.py", line 383, in parse
    loader.exec_module(new_module)
  File "<frozen importlib._bootstrap_external>", line 999, in exec_module
  File "<frozen importlib._bootstrap>", line 488, in _call_with_frames_removed
  File "/opt/airflow/dags/ML/ML1.py", line 17, in <module>
    with DAG(
         ^^^^
  File "/home/airflow/.local/lib/python3.12/site-packages/airflow/models/dag.py", line 593, in __init__
    validate_key(dag_id)
  File "/home/airflow/.local/lib/python3.12/site-packages/airflow/utils/helpers.py", line 57, in validate_key
    raise AirflowException(
airflow.exceptions.AirflowException: The key 'ML 1' has to be made of alphanumeric characters, dashes, dots and underscores exclusively
[2025-04-23T20:22:45.074+0000] {processor.py:927} WARNING - No viable dags retrieved from /opt/airflow/dags/ML/ML1.py
[2025-04-23T20:22:45.154+0000] {processor.py:208} INFO - Processing /opt/airflow/dags/ML/ML1.py took 0.562 seconds
[2025-04-23T20:23:16.124+0000] {processor.py:186} INFO - Started process (PID=720) to work on /opt/airflow/dags/ML/ML1.py
[2025-04-23T20:23:16.125+0000] {processor.py:914} INFO - Processing file /opt/airflow/dags/ML/ML1.py for tasks to queue
[2025-04-23T20:23:16.127+0000] {logging_mixin.py:190} INFO - [2025-04-23T20:23:16.127+0000] {dagbag.py:588} INFO - Filling up the DagBag from /opt/airflow/dags/ML/ML1.py
[2025-04-23T20:23:16.594+0000] {logging_mixin.py:190} INFO - [2025-04-23T20:23:16.587+0000] {dagbag.py:387} ERROR - Failed to import: /opt/airflow/dags/ML/ML1.py
Traceback (most recent call last):
  File "/home/airflow/.local/lib/python3.12/site-packages/airflow/models/dagbag.py", line 383, in parse
    loader.exec_module(new_module)
  File "<frozen importlib._bootstrap_external>", line 999, in exec_module
  File "<frozen importlib._bootstrap>", line 488, in _call_with_frames_removed
  File "/opt/airflow/dags/ML/ML1.py", line 17, in <module>
    with DAG(
         ^^^^
  File "/home/airflow/.local/lib/python3.12/site-packages/airflow/models/dag.py", line 593, in __init__
    validate_key(dag_id)
  File "/home/airflow/.local/lib/python3.12/site-packages/airflow/utils/helpers.py", line 57, in validate_key
    raise AirflowException(
airflow.exceptions.AirflowException: The key 'ML 1' has to be made of alphanumeric characters, dashes, dots and underscores exclusively
[2025-04-23T20:23:16.595+0000] {processor.py:927} WARNING - No viable dags retrieved from /opt/airflow/dags/ML/ML1.py
[2025-04-23T20:23:16.663+0000] {processor.py:208} INFO - Processing /opt/airflow/dags/ML/ML1.py took 0.546 seconds
[2025-04-23T20:23:33.228+0000] {processor.py:186} INFO - Started process (PID=749) to work on /opt/airflow/dags/ML/ML1.py
[2025-04-23T20:23:33.229+0000] {processor.py:914} INFO - Processing file /opt/airflow/dags/ML/ML1.py for tasks to queue
[2025-04-23T20:23:33.231+0000] {logging_mixin.py:190} INFO - [2025-04-23T20:23:33.231+0000] {dagbag.py:588} INFO - Filling up the DagBag from /opt/airflow/dags/ML/ML1.py
[2025-04-23T20:23:33.673+0000] {logging_mixin.py:190} INFO - [2025-04-23T20:23:33.668+0000] {dagbag.py:387} ERROR - Failed to import: /opt/airflow/dags/ML/ML1.py
Traceback (most recent call last):
  File "/home/airflow/.local/lib/python3.12/site-packages/airflow/models/dagbag.py", line 383, in parse
    loader.exec_module(new_module)
  File "<frozen importlib._bootstrap_external>", line 999, in exec_module
  File "<frozen importlib._bootstrap>", line 488, in _call_with_frames_removed
  File "/opt/airflow/dags/ML/ML1.py", line 17, in <module>
    with DAG(
         ^^^^
  File "/home/airflow/.local/lib/python3.12/site-packages/airflow/models/dag.py", line 593, in __init__
    validate_key(dag_id)
  File "/home/airflow/.local/lib/python3.12/site-packages/airflow/utils/helpers.py", line 57, in validate_key
    raise AirflowException(
airflow.exceptions.AirflowException: The key 'ML 1' has to be made of alphanumeric characters, dashes, dots and underscores exclusively
[2025-04-23T20:23:33.674+0000] {processor.py:927} WARNING - No viable dags retrieved from /opt/airflow/dags/ML/ML1.py
[2025-04-23T20:23:33.728+0000] {processor.py:208} INFO - Processing /opt/airflow/dags/ML/ML1.py took 0.504 seconds
[2025-04-23T20:24:04.616+0000] {processor.py:186} INFO - Started process (PID=778) to work on /opt/airflow/dags/ML/ML1.py
[2025-04-23T20:24:04.618+0000] {processor.py:914} INFO - Processing file /opt/airflow/dags/ML/ML1.py for tasks to queue
[2025-04-23T20:24:04.620+0000] {logging_mixin.py:190} INFO - [2025-04-23T20:24:04.620+0000] {dagbag.py:588} INFO - Filling up the DagBag from /opt/airflow/dags/ML/ML1.py
[2025-04-23T20:24:05.161+0000] {logging_mixin.py:190} INFO - [2025-04-23T20:24:05.152+0000] {dagbag.py:387} ERROR - Failed to import: /opt/airflow/dags/ML/ML1.py
Traceback (most recent call last):
  File "/home/airflow/.local/lib/python3.12/site-packages/airflow/models/dagbag.py", line 383, in parse
    loader.exec_module(new_module)
  File "<frozen importlib._bootstrap_external>", line 999, in exec_module
  File "<frozen importlib._bootstrap>", line 488, in _call_with_frames_removed
  File "/opt/airflow/dags/ML/ML1.py", line 17, in <module>
    with DAG(
         ^^^^
  File "/home/airflow/.local/lib/python3.12/site-packages/airflow/models/dag.py", line 593, in __init__
    validate_key(dag_id)
  File "/home/airflow/.local/lib/python3.12/site-packages/airflow/utils/helpers.py", line 57, in validate_key
    raise AirflowException(
airflow.exceptions.AirflowException: The key 'ML 1' has to be made of alphanumeric characters, dashes, dots and underscores exclusively
[2025-04-23T20:24:05.162+0000] {processor.py:927} WARNING - No viable dags retrieved from /opt/airflow/dags/ML/ML1.py
[2025-04-23T20:24:05.260+0000] {processor.py:208} INFO - Processing /opt/airflow/dags/ML/ML1.py took 0.653 seconds
[2025-04-23T20:24:35.585+0000] {processor.py:186} INFO - Started process (PID=807) to work on /opt/airflow/dags/ML/ML1.py
[2025-04-23T20:24:35.590+0000] {processor.py:914} INFO - Processing file /opt/airflow/dags/ML/ML1.py for tasks to queue
[2025-04-23T20:24:35.593+0000] {logging_mixin.py:190} INFO - [2025-04-23T20:24:35.592+0000] {dagbag.py:588} INFO - Filling up the DagBag from /opt/airflow/dags/ML/ML1.py
[2025-04-23T20:24:36.046+0000] {logging_mixin.py:190} INFO - [2025-04-23T20:24:36.038+0000] {dagbag.py:387} ERROR - Failed to import: /opt/airflow/dags/ML/ML1.py
Traceback (most recent call last):
  File "/home/airflow/.local/lib/python3.12/site-packages/airflow/models/dagbag.py", line 383, in parse
    loader.exec_module(new_module)
  File "<frozen importlib._bootstrap_external>", line 999, in exec_module
  File "<frozen importlib._bootstrap>", line 488, in _call_with_frames_removed
  File "/opt/airflow/dags/ML/ML1.py", line 17, in <module>
    with DAG(
         ^^^^
  File "/home/airflow/.local/lib/python3.12/site-packages/airflow/models/dag.py", line 593, in __init__
    validate_key(dag_id)
  File "/home/airflow/.local/lib/python3.12/site-packages/airflow/utils/helpers.py", line 57, in validate_key
    raise AirflowException(
airflow.exceptions.AirflowException: The key 'ML 1' has to be made of alphanumeric characters, dashes, dots and underscores exclusively
[2025-04-23T20:24:36.047+0000] {processor.py:927} WARNING - No viable dags retrieved from /opt/airflow/dags/ML/ML1.py
[2025-04-23T20:24:36.135+0000] {processor.py:208} INFO - Processing /opt/airflow/dags/ML/ML1.py took 0.559 seconds
[2025-04-23T20:25:06.283+0000] {processor.py:186} INFO - Started process (PID=836) to work on /opt/airflow/dags/ML/ML1.py
[2025-04-23T20:25:06.284+0000] {processor.py:914} INFO - Processing file /opt/airflow/dags/ML/ML1.py for tasks to queue
[2025-04-23T20:25:06.287+0000] {logging_mixin.py:190} INFO - [2025-04-23T20:25:06.286+0000] {dagbag.py:588} INFO - Filling up the DagBag from /opt/airflow/dags/ML/ML1.py
[2025-04-23T20:25:06.903+0000] {logging_mixin.py:190} INFO - [2025-04-23T20:25:06.887+0000] {dagbag.py:387} ERROR - Failed to import: /opt/airflow/dags/ML/ML1.py
Traceback (most recent call last):
  File "/home/airflow/.local/lib/python3.12/site-packages/airflow/models/dagbag.py", line 383, in parse
    loader.exec_module(new_module)
  File "<frozen importlib._bootstrap_external>", line 999, in exec_module
  File "<frozen importlib._bootstrap>", line 488, in _call_with_frames_removed
  File "/opt/airflow/dags/ML/ML1.py", line 17, in <module>
    with DAG(
         ^^^^
  File "/home/airflow/.local/lib/python3.12/site-packages/airflow/models/dag.py", line 593, in __init__
    validate_key(dag_id)
  File "/home/airflow/.local/lib/python3.12/site-packages/airflow/utils/helpers.py", line 57, in validate_key
    raise AirflowException(
airflow.exceptions.AirflowException: The key 'ML 1' has to be made of alphanumeric characters, dashes, dots and underscores exclusively
[2025-04-23T20:25:06.905+0000] {processor.py:927} WARNING - No viable dags retrieved from /opt/airflow/dags/ML/ML1.py
[2025-04-23T20:25:06.994+0000] {processor.py:208} INFO - Processing /opt/airflow/dags/ML/ML1.py took 0.717 seconds
[2025-04-23T20:25:37.095+0000] {processor.py:186} INFO - Started process (PID=864) to work on /opt/airflow/dags/ML/ML1.py
[2025-04-23T20:25:37.097+0000] {processor.py:914} INFO - Processing file /opt/airflow/dags/ML/ML1.py for tasks to queue
[2025-04-23T20:25:37.099+0000] {logging_mixin.py:190} INFO - [2025-04-23T20:25:37.099+0000] {dagbag.py:588} INFO - Filling up the DagBag from /opt/airflow/dags/ML/ML1.py
[2025-04-23T20:25:37.486+0000] {logging_mixin.py:190} INFO - [2025-04-23T20:25:37.478+0000] {dagbag.py:387} ERROR - Failed to import: /opt/airflow/dags/ML/ML1.py
Traceback (most recent call last):
  File "/home/airflow/.local/lib/python3.12/site-packages/airflow/models/dagbag.py", line 383, in parse
    loader.exec_module(new_module)
  File "<frozen importlib._bootstrap_external>", line 999, in exec_module
  File "<frozen importlib._bootstrap>", line 488, in _call_with_frames_removed
  File "/opt/airflow/dags/ML/ML1.py", line 17, in <module>
    with DAG(
         ^^^^
  File "/home/airflow/.local/lib/python3.12/site-packages/airflow/models/dag.py", line 593, in __init__
    validate_key(dag_id)
  File "/home/airflow/.local/lib/python3.12/site-packages/airflow/utils/helpers.py", line 57, in validate_key
    raise AirflowException(
airflow.exceptions.AirflowException: The key 'ML 1' has to be made of alphanumeric characters, dashes, dots and underscores exclusively
[2025-04-23T20:25:37.487+0000] {processor.py:927} WARNING - No viable dags retrieved from /opt/airflow/dags/ML/ML1.py
[2025-04-23T20:25:37.557+0000] {processor.py:208} INFO - Processing /opt/airflow/dags/ML/ML1.py took 0.466 seconds
[2025-04-23T20:26:07.895+0000] {processor.py:186} INFO - Started process (PID=893) to work on /opt/airflow/dags/ML/ML1.py
[2025-04-23T20:26:07.899+0000] {processor.py:914} INFO - Processing file /opt/airflow/dags/ML/ML1.py for tasks to queue
[2025-04-23T20:26:07.905+0000] {logging_mixin.py:190} INFO - [2025-04-23T20:26:07.905+0000] {dagbag.py:588} INFO - Filling up the DagBag from /opt/airflow/dags/ML/ML1.py
[2025-04-23T20:26:08.314+0000] {logging_mixin.py:190} INFO - [2025-04-23T20:26:08.303+0000] {dagbag.py:387} ERROR - Failed to import: /opt/airflow/dags/ML/ML1.py
Traceback (most recent call last):
  File "/home/airflow/.local/lib/python3.12/site-packages/airflow/models/dagbag.py", line 383, in parse
    loader.exec_module(new_module)
  File "<frozen importlib._bootstrap_external>", line 999, in exec_module
  File "<frozen importlib._bootstrap>", line 488, in _call_with_frames_removed
  File "/opt/airflow/dags/ML/ML1.py", line 17, in <module>
    with DAG(
         ^^^^
  File "/home/airflow/.local/lib/python3.12/site-packages/airflow/models/dag.py", line 593, in __init__
    validate_key(dag_id)
  File "/home/airflow/.local/lib/python3.12/site-packages/airflow/utils/helpers.py", line 57, in validate_key
    raise AirflowException(
airflow.exceptions.AirflowException: The key 'ML 1' has to be made of alphanumeric characters, dashes, dots and underscores exclusively
[2025-04-23T20:26:08.315+0000] {processor.py:927} WARNING - No viable dags retrieved from /opt/airflow/dags/ML/ML1.py
[2025-04-23T20:26:08.407+0000] {processor.py:208} INFO - Processing /opt/airflow/dags/ML/ML1.py took 0.536 seconds
[2025-04-23T20:26:39.157+0000] {processor.py:186} INFO - Started process (PID=922) to work on /opt/airflow/dags/ML/ML1.py
[2025-04-23T20:26:39.159+0000] {processor.py:914} INFO - Processing file /opt/airflow/dags/ML/ML1.py for tasks to queue
[2025-04-23T20:26:39.164+0000] {logging_mixin.py:190} INFO - [2025-04-23T20:26:39.163+0000] {dagbag.py:588} INFO - Filling up the DagBag from /opt/airflow/dags/ML/ML1.py
[2025-04-23T20:26:39.532+0000] {logging_mixin.py:190} INFO - [2025-04-23T20:26:39.522+0000] {dagbag.py:387} ERROR - Failed to import: /opt/airflow/dags/ML/ML1.py
Traceback (most recent call last):
  File "/home/airflow/.local/lib/python3.12/site-packages/airflow/models/dagbag.py", line 383, in parse
    loader.exec_module(new_module)
  File "<frozen importlib._bootstrap_external>", line 999, in exec_module
  File "<frozen importlib._bootstrap>", line 488, in _call_with_frames_removed
  File "/opt/airflow/dags/ML/ML1.py", line 17, in <module>
    with DAG(
         ^^^^
  File "/home/airflow/.local/lib/python3.12/site-packages/airflow/models/dag.py", line 593, in __init__
    validate_key(dag_id)
  File "/home/airflow/.local/lib/python3.12/site-packages/airflow/utils/helpers.py", line 57, in validate_key
    raise AirflowException(
airflow.exceptions.AirflowException: The key 'ML 1' has to be made of alphanumeric characters, dashes, dots and underscores exclusively
[2025-04-23T20:26:39.533+0000] {processor.py:927} WARNING - No viable dags retrieved from /opt/airflow/dags/ML/ML1.py
[2025-04-23T20:26:39.607+0000] {processor.py:208} INFO - Processing /opt/airflow/dags/ML/ML1.py took 0.459 seconds
[2025-04-23T20:27:10.220+0000] {processor.py:186} INFO - Started process (PID=951) to work on /opt/airflow/dags/ML/ML1.py
[2025-04-23T20:27:10.222+0000] {processor.py:914} INFO - Processing file /opt/airflow/dags/ML/ML1.py for tasks to queue
[2025-04-23T20:27:10.224+0000] {logging_mixin.py:190} INFO - [2025-04-23T20:27:10.224+0000] {dagbag.py:588} INFO - Filling up the DagBag from /opt/airflow/dags/ML/ML1.py
[2025-04-23T20:27:10.541+0000] {logging_mixin.py:190} INFO - [2025-04-23T20:27:10.531+0000] {dagbag.py:387} ERROR - Failed to import: /opt/airflow/dags/ML/ML1.py
Traceback (most recent call last):
  File "/home/airflow/.local/lib/python3.12/site-packages/airflow/models/dagbag.py", line 383, in parse
    loader.exec_module(new_module)
  File "<frozen importlib._bootstrap_external>", line 999, in exec_module
  File "<frozen importlib._bootstrap>", line 488, in _call_with_frames_removed
  File "/opt/airflow/dags/ML/ML1.py", line 17, in <module>
    with DAG(
         ^^^^
  File "/home/airflow/.local/lib/python3.12/site-packages/airflow/models/dag.py", line 593, in __init__
    validate_key(dag_id)
  File "/home/airflow/.local/lib/python3.12/site-packages/airflow/utils/helpers.py", line 57, in validate_key
    raise AirflowException(
airflow.exceptions.AirflowException: The key 'ML 1' has to be made of alphanumeric characters, dashes, dots and underscores exclusively
[2025-04-23T20:27:10.542+0000] {processor.py:927} WARNING - No viable dags retrieved from /opt/airflow/dags/ML/ML1.py
[2025-04-23T20:27:10.606+0000] {processor.py:208} INFO - Processing /opt/airflow/dags/ML/ML1.py took 0.392 seconds
[2025-04-23T20:27:40.928+0000] {processor.py:186} INFO - Started process (PID=980) to work on /opt/airflow/dags/ML/ML1.py
[2025-04-23T20:27:40.929+0000] {processor.py:914} INFO - Processing file /opt/airflow/dags/ML/ML1.py for tasks to queue
[2025-04-23T20:27:40.931+0000] {logging_mixin.py:190} INFO - [2025-04-23T20:27:40.930+0000] {dagbag.py:588} INFO - Filling up the DagBag from /opt/airflow/dags/ML/ML1.py
[2025-04-23T20:27:41.201+0000] {logging_mixin.py:190} INFO - [2025-04-23T20:27:41.192+0000] {dagbag.py:387} ERROR - Failed to import: /opt/airflow/dags/ML/ML1.py
Traceback (most recent call last):
  File "/home/airflow/.local/lib/python3.12/site-packages/airflow/models/dagbag.py", line 383, in parse
    loader.exec_module(new_module)
  File "<frozen importlib._bootstrap_external>", line 999, in exec_module
  File "<frozen importlib._bootstrap>", line 488, in _call_with_frames_removed
  File "/opt/airflow/dags/ML/ML1.py", line 17, in <module>
    with DAG(
         ^^^^
  File "/home/airflow/.local/lib/python3.12/site-packages/airflow/models/dag.py", line 593, in __init__
    validate_key(dag_id)
  File "/home/airflow/.local/lib/python3.12/site-packages/airflow/utils/helpers.py", line 57, in validate_key
    raise AirflowException(
airflow.exceptions.AirflowException: The key 'ML 1' has to be made of alphanumeric characters, dashes, dots and underscores exclusively
[2025-04-23T20:27:41.202+0000] {processor.py:927} WARNING - No viable dags retrieved from /opt/airflow/dags/ML/ML1.py
[2025-04-23T20:27:41.272+0000] {processor.py:208} INFO - Processing /opt/airflow/dags/ML/ML1.py took 0.350 seconds
[2025-04-23T20:28:11.825+0000] {processor.py:186} INFO - Started process (PID=1009) to work on /opt/airflow/dags/ML/ML1.py
[2025-04-23T20:28:11.826+0000] {processor.py:914} INFO - Processing file /opt/airflow/dags/ML/ML1.py for tasks to queue
[2025-04-23T20:28:11.829+0000] {logging_mixin.py:190} INFO - [2025-04-23T20:28:11.829+0000] {dagbag.py:588} INFO - Filling up the DagBag from /opt/airflow/dags/ML/ML1.py
[2025-04-23T20:28:12.133+0000] {logging_mixin.py:190} INFO - [2025-04-23T20:28:12.125+0000] {dagbag.py:387} ERROR - Failed to import: /opt/airflow/dags/ML/ML1.py
Traceback (most recent call last):
  File "/home/airflow/.local/lib/python3.12/site-packages/airflow/models/dagbag.py", line 383, in parse
    loader.exec_module(new_module)
  File "<frozen importlib._bootstrap_external>", line 999, in exec_module
  File "<frozen importlib._bootstrap>", line 488, in _call_with_frames_removed
  File "/opt/airflow/dags/ML/ML1.py", line 17, in <module>
    with DAG(
         ^^^^
  File "/home/airflow/.local/lib/python3.12/site-packages/airflow/models/dag.py", line 593, in __init__
    validate_key(dag_id)
  File "/home/airflow/.local/lib/python3.12/site-packages/airflow/utils/helpers.py", line 57, in validate_key
    raise AirflowException(
airflow.exceptions.AirflowException: The key 'ML 1' has to be made of alphanumeric characters, dashes, dots and underscores exclusively
[2025-04-23T20:28:12.134+0000] {processor.py:927} WARNING - No viable dags retrieved from /opt/airflow/dags/ML/ML1.py
[2025-04-23T20:28:12.210+0000] {processor.py:208} INFO - Processing /opt/airflow/dags/ML/ML1.py took 0.395 seconds
[2025-04-23T20:28:42.638+0000] {processor.py:186} INFO - Started process (PID=1038) to work on /opt/airflow/dags/ML/ML1.py
[2025-04-23T20:28:42.640+0000] {processor.py:914} INFO - Processing file /opt/airflow/dags/ML/ML1.py for tasks to queue
[2025-04-23T20:28:42.643+0000] {logging_mixin.py:190} INFO - [2025-04-23T20:28:42.642+0000] {dagbag.py:588} INFO - Filling up the DagBag from /opt/airflow/dags/ML/ML1.py
[2025-04-23T20:28:43.011+0000] {logging_mixin.py:190} INFO - [2025-04-23T20:28:43.004+0000] {dagbag.py:387} ERROR - Failed to import: /opt/airflow/dags/ML/ML1.py
Traceback (most recent call last):
  File "/home/airflow/.local/lib/python3.12/site-packages/airflow/models/dagbag.py", line 383, in parse
    loader.exec_module(new_module)
  File "<frozen importlib._bootstrap_external>", line 999, in exec_module
  File "<frozen importlib._bootstrap>", line 488, in _call_with_frames_removed
  File "/opt/airflow/dags/ML/ML1.py", line 17, in <module>
    with DAG(
         ^^^^
  File "/home/airflow/.local/lib/python3.12/site-packages/airflow/models/dag.py", line 593, in __init__
    validate_key(dag_id)
  File "/home/airflow/.local/lib/python3.12/site-packages/airflow/utils/helpers.py", line 57, in validate_key
    raise AirflowException(
airflow.exceptions.AirflowException: The key 'ML 1' has to be made of alphanumeric characters, dashes, dots and underscores exclusively
[2025-04-23T20:28:43.012+0000] {processor.py:927} WARNING - No viable dags retrieved from /opt/airflow/dags/ML/ML1.py
[2025-04-23T20:28:43.109+0000] {processor.py:208} INFO - Processing /opt/airflow/dags/ML/ML1.py took 0.477 seconds
[2025-04-23T20:29:13.550+0000] {processor.py:186} INFO - Started process (PID=1067) to work on /opt/airflow/dags/ML/ML1.py
[2025-04-23T20:29:13.553+0000] {processor.py:914} INFO - Processing file /opt/airflow/dags/ML/ML1.py for tasks to queue
[2025-04-23T20:29:13.561+0000] {logging_mixin.py:190} INFO - [2025-04-23T20:29:13.560+0000] {dagbag.py:588} INFO - Filling up the DagBag from /opt/airflow/dags/ML/ML1.py
[2025-04-23T20:29:13.906+0000] {logging_mixin.py:190} INFO - [2025-04-23T20:29:13.893+0000] {dagbag.py:387} ERROR - Failed to import: /opt/airflow/dags/ML/ML1.py
Traceback (most recent call last):
  File "/home/airflow/.local/lib/python3.12/site-packages/airflow/models/dagbag.py", line 383, in parse
    loader.exec_module(new_module)
  File "<frozen importlib._bootstrap_external>", line 999, in exec_module
  File "<frozen importlib._bootstrap>", line 488, in _call_with_frames_removed
  File "/opt/airflow/dags/ML/ML1.py", line 17, in <module>
    with DAG(
         ^^^^
  File "/home/airflow/.local/lib/python3.12/site-packages/airflow/models/dag.py", line 593, in __init__
    validate_key(dag_id)
  File "/home/airflow/.local/lib/python3.12/site-packages/airflow/utils/helpers.py", line 57, in validate_key
    raise AirflowException(
airflow.exceptions.AirflowException: The key 'ML 1' has to be made of alphanumeric characters, dashes, dots and underscores exclusively
[2025-04-23T20:29:13.907+0000] {processor.py:927} WARNING - No viable dags retrieved from /opt/airflow/dags/ML/ML1.py
[2025-04-23T20:29:13.974+0000] {processor.py:208} INFO - Processing /opt/airflow/dags/ML/ML1.py took 0.441 seconds
[2025-04-23T20:29:44.238+0000] {processor.py:186} INFO - Started process (PID=1096) to work on /opt/airflow/dags/ML/ML1.py
[2025-04-23T20:29:44.240+0000] {processor.py:914} INFO - Processing file /opt/airflow/dags/ML/ML1.py for tasks to queue
[2025-04-23T20:29:44.242+0000] {logging_mixin.py:190} INFO - [2025-04-23T20:29:44.242+0000] {dagbag.py:588} INFO - Filling up the DagBag from /opt/airflow/dags/ML/ML1.py
[2025-04-23T20:29:44.523+0000] {logging_mixin.py:190} INFO - [2025-04-23T20:29:44.515+0000] {dagbag.py:387} ERROR - Failed to import: /opt/airflow/dags/ML/ML1.py
Traceback (most recent call last):
  File "/home/airflow/.local/lib/python3.12/site-packages/airflow/models/dagbag.py", line 383, in parse
    loader.exec_module(new_module)
  File "<frozen importlib._bootstrap_external>", line 999, in exec_module
  File "<frozen importlib._bootstrap>", line 488, in _call_with_frames_removed
  File "/opt/airflow/dags/ML/ML1.py", line 17, in <module>
    with DAG(
         ^^^^
  File "/home/airflow/.local/lib/python3.12/site-packages/airflow/models/dag.py", line 593, in __init__
    validate_key(dag_id)
  File "/home/airflow/.local/lib/python3.12/site-packages/airflow/utils/helpers.py", line 57, in validate_key
    raise AirflowException(
airflow.exceptions.AirflowException: The key 'ML 1' has to be made of alphanumeric characters, dashes, dots and underscores exclusively
[2025-04-23T20:29:44.524+0000] {processor.py:927} WARNING - No viable dags retrieved from /opt/airflow/dags/ML/ML1.py
[2025-04-23T20:29:44.625+0000] {processor.py:208} INFO - Processing /opt/airflow/dags/ML/ML1.py took 0.394 seconds
[2025-04-23T20:30:16.034+0000] {processor.py:186} INFO - Started process (PID=1125) to work on /opt/airflow/dags/ML/ML1.py
[2025-04-23T20:30:16.036+0000] {processor.py:914} INFO - Processing file /opt/airflow/dags/ML/ML1.py for tasks to queue
[2025-04-23T20:30:16.038+0000] {logging_mixin.py:190} INFO - [2025-04-23T20:30:16.037+0000] {dagbag.py:588} INFO - Filling up the DagBag from /opt/airflow/dags/ML/ML1.py
[2025-04-23T20:30:16.439+0000] {logging_mixin.py:190} INFO - [2025-04-23T20:30:16.431+0000] {dagbag.py:387} ERROR - Failed to import: /opt/airflow/dags/ML/ML1.py
Traceback (most recent call last):
  File "/home/airflow/.local/lib/python3.12/site-packages/airflow/models/dagbag.py", line 383, in parse
    loader.exec_module(new_module)
  File "<frozen importlib._bootstrap_external>", line 999, in exec_module
  File "<frozen importlib._bootstrap>", line 488, in _call_with_frames_removed
  File "/opt/airflow/dags/ML/ML1.py", line 17, in <module>
    with DAG(
         ^^^^
  File "/home/airflow/.local/lib/python3.12/site-packages/airflow/models/dag.py", line 593, in __init__
    validate_key(dag_id)
  File "/home/airflow/.local/lib/python3.12/site-packages/airflow/utils/helpers.py", line 57, in validate_key
    raise AirflowException(
airflow.exceptions.AirflowException: The key 'ML 1' has to be made of alphanumeric characters, dashes, dots and underscores exclusively
[2025-04-23T20:30:16.440+0000] {processor.py:927} WARNING - No viable dags retrieved from /opt/airflow/dags/ML/ML1.py
[2025-04-23T20:30:16.504+0000] {processor.py:208} INFO - Processing /opt/airflow/dags/ML/ML1.py took 0.477 seconds
[2025-04-23T20:30:46.851+0000] {processor.py:186} INFO - Started process (PID=1153) to work on /opt/airflow/dags/ML/ML1.py
[2025-04-23T20:30:46.852+0000] {processor.py:914} INFO - Processing file /opt/airflow/dags/ML/ML1.py for tasks to queue
[2025-04-23T20:30:46.854+0000] {logging_mixin.py:190} INFO - [2025-04-23T20:30:46.853+0000] {dagbag.py:588} INFO - Filling up the DagBag from /opt/airflow/dags/ML/ML1.py
[2025-04-23T20:30:47.141+0000] {logging_mixin.py:190} INFO - [2025-04-23T20:30:47.132+0000] {dagbag.py:387} ERROR - Failed to import: /opt/airflow/dags/ML/ML1.py
Traceback (most recent call last):
  File "/home/airflow/.local/lib/python3.12/site-packages/airflow/models/dagbag.py", line 383, in parse
    loader.exec_module(new_module)
  File "<frozen importlib._bootstrap_external>", line 999, in exec_module
  File "<frozen importlib._bootstrap>", line 488, in _call_with_frames_removed
  File "/opt/airflow/dags/ML/ML1.py", line 17, in <module>
    with DAG(
         ^^^^
  File "/home/airflow/.local/lib/python3.12/site-packages/airflow/models/dag.py", line 593, in __init__
    validate_key(dag_id)
  File "/home/airflow/.local/lib/python3.12/site-packages/airflow/utils/helpers.py", line 57, in validate_key
    raise AirflowException(
airflow.exceptions.AirflowException: The key 'ML 1' has to be made of alphanumeric characters, dashes, dots and underscores exclusively
[2025-04-23T20:30:47.142+0000] {processor.py:927} WARNING - No viable dags retrieved from /opt/airflow/dags/ML/ML1.py
[2025-04-23T20:30:47.231+0000] {processor.py:208} INFO - Processing /opt/airflow/dags/ML/ML1.py took 0.386 seconds
[2025-04-23T20:31:17.916+0000] {processor.py:186} INFO - Started process (PID=1182) to work on /opt/airflow/dags/ML/ML1.py
[2025-04-23T20:31:17.921+0000] {processor.py:914} INFO - Processing file /opt/airflow/dags/ML/ML1.py for tasks to queue
[2025-04-23T20:31:17.929+0000] {logging_mixin.py:190} INFO - [2025-04-23T20:31:17.928+0000] {dagbag.py:588} INFO - Filling up the DagBag from /opt/airflow/dags/ML/ML1.py
[2025-04-23T20:31:18.308+0000] {logging_mixin.py:190} INFO - [2025-04-23T20:31:18.299+0000] {dagbag.py:387} ERROR - Failed to import: /opt/airflow/dags/ML/ML1.py
Traceback (most recent call last):
  File "/home/airflow/.local/lib/python3.12/site-packages/airflow/models/dagbag.py", line 383, in parse
    loader.exec_module(new_module)
  File "<frozen importlib._bootstrap_external>", line 999, in exec_module
  File "<frozen importlib._bootstrap>", line 488, in _call_with_frames_removed
  File "/opt/airflow/dags/ML/ML1.py", line 17, in <module>
    with DAG(
         ^^^^
  File "/home/airflow/.local/lib/python3.12/site-packages/airflow/models/dag.py", line 593, in __init__
    validate_key(dag_id)
  File "/home/airflow/.local/lib/python3.12/site-packages/airflow/utils/helpers.py", line 57, in validate_key
    raise AirflowException(
airflow.exceptions.AirflowException: The key 'ML 1' has to be made of alphanumeric characters, dashes, dots and underscores exclusively
[2025-04-23T20:31:18.309+0000] {processor.py:927} WARNING - No viable dags retrieved from /opt/airflow/dags/ML/ML1.py
[2025-04-23T20:31:18.387+0000] {processor.py:208} INFO - Processing /opt/airflow/dags/ML/ML1.py took 0.481 seconds
[2025-04-23T20:31:49.042+0000] {processor.py:186} INFO - Started process (PID=1211) to work on /opt/airflow/dags/ML/ML1.py
[2025-04-23T20:31:49.043+0000] {processor.py:914} INFO - Processing file /opt/airflow/dags/ML/ML1.py for tasks to queue
[2025-04-23T20:31:49.046+0000] {logging_mixin.py:190} INFO - [2025-04-23T20:31:49.045+0000] {dagbag.py:588} INFO - Filling up the DagBag from /opt/airflow/dags/ML/ML1.py
[2025-04-23T20:31:49.338+0000] {logging_mixin.py:190} INFO - [2025-04-23T20:31:49.330+0000] {dagbag.py:387} ERROR - Failed to import: /opt/airflow/dags/ML/ML1.py
Traceback (most recent call last):
  File "/home/airflow/.local/lib/python3.12/site-packages/airflow/models/dagbag.py", line 383, in parse
    loader.exec_module(new_module)
  File "<frozen importlib._bootstrap_external>", line 999, in exec_module
  File "<frozen importlib._bootstrap>", line 488, in _call_with_frames_removed
  File "/opt/airflow/dags/ML/ML1.py", line 17, in <module>
    with DAG(
         ^^^^
  File "/home/airflow/.local/lib/python3.12/site-packages/airflow/models/dag.py", line 593, in __init__
    validate_key(dag_id)
  File "/home/airflow/.local/lib/python3.12/site-packages/airflow/utils/helpers.py", line 57, in validate_key
    raise AirflowException(
airflow.exceptions.AirflowException: The key 'ML 1' has to be made of alphanumeric characters, dashes, dots and underscores exclusively
[2025-04-23T20:31:49.339+0000] {processor.py:927} WARNING - No viable dags retrieved from /opt/airflow/dags/ML/ML1.py
[2025-04-23T20:31:49.407+0000] {processor.py:208} INFO - Processing /opt/airflow/dags/ML/ML1.py took 0.371 seconds
[2025-04-23T20:32:20.225+0000] {processor.py:186} INFO - Started process (PID=1246) to work on /opt/airflow/dags/ML/ML1.py
[2025-04-23T20:32:20.226+0000] {processor.py:914} INFO - Processing file /opt/airflow/dags/ML/ML1.py for tasks to queue
[2025-04-23T20:32:20.228+0000] {logging_mixin.py:190} INFO - [2025-04-23T20:32:20.228+0000] {dagbag.py:588} INFO - Filling up the DagBag from /opt/airflow/dags/ML/ML1.py
[2025-04-23T20:32:20.506+0000] {logging_mixin.py:190} INFO - [2025-04-23T20:32:20.499+0000] {dagbag.py:387} ERROR - Failed to import: /opt/airflow/dags/ML/ML1.py
Traceback (most recent call last):
  File "/home/airflow/.local/lib/python3.12/site-packages/airflow/models/dagbag.py", line 383, in parse
    loader.exec_module(new_module)
  File "<frozen importlib._bootstrap_external>", line 999, in exec_module
  File "<frozen importlib._bootstrap>", line 488, in _call_with_frames_removed
  File "/opt/airflow/dags/ML/ML1.py", line 17, in <module>
    with DAG(
         ^^^^
  File "/home/airflow/.local/lib/python3.12/site-packages/airflow/models/dag.py", line 593, in __init__
    validate_key(dag_id)
  File "/home/airflow/.local/lib/python3.12/site-packages/airflow/utils/helpers.py", line 57, in validate_key
    raise AirflowException(
airflow.exceptions.AirflowException: The key 'ML 1' has to be made of alphanumeric characters, dashes, dots and underscores exclusively
[2025-04-23T20:32:20.507+0000] {processor.py:927} WARNING - No viable dags retrieved from /opt/airflow/dags/ML/ML1.py
[2025-04-23T20:32:20.575+0000] {processor.py:208} INFO - Processing /opt/airflow/dags/ML/ML1.py took 0.355 seconds
[2025-04-23T20:32:50.675+0000] {processor.py:186} INFO - Started process (PID=1275) to work on /opt/airflow/dags/ML/ML1.py
[2025-04-23T20:32:50.676+0000] {processor.py:914} INFO - Processing file /opt/airflow/dags/ML/ML1.py for tasks to queue
[2025-04-23T20:32:50.681+0000] {logging_mixin.py:190} INFO - [2025-04-23T20:32:50.680+0000] {dagbag.py:588} INFO - Filling up the DagBag from /opt/airflow/dags/ML/ML1.py
[2025-04-23T20:32:51.071+0000] {logging_mixin.py:190} INFO - [2025-04-23T20:32:51.059+0000] {dagbag.py:387} ERROR - Failed to import: /opt/airflow/dags/ML/ML1.py
Traceback (most recent call last):
  File "/home/airflow/.local/lib/python3.12/site-packages/airflow/models/dagbag.py", line 383, in parse
    loader.exec_module(new_module)
  File "<frozen importlib._bootstrap_external>", line 999, in exec_module
  File "<frozen importlib._bootstrap>", line 488, in _call_with_frames_removed
  File "/opt/airflow/dags/ML/ML1.py", line 17, in <module>
    with DAG(
         ^^^^
  File "/home/airflow/.local/lib/python3.12/site-packages/airflow/models/dag.py", line 593, in __init__
    validate_key(dag_id)
  File "/home/airflow/.local/lib/python3.12/site-packages/airflow/utils/helpers.py", line 57, in validate_key
    raise AirflowException(
airflow.exceptions.AirflowException: The key 'ML 1' has to be made of alphanumeric characters, dashes, dots and underscores exclusively
[2025-04-23T20:32:51.072+0000] {processor.py:927} WARNING - No viable dags retrieved from /opt/airflow/dags/ML/ML1.py
[2025-04-23T20:32:51.138+0000] {processor.py:208} INFO - Processing /opt/airflow/dags/ML/ML1.py took 0.469 seconds
[2025-04-23T20:33:21.617+0000] {processor.py:186} INFO - Started process (PID=1304) to work on /opt/airflow/dags/ML/ML1.py
[2025-04-23T20:33:21.621+0000] {processor.py:914} INFO - Processing file /opt/airflow/dags/ML/ML1.py for tasks to queue
[2025-04-23T20:33:21.625+0000] {logging_mixin.py:190} INFO - [2025-04-23T20:33:21.624+0000] {dagbag.py:588} INFO - Filling up the DagBag from /opt/airflow/dags/ML/ML1.py
[2025-04-23T20:33:21.977+0000] {logging_mixin.py:190} INFO - [2025-04-23T20:33:21.965+0000] {dagbag.py:387} ERROR - Failed to import: /opt/airflow/dags/ML/ML1.py
Traceback (most recent call last):
  File "/home/airflow/.local/lib/python3.12/site-packages/airflow/models/dagbag.py", line 383, in parse
    loader.exec_module(new_module)
  File "<frozen importlib._bootstrap_external>", line 999, in exec_module
  File "<frozen importlib._bootstrap>", line 488, in _call_with_frames_removed
  File "/opt/airflow/dags/ML/ML1.py", line 17, in <module>
    with DAG(
         ^^^^
  File "/home/airflow/.local/lib/python3.12/site-packages/airflow/models/dag.py", line 593, in __init__
    validate_key(dag_id)
  File "/home/airflow/.local/lib/python3.12/site-packages/airflow/utils/helpers.py", line 57, in validate_key
    raise AirflowException(
airflow.exceptions.AirflowException: The key 'ML 1' has to be made of alphanumeric characters, dashes, dots and underscores exclusively
[2025-04-23T20:33:21.979+0000] {processor.py:927} WARNING - No viable dags retrieved from /opt/airflow/dags/ML/ML1.py
[2025-04-23T20:33:22.063+0000] {processor.py:208} INFO - Processing /opt/airflow/dags/ML/ML1.py took 0.472 seconds
[2025-04-23T20:33:52.249+0000] {processor.py:186} INFO - Started process (PID=1333) to work on /opt/airflow/dags/ML/ML1.py
[2025-04-23T20:33:52.250+0000] {processor.py:914} INFO - Processing file /opt/airflow/dags/ML/ML1.py for tasks to queue
[2025-04-23T20:33:52.253+0000] {logging_mixin.py:190} INFO - [2025-04-23T20:33:52.252+0000] {dagbag.py:588} INFO - Filling up the DagBag from /opt/airflow/dags/ML/ML1.py
[2025-04-23T20:33:52.539+0000] {logging_mixin.py:190} INFO - [2025-04-23T20:33:52.529+0000] {dagbag.py:387} ERROR - Failed to import: /opt/airflow/dags/ML/ML1.py
Traceback (most recent call last):
  File "/home/airflow/.local/lib/python3.12/site-packages/airflow/models/dagbag.py", line 383, in parse
    loader.exec_module(new_module)
  File "<frozen importlib._bootstrap_external>", line 999, in exec_module
  File "<frozen importlib._bootstrap>", line 488, in _call_with_frames_removed
  File "/opt/airflow/dags/ML/ML1.py", line 17, in <module>
    with DAG(
         ^^^^
  File "/home/airflow/.local/lib/python3.12/site-packages/airflow/models/dag.py", line 593, in __init__
    validate_key(dag_id)
  File "/home/airflow/.local/lib/python3.12/site-packages/airflow/utils/helpers.py", line 57, in validate_key
    raise AirflowException(
airflow.exceptions.AirflowException: The key 'ML 1' has to be made of alphanumeric characters, dashes, dots and underscores exclusively
[2025-04-23T20:33:52.541+0000] {processor.py:927} WARNING - No viable dags retrieved from /opt/airflow/dags/ML/ML1.py
[2025-04-23T20:33:52.743+0000] {processor.py:208} INFO - Processing /opt/airflow/dags/ML/ML1.py took 0.501 seconds
[2025-04-23T20:34:23.363+0000] {processor.py:186} INFO - Started process (PID=1362) to work on /opt/airflow/dags/ML/ML1.py
[2025-04-23T20:34:23.365+0000] {processor.py:914} INFO - Processing file /opt/airflow/dags/ML/ML1.py for tasks to queue
[2025-04-23T20:34:23.369+0000] {logging_mixin.py:190} INFO - [2025-04-23T20:34:23.368+0000] {dagbag.py:588} INFO - Filling up the DagBag from /opt/airflow/dags/ML/ML1.py
[2025-04-23T20:34:23.806+0000] {logging_mixin.py:190} INFO - [2025-04-23T20:34:23.780+0000] {dagbag.py:387} ERROR - Failed to import: /opt/airflow/dags/ML/ML1.py
Traceback (most recent call last):
  File "/home/airflow/.local/lib/python3.12/site-packages/airflow/models/dagbag.py", line 383, in parse
    loader.exec_module(new_module)
  File "<frozen importlib._bootstrap_external>", line 999, in exec_module
  File "<frozen importlib._bootstrap>", line 488, in _call_with_frames_removed
  File "/opt/airflow/dags/ML/ML1.py", line 17, in <module>
    with DAG(
         ^^^^
  File "/home/airflow/.local/lib/python3.12/site-packages/airflow/models/dag.py", line 593, in __init__
    validate_key(dag_id)
  File "/home/airflow/.local/lib/python3.12/site-packages/airflow/utils/helpers.py", line 57, in validate_key
    raise AirflowException(
airflow.exceptions.AirflowException: The key 'ML 1' has to be made of alphanumeric characters, dashes, dots and underscores exclusively
[2025-04-23T20:34:23.808+0000] {processor.py:927} WARNING - No viable dags retrieved from /opt/airflow/dags/ML/ML1.py
[2025-04-23T20:34:23.939+0000] {processor.py:208} INFO - Processing /opt/airflow/dags/ML/ML1.py took 0.587 seconds
[2025-04-23T20:34:54.704+0000] {processor.py:186} INFO - Started process (PID=1391) to work on /opt/airflow/dags/ML/ML1.py
[2025-04-23T20:34:54.706+0000] {processor.py:914} INFO - Processing file /opt/airflow/dags/ML/ML1.py for tasks to queue
[2025-04-23T20:34:54.710+0000] {logging_mixin.py:190} INFO - [2025-04-23T20:34:54.709+0000] {dagbag.py:588} INFO - Filling up the DagBag from /opt/airflow/dags/ML/ML1.py
[2025-04-23T20:34:55.055+0000] {logging_mixin.py:190} INFO - [2025-04-23T20:34:55.045+0000] {dagbag.py:387} ERROR - Failed to import: /opt/airflow/dags/ML/ML1.py
Traceback (most recent call last):
  File "/home/airflow/.local/lib/python3.12/site-packages/airflow/models/dagbag.py", line 383, in parse
    loader.exec_module(new_module)
  File "<frozen importlib._bootstrap_external>", line 999, in exec_module
  File "<frozen importlib._bootstrap>", line 488, in _call_with_frames_removed
  File "/opt/airflow/dags/ML/ML1.py", line 17, in <module>
    with DAG(
         ^^^^
  File "/home/airflow/.local/lib/python3.12/site-packages/airflow/models/dag.py", line 593, in __init__
    validate_key(dag_id)
  File "/home/airflow/.local/lib/python3.12/site-packages/airflow/utils/helpers.py", line 57, in validate_key
    raise AirflowException(
airflow.exceptions.AirflowException: The key 'ML 1' has to be made of alphanumeric characters, dashes, dots and underscores exclusively
[2025-04-23T20:34:55.056+0000] {processor.py:927} WARNING - No viable dags retrieved from /opt/airflow/dags/ML/ML1.py
[2025-04-23T20:34:55.127+0000] {processor.py:208} INFO - Processing /opt/airflow/dags/ML/ML1.py took 0.432 seconds
[2025-04-23T20:35:25.409+0000] {processor.py:186} INFO - Started process (PID=1420) to work on /opt/airflow/dags/ML/ML1.py
[2025-04-23T20:35:25.410+0000] {processor.py:914} INFO - Processing file /opt/airflow/dags/ML/ML1.py for tasks to queue
[2025-04-23T20:35:25.413+0000] {logging_mixin.py:190} INFO - [2025-04-23T20:35:25.413+0000] {dagbag.py:588} INFO - Filling up the DagBag from /opt/airflow/dags/ML/ML1.py
[2025-04-23T20:35:25.735+0000] {logging_mixin.py:190} INFO - [2025-04-23T20:35:25.728+0000] {dagbag.py:387} ERROR - Failed to import: /opt/airflow/dags/ML/ML1.py
Traceback (most recent call last):
  File "/home/airflow/.local/lib/python3.12/site-packages/airflow/models/dagbag.py", line 383, in parse
    loader.exec_module(new_module)
  File "<frozen importlib._bootstrap_external>", line 999, in exec_module
  File "<frozen importlib._bootstrap>", line 488, in _call_with_frames_removed
  File "/opt/airflow/dags/ML/ML1.py", line 17, in <module>
    with DAG(
         ^^^^
  File "/home/airflow/.local/lib/python3.12/site-packages/airflow/models/dag.py", line 593, in __init__
    validate_key(dag_id)
  File "/home/airflow/.local/lib/python3.12/site-packages/airflow/utils/helpers.py", line 57, in validate_key
    raise AirflowException(
airflow.exceptions.AirflowException: The key 'ML 1' has to be made of alphanumeric characters, dashes, dots and underscores exclusively
[2025-04-23T20:35:25.736+0000] {processor.py:927} WARNING - No viable dags retrieved from /opt/airflow/dags/ML/ML1.py
[2025-04-23T20:35:25.807+0000] {processor.py:208} INFO - Processing /opt/airflow/dags/ML/ML1.py took 0.404 seconds
[2025-04-23T20:35:56.669+0000] {processor.py:186} INFO - Started process (PID=1449) to work on /opt/airflow/dags/ML/ML1.py
[2025-04-23T20:35:56.678+0000] {processor.py:914} INFO - Processing file /opt/airflow/dags/ML/ML1.py for tasks to queue
[2025-04-23T20:35:56.685+0000] {logging_mixin.py:190} INFO - [2025-04-23T20:35:56.684+0000] {dagbag.py:588} INFO - Filling up the DagBag from /opt/airflow/dags/ML/ML1.py
[2025-04-23T20:35:57.091+0000] {logging_mixin.py:190} INFO - [2025-04-23T20:35:57.082+0000] {dagbag.py:387} ERROR - Failed to import: /opt/airflow/dags/ML/ML1.py
Traceback (most recent call last):
  File "/home/airflow/.local/lib/python3.12/site-packages/airflow/models/dagbag.py", line 383, in parse
    loader.exec_module(new_module)
  File "<frozen importlib._bootstrap_external>", line 999, in exec_module
  File "<frozen importlib._bootstrap>", line 488, in _call_with_frames_removed
  File "/opt/airflow/dags/ML/ML1.py", line 17, in <module>
    with DAG(
         ^^^^
  File "/home/airflow/.local/lib/python3.12/site-packages/airflow/models/dag.py", line 593, in __init__
    validate_key(dag_id)
  File "/home/airflow/.local/lib/python3.12/site-packages/airflow/utils/helpers.py", line 57, in validate_key
    raise AirflowException(
airflow.exceptions.AirflowException: The key 'ML 1' has to be made of alphanumeric characters, dashes, dots and underscores exclusively
[2025-04-23T20:35:57.092+0000] {processor.py:927} WARNING - No viable dags retrieved from /opt/airflow/dags/ML/ML1.py
[2025-04-23T20:35:57.200+0000] {processor.py:208} INFO - Processing /opt/airflow/dags/ML/ML1.py took 0.554 seconds
[2025-04-23T20:36:27.386+0000] {processor.py:186} INFO - Started process (PID=1478) to work on /opt/airflow/dags/ML/ML1.py
[2025-04-23T20:36:27.387+0000] {processor.py:914} INFO - Processing file /opt/airflow/dags/ML/ML1.py for tasks to queue
[2025-04-23T20:36:27.391+0000] {logging_mixin.py:190} INFO - [2025-04-23T20:36:27.390+0000] {dagbag.py:588} INFO - Filling up the DagBag from /opt/airflow/dags/ML/ML1.py
[2025-04-23T20:36:27.700+0000] {logging_mixin.py:190} INFO - [2025-04-23T20:36:27.689+0000] {dagbag.py:387} ERROR - Failed to import: /opt/airflow/dags/ML/ML1.py
Traceback (most recent call last):
  File "/home/airflow/.local/lib/python3.12/site-packages/airflow/models/dagbag.py", line 383, in parse
    loader.exec_module(new_module)
  File "<frozen importlib._bootstrap_external>", line 999, in exec_module
  File "<frozen importlib._bootstrap>", line 488, in _call_with_frames_removed
  File "/opt/airflow/dags/ML/ML1.py", line 17, in <module>
    with DAG(
         ^^^^
  File "/home/airflow/.local/lib/python3.12/site-packages/airflow/models/dag.py", line 593, in __init__
    validate_key(dag_id)
  File "/home/airflow/.local/lib/python3.12/site-packages/airflow/utils/helpers.py", line 57, in validate_key
    raise AirflowException(
airflow.exceptions.AirflowException: The key 'ML 1' has to be made of alphanumeric characters, dashes, dots and underscores exclusively
[2025-04-23T20:36:27.701+0000] {processor.py:927} WARNING - No viable dags retrieved from /opt/airflow/dags/ML/ML1.py
[2025-04-23T20:36:27.783+0000] {processor.py:208} INFO - Processing /opt/airflow/dags/ML/ML1.py took 0.402 seconds
[2025-04-23T20:36:57.955+0000] {processor.py:186} INFO - Started process (PID=1507) to work on /opt/airflow/dags/ML/ML1.py
[2025-04-23T20:36:57.957+0000] {processor.py:914} INFO - Processing file /opt/airflow/dags/ML/ML1.py for tasks to queue
[2025-04-23T20:36:57.963+0000] {logging_mixin.py:190} INFO - [2025-04-23T20:36:57.962+0000] {dagbag.py:588} INFO - Filling up the DagBag from /opt/airflow/dags/ML/ML1.py
[2025-04-23T20:36:58.279+0000] {logging_mixin.py:190} INFO - [2025-04-23T20:36:58.271+0000] {dagbag.py:387} ERROR - Failed to import: /opt/airflow/dags/ML/ML1.py
Traceback (most recent call last):
  File "/home/airflow/.local/lib/python3.12/site-packages/airflow/models/dagbag.py", line 383, in parse
    loader.exec_module(new_module)
  File "<frozen importlib._bootstrap_external>", line 999, in exec_module
  File "<frozen importlib._bootstrap>", line 488, in _call_with_frames_removed
  File "/opt/airflow/dags/ML/ML1.py", line 17, in <module>
    with DAG(
         ^^^^
  File "/home/airflow/.local/lib/python3.12/site-packages/airflow/models/dag.py", line 593, in __init__
    validate_key(dag_id)
  File "/home/airflow/.local/lib/python3.12/site-packages/airflow/utils/helpers.py", line 57, in validate_key
    raise AirflowException(
airflow.exceptions.AirflowException: The key 'ML 1' has to be made of alphanumeric characters, dashes, dots and underscores exclusively
[2025-04-23T20:36:58.280+0000] {processor.py:927} WARNING - No viable dags retrieved from /opt/airflow/dags/ML/ML1.py
[2025-04-23T20:36:58.374+0000] {processor.py:208} INFO - Processing /opt/airflow/dags/ML/ML1.py took 0.431 seconds
[2025-04-23T20:37:28.893+0000] {processor.py:186} INFO - Started process (PID=1536) to work on /opt/airflow/dags/ML/ML1.py
[2025-04-23T20:37:28.895+0000] {processor.py:914} INFO - Processing file /opt/airflow/dags/ML/ML1.py for tasks to queue
[2025-04-23T20:37:28.900+0000] {logging_mixin.py:190} INFO - [2025-04-23T20:37:28.899+0000] {dagbag.py:588} INFO - Filling up the DagBag from /opt/airflow/dags/ML/ML1.py
[2025-04-23T20:37:29.216+0000] {logging_mixin.py:190} INFO - [2025-04-23T20:37:29.210+0000] {dagbag.py:387} ERROR - Failed to import: /opt/airflow/dags/ML/ML1.py
Traceback (most recent call last):
  File "/home/airflow/.local/lib/python3.12/site-packages/airflow/models/dagbag.py", line 383, in parse
    loader.exec_module(new_module)
  File "<frozen importlib._bootstrap_external>", line 999, in exec_module
  File "<frozen importlib._bootstrap>", line 488, in _call_with_frames_removed
  File "/opt/airflow/dags/ML/ML1.py", line 17, in <module>
    with DAG(
         ^^^^
  File "/home/airflow/.local/lib/python3.12/site-packages/airflow/models/dag.py", line 593, in __init__
    validate_key(dag_id)
  File "/home/airflow/.local/lib/python3.12/site-packages/airflow/utils/helpers.py", line 57, in validate_key
    raise AirflowException(
airflow.exceptions.AirflowException: The key 'ML 1' has to be made of alphanumeric characters, dashes, dots and underscores exclusively
[2025-04-23T20:37:29.217+0000] {processor.py:927} WARNING - No viable dags retrieved from /opt/airflow/dags/ML/ML1.py
[2025-04-23T20:37:29.290+0000] {processor.py:208} INFO - Processing /opt/airflow/dags/ML/ML1.py took 0.411 seconds
[2025-04-23T20:37:59.394+0000] {processor.py:186} INFO - Started process (PID=1566) to work on /opt/airflow/dags/ML/ML1.py
[2025-04-23T20:37:59.395+0000] {processor.py:914} INFO - Processing file /opt/airflow/dags/ML/ML1.py for tasks to queue
[2025-04-23T20:37:59.398+0000] {logging_mixin.py:190} INFO - [2025-04-23T20:37:59.397+0000] {dagbag.py:588} INFO - Filling up the DagBag from /opt/airflow/dags/ML/ML1.py
[2025-04-23T20:37:59.681+0000] {logging_mixin.py:190} INFO - [2025-04-23T20:37:59.669+0000] {dagbag.py:387} ERROR - Failed to import: /opt/airflow/dags/ML/ML1.py
Traceback (most recent call last):
  File "/home/airflow/.local/lib/python3.12/site-packages/airflow/models/dagbag.py", line 383, in parse
    loader.exec_module(new_module)
  File "<frozen importlib._bootstrap_external>", line 999, in exec_module
  File "<frozen importlib._bootstrap>", line 488, in _call_with_frames_removed
  File "/opt/airflow/dags/ML/ML1.py", line 17, in <module>
    with DAG(
         ^^^^
  File "/home/airflow/.local/lib/python3.12/site-packages/airflow/models/dag.py", line 593, in __init__
    validate_key(dag_id)
  File "/home/airflow/.local/lib/python3.12/site-packages/airflow/utils/helpers.py", line 57, in validate_key
    raise AirflowException(
airflow.exceptions.AirflowException: The key 'ML 1' has to be made of alphanumeric characters, dashes, dots and underscores exclusively
[2025-04-23T20:37:59.683+0000] {processor.py:927} WARNING - No viable dags retrieved from /opt/airflow/dags/ML/ML1.py
[2025-04-23T20:37:59.773+0000] {processor.py:208} INFO - Processing /opt/airflow/dags/ML/ML1.py took 0.385 seconds
[2025-04-23T20:38:29.900+0000] {processor.py:186} INFO - Started process (PID=1595) to work on /opt/airflow/dags/ML/ML1.py
[2025-04-23T20:38:29.902+0000] {processor.py:914} INFO - Processing file /opt/airflow/dags/ML/ML1.py for tasks to queue
[2025-04-23T20:38:29.904+0000] {logging_mixin.py:190} INFO - [2025-04-23T20:38:29.904+0000] {dagbag.py:588} INFO - Filling up the DagBag from /opt/airflow/dags/ML/ML1.py
[2025-04-23T20:38:30.163+0000] {logging_mixin.py:190} INFO - [2025-04-23T20:38:30.152+0000] {dagbag.py:387} ERROR - Failed to import: /opt/airflow/dags/ML/ML1.py
Traceback (most recent call last):
  File "/home/airflow/.local/lib/python3.12/site-packages/airflow/models/dagbag.py", line 383, in parse
    loader.exec_module(new_module)
  File "<frozen importlib._bootstrap_external>", line 999, in exec_module
  File "<frozen importlib._bootstrap>", line 488, in _call_with_frames_removed
  File "/opt/airflow/dags/ML/ML1.py", line 17, in <module>
    with DAG(
         ^^^^
  File "/home/airflow/.local/lib/python3.12/site-packages/airflow/models/dag.py", line 593, in __init__
    validate_key(dag_id)
  File "/home/airflow/.local/lib/python3.12/site-packages/airflow/utils/helpers.py", line 57, in validate_key
    raise AirflowException(
airflow.exceptions.AirflowException: The key 'ML 1' has to be made of alphanumeric characters, dashes, dots and underscores exclusively
[2025-04-23T20:38:30.164+0000] {processor.py:927} WARNING - No viable dags retrieved from /opt/airflow/dags/ML/ML1.py
[2025-04-23T20:38:30.241+0000] {processor.py:208} INFO - Processing /opt/airflow/dags/ML/ML1.py took 0.346 seconds
[2025-04-23T20:39:00.556+0000] {processor.py:186} INFO - Started process (PID=1624) to work on /opt/airflow/dags/ML/ML1.py
[2025-04-23T20:39:00.558+0000] {processor.py:914} INFO - Processing file /opt/airflow/dags/ML/ML1.py for tasks to queue
[2025-04-23T20:39:00.561+0000] {logging_mixin.py:190} INFO - [2025-04-23T20:39:00.561+0000] {dagbag.py:588} INFO - Filling up the DagBag from /opt/airflow/dags/ML/ML1.py
[2025-04-23T20:39:00.849+0000] {logging_mixin.py:190} INFO - [2025-04-23T20:39:00.841+0000] {dagbag.py:387} ERROR - Failed to import: /opt/airflow/dags/ML/ML1.py
Traceback (most recent call last):
  File "/home/airflow/.local/lib/python3.12/site-packages/airflow/models/dagbag.py", line 383, in parse
    loader.exec_module(new_module)
  File "<frozen importlib._bootstrap_external>", line 999, in exec_module
  File "<frozen importlib._bootstrap>", line 488, in _call_with_frames_removed
  File "/opt/airflow/dags/ML/ML1.py", line 17, in <module>
    with DAG(
         ^^^^
  File "/home/airflow/.local/lib/python3.12/site-packages/airflow/models/dag.py", line 593, in __init__
    validate_key(dag_id)
  File "/home/airflow/.local/lib/python3.12/site-packages/airflow/utils/helpers.py", line 57, in validate_key
    raise AirflowException(
airflow.exceptions.AirflowException: The key 'ML 1' has to be made of alphanumeric characters, dashes, dots and underscores exclusively
[2025-04-23T20:39:00.849+0000] {processor.py:927} WARNING - No viable dags retrieved from /opt/airflow/dags/ML/ML1.py
[2025-04-23T20:39:00.913+0000] {processor.py:208} INFO - Processing /opt/airflow/dags/ML/ML1.py took 0.364 seconds
[2025-04-23T20:39:31.219+0000] {processor.py:186} INFO - Started process (PID=1653) to work on /opt/airflow/dags/ML/ML1.py
[2025-04-23T20:39:31.220+0000] {processor.py:914} INFO - Processing file /opt/airflow/dags/ML/ML1.py for tasks to queue
[2025-04-23T20:39:31.222+0000] {logging_mixin.py:190} INFO - [2025-04-23T20:39:31.222+0000] {dagbag.py:588} INFO - Filling up the DagBag from /opt/airflow/dags/ML/ML1.py
[2025-04-23T20:39:31.474+0000] {logging_mixin.py:190} INFO - [2025-04-23T20:39:31.468+0000] {dagbag.py:387} ERROR - Failed to import: /opt/airflow/dags/ML/ML1.py
Traceback (most recent call last):
  File "/home/airflow/.local/lib/python3.12/site-packages/airflow/models/dagbag.py", line 383, in parse
    loader.exec_module(new_module)
  File "<frozen importlib._bootstrap_external>", line 999, in exec_module
  File "<frozen importlib._bootstrap>", line 488, in _call_with_frames_removed
  File "/opt/airflow/dags/ML/ML1.py", line 17, in <module>
    with DAG(
         ^^^^
  File "/home/airflow/.local/lib/python3.12/site-packages/airflow/models/dag.py", line 593, in __init__
    validate_key(dag_id)
  File "/home/airflow/.local/lib/python3.12/site-packages/airflow/utils/helpers.py", line 57, in validate_key
    raise AirflowException(
airflow.exceptions.AirflowException: The key 'ML 1' has to be made of alphanumeric characters, dashes, dots and underscores exclusively
[2025-04-23T20:39:31.475+0000] {processor.py:927} WARNING - No viable dags retrieved from /opt/airflow/dags/ML/ML1.py
[2025-04-23T20:39:31.533+0000] {processor.py:208} INFO - Processing /opt/airflow/dags/ML/ML1.py took 0.319 seconds
[2025-04-23T20:40:01.886+0000] {processor.py:186} INFO - Started process (PID=1682) to work on /opt/airflow/dags/ML/ML1.py
[2025-04-23T20:40:01.887+0000] {processor.py:914} INFO - Processing file /opt/airflow/dags/ML/ML1.py for tasks to queue
[2025-04-23T20:40:01.890+0000] {logging_mixin.py:190} INFO - [2025-04-23T20:40:01.890+0000] {dagbag.py:588} INFO - Filling up the DagBag from /opt/airflow/dags/ML/ML1.py
[2025-04-23T20:40:02.171+0000] {logging_mixin.py:190} INFO - [2025-04-23T20:40:02.159+0000] {dagbag.py:387} ERROR - Failed to import: /opt/airflow/dags/ML/ML1.py
Traceback (most recent call last):
  File "/home/airflow/.local/lib/python3.12/site-packages/airflow/models/dagbag.py", line 383, in parse
    loader.exec_module(new_module)
  File "<frozen importlib._bootstrap_external>", line 999, in exec_module
  File "<frozen importlib._bootstrap>", line 488, in _call_with_frames_removed
  File "/opt/airflow/dags/ML/ML1.py", line 17, in <module>
    with DAG(
         ^^^^
  File "/home/airflow/.local/lib/python3.12/site-packages/airflow/models/dag.py", line 593, in __init__
    validate_key(dag_id)
  File "/home/airflow/.local/lib/python3.12/site-packages/airflow/utils/helpers.py", line 57, in validate_key
    raise AirflowException(
airflow.exceptions.AirflowException: The key 'ML 1' has to be made of alphanumeric characters, dashes, dots and underscores exclusively
[2025-04-23T20:40:02.173+0000] {processor.py:927} WARNING - No viable dags retrieved from /opt/airflow/dags/ML/ML1.py
[2025-04-23T20:40:02.257+0000] {processor.py:208} INFO - Processing /opt/airflow/dags/ML/ML1.py took 0.378 seconds
[2025-04-23T20:40:32.566+0000] {processor.py:186} INFO - Started process (PID=1711) to work on /opt/airflow/dags/ML/ML1.py
[2025-04-23T20:40:32.568+0000] {processor.py:914} INFO - Processing file /opt/airflow/dags/ML/ML1.py for tasks to queue
[2025-04-23T20:40:32.570+0000] {logging_mixin.py:190} INFO - [2025-04-23T20:40:32.570+0000] {dagbag.py:588} INFO - Filling up the DagBag from /opt/airflow/dags/ML/ML1.py
[2025-04-23T20:40:32.845+0000] {logging_mixin.py:190} INFO - [2025-04-23T20:40:32.835+0000] {dagbag.py:387} ERROR - Failed to import: /opt/airflow/dags/ML/ML1.py
Traceback (most recent call last):
  File "/home/airflow/.local/lib/python3.12/site-packages/airflow/models/dagbag.py", line 383, in parse
    loader.exec_module(new_module)
  File "<frozen importlib._bootstrap_external>", line 999, in exec_module
  File "<frozen importlib._bootstrap>", line 488, in _call_with_frames_removed
  File "/opt/airflow/dags/ML/ML1.py", line 17, in <module>
    with DAG(
         ^^^^
  File "/home/airflow/.local/lib/python3.12/site-packages/airflow/models/dag.py", line 593, in __init__
    validate_key(dag_id)
  File "/home/airflow/.local/lib/python3.12/site-packages/airflow/utils/helpers.py", line 57, in validate_key
    raise AirflowException(
airflow.exceptions.AirflowException: The key 'ML 1' has to be made of alphanumeric characters, dashes, dots and underscores exclusively
[2025-04-23T20:40:32.846+0000] {processor.py:927} WARNING - No viable dags retrieved from /opt/airflow/dags/ML/ML1.py
[2025-04-23T20:40:32.925+0000] {processor.py:208} INFO - Processing /opt/airflow/dags/ML/ML1.py took 0.365 seconds
[2025-04-23T20:41:03.157+0000] {processor.py:186} INFO - Started process (PID=1740) to work on /opt/airflow/dags/ML/ML1.py
[2025-04-23T20:41:03.159+0000] {processor.py:914} INFO - Processing file /opt/airflow/dags/ML/ML1.py for tasks to queue
[2025-04-23T20:41:03.161+0000] {logging_mixin.py:190} INFO - [2025-04-23T20:41:03.161+0000] {dagbag.py:588} INFO - Filling up the DagBag from /opt/airflow/dags/ML/ML1.py
[2025-04-23T20:41:03.473+0000] {logging_mixin.py:190} INFO - [2025-04-23T20:41:03.436+0000] {dagbag.py:387} ERROR - Failed to import: /opt/airflow/dags/ML/ML1.py
Traceback (most recent call last):
  File "/home/airflow/.local/lib/python3.12/site-packages/airflow/models/dagbag.py", line 383, in parse
    loader.exec_module(new_module)
  File "<frozen importlib._bootstrap_external>", line 999, in exec_module
  File "<frozen importlib._bootstrap>", line 488, in _call_with_frames_removed
  File "/opt/airflow/dags/ML/ML1.py", line 17, in <module>
    with DAG(
         ^^^^
  File "/home/airflow/.local/lib/python3.12/site-packages/airflow/models/dag.py", line 593, in __init__
    validate_key(dag_id)
  File "/home/airflow/.local/lib/python3.12/site-packages/airflow/utils/helpers.py", line 57, in validate_key
    raise AirflowException(
airflow.exceptions.AirflowException: The key 'ML 1' has to be made of alphanumeric characters, dashes, dots and underscores exclusively
[2025-04-23T20:41:03.474+0000] {processor.py:927} WARNING - No viable dags retrieved from /opt/airflow/dags/ML/ML1.py
[2025-04-23T20:41:03.539+0000] {processor.py:208} INFO - Processing /opt/airflow/dags/ML/ML1.py took 0.388 seconds
[2025-04-23T20:41:34.145+0000] {processor.py:186} INFO - Started process (PID=1769) to work on /opt/airflow/dags/ML/ML1.py
[2025-04-23T20:41:34.146+0000] {processor.py:914} INFO - Processing file /opt/airflow/dags/ML/ML1.py for tasks to queue
[2025-04-23T20:41:34.148+0000] {logging_mixin.py:190} INFO - [2025-04-23T20:41:34.147+0000] {dagbag.py:588} INFO - Filling up the DagBag from /opt/airflow/dags/ML/ML1.py
[2025-04-23T20:41:34.389+0000] {logging_mixin.py:190} INFO - [2025-04-23T20:41:34.381+0000] {dagbag.py:387} ERROR - Failed to import: /opt/airflow/dags/ML/ML1.py
Traceback (most recent call last):
  File "/home/airflow/.local/lib/python3.12/site-packages/airflow/models/dagbag.py", line 383, in parse
    loader.exec_module(new_module)
  File "<frozen importlib._bootstrap_external>", line 999, in exec_module
  File "<frozen importlib._bootstrap>", line 488, in _call_with_frames_removed
  File "/opt/airflow/dags/ML/ML1.py", line 17, in <module>
    with DAG(
         ^^^^
  File "/home/airflow/.local/lib/python3.12/site-packages/airflow/models/dag.py", line 593, in __init__
    validate_key(dag_id)
  File "/home/airflow/.local/lib/python3.12/site-packages/airflow/utils/helpers.py", line 57, in validate_key
    raise AirflowException(
airflow.exceptions.AirflowException: The key 'ML 1' has to be made of alphanumeric characters, dashes, dots and underscores exclusively
[2025-04-23T20:41:34.389+0000] {processor.py:927} WARNING - No viable dags retrieved from /opt/airflow/dags/ML/ML1.py
[2025-04-23T20:41:34.449+0000] {processor.py:208} INFO - Processing /opt/airflow/dags/ML/ML1.py took 0.309 seconds
[2025-04-23T20:42:04.613+0000] {processor.py:186} INFO - Started process (PID=1798) to work on /opt/airflow/dags/ML/ML1.py
[2025-04-23T20:42:04.614+0000] {processor.py:914} INFO - Processing file /opt/airflow/dags/ML/ML1.py for tasks to queue
[2025-04-23T20:42:04.617+0000] {logging_mixin.py:190} INFO - [2025-04-23T20:42:04.616+0000] {dagbag.py:588} INFO - Filling up the DagBag from /opt/airflow/dags/ML/ML1.py
[2025-04-23T20:42:04.898+0000] {logging_mixin.py:190} INFO - [2025-04-23T20:42:04.888+0000] {dagbag.py:387} ERROR - Failed to import: /opt/airflow/dags/ML/ML1.py
Traceback (most recent call last):
  File "/home/airflow/.local/lib/python3.12/site-packages/airflow/models/dagbag.py", line 383, in parse
    loader.exec_module(new_module)
  File "<frozen importlib._bootstrap_external>", line 999, in exec_module
  File "<frozen importlib._bootstrap>", line 488, in _call_with_frames_removed
  File "/opt/airflow/dags/ML/ML1.py", line 17, in <module>
    with DAG(
         ^^^^
  File "/home/airflow/.local/lib/python3.12/site-packages/airflow/models/dag.py", line 593, in __init__
    validate_key(dag_id)
  File "/home/airflow/.local/lib/python3.12/site-packages/airflow/utils/helpers.py", line 57, in validate_key
    raise AirflowException(
airflow.exceptions.AirflowException: The key 'ML 1' has to be made of alphanumeric characters, dashes, dots and underscores exclusively
[2025-04-23T20:42:04.899+0000] {processor.py:927} WARNING - No viable dags retrieved from /opt/airflow/dags/ML/ML1.py
[2025-04-23T20:42:04.961+0000] {processor.py:208} INFO - Processing /opt/airflow/dags/ML/ML1.py took 0.357 seconds
[2025-04-23T20:42:35.265+0000] {processor.py:186} INFO - Started process (PID=1827) to work on /opt/airflow/dags/ML/ML1.py
[2025-04-23T20:42:35.266+0000] {processor.py:914} INFO - Processing file /opt/airflow/dags/ML/ML1.py for tasks to queue
[2025-04-23T20:42:35.268+0000] {logging_mixin.py:190} INFO - [2025-04-23T20:42:35.268+0000] {dagbag.py:588} INFO - Filling up the DagBag from /opt/airflow/dags/ML/ML1.py
[2025-04-23T20:42:35.557+0000] {logging_mixin.py:190} INFO - [2025-04-23T20:42:35.549+0000] {dagbag.py:387} ERROR - Failed to import: /opt/airflow/dags/ML/ML1.py
Traceback (most recent call last):
  File "/home/airflow/.local/lib/python3.12/site-packages/airflow/models/dagbag.py", line 383, in parse
    loader.exec_module(new_module)
  File "<frozen importlib._bootstrap_external>", line 999, in exec_module
  File "<frozen importlib._bootstrap>", line 488, in _call_with_frames_removed
  File "/opt/airflow/dags/ML/ML1.py", line 17, in <module>
    with DAG(
         ^^^^
  File "/home/airflow/.local/lib/python3.12/site-packages/airflow/models/dag.py", line 593, in __init__
    validate_key(dag_id)
  File "/home/airflow/.local/lib/python3.12/site-packages/airflow/utils/helpers.py", line 57, in validate_key
    raise AirflowException(
airflow.exceptions.AirflowException: The key 'ML 1' has to be made of alphanumeric characters, dashes, dots and underscores exclusively
[2025-04-23T20:42:35.558+0000] {processor.py:927} WARNING - No viable dags retrieved from /opt/airflow/dags/ML/ML1.py
[2025-04-23T20:42:35.626+0000] {processor.py:208} INFO - Processing /opt/airflow/dags/ML/ML1.py took 0.367 seconds
[2025-04-23T20:43:05.956+0000] {processor.py:186} INFO - Started process (PID=1856) to work on /opt/airflow/dags/ML/ML1.py
[2025-04-23T20:43:05.957+0000] {processor.py:914} INFO - Processing file /opt/airflow/dags/ML/ML1.py for tasks to queue
[2025-04-23T20:43:05.961+0000] {logging_mixin.py:190} INFO - [2025-04-23T20:43:05.960+0000] {dagbag.py:588} INFO - Filling up the DagBag from /opt/airflow/dags/ML/ML1.py
[2025-04-23T20:43:06.253+0000] {logging_mixin.py:190} INFO - [2025-04-23T20:43:06.242+0000] {dagbag.py:387} ERROR - Failed to import: /opt/airflow/dags/ML/ML1.py
Traceback (most recent call last):
  File "/home/airflow/.local/lib/python3.12/site-packages/airflow/models/dagbag.py", line 383, in parse
    loader.exec_module(new_module)
  File "<frozen importlib._bootstrap_external>", line 999, in exec_module
  File "<frozen importlib._bootstrap>", line 488, in _call_with_frames_removed
  File "/opt/airflow/dags/ML/ML1.py", line 17, in <module>
    with DAG(
         ^^^^
  File "/home/airflow/.local/lib/python3.12/site-packages/airflow/models/dag.py", line 593, in __init__
    validate_key(dag_id)
  File "/home/airflow/.local/lib/python3.12/site-packages/airflow/utils/helpers.py", line 57, in validate_key
    raise AirflowException(
airflow.exceptions.AirflowException: The key 'ML 1' has to be made of alphanumeric characters, dashes, dots and underscores exclusively
[2025-04-23T20:43:06.253+0000] {processor.py:927} WARNING - No viable dags retrieved from /opt/airflow/dags/ML/ML1.py
[2025-04-23T20:43:06.358+0000] {processor.py:208} INFO - Processing /opt/airflow/dags/ML/ML1.py took 0.409 seconds
[2025-04-23T20:43:36.727+0000] {processor.py:186} INFO - Started process (PID=1885) to work on /opt/airflow/dags/ML/ML1.py
[2025-04-23T20:43:36.729+0000] {processor.py:914} INFO - Processing file /opt/airflow/dags/ML/ML1.py for tasks to queue
[2025-04-23T20:43:36.731+0000] {logging_mixin.py:190} INFO - [2025-04-23T20:43:36.731+0000] {dagbag.py:588} INFO - Filling up the DagBag from /opt/airflow/dags/ML/ML1.py
[2025-04-23T20:43:37.074+0000] {logging_mixin.py:190} INFO - [2025-04-23T20:43:37.055+0000] {dagbag.py:387} ERROR - Failed to import: /opt/airflow/dags/ML/ML1.py
Traceback (most recent call last):
  File "/home/airflow/.local/lib/python3.12/site-packages/airflow/models/dagbag.py", line 383, in parse
    loader.exec_module(new_module)
  File "<frozen importlib._bootstrap_external>", line 999, in exec_module
  File "<frozen importlib._bootstrap>", line 488, in _call_with_frames_removed
  File "/opt/airflow/dags/ML/ML1.py", line 17, in <module>
    with DAG(
         ^^^^
  File "/home/airflow/.local/lib/python3.12/site-packages/airflow/models/dag.py", line 593, in __init__
    validate_key(dag_id)
  File "/home/airflow/.local/lib/python3.12/site-packages/airflow/utils/helpers.py", line 57, in validate_key
    raise AirflowException(
airflow.exceptions.AirflowException: The key 'ML 1' has to be made of alphanumeric characters, dashes, dots and underscores exclusively
[2025-04-23T20:43:37.075+0000] {processor.py:927} WARNING - No viable dags retrieved from /opt/airflow/dags/ML/ML1.py
[2025-04-23T20:43:37.184+0000] {processor.py:208} INFO - Processing /opt/airflow/dags/ML/ML1.py took 0.463 seconds
[2025-04-23T20:44:07.640+0000] {processor.py:186} INFO - Started process (PID=1914) to work on /opt/airflow/dags/ML/ML1.py
[2025-04-23T20:44:07.641+0000] {processor.py:914} INFO - Processing file /opt/airflow/dags/ML/ML1.py for tasks to queue
[2025-04-23T20:44:07.645+0000] {logging_mixin.py:190} INFO - [2025-04-23T20:44:07.644+0000] {dagbag.py:588} INFO - Filling up the DagBag from /opt/airflow/dags/ML/ML1.py
[2025-04-23T20:44:07.918+0000] {logging_mixin.py:190} INFO - [2025-04-23T20:44:07.910+0000] {dagbag.py:387} ERROR - Failed to import: /opt/airflow/dags/ML/ML1.py
Traceback (most recent call last):
  File "/home/airflow/.local/lib/python3.12/site-packages/airflow/models/dagbag.py", line 383, in parse
    loader.exec_module(new_module)
  File "<frozen importlib._bootstrap_external>", line 999, in exec_module
  File "<frozen importlib._bootstrap>", line 488, in _call_with_frames_removed
  File "/opt/airflow/dags/ML/ML1.py", line 17, in <module>
    with DAG(
         ^^^^
  File "/home/airflow/.local/lib/python3.12/site-packages/airflow/models/dag.py", line 593, in __init__
    validate_key(dag_id)
  File "/home/airflow/.local/lib/python3.12/site-packages/airflow/utils/helpers.py", line 57, in validate_key
    raise AirflowException(
airflow.exceptions.AirflowException: The key 'ML 1' has to be made of alphanumeric characters, dashes, dots and underscores exclusively
[2025-04-23T20:44:07.920+0000] {processor.py:927} WARNING - No viable dags retrieved from /opt/airflow/dags/ML/ML1.py
[2025-04-23T20:44:07.988+0000] {processor.py:208} INFO - Processing /opt/airflow/dags/ML/ML1.py took 0.355 seconds
[2025-04-23T20:44:38.458+0000] {processor.py:186} INFO - Started process (PID=1943) to work on /opt/airflow/dags/ML/ML1.py
[2025-04-23T20:44:38.459+0000] {processor.py:914} INFO - Processing file /opt/airflow/dags/ML/ML1.py for tasks to queue
[2025-04-23T20:44:38.464+0000] {logging_mixin.py:190} INFO - [2025-04-23T20:44:38.463+0000] {dagbag.py:588} INFO - Filling up the DagBag from /opt/airflow/dags/ML/ML1.py
[2025-04-23T20:44:38.742+0000] {logging_mixin.py:190} INFO - [2025-04-23T20:44:38.732+0000] {dagbag.py:387} ERROR - Failed to import: /opt/airflow/dags/ML/ML1.py
Traceback (most recent call last):
  File "/home/airflow/.local/lib/python3.12/site-packages/airflow/models/dagbag.py", line 383, in parse
    loader.exec_module(new_module)
  File "<frozen importlib._bootstrap_external>", line 999, in exec_module
  File "<frozen importlib._bootstrap>", line 488, in _call_with_frames_removed
  File "/opt/airflow/dags/ML/ML1.py", line 17, in <module>
    with DAG(
         ^^^^
  File "/home/airflow/.local/lib/python3.12/site-packages/airflow/models/dag.py", line 593, in __init__
    validate_key(dag_id)
  File "/home/airflow/.local/lib/python3.12/site-packages/airflow/utils/helpers.py", line 57, in validate_key
    raise AirflowException(
airflow.exceptions.AirflowException: The key 'ML 1' has to be made of alphanumeric characters, dashes, dots and underscores exclusively
[2025-04-23T20:44:38.743+0000] {processor.py:927} WARNING - No viable dags retrieved from /opt/airflow/dags/ML/ML1.py
[2025-04-23T20:44:38.816+0000] {processor.py:208} INFO - Processing /opt/airflow/dags/ML/ML1.py took 0.363 seconds
[2025-04-23T20:45:09.202+0000] {processor.py:186} INFO - Started process (PID=1971) to work on /opt/airflow/dags/ML/ML1.py
[2025-04-23T20:45:09.203+0000] {processor.py:914} INFO - Processing file /opt/airflow/dags/ML/ML1.py for tasks to queue
[2025-04-23T20:45:09.206+0000] {logging_mixin.py:190} INFO - [2025-04-23T20:45:09.206+0000] {dagbag.py:588} INFO - Filling up the DagBag from /opt/airflow/dags/ML/ML1.py
[2025-04-23T20:45:09.477+0000] {logging_mixin.py:190} INFO - [2025-04-23T20:45:09.469+0000] {dagbag.py:387} ERROR - Failed to import: /opt/airflow/dags/ML/ML1.py
Traceback (most recent call last):
  File "/home/airflow/.local/lib/python3.12/site-packages/airflow/models/dagbag.py", line 383, in parse
    loader.exec_module(new_module)
  File "<frozen importlib._bootstrap_external>", line 999, in exec_module
  File "<frozen importlib._bootstrap>", line 488, in _call_with_frames_removed
  File "/opt/airflow/dags/ML/ML1.py", line 17, in <module>
    with DAG(
         ^^^^
  File "/home/airflow/.local/lib/python3.12/site-packages/airflow/models/dag.py", line 593, in __init__
    validate_key(dag_id)
  File "/home/airflow/.local/lib/python3.12/site-packages/airflow/utils/helpers.py", line 57, in validate_key
    raise AirflowException(
airflow.exceptions.AirflowException: The key 'ML 1' has to be made of alphanumeric characters, dashes, dots and underscores exclusively
[2025-04-23T20:45:09.478+0000] {processor.py:927} WARNING - No viable dags retrieved from /opt/airflow/dags/ML/ML1.py
[2025-04-23T20:45:09.558+0000] {processor.py:208} INFO - Processing /opt/airflow/dags/ML/ML1.py took 0.362 seconds
[2025-04-23T20:45:40.288+0000] {processor.py:186} INFO - Started process (PID=2000) to work on /opt/airflow/dags/ML/ML1.py
[2025-04-23T20:45:40.290+0000] {processor.py:914} INFO - Processing file /opt/airflow/dags/ML/ML1.py for tasks to queue
[2025-04-23T20:45:40.294+0000] {logging_mixin.py:190} INFO - [2025-04-23T20:45:40.293+0000] {dagbag.py:588} INFO - Filling up the DagBag from /opt/airflow/dags/ML/ML1.py
[2025-04-23T20:45:40.631+0000] {logging_mixin.py:190} INFO - [2025-04-23T20:45:40.624+0000] {dagbag.py:387} ERROR - Failed to import: /opt/airflow/dags/ML/ML1.py
Traceback (most recent call last):
  File "/home/airflow/.local/lib/python3.12/site-packages/airflow/models/dagbag.py", line 383, in parse
    loader.exec_module(new_module)
  File "<frozen importlib._bootstrap_external>", line 999, in exec_module
  File "<frozen importlib._bootstrap>", line 488, in _call_with_frames_removed
  File "/opt/airflow/dags/ML/ML1.py", line 17, in <module>
    with DAG(
         ^^^^
  File "/home/airflow/.local/lib/python3.12/site-packages/airflow/models/dag.py", line 593, in __init__
    validate_key(dag_id)
  File "/home/airflow/.local/lib/python3.12/site-packages/airflow/utils/helpers.py", line 57, in validate_key
    raise AirflowException(
airflow.exceptions.AirflowException: The key 'ML 1' has to be made of alphanumeric characters, dashes, dots and underscores exclusively
[2025-04-23T20:45:40.632+0000] {processor.py:927} WARNING - No viable dags retrieved from /opt/airflow/dags/ML/ML1.py
[2025-04-23T20:45:40.701+0000] {processor.py:208} INFO - Processing /opt/airflow/dags/ML/ML1.py took 0.423 seconds
[2025-04-23T20:46:11.183+0000] {processor.py:186} INFO - Started process (PID=2029) to work on /opt/airflow/dags/ML/ML1.py
[2025-04-23T20:46:11.184+0000] {processor.py:914} INFO - Processing file /opt/airflow/dags/ML/ML1.py for tasks to queue
[2025-04-23T20:46:11.187+0000] {logging_mixin.py:190} INFO - [2025-04-23T20:46:11.187+0000] {dagbag.py:588} INFO - Filling up the DagBag from /opt/airflow/dags/ML/ML1.py
[2025-04-23T20:46:11.443+0000] {logging_mixin.py:190} INFO - [2025-04-23T20:46:11.437+0000] {dagbag.py:387} ERROR - Failed to import: /opt/airflow/dags/ML/ML1.py
Traceback (most recent call last):
  File "/home/airflow/.local/lib/python3.12/site-packages/airflow/models/dagbag.py", line 383, in parse
    loader.exec_module(new_module)
  File "<frozen importlib._bootstrap_external>", line 999, in exec_module
  File "<frozen importlib._bootstrap>", line 488, in _call_with_frames_removed
  File "/opt/airflow/dags/ML/ML1.py", line 17, in <module>
    with DAG(
         ^^^^
  File "/home/airflow/.local/lib/python3.12/site-packages/airflow/models/dag.py", line 593, in __init__
    validate_key(dag_id)
  File "/home/airflow/.local/lib/python3.12/site-packages/airflow/utils/helpers.py", line 57, in validate_key
    raise AirflowException(
airflow.exceptions.AirflowException: The key 'ML 1' has to be made of alphanumeric characters, dashes, dots and underscores exclusively
[2025-04-23T20:46:11.444+0000] {processor.py:927} WARNING - No viable dags retrieved from /opt/airflow/dags/ML/ML1.py
[2025-04-23T20:46:11.503+0000] {processor.py:208} INFO - Processing /opt/airflow/dags/ML/ML1.py took 0.326 seconds
[2025-04-23T20:46:41.654+0000] {processor.py:186} INFO - Started process (PID=2058) to work on /opt/airflow/dags/ML/ML1.py
[2025-04-23T20:46:41.656+0000] {processor.py:914} INFO - Processing file /opt/airflow/dags/ML/ML1.py for tasks to queue
[2025-04-23T20:46:41.659+0000] {logging_mixin.py:190} INFO - [2025-04-23T20:46:41.659+0000] {dagbag.py:588} INFO - Filling up the DagBag from /opt/airflow/dags/ML/ML1.py
[2025-04-23T20:46:41.946+0000] {logging_mixin.py:190} INFO - [2025-04-23T20:46:41.936+0000] {dagbag.py:387} ERROR - Failed to import: /opt/airflow/dags/ML/ML1.py
Traceback (most recent call last):
  File "/home/airflow/.local/lib/python3.12/site-packages/airflow/models/dagbag.py", line 383, in parse
    loader.exec_module(new_module)
  File "<frozen importlib._bootstrap_external>", line 999, in exec_module
  File "<frozen importlib._bootstrap>", line 488, in _call_with_frames_removed
  File "/opt/airflow/dags/ML/ML1.py", line 17, in <module>
    with DAG(
         ^^^^
  File "/home/airflow/.local/lib/python3.12/site-packages/airflow/models/dag.py", line 593, in __init__
    validate_key(dag_id)
  File "/home/airflow/.local/lib/python3.12/site-packages/airflow/utils/helpers.py", line 57, in validate_key
    raise AirflowException(
airflow.exceptions.AirflowException: The key 'ML 1' has to be made of alphanumeric characters, dashes, dots and underscores exclusively
[2025-04-23T20:46:41.947+0000] {processor.py:927} WARNING - No viable dags retrieved from /opt/airflow/dags/ML/ML1.py
[2025-04-23T20:46:42.023+0000] {processor.py:208} INFO - Processing /opt/airflow/dags/ML/ML1.py took 0.377 seconds
[2025-04-23T20:47:12.206+0000] {processor.py:186} INFO - Started process (PID=2087) to work on /opt/airflow/dags/ML/ML1.py
[2025-04-23T20:47:12.207+0000] {processor.py:914} INFO - Processing file /opt/airflow/dags/ML/ML1.py for tasks to queue
[2025-04-23T20:47:12.210+0000] {logging_mixin.py:190} INFO - [2025-04-23T20:47:12.209+0000] {dagbag.py:588} INFO - Filling up the DagBag from /opt/airflow/dags/ML/ML1.py
[2025-04-23T20:47:12.490+0000] {logging_mixin.py:190} INFO - [2025-04-23T20:47:12.481+0000] {dagbag.py:387} ERROR - Failed to import: /opt/airflow/dags/ML/ML1.py
Traceback (most recent call last):
  File "/home/airflow/.local/lib/python3.12/site-packages/airflow/models/dagbag.py", line 383, in parse
    loader.exec_module(new_module)
  File "<frozen importlib._bootstrap_external>", line 999, in exec_module
  File "<frozen importlib._bootstrap>", line 488, in _call_with_frames_removed
  File "/opt/airflow/dags/ML/ML1.py", line 17, in <module>
    with DAG(
         ^^^^
  File "/home/airflow/.local/lib/python3.12/site-packages/airflow/models/dag.py", line 593, in __init__
    validate_key(dag_id)
  File "/home/airflow/.local/lib/python3.12/site-packages/airflow/utils/helpers.py", line 57, in validate_key
    raise AirflowException(
airflow.exceptions.AirflowException: The key 'ML 1' has to be made of alphanumeric characters, dashes, dots and underscores exclusively
[2025-04-23T20:47:12.491+0000] {processor.py:927} WARNING - No viable dags retrieved from /opt/airflow/dags/ML/ML1.py
[2025-04-23T20:47:12.602+0000] {processor.py:208} INFO - Processing /opt/airflow/dags/ML/ML1.py took 0.414 seconds
[2025-04-23T20:47:43.214+0000] {processor.py:186} INFO - Started process (PID=2116) to work on /opt/airflow/dags/ML/ML1.py
[2025-04-23T20:47:43.215+0000] {processor.py:914} INFO - Processing file /opt/airflow/dags/ML/ML1.py for tasks to queue
[2025-04-23T20:47:43.218+0000] {logging_mixin.py:190} INFO - [2025-04-23T20:47:43.217+0000] {dagbag.py:588} INFO - Filling up the DagBag from /opt/airflow/dags/ML/ML1.py
[2025-04-23T20:47:43.504+0000] {logging_mixin.py:190} INFO - [2025-04-23T20:47:43.495+0000] {dagbag.py:387} ERROR - Failed to import: /opt/airflow/dags/ML/ML1.py
Traceback (most recent call last):
  File "/home/airflow/.local/lib/python3.12/site-packages/airflow/models/dagbag.py", line 383, in parse
    loader.exec_module(new_module)
  File "<frozen importlib._bootstrap_external>", line 999, in exec_module
  File "<frozen importlib._bootstrap>", line 488, in _call_with_frames_removed
  File "/opt/airflow/dags/ML/ML1.py", line 17, in <module>
    with DAG(
         ^^^^
  File "/home/airflow/.local/lib/python3.12/site-packages/airflow/models/dag.py", line 593, in __init__
    validate_key(dag_id)
  File "/home/airflow/.local/lib/python3.12/site-packages/airflow/utils/helpers.py", line 57, in validate_key
    raise AirflowException(
airflow.exceptions.AirflowException: The key 'ML 1' has to be made of alphanumeric characters, dashes, dots and underscores exclusively
[2025-04-23T20:47:43.504+0000] {processor.py:927} WARNING - No viable dags retrieved from /opt/airflow/dags/ML/ML1.py
[2025-04-23T20:47:43.565+0000] {processor.py:208} INFO - Processing /opt/airflow/dags/ML/ML1.py took 0.357 seconds
[2025-04-23T20:48:14.015+0000] {processor.py:186} INFO - Started process (PID=2145) to work on /opt/airflow/dags/ML/ML1.py
[2025-04-23T20:48:14.016+0000] {processor.py:914} INFO - Processing file /opt/airflow/dags/ML/ML1.py for tasks to queue
[2025-04-23T20:48:14.019+0000] {logging_mixin.py:190} INFO - [2025-04-23T20:48:14.018+0000] {dagbag.py:588} INFO - Filling up the DagBag from /opt/airflow/dags/ML/ML1.py
[2025-04-23T20:48:14.305+0000] {logging_mixin.py:190} INFO - [2025-04-23T20:48:14.292+0000] {dagbag.py:387} ERROR - Failed to import: /opt/airflow/dags/ML/ML1.py
Traceback (most recent call last):
  File "/home/airflow/.local/lib/python3.12/site-packages/airflow/models/dagbag.py", line 383, in parse
    loader.exec_module(new_module)
  File "<frozen importlib._bootstrap_external>", line 999, in exec_module
  File "<frozen importlib._bootstrap>", line 488, in _call_with_frames_removed
  File "/opt/airflow/dags/ML/ML1.py", line 17, in <module>
    with DAG(
         ^^^^
  File "/home/airflow/.local/lib/python3.12/site-packages/airflow/models/dag.py", line 593, in __init__
    validate_key(dag_id)
  File "/home/airflow/.local/lib/python3.12/site-packages/airflow/utils/helpers.py", line 57, in validate_key
    raise AirflowException(
airflow.exceptions.AirflowException: The key 'ML 1' has to be made of alphanumeric characters, dashes, dots and underscores exclusively
[2025-04-23T20:48:14.307+0000] {processor.py:927} WARNING - No viable dags retrieved from /opt/airflow/dags/ML/ML1.py
[2025-04-23T20:48:14.395+0000] {processor.py:208} INFO - Processing /opt/airflow/dags/ML/ML1.py took 0.385 seconds
[2025-04-23T20:48:44.768+0000] {processor.py:186} INFO - Started process (PID=2174) to work on /opt/airflow/dags/ML/ML1.py
[2025-04-23T20:48:44.769+0000] {processor.py:914} INFO - Processing file /opt/airflow/dags/ML/ML1.py for tasks to queue
[2025-04-23T20:48:44.772+0000] {logging_mixin.py:190} INFO - [2025-04-23T20:48:44.772+0000] {dagbag.py:588} INFO - Filling up the DagBag from /opt/airflow/dags/ML/ML1.py
[2025-04-23T20:48:45.067+0000] {logging_mixin.py:190} INFO - [2025-04-23T20:48:45.060+0000] {dagbag.py:387} ERROR - Failed to import: /opt/airflow/dags/ML/ML1.py
Traceback (most recent call last):
  File "/home/airflow/.local/lib/python3.12/site-packages/airflow/models/dagbag.py", line 383, in parse
    loader.exec_module(new_module)
  File "<frozen importlib._bootstrap_external>", line 999, in exec_module
  File "<frozen importlib._bootstrap>", line 488, in _call_with_frames_removed
  File "/opt/airflow/dags/ML/ML1.py", line 17, in <module>
    with DAG(
         ^^^^
  File "/home/airflow/.local/lib/python3.12/site-packages/airflow/models/dag.py", line 593, in __init__
    validate_key(dag_id)
  File "/home/airflow/.local/lib/python3.12/site-packages/airflow/utils/helpers.py", line 57, in validate_key
    raise AirflowException(
airflow.exceptions.AirflowException: The key 'ML 1' has to be made of alphanumeric characters, dashes, dots and underscores exclusively
[2025-04-23T20:48:45.068+0000] {processor.py:927} WARNING - No viable dags retrieved from /opt/airflow/dags/ML/ML1.py
[2025-04-23T20:48:45.135+0000] {processor.py:208} INFO - Processing /opt/airflow/dags/ML/ML1.py took 0.375 seconds
[2025-04-23T20:49:15.234+0000] {processor.py:186} INFO - Started process (PID=2203) to work on /opt/airflow/dags/ML/ML1.py
[2025-04-23T20:49:15.236+0000] {processor.py:914} INFO - Processing file /opt/airflow/dags/ML/ML1.py for tasks to queue
[2025-04-23T20:49:15.238+0000] {logging_mixin.py:190} INFO - [2025-04-23T20:49:15.238+0000] {dagbag.py:588} INFO - Filling up the DagBag from /opt/airflow/dags/ML/ML1.py
[2025-04-23T20:49:15.507+0000] {logging_mixin.py:190} INFO - [2025-04-23T20:49:15.491+0000] {dagbag.py:387} ERROR - Failed to import: /opt/airflow/dags/ML/ML1.py
Traceback (most recent call last):
  File "/home/airflow/.local/lib/python3.12/site-packages/airflow/models/dagbag.py", line 383, in parse
    loader.exec_module(new_module)
  File "<frozen importlib._bootstrap_external>", line 999, in exec_module
  File "<frozen importlib._bootstrap>", line 488, in _call_with_frames_removed
  File "/opt/airflow/dags/ML/ML1.py", line 17, in <module>
    with DAG(
         ^^^^
  File "/home/airflow/.local/lib/python3.12/site-packages/airflow/models/dag.py", line 593, in __init__
    validate_key(dag_id)
  File "/home/airflow/.local/lib/python3.12/site-packages/airflow/utils/helpers.py", line 57, in validate_key
    raise AirflowException(
airflow.exceptions.AirflowException: The key 'ML 1' has to be made of alphanumeric characters, dashes, dots and underscores exclusively
[2025-04-23T20:49:15.508+0000] {processor.py:927} WARNING - No viable dags retrieved from /opt/airflow/dags/ML/ML1.py
[2025-04-23T20:49:15.570+0000] {processor.py:208} INFO - Processing /opt/airflow/dags/ML/ML1.py took 0.342 seconds
[2025-04-23T20:49:45.923+0000] {processor.py:186} INFO - Started process (PID=2232) to work on /opt/airflow/dags/ML/ML1.py
[2025-04-23T20:49:45.924+0000] {processor.py:914} INFO - Processing file /opt/airflow/dags/ML/ML1.py for tasks to queue
[2025-04-23T20:49:45.926+0000] {logging_mixin.py:190} INFO - [2025-04-23T20:49:45.925+0000] {dagbag.py:588} INFO - Filling up the DagBag from /opt/airflow/dags/ML/ML1.py
[2025-04-23T20:49:46.190+0000] {logging_mixin.py:190} INFO - [2025-04-23T20:49:46.182+0000] {dagbag.py:387} ERROR - Failed to import: /opt/airflow/dags/ML/ML1.py
Traceback (most recent call last):
  File "/home/airflow/.local/lib/python3.12/site-packages/airflow/models/dagbag.py", line 383, in parse
    loader.exec_module(new_module)
  File "<frozen importlib._bootstrap_external>", line 999, in exec_module
  File "<frozen importlib._bootstrap>", line 488, in _call_with_frames_removed
  File "/opt/airflow/dags/ML/ML1.py", line 17, in <module>
    with DAG(
         ^^^^
  File "/home/airflow/.local/lib/python3.12/site-packages/airflow/models/dag.py", line 593, in __init__
    validate_key(dag_id)
  File "/home/airflow/.local/lib/python3.12/site-packages/airflow/utils/helpers.py", line 57, in validate_key
    raise AirflowException(
airflow.exceptions.AirflowException: The key 'ML 1' has to be made of alphanumeric characters, dashes, dots and underscores exclusively
[2025-04-23T20:49:46.191+0000] {processor.py:927} WARNING - No viable dags retrieved from /opt/airflow/dags/ML/ML1.py
[2025-04-23T20:49:46.260+0000] {processor.py:208} INFO - Processing /opt/airflow/dags/ML/ML1.py took 0.343 seconds
[2025-04-23T20:50:17.152+0000] {processor.py:186} INFO - Started process (PID=2261) to work on /opt/airflow/dags/ML/ML1.py
[2025-04-23T20:50:17.154+0000] {processor.py:914} INFO - Processing file /opt/airflow/dags/ML/ML1.py for tasks to queue
[2025-04-23T20:50:17.158+0000] {logging_mixin.py:190} INFO - [2025-04-23T20:50:17.157+0000] {dagbag.py:588} INFO - Filling up the DagBag from /opt/airflow/dags/ML/ML1.py
[2025-04-23T20:50:17.491+0000] {logging_mixin.py:190} INFO - [2025-04-23T20:50:17.483+0000] {dagbag.py:387} ERROR - Failed to import: /opt/airflow/dags/ML/ML1.py
Traceback (most recent call last):
  File "/home/airflow/.local/lib/python3.12/site-packages/airflow/models/dagbag.py", line 383, in parse
    loader.exec_module(new_module)
  File "<frozen importlib._bootstrap_external>", line 999, in exec_module
  File "<frozen importlib._bootstrap>", line 488, in _call_with_frames_removed
  File "/opt/airflow/dags/ML/ML1.py", line 17, in <module>
    with DAG(
         ^^^^
  File "/home/airflow/.local/lib/python3.12/site-packages/airflow/models/dag.py", line 593, in __init__
    validate_key(dag_id)
  File "/home/airflow/.local/lib/python3.12/site-packages/airflow/utils/helpers.py", line 57, in validate_key
    raise AirflowException(
airflow.exceptions.AirflowException: The key 'ML 1' has to be made of alphanumeric characters, dashes, dots and underscores exclusively
[2025-04-23T20:50:17.492+0000] {processor.py:927} WARNING - No viable dags retrieved from /opt/airflow/dags/ML/ML1.py
[2025-04-23T20:50:17.560+0000] {processor.py:208} INFO - Processing /opt/airflow/dags/ML/ML1.py took 0.420 seconds
[2025-04-23T20:50:47.896+0000] {processor.py:186} INFO - Started process (PID=2290) to work on /opt/airflow/dags/ML/ML1.py
[2025-04-23T20:50:47.898+0000] {processor.py:914} INFO - Processing file /opt/airflow/dags/ML/ML1.py for tasks to queue
[2025-04-23T20:50:47.900+0000] {logging_mixin.py:190} INFO - [2025-04-23T20:50:47.900+0000] {dagbag.py:588} INFO - Filling up the DagBag from /opt/airflow/dags/ML/ML1.py
[2025-04-23T20:50:48.204+0000] {logging_mixin.py:190} INFO - [2025-04-23T20:50:48.195+0000] {dagbag.py:387} ERROR - Failed to import: /opt/airflow/dags/ML/ML1.py
Traceback (most recent call last):
  File "/home/airflow/.local/lib/python3.12/site-packages/airflow/models/dagbag.py", line 383, in parse
    loader.exec_module(new_module)
  File "<frozen importlib._bootstrap_external>", line 999, in exec_module
  File "<frozen importlib._bootstrap>", line 488, in _call_with_frames_removed
  File "/opt/airflow/dags/ML/ML1.py", line 17, in <module>
    with DAG(
         ^^^^
  File "/home/airflow/.local/lib/python3.12/site-packages/airflow/models/dag.py", line 593, in __init__
    validate_key(dag_id)
  File "/home/airflow/.local/lib/python3.12/site-packages/airflow/utils/helpers.py", line 57, in validate_key
    raise AirflowException(
airflow.exceptions.AirflowException: The key 'ML 1' has to be made of alphanumeric characters, dashes, dots and underscores exclusively
[2025-04-23T20:50:48.205+0000] {processor.py:927} WARNING - No viable dags retrieved from /opt/airflow/dags/ML/ML1.py
[2025-04-23T20:50:48.277+0000] {processor.py:208} INFO - Processing /opt/airflow/dags/ML/ML1.py took 0.388 seconds
[2025-04-23T20:51:18.707+0000] {processor.py:186} INFO - Started process (PID=2319) to work on /opt/airflow/dags/ML/ML1.py
[2025-04-23T20:51:18.710+0000] {processor.py:914} INFO - Processing file /opt/airflow/dags/ML/ML1.py for tasks to queue
[2025-04-23T20:51:18.713+0000] {logging_mixin.py:190} INFO - [2025-04-23T20:51:18.713+0000] {dagbag.py:588} INFO - Filling up the DagBag from /opt/airflow/dags/ML/ML1.py
[2025-04-23T20:51:19.009+0000] {logging_mixin.py:190} INFO - [2025-04-23T20:51:19.000+0000] {dagbag.py:387} ERROR - Failed to import: /opt/airflow/dags/ML/ML1.py
Traceback (most recent call last):
  File "/home/airflow/.local/lib/python3.12/site-packages/airflow/models/dagbag.py", line 383, in parse
    loader.exec_module(new_module)
  File "<frozen importlib._bootstrap_external>", line 999, in exec_module
  File "<frozen importlib._bootstrap>", line 488, in _call_with_frames_removed
  File "/opt/airflow/dags/ML/ML1.py", line 17, in <module>
    with DAG(
         ^^^^
  File "/home/airflow/.local/lib/python3.12/site-packages/airflow/models/dag.py", line 593, in __init__
    validate_key(dag_id)
  File "/home/airflow/.local/lib/python3.12/site-packages/airflow/utils/helpers.py", line 57, in validate_key
    raise AirflowException(
airflow.exceptions.AirflowException: The key 'ML 1' has to be made of alphanumeric characters, dashes, dots and underscores exclusively
[2025-04-23T20:51:19.010+0000] {processor.py:927} WARNING - No viable dags retrieved from /opt/airflow/dags/ML/ML1.py
[2025-04-23T20:51:19.078+0000] {processor.py:208} INFO - Processing /opt/airflow/dags/ML/ML1.py took 0.378 seconds
[2025-04-23T20:51:49.388+0000] {processor.py:186} INFO - Started process (PID=2349) to work on /opt/airflow/dags/ML/ML1.py
[2025-04-23T20:51:49.389+0000] {processor.py:914} INFO - Processing file /opt/airflow/dags/ML/ML1.py for tasks to queue
[2025-04-23T20:51:49.393+0000] {logging_mixin.py:190} INFO - [2025-04-23T20:51:49.392+0000] {dagbag.py:588} INFO - Filling up the DagBag from /opt/airflow/dags/ML/ML1.py
[2025-04-23T20:51:49.670+0000] {logging_mixin.py:190} INFO - [2025-04-23T20:51:49.662+0000] {dagbag.py:387} ERROR - Failed to import: /opt/airflow/dags/ML/ML1.py
Traceback (most recent call last):
  File "/home/airflow/.local/lib/python3.12/site-packages/airflow/models/dagbag.py", line 383, in parse
    loader.exec_module(new_module)
  File "<frozen importlib._bootstrap_external>", line 999, in exec_module
  File "<frozen importlib._bootstrap>", line 488, in _call_with_frames_removed
  File "/opt/airflow/dags/ML/ML1.py", line 17, in <module>
    with DAG(
         ^^^^
  File "/home/airflow/.local/lib/python3.12/site-packages/airflow/models/dag.py", line 593, in __init__
    validate_key(dag_id)
  File "/home/airflow/.local/lib/python3.12/site-packages/airflow/utils/helpers.py", line 57, in validate_key
    raise AirflowException(
airflow.exceptions.AirflowException: The key 'ML 1' has to be made of alphanumeric characters, dashes, dots and underscores exclusively
[2025-04-23T20:51:49.671+0000] {processor.py:927} WARNING - No viable dags retrieved from /opt/airflow/dags/ML/ML1.py
[2025-04-23T20:51:49.743+0000] {processor.py:208} INFO - Processing /opt/airflow/dags/ML/ML1.py took 0.363 seconds
[2025-04-23T20:52:20.212+0000] {processor.py:186} INFO - Started process (PID=2378) to work on /opt/airflow/dags/ML/ML1.py
[2025-04-23T20:52:20.213+0000] {processor.py:914} INFO - Processing file /opt/airflow/dags/ML/ML1.py for tasks to queue
[2025-04-23T20:52:20.216+0000] {logging_mixin.py:190} INFO - [2025-04-23T20:52:20.216+0000] {dagbag.py:588} INFO - Filling up the DagBag from /opt/airflow/dags/ML/ML1.py
[2025-04-23T20:52:20.494+0000] {logging_mixin.py:190} INFO - [2025-04-23T20:52:20.483+0000] {dagbag.py:387} ERROR - Failed to import: /opt/airflow/dags/ML/ML1.py
Traceback (most recent call last):
  File "/home/airflow/.local/lib/python3.12/site-packages/airflow/models/dagbag.py", line 383, in parse
    loader.exec_module(new_module)
  File "<frozen importlib._bootstrap_external>", line 999, in exec_module
  File "<frozen importlib._bootstrap>", line 488, in _call_with_frames_removed
  File "/opt/airflow/dags/ML/ML1.py", line 17, in <module>
    with DAG(
         ^^^^
  File "/home/airflow/.local/lib/python3.12/site-packages/airflow/models/dag.py", line 593, in __init__
    validate_key(dag_id)
  File "/home/airflow/.local/lib/python3.12/site-packages/airflow/utils/helpers.py", line 57, in validate_key
    raise AirflowException(
airflow.exceptions.AirflowException: The key 'ML 1' has to be made of alphanumeric characters, dashes, dots and underscores exclusively
[2025-04-23T20:52:20.495+0000] {processor.py:927} WARNING - No viable dags retrieved from /opt/airflow/dags/ML/ML1.py
[2025-04-23T20:52:20.574+0000] {processor.py:208} INFO - Processing /opt/airflow/dags/ML/ML1.py took 0.367 seconds
[2025-04-23T20:52:50.809+0000] {processor.py:186} INFO - Started process (PID=2407) to work on /opt/airflow/dags/ML/ML1.py
[2025-04-23T20:52:50.810+0000] {processor.py:914} INFO - Processing file /opt/airflow/dags/ML/ML1.py for tasks to queue
[2025-04-23T20:52:50.812+0000] {logging_mixin.py:190} INFO - [2025-04-23T20:52:50.812+0000] {dagbag.py:588} INFO - Filling up the DagBag from /opt/airflow/dags/ML/ML1.py
[2025-04-23T20:52:51.106+0000] {logging_mixin.py:190} INFO - [2025-04-23T20:52:51.097+0000] {dagbag.py:387} ERROR - Failed to import: /opt/airflow/dags/ML/ML1.py
Traceback (most recent call last):
  File "/home/airflow/.local/lib/python3.12/site-packages/airflow/models/dagbag.py", line 383, in parse
    loader.exec_module(new_module)
  File "<frozen importlib._bootstrap_external>", line 999, in exec_module
  File "<frozen importlib._bootstrap>", line 488, in _call_with_frames_removed
  File "/opt/airflow/dags/ML/ML1.py", line 17, in <module>
    with DAG(
         ^^^^
  File "/home/airflow/.local/lib/python3.12/site-packages/airflow/models/dag.py", line 593, in __init__
    validate_key(dag_id)
  File "/home/airflow/.local/lib/python3.12/site-packages/airflow/utils/helpers.py", line 57, in validate_key
    raise AirflowException(
airflow.exceptions.AirflowException: The key 'ML 1' has to be made of alphanumeric characters, dashes, dots and underscores exclusively
[2025-04-23T20:52:51.107+0000] {processor.py:927} WARNING - No viable dags retrieved from /opt/airflow/dags/ML/ML1.py
[2025-04-23T20:52:51.180+0000] {processor.py:208} INFO - Processing /opt/airflow/dags/ML/ML1.py took 0.381 seconds
[2025-04-23T20:53:21.483+0000] {processor.py:186} INFO - Started process (PID=2442) to work on /opt/airflow/dags/ML/ML1.py
[2025-04-23T20:53:21.484+0000] {processor.py:914} INFO - Processing file /opt/airflow/dags/ML/ML1.py for tasks to queue
[2025-04-23T20:53:21.487+0000] {logging_mixin.py:190} INFO - [2025-04-23T20:53:21.487+0000] {dagbag.py:588} INFO - Filling up the DagBag from /opt/airflow/dags/ML/ML1.py
[2025-04-23T20:53:21.776+0000] {logging_mixin.py:190} INFO - [2025-04-23T20:53:21.766+0000] {dagbag.py:387} ERROR - Failed to import: /opt/airflow/dags/ML/ML1.py
Traceback (most recent call last):
  File "/home/airflow/.local/lib/python3.12/site-packages/airflow/models/dagbag.py", line 383, in parse
    loader.exec_module(new_module)
  File "<frozen importlib._bootstrap_external>", line 999, in exec_module
  File "<frozen importlib._bootstrap>", line 488, in _call_with_frames_removed
  File "/opt/airflow/dags/ML/ML1.py", line 17, in <module>
    with DAG(
         ^^^^
  File "/home/airflow/.local/lib/python3.12/site-packages/airflow/models/dag.py", line 593, in __init__
    validate_key(dag_id)
  File "/home/airflow/.local/lib/python3.12/site-packages/airflow/utils/helpers.py", line 57, in validate_key
    raise AirflowException(
airflow.exceptions.AirflowException: The key 'ML 1' has to be made of alphanumeric characters, dashes, dots and underscores exclusively
[2025-04-23T20:53:21.778+0000] {processor.py:927} WARNING - No viable dags retrieved from /opt/airflow/dags/ML/ML1.py
[2025-04-23T20:53:21.851+0000] {processor.py:208} INFO - Processing /opt/airflow/dags/ML/ML1.py took 0.374 seconds
[2025-04-23T20:53:52.213+0000] {processor.py:186} INFO - Started process (PID=2471) to work on /opt/airflow/dags/ML/ML1.py
[2025-04-23T20:53:52.215+0000] {processor.py:914} INFO - Processing file /opt/airflow/dags/ML/ML1.py for tasks to queue
[2025-04-23T20:53:52.219+0000] {logging_mixin.py:190} INFO - [2025-04-23T20:53:52.218+0000] {dagbag.py:588} INFO - Filling up the DagBag from /opt/airflow/dags/ML/ML1.py
[2025-04-23T20:53:52.491+0000] {logging_mixin.py:190} INFO - [2025-04-23T20:53:52.481+0000] {dagbag.py:387} ERROR - Failed to import: /opt/airflow/dags/ML/ML1.py
Traceback (most recent call last):
  File "/home/airflow/.local/lib/python3.12/site-packages/airflow/models/dagbag.py", line 383, in parse
    loader.exec_module(new_module)
  File "<frozen importlib._bootstrap_external>", line 999, in exec_module
  File "<frozen importlib._bootstrap>", line 488, in _call_with_frames_removed
  File "/opt/airflow/dags/ML/ML1.py", line 17, in <module>
    with DAG(
         ^^^^
  File "/home/airflow/.local/lib/python3.12/site-packages/airflow/models/dag.py", line 593, in __init__
    validate_key(dag_id)
  File "/home/airflow/.local/lib/python3.12/site-packages/airflow/utils/helpers.py", line 57, in validate_key
    raise AirflowException(
airflow.exceptions.AirflowException: The key 'ML 1' has to be made of alphanumeric characters, dashes, dots and underscores exclusively
[2025-04-23T20:53:52.492+0000] {processor.py:927} WARNING - No viable dags retrieved from /opt/airflow/dags/ML/ML1.py
[2025-04-23T20:53:52.555+0000] {processor.py:208} INFO - Processing /opt/airflow/dags/ML/ML1.py took 0.347 seconds
[2025-04-23T20:54:23.004+0000] {processor.py:186} INFO - Started process (PID=2500) to work on /opt/airflow/dags/ML/ML1.py
[2025-04-23T20:54:23.006+0000] {processor.py:914} INFO - Processing file /opt/airflow/dags/ML/ML1.py for tasks to queue
[2025-04-23T20:54:23.010+0000] {logging_mixin.py:190} INFO - [2025-04-23T20:54:23.009+0000] {dagbag.py:588} INFO - Filling up the DagBag from /opt/airflow/dags/ML/ML1.py
[2025-04-23T20:54:23.325+0000] {logging_mixin.py:190} INFO - [2025-04-23T20:54:23.315+0000] {dagbag.py:387} ERROR - Failed to import: /opt/airflow/dags/ML/ML1.py
Traceback (most recent call last):
  File "/home/airflow/.local/lib/python3.12/site-packages/airflow/models/dagbag.py", line 383, in parse
    loader.exec_module(new_module)
  File "<frozen importlib._bootstrap_external>", line 999, in exec_module
  File "<frozen importlib._bootstrap>", line 488, in _call_with_frames_removed
  File "/opt/airflow/dags/ML/ML1.py", line 17, in <module>
    with DAG(
         ^^^^
  File "/home/airflow/.local/lib/python3.12/site-packages/airflow/models/dag.py", line 593, in __init__
    validate_key(dag_id)
  File "/home/airflow/.local/lib/python3.12/site-packages/airflow/utils/helpers.py", line 57, in validate_key
    raise AirflowException(
airflow.exceptions.AirflowException: The key 'ML 1' has to be made of alphanumeric characters, dashes, dots and underscores exclusively
[2025-04-23T20:54:23.326+0000] {processor.py:927} WARNING - No viable dags retrieved from /opt/airflow/dags/ML/ML1.py
[2025-04-23T20:54:23.440+0000] {processor.py:208} INFO - Processing /opt/airflow/dags/ML/ML1.py took 0.444 seconds
[2025-04-23T20:54:53.547+0000] {processor.py:186} INFO - Started process (PID=2529) to work on /opt/airflow/dags/ML/ML1.py
[2025-04-23T20:54:53.549+0000] {processor.py:914} INFO - Processing file /opt/airflow/dags/ML/ML1.py for tasks to queue
[2025-04-23T20:54:53.552+0000] {logging_mixin.py:190} INFO - [2025-04-23T20:54:53.552+0000] {dagbag.py:588} INFO - Filling up the DagBag from /opt/airflow/dags/ML/ML1.py
[2025-04-23T20:54:53.845+0000] {logging_mixin.py:190} INFO - [2025-04-23T20:54:53.837+0000] {dagbag.py:387} ERROR - Failed to import: /opt/airflow/dags/ML/ML1.py
Traceback (most recent call last):
  File "/home/airflow/.local/lib/python3.12/site-packages/airflow/models/dagbag.py", line 383, in parse
    loader.exec_module(new_module)
  File "<frozen importlib._bootstrap_external>", line 999, in exec_module
  File "<frozen importlib._bootstrap>", line 488, in _call_with_frames_removed
  File "/opt/airflow/dags/ML/ML1.py", line 17, in <module>
    with DAG(
         ^^^^
  File "/home/airflow/.local/lib/python3.12/site-packages/airflow/models/dag.py", line 593, in __init__
    validate_key(dag_id)
  File "/home/airflow/.local/lib/python3.12/site-packages/airflow/utils/helpers.py", line 57, in validate_key
    raise AirflowException(
airflow.exceptions.AirflowException: The key 'ML 1' has to be made of alphanumeric characters, dashes, dots and underscores exclusively
[2025-04-23T20:54:53.846+0000] {processor.py:927} WARNING - No viable dags retrieved from /opt/airflow/dags/ML/ML1.py
[2025-04-23T20:54:53.913+0000] {processor.py:208} INFO - Processing /opt/airflow/dags/ML/ML1.py took 0.373 seconds
[2025-04-23T20:55:24.026+0000] {processor.py:186} INFO - Started process (PID=2558) to work on /opt/airflow/dags/ML/ML1.py
[2025-04-23T20:55:24.027+0000] {processor.py:914} INFO - Processing file /opt/airflow/dags/ML/ML1.py for tasks to queue
[2025-04-23T20:55:24.029+0000] {logging_mixin.py:190} INFO - [2025-04-23T20:55:24.029+0000] {dagbag.py:588} INFO - Filling up the DagBag from /opt/airflow/dags/ML/ML1.py
[2025-04-23T20:55:24.295+0000] {logging_mixin.py:190} INFO - [2025-04-23T20:55:24.284+0000] {dagbag.py:387} ERROR - Failed to import: /opt/airflow/dags/ML/ML1.py
Traceback (most recent call last):
  File "/home/airflow/.local/lib/python3.12/site-packages/airflow/models/dagbag.py", line 383, in parse
    loader.exec_module(new_module)
  File "<frozen importlib._bootstrap_external>", line 999, in exec_module
  File "<frozen importlib._bootstrap>", line 488, in _call_with_frames_removed
  File "/opt/airflow/dags/ML/ML1.py", line 17, in <module>
    with DAG(
         ^^^^
  File "/home/airflow/.local/lib/python3.12/site-packages/airflow/models/dag.py", line 593, in __init__
    validate_key(dag_id)
  File "/home/airflow/.local/lib/python3.12/site-packages/airflow/utils/helpers.py", line 57, in validate_key
    raise AirflowException(
airflow.exceptions.AirflowException: The key 'ML 1' has to be made of alphanumeric characters, dashes, dots and underscores exclusively
[2025-04-23T20:55:24.296+0000] {processor.py:927} WARNING - No viable dags retrieved from /opt/airflow/dags/ML/ML1.py
[2025-04-23T20:55:24.380+0000] {processor.py:208} INFO - Processing /opt/airflow/dags/ML/ML1.py took 0.362 seconds
[2025-04-23T20:55:54.569+0000] {processor.py:186} INFO - Started process (PID=2587) to work on /opt/airflow/dags/ML/ML1.py
[2025-04-23T20:55:54.572+0000] {processor.py:914} INFO - Processing file /opt/airflow/dags/ML/ML1.py for tasks to queue
[2025-04-23T20:55:54.577+0000] {logging_mixin.py:190} INFO - [2025-04-23T20:55:54.577+0000] {dagbag.py:588} INFO - Filling up the DagBag from /opt/airflow/dags/ML/ML1.py
[2025-04-23T20:55:54.950+0000] {logging_mixin.py:190} INFO - [2025-04-23T20:55:54.939+0000] {dagbag.py:387} ERROR - Failed to import: /opt/airflow/dags/ML/ML1.py
Traceback (most recent call last):
  File "/home/airflow/.local/lib/python3.12/site-packages/airflow/models/dagbag.py", line 383, in parse
    loader.exec_module(new_module)
  File "<frozen importlib._bootstrap_external>", line 999, in exec_module
  File "<frozen importlib._bootstrap>", line 488, in _call_with_frames_removed
  File "/opt/airflow/dags/ML/ML1.py", line 17, in <module>
    with DAG(
         ^^^^
  File "/home/airflow/.local/lib/python3.12/site-packages/airflow/models/dag.py", line 593, in __init__
    validate_key(dag_id)
  File "/home/airflow/.local/lib/python3.12/site-packages/airflow/utils/helpers.py", line 57, in validate_key
    raise AirflowException(
airflow.exceptions.AirflowException: The key 'ML 1' has to be made of alphanumeric characters, dashes, dots and underscores exclusively
[2025-04-23T20:55:54.952+0000] {processor.py:927} WARNING - No viable dags retrieved from /opt/airflow/dags/ML/ML1.py
[2025-04-23T20:55:55.071+0000] {processor.py:208} INFO - Processing /opt/airflow/dags/ML/ML1.py took 0.519 seconds
[2025-04-23T20:56:25.747+0000] {processor.py:186} INFO - Started process (PID=2616) to work on /opt/airflow/dags/ML/ML1.py
[2025-04-23T20:56:25.749+0000] {processor.py:914} INFO - Processing file /opt/airflow/dags/ML/ML1.py for tasks to queue
[2025-04-23T20:56:25.753+0000] {logging_mixin.py:190} INFO - [2025-04-23T20:56:25.753+0000] {dagbag.py:588} INFO - Filling up the DagBag from /opt/airflow/dags/ML/ML1.py
[2025-04-23T20:56:26.186+0000] {logging_mixin.py:190} INFO - [2025-04-23T20:56:26.177+0000] {dagbag.py:387} ERROR - Failed to import: /opt/airflow/dags/ML/ML1.py
Traceback (most recent call last):
  File "/home/airflow/.local/lib/python3.12/site-packages/airflow/models/dagbag.py", line 383, in parse
    loader.exec_module(new_module)
  File "<frozen importlib._bootstrap_external>", line 999, in exec_module
  File "<frozen importlib._bootstrap>", line 488, in _call_with_frames_removed
  File "/opt/airflow/dags/ML/ML1.py", line 17, in <module>
    with DAG(
         ^^^^
  File "/home/airflow/.local/lib/python3.12/site-packages/airflow/models/dag.py", line 593, in __init__
    validate_key(dag_id)
  File "/home/airflow/.local/lib/python3.12/site-packages/airflow/utils/helpers.py", line 57, in validate_key
    raise AirflowException(
airflow.exceptions.AirflowException: The key 'ML 1' has to be made of alphanumeric characters, dashes, dots and underscores exclusively
[2025-04-23T20:56:26.187+0000] {processor.py:927} WARNING - No viable dags retrieved from /opt/airflow/dags/ML/ML1.py
[2025-04-23T20:56:26.259+0000] {processor.py:208} INFO - Processing /opt/airflow/dags/ML/ML1.py took 0.521 seconds
[2025-04-23T20:56:56.890+0000] {processor.py:186} INFO - Started process (PID=2645) to work on /opt/airflow/dags/ML/ML1.py
[2025-04-23T20:56:56.892+0000] {processor.py:914} INFO - Processing file /opt/airflow/dags/ML/ML1.py for tasks to queue
[2025-04-23T20:56:56.895+0000] {logging_mixin.py:190} INFO - [2025-04-23T20:56:56.895+0000] {dagbag.py:588} INFO - Filling up the DagBag from /opt/airflow/dags/ML/ML1.py
[2025-04-23T20:56:57.175+0000] {logging_mixin.py:190} INFO - [2025-04-23T20:56:57.169+0000] {dagbag.py:387} ERROR - Failed to import: /opt/airflow/dags/ML/ML1.py
Traceback (most recent call last):
  File "/home/airflow/.local/lib/python3.12/site-packages/airflow/models/dagbag.py", line 383, in parse
    loader.exec_module(new_module)
  File "<frozen importlib._bootstrap_external>", line 999, in exec_module
  File "<frozen importlib._bootstrap>", line 488, in _call_with_frames_removed
  File "/opt/airflow/dags/ML/ML1.py", line 17, in <module>
    with DAG(
         ^^^^
  File "/home/airflow/.local/lib/python3.12/site-packages/airflow/models/dag.py", line 593, in __init__
    validate_key(dag_id)
  File "/home/airflow/.local/lib/python3.12/site-packages/airflow/utils/helpers.py", line 57, in validate_key
    raise AirflowException(
airflow.exceptions.AirflowException: The key 'ML 1' has to be made of alphanumeric characters, dashes, dots and underscores exclusively
[2025-04-23T20:56:57.176+0000] {processor.py:927} WARNING - No viable dags retrieved from /opt/airflow/dags/ML/ML1.py
[2025-04-23T20:56:57.255+0000] {processor.py:208} INFO - Processing /opt/airflow/dags/ML/ML1.py took 0.371 seconds
[2025-04-23T20:57:27.607+0000] {processor.py:186} INFO - Started process (PID=2674) to work on /opt/airflow/dags/ML/ML1.py
[2025-04-23T20:57:27.608+0000] {processor.py:914} INFO - Processing file /opt/airflow/dags/ML/ML1.py for tasks to queue
[2025-04-23T20:57:27.610+0000] {logging_mixin.py:190} INFO - [2025-04-23T20:57:27.610+0000] {dagbag.py:588} INFO - Filling up the DagBag from /opt/airflow/dags/ML/ML1.py
[2025-04-23T20:57:27.890+0000] {logging_mixin.py:190} INFO - [2025-04-23T20:57:27.879+0000] {dagbag.py:387} ERROR - Failed to import: /opt/airflow/dags/ML/ML1.py
Traceback (most recent call last):
  File "/home/airflow/.local/lib/python3.12/site-packages/airflow/models/dagbag.py", line 383, in parse
    loader.exec_module(new_module)
  File "<frozen importlib._bootstrap_external>", line 999, in exec_module
  File "<frozen importlib._bootstrap>", line 488, in _call_with_frames_removed
  File "/opt/airflow/dags/ML/ML1.py", line 17, in <module>
    with DAG(
         ^^^^
  File "/home/airflow/.local/lib/python3.12/site-packages/airflow/models/dag.py", line 593, in __init__
    validate_key(dag_id)
  File "/home/airflow/.local/lib/python3.12/site-packages/airflow/utils/helpers.py", line 57, in validate_key
    raise AirflowException(
airflow.exceptions.AirflowException: The key 'ML 1' has to be made of alphanumeric characters, dashes, dots and underscores exclusively
[2025-04-23T20:57:27.891+0000] {processor.py:927} WARNING - No viable dags retrieved from /opt/airflow/dags/ML/ML1.py
[2025-04-23T20:57:27.958+0000] {processor.py:208} INFO - Processing /opt/airflow/dags/ML/ML1.py took 0.357 seconds
[2025-04-23T20:57:58.142+0000] {processor.py:186} INFO - Started process (PID=2703) to work on /opt/airflow/dags/ML/ML1.py
[2025-04-23T20:57:58.144+0000] {processor.py:914} INFO - Processing file /opt/airflow/dags/ML/ML1.py for tasks to queue
[2025-04-23T20:57:58.146+0000] {logging_mixin.py:190} INFO - [2025-04-23T20:57:58.146+0000] {dagbag.py:588} INFO - Filling up the DagBag from /opt/airflow/dags/ML/ML1.py
[2025-04-23T20:57:58.425+0000] {logging_mixin.py:190} INFO - [2025-04-23T20:57:58.415+0000] {dagbag.py:387} ERROR - Failed to import: /opt/airflow/dags/ML/ML1.py
Traceback (most recent call last):
  File "/home/airflow/.local/lib/python3.12/site-packages/airflow/models/dagbag.py", line 383, in parse
    loader.exec_module(new_module)
  File "<frozen importlib._bootstrap_external>", line 999, in exec_module
  File "<frozen importlib._bootstrap>", line 488, in _call_with_frames_removed
  File "/opt/airflow/dags/ML/ML1.py", line 17, in <module>
    with DAG(
         ^^^^
  File "/home/airflow/.local/lib/python3.12/site-packages/airflow/models/dag.py", line 593, in __init__
    validate_key(dag_id)
  File "/home/airflow/.local/lib/python3.12/site-packages/airflow/utils/helpers.py", line 57, in validate_key
    raise AirflowException(
airflow.exceptions.AirflowException: The key 'ML 1' has to be made of alphanumeric characters, dashes, dots and underscores exclusively
[2025-04-23T20:57:58.426+0000] {processor.py:927} WARNING - No viable dags retrieved from /opt/airflow/dags/ML/ML1.py
[2025-04-23T20:57:58.500+0000] {processor.py:208} INFO - Processing /opt/airflow/dags/ML/ML1.py took 0.364 seconds
[2025-04-23T20:58:29.028+0000] {processor.py:186} INFO - Started process (PID=2732) to work on /opt/airflow/dags/ML/ML1.py
[2025-04-23T20:58:29.029+0000] {processor.py:914} INFO - Processing file /opt/airflow/dags/ML/ML1.py for tasks to queue
[2025-04-23T20:58:29.032+0000] {logging_mixin.py:190} INFO - [2025-04-23T20:58:29.032+0000] {dagbag.py:588} INFO - Filling up the DagBag from /opt/airflow/dags/ML/ML1.py
[2025-04-23T20:58:29.341+0000] {logging_mixin.py:190} INFO - [2025-04-23T20:58:29.333+0000] {dagbag.py:387} ERROR - Failed to import: /opt/airflow/dags/ML/ML1.py
Traceback (most recent call last):
  File "/home/airflow/.local/lib/python3.12/site-packages/airflow/models/dagbag.py", line 383, in parse
    loader.exec_module(new_module)
  File "<frozen importlib._bootstrap_external>", line 999, in exec_module
  File "<frozen importlib._bootstrap>", line 488, in _call_with_frames_removed
  File "/opt/airflow/dags/ML/ML1.py", line 17, in <module>
    with DAG(
         ^^^^
  File "/home/airflow/.local/lib/python3.12/site-packages/airflow/models/dag.py", line 593, in __init__
    validate_key(dag_id)
  File "/home/airflow/.local/lib/python3.12/site-packages/airflow/utils/helpers.py", line 57, in validate_key
    raise AirflowException(
airflow.exceptions.AirflowException: The key 'ML 1' has to be made of alphanumeric characters, dashes, dots and underscores exclusively
[2025-04-23T20:58:29.342+0000] {processor.py:927} WARNING - No viable dags retrieved from /opt/airflow/dags/ML/ML1.py
[2025-04-23T20:58:29.407+0000] {processor.py:208} INFO - Processing /opt/airflow/dags/ML/ML1.py took 0.393 seconds
[2025-04-23T20:58:59.590+0000] {processor.py:186} INFO - Started process (PID=2761) to work on /opt/airflow/dags/ML/ML1.py
[2025-04-23T20:58:59.591+0000] {processor.py:914} INFO - Processing file /opt/airflow/dags/ML/ML1.py for tasks to queue
[2025-04-23T20:58:59.594+0000] {logging_mixin.py:190} INFO - [2025-04-23T20:58:59.594+0000] {dagbag.py:588} INFO - Filling up the DagBag from /opt/airflow/dags/ML/ML1.py
[2025-04-23T20:58:59.864+0000] {logging_mixin.py:190} INFO - [2025-04-23T20:58:59.857+0000] {dagbag.py:387} ERROR - Failed to import: /opt/airflow/dags/ML/ML1.py
Traceback (most recent call last):
  File "/home/airflow/.local/lib/python3.12/site-packages/airflow/models/dagbag.py", line 383, in parse
    loader.exec_module(new_module)
  File "<frozen importlib._bootstrap_external>", line 999, in exec_module
  File "<frozen importlib._bootstrap>", line 488, in _call_with_frames_removed
  File "/opt/airflow/dags/ML/ML1.py", line 17, in <module>
    with DAG(
         ^^^^
  File "/home/airflow/.local/lib/python3.12/site-packages/airflow/models/dag.py", line 593, in __init__
    validate_key(dag_id)
  File "/home/airflow/.local/lib/python3.12/site-packages/airflow/utils/helpers.py", line 57, in validate_key
    raise AirflowException(
airflow.exceptions.AirflowException: The key 'ML 1' has to be made of alphanumeric characters, dashes, dots and underscores exclusively
[2025-04-23T20:58:59.865+0000] {processor.py:927} WARNING - No viable dags retrieved from /opt/airflow/dags/ML/ML1.py
[2025-04-23T20:58:59.936+0000] {processor.py:208} INFO - Processing /opt/airflow/dags/ML/ML1.py took 0.351 seconds
[2025-04-23T20:59:30.268+0000] {processor.py:186} INFO - Started process (PID=2790) to work on /opt/airflow/dags/ML/ML1.py
[2025-04-23T20:59:30.270+0000] {processor.py:914} INFO - Processing file /opt/airflow/dags/ML/ML1.py for tasks to queue
[2025-04-23T20:59:30.279+0000] {logging_mixin.py:190} INFO - [2025-04-23T20:59:30.278+0000] {dagbag.py:588} INFO - Filling up the DagBag from /opt/airflow/dags/ML/ML1.py
[2025-04-23T20:59:30.549+0000] {logging_mixin.py:190} INFO - [2025-04-23T20:59:30.541+0000] {dagbag.py:387} ERROR - Failed to import: /opt/airflow/dags/ML/ML1.py
Traceback (most recent call last):
  File "/home/airflow/.local/lib/python3.12/site-packages/airflow/models/dagbag.py", line 383, in parse
    loader.exec_module(new_module)
  File "<frozen importlib._bootstrap_external>", line 999, in exec_module
  File "<frozen importlib._bootstrap>", line 488, in _call_with_frames_removed
  File "/opt/airflow/dags/ML/ML1.py", line 17, in <module>
    with DAG(
         ^^^^
  File "/home/airflow/.local/lib/python3.12/site-packages/airflow/models/dag.py", line 593, in __init__
    validate_key(dag_id)
  File "/home/airflow/.local/lib/python3.12/site-packages/airflow/utils/helpers.py", line 57, in validate_key
    raise AirflowException(
airflow.exceptions.AirflowException: The key 'ML 1' has to be made of alphanumeric characters, dashes, dots and underscores exclusively
[2025-04-23T20:59:30.550+0000] {processor.py:927} WARNING - No viable dags retrieved from /opt/airflow/dags/ML/ML1.py
[2025-04-23T20:59:30.636+0000] {processor.py:208} INFO - Processing /opt/airflow/dags/ML/ML1.py took 0.375 seconds
[2025-04-23T21:00:01.124+0000] {processor.py:186} INFO - Started process (PID=2818) to work on /opt/airflow/dags/ML/ML1.py
[2025-04-23T21:00:01.125+0000] {processor.py:914} INFO - Processing file /opt/airflow/dags/ML/ML1.py for tasks to queue
[2025-04-23T21:00:01.127+0000] {logging_mixin.py:190} INFO - [2025-04-23T21:00:01.127+0000] {dagbag.py:588} INFO - Filling up the DagBag from /opt/airflow/dags/ML/ML1.py
[2025-04-23T21:00:01.405+0000] {logging_mixin.py:190} INFO - [2025-04-23T21:00:01.390+0000] {dagbag.py:387} ERROR - Failed to import: /opt/airflow/dags/ML/ML1.py
Traceback (most recent call last):
  File "/home/airflow/.local/lib/python3.12/site-packages/airflow/models/dagbag.py", line 383, in parse
    loader.exec_module(new_module)
  File "<frozen importlib._bootstrap_external>", line 999, in exec_module
  File "<frozen importlib._bootstrap>", line 488, in _call_with_frames_removed
  File "/opt/airflow/dags/ML/ML1.py", line 17, in <module>
    with DAG(
         ^^^^
  File "/home/airflow/.local/lib/python3.12/site-packages/airflow/models/dag.py", line 593, in __init__
    validate_key(dag_id)
  File "/home/airflow/.local/lib/python3.12/site-packages/airflow/utils/helpers.py", line 57, in validate_key
    raise AirflowException(
airflow.exceptions.AirflowException: The key 'ML 1' has to be made of alphanumeric characters, dashes, dots and underscores exclusively
[2025-04-23T21:00:01.406+0000] {processor.py:927} WARNING - No viable dags retrieved from /opt/airflow/dags/ML/ML1.py
[2025-04-23T21:00:01.501+0000] {processor.py:208} INFO - Processing /opt/airflow/dags/ML/ML1.py took 0.383 seconds
[2025-04-23T21:00:32.022+0000] {processor.py:186} INFO - Started process (PID=2847) to work on /opt/airflow/dags/ML/ML1.py
[2025-04-23T21:00:32.023+0000] {processor.py:914} INFO - Processing file /opt/airflow/dags/ML/ML1.py for tasks to queue
[2025-04-23T21:00:32.026+0000] {logging_mixin.py:190} INFO - [2025-04-23T21:00:32.025+0000] {dagbag.py:588} INFO - Filling up the DagBag from /opt/airflow/dags/ML/ML1.py
[2025-04-23T21:00:32.380+0000] {logging_mixin.py:190} INFO - [2025-04-23T21:00:32.373+0000] {dagbag.py:387} ERROR - Failed to import: /opt/airflow/dags/ML/ML1.py
Traceback (most recent call last):
  File "/home/airflow/.local/lib/python3.12/site-packages/airflow/models/dagbag.py", line 383, in parse
    loader.exec_module(new_module)
  File "<frozen importlib._bootstrap_external>", line 999, in exec_module
  File "<frozen importlib._bootstrap>", line 488, in _call_with_frames_removed
  File "/opt/airflow/dags/ML/ML1.py", line 17, in <module>
    with DAG(
         ^^^^
  File "/home/airflow/.local/lib/python3.12/site-packages/airflow/models/dag.py", line 593, in __init__
    validate_key(dag_id)
  File "/home/airflow/.local/lib/python3.12/site-packages/airflow/utils/helpers.py", line 57, in validate_key
    raise AirflowException(
airflow.exceptions.AirflowException: The key 'ML 1' has to be made of alphanumeric characters, dashes, dots and underscores exclusively
[2025-04-23T21:00:32.381+0000] {processor.py:927} WARNING - No viable dags retrieved from /opt/airflow/dags/ML/ML1.py
[2025-04-23T21:00:32.443+0000] {processor.py:208} INFO - Processing /opt/airflow/dags/ML/ML1.py took 0.431 seconds
[2025-04-23T21:01:03.009+0000] {processor.py:186} INFO - Started process (PID=2876) to work on /opt/airflow/dags/ML/ML1.py
[2025-04-23T21:01:03.010+0000] {processor.py:914} INFO - Processing file /opt/airflow/dags/ML/ML1.py for tasks to queue
[2025-04-23T21:01:03.012+0000] {logging_mixin.py:190} INFO - [2025-04-23T21:01:03.012+0000] {dagbag.py:588} INFO - Filling up the DagBag from /opt/airflow/dags/ML/ML1.py
[2025-04-23T21:01:03.280+0000] {logging_mixin.py:190} INFO - [2025-04-23T21:01:03.270+0000] {dagbag.py:387} ERROR - Failed to import: /opt/airflow/dags/ML/ML1.py
Traceback (most recent call last):
  File "/home/airflow/.local/lib/python3.12/site-packages/airflow/models/dagbag.py", line 383, in parse
    loader.exec_module(new_module)
  File "<frozen importlib._bootstrap_external>", line 999, in exec_module
  File "<frozen importlib._bootstrap>", line 488, in _call_with_frames_removed
  File "/opt/airflow/dags/ML/ML1.py", line 17, in <module>
    with DAG(
         ^^^^
  File "/home/airflow/.local/lib/python3.12/site-packages/airflow/models/dag.py", line 593, in __init__
    validate_key(dag_id)
  File "/home/airflow/.local/lib/python3.12/site-packages/airflow/utils/helpers.py", line 57, in validate_key
    raise AirflowException(
airflow.exceptions.AirflowException: The key 'ML 1' has to be made of alphanumeric characters, dashes, dots and underscores exclusively
[2025-04-23T21:01:03.281+0000] {processor.py:927} WARNING - No viable dags retrieved from /opt/airflow/dags/ML/ML1.py
[2025-04-23T21:01:03.356+0000] {processor.py:208} INFO - Processing /opt/airflow/dags/ML/ML1.py took 0.353 seconds
[2025-04-23T21:01:33.459+0000] {processor.py:186} INFO - Started process (PID=2905) to work on /opt/airflow/dags/ML/ML1.py
[2025-04-23T21:01:33.460+0000] {processor.py:914} INFO - Processing file /opt/airflow/dags/ML/ML1.py for tasks to queue
[2025-04-23T21:01:33.463+0000] {logging_mixin.py:190} INFO - [2025-04-23T21:01:33.463+0000] {dagbag.py:588} INFO - Filling up the DagBag from /opt/airflow/dags/ML/ML1.py
[2025-04-23T21:01:33.750+0000] {logging_mixin.py:190} INFO - [2025-04-23T21:01:33.741+0000] {dagbag.py:387} ERROR - Failed to import: /opt/airflow/dags/ML/ML1.py
Traceback (most recent call last):
  File "/home/airflow/.local/lib/python3.12/site-packages/airflow/models/dagbag.py", line 383, in parse
    loader.exec_module(new_module)
  File "<frozen importlib._bootstrap_external>", line 999, in exec_module
  File "<frozen importlib._bootstrap>", line 488, in _call_with_frames_removed
  File "/opt/airflow/dags/ML/ML1.py", line 17, in <module>
    with DAG(
         ^^^^
  File "/home/airflow/.local/lib/python3.12/site-packages/airflow/models/dag.py", line 593, in __init__
    validate_key(dag_id)
  File "/home/airflow/.local/lib/python3.12/site-packages/airflow/utils/helpers.py", line 57, in validate_key
    raise AirflowException(
airflow.exceptions.AirflowException: The key 'ML 1' has to be made of alphanumeric characters, dashes, dots and underscores exclusively
[2025-04-23T21:01:33.751+0000] {processor.py:927} WARNING - No viable dags retrieved from /opt/airflow/dags/ML/ML1.py
[2025-04-23T21:01:33.823+0000] {processor.py:208} INFO - Processing /opt/airflow/dags/ML/ML1.py took 0.370 seconds
[2025-04-23T21:02:04.139+0000] {processor.py:186} INFO - Started process (PID=2934) to work on /opt/airflow/dags/ML/ML1.py
[2025-04-23T21:02:04.141+0000] {processor.py:914} INFO - Processing file /opt/airflow/dags/ML/ML1.py for tasks to queue
[2025-04-23T21:02:04.144+0000] {logging_mixin.py:190} INFO - [2025-04-23T21:02:04.143+0000] {dagbag.py:588} INFO - Filling up the DagBag from /opt/airflow/dags/ML/ML1.py
[2025-04-23T21:02:04.444+0000] {logging_mixin.py:190} INFO - [2025-04-23T21:02:04.435+0000] {dagbag.py:387} ERROR - Failed to import: /opt/airflow/dags/ML/ML1.py
Traceback (most recent call last):
  File "/home/airflow/.local/lib/python3.12/site-packages/airflow/models/dagbag.py", line 383, in parse
    loader.exec_module(new_module)
  File "<frozen importlib._bootstrap_external>", line 999, in exec_module
  File "<frozen importlib._bootstrap>", line 488, in _call_with_frames_removed
  File "/opt/airflow/dags/ML/ML1.py", line 17, in <module>
    with DAG(
         ^^^^
  File "/home/airflow/.local/lib/python3.12/site-packages/airflow/models/dag.py", line 593, in __init__
    validate_key(dag_id)
  File "/home/airflow/.local/lib/python3.12/site-packages/airflow/utils/helpers.py", line 57, in validate_key
    raise AirflowException(
airflow.exceptions.AirflowException: The key 'ML 1' has to be made of alphanumeric characters, dashes, dots and underscores exclusively
[2025-04-23T21:02:04.445+0000] {processor.py:927} WARNING - No viable dags retrieved from /opt/airflow/dags/ML/ML1.py
[2025-04-23T21:02:04.519+0000] {processor.py:208} INFO - Processing /opt/airflow/dags/ML/ML1.py took 0.385 seconds
[2025-04-23T21:02:34.816+0000] {processor.py:186} INFO - Started process (PID=2963) to work on /opt/airflow/dags/ML/ML1.py
[2025-04-23T21:02:34.820+0000] {processor.py:914} INFO - Processing file /opt/airflow/dags/ML/ML1.py for tasks to queue
[2025-04-23T21:02:34.823+0000] {logging_mixin.py:190} INFO - [2025-04-23T21:02:34.823+0000] {dagbag.py:588} INFO - Filling up the DagBag from /opt/airflow/dags/ML/ML1.py
[2025-04-23T21:02:35.108+0000] {logging_mixin.py:190} INFO - [2025-04-23T21:02:35.098+0000] {dagbag.py:387} ERROR - Failed to import: /opt/airflow/dags/ML/ML1.py
Traceback (most recent call last):
  File "/home/airflow/.local/lib/python3.12/site-packages/airflow/models/dagbag.py", line 383, in parse
    loader.exec_module(new_module)
  File "<frozen importlib._bootstrap_external>", line 999, in exec_module
  File "<frozen importlib._bootstrap>", line 488, in _call_with_frames_removed
  File "/opt/airflow/dags/ML/ML1.py", line 17, in <module>
    with DAG(
         ^^^^
  File "/home/airflow/.local/lib/python3.12/site-packages/airflow/models/dag.py", line 593, in __init__
    validate_key(dag_id)
  File "/home/airflow/.local/lib/python3.12/site-packages/airflow/utils/helpers.py", line 57, in validate_key
    raise AirflowException(
airflow.exceptions.AirflowException: The key 'ML 1' has to be made of alphanumeric characters, dashes, dots and underscores exclusively
[2025-04-23T21:02:35.109+0000] {processor.py:927} WARNING - No viable dags retrieved from /opt/airflow/dags/ML/ML1.py
[2025-04-23T21:02:35.174+0000] {processor.py:208} INFO - Processing /opt/airflow/dags/ML/ML1.py took 0.368 seconds
[2025-04-23T21:03:05.800+0000] {processor.py:186} INFO - Started process (PID=2992) to work on /opt/airflow/dags/ML/ML1.py
[2025-04-23T21:03:05.802+0000] {processor.py:914} INFO - Processing file /opt/airflow/dags/ML/ML1.py for tasks to queue
[2025-04-23T21:03:05.804+0000] {logging_mixin.py:190} INFO - [2025-04-23T21:03:05.803+0000] {dagbag.py:588} INFO - Filling up the DagBag from /opt/airflow/dags/ML/ML1.py
[2025-04-23T21:03:06.071+0000] {logging_mixin.py:190} INFO - [2025-04-23T21:03:06.064+0000] {dagbag.py:387} ERROR - Failed to import: /opt/airflow/dags/ML/ML1.py
Traceback (most recent call last):
  File "/home/airflow/.local/lib/python3.12/site-packages/airflow/models/dagbag.py", line 383, in parse
    loader.exec_module(new_module)
  File "<frozen importlib._bootstrap_external>", line 999, in exec_module
  File "<frozen importlib._bootstrap>", line 488, in _call_with_frames_removed
  File "/opt/airflow/dags/ML/ML1.py", line 17, in <module>
    with DAG(
         ^^^^
  File "/home/airflow/.local/lib/python3.12/site-packages/airflow/models/dag.py", line 593, in __init__
    validate_key(dag_id)
  File "/home/airflow/.local/lib/python3.12/site-packages/airflow/utils/helpers.py", line 57, in validate_key
    raise AirflowException(
airflow.exceptions.AirflowException: The key 'ML 1' has to be made of alphanumeric characters, dashes, dots and underscores exclusively
[2025-04-23T21:03:06.072+0000] {processor.py:927} WARNING - No viable dags retrieved from /opt/airflow/dags/ML/ML1.py
[2025-04-23T21:03:06.135+0000] {processor.py:208} INFO - Processing /opt/airflow/dags/ML/ML1.py took 0.341 seconds
[2025-04-23T21:03:36.538+0000] {processor.py:186} INFO - Started process (PID=3020) to work on /opt/airflow/dags/ML/ML1.py
[2025-04-23T21:03:36.539+0000] {processor.py:914} INFO - Processing file /opt/airflow/dags/ML/ML1.py for tasks to queue
[2025-04-23T21:03:36.541+0000] {logging_mixin.py:190} INFO - [2025-04-23T21:03:36.541+0000] {dagbag.py:588} INFO - Filling up the DagBag from /opt/airflow/dags/ML/ML1.py
[2025-04-23T21:03:36.801+0000] {logging_mixin.py:190} INFO - [2025-04-23T21:03:36.794+0000] {dagbag.py:387} ERROR - Failed to import: /opt/airflow/dags/ML/ML1.py
Traceback (most recent call last):
  File "/home/airflow/.local/lib/python3.12/site-packages/airflow/models/dagbag.py", line 383, in parse
    loader.exec_module(new_module)
  File "<frozen importlib._bootstrap_external>", line 999, in exec_module
  File "<frozen importlib._bootstrap>", line 488, in _call_with_frames_removed
  File "/opt/airflow/dags/ML/ML1.py", line 17, in <module>
    with DAG(
         ^^^^
  File "/home/airflow/.local/lib/python3.12/site-packages/airflow/models/dag.py", line 593, in __init__
    validate_key(dag_id)
  File "/home/airflow/.local/lib/python3.12/site-packages/airflow/utils/helpers.py", line 57, in validate_key
    raise AirflowException(
airflow.exceptions.AirflowException: The key 'ML 1' has to be made of alphanumeric characters, dashes, dots and underscores exclusively
[2025-04-23T21:03:36.803+0000] {processor.py:927} WARNING - No viable dags retrieved from /opt/airflow/dags/ML/ML1.py
[2025-04-23T21:03:36.882+0000] {processor.py:208} INFO - Processing /opt/airflow/dags/ML/ML1.py took 0.350 seconds
[2025-04-23T21:04:07.046+0000] {processor.py:186} INFO - Started process (PID=3049) to work on /opt/airflow/dags/ML/ML1.py
[2025-04-23T21:04:07.047+0000] {processor.py:914} INFO - Processing file /opt/airflow/dags/ML/ML1.py for tasks to queue
[2025-04-23T21:04:07.050+0000] {logging_mixin.py:190} INFO - [2025-04-23T21:04:07.049+0000] {dagbag.py:588} INFO - Filling up the DagBag from /opt/airflow/dags/ML/ML1.py
[2025-04-23T21:04:07.332+0000] {logging_mixin.py:190} INFO - [2025-04-23T21:04:07.324+0000] {dagbag.py:387} ERROR - Failed to import: /opt/airflow/dags/ML/ML1.py
Traceback (most recent call last):
  File "/home/airflow/.local/lib/python3.12/site-packages/airflow/models/dagbag.py", line 383, in parse
    loader.exec_module(new_module)
  File "<frozen importlib._bootstrap_external>", line 999, in exec_module
  File "<frozen importlib._bootstrap>", line 488, in _call_with_frames_removed
  File "/opt/airflow/dags/ML/ML1.py", line 17, in <module>
    with DAG(
         ^^^^
  File "/home/airflow/.local/lib/python3.12/site-packages/airflow/models/dag.py", line 593, in __init__
    validate_key(dag_id)
  File "/home/airflow/.local/lib/python3.12/site-packages/airflow/utils/helpers.py", line 57, in validate_key
    raise AirflowException(
airflow.exceptions.AirflowException: The key 'ML 1' has to be made of alphanumeric characters, dashes, dots and underscores exclusively
[2025-04-23T21:04:07.333+0000] {processor.py:927} WARNING - No viable dags retrieved from /opt/airflow/dags/ML/ML1.py
[2025-04-23T21:04:07.412+0000] {processor.py:208} INFO - Processing /opt/airflow/dags/ML/ML1.py took 0.372 seconds
[2025-04-23T21:04:37.646+0000] {processor.py:186} INFO - Started process (PID=3078) to work on /opt/airflow/dags/ML/ML1.py
[2025-04-23T21:04:37.647+0000] {processor.py:914} INFO - Processing file /opt/airflow/dags/ML/ML1.py for tasks to queue
[2025-04-23T21:04:37.650+0000] {logging_mixin.py:190} INFO - [2025-04-23T21:04:37.649+0000] {dagbag.py:588} INFO - Filling up the DagBag from /opt/airflow/dags/ML/ML1.py
[2025-04-23T21:04:37.971+0000] {logging_mixin.py:190} INFO - [2025-04-23T21:04:37.961+0000] {dagbag.py:387} ERROR - Failed to import: /opt/airflow/dags/ML/ML1.py
Traceback (most recent call last):
  File "/home/airflow/.local/lib/python3.12/site-packages/airflow/models/dagbag.py", line 383, in parse
    loader.exec_module(new_module)
  File "<frozen importlib._bootstrap_external>", line 999, in exec_module
  File "<frozen importlib._bootstrap>", line 488, in _call_with_frames_removed
  File "/opt/airflow/dags/ML/ML1.py", line 17, in <module>
    with DAG(
         ^^^^
  File "/home/airflow/.local/lib/python3.12/site-packages/airflow/models/dag.py", line 593, in __init__
    validate_key(dag_id)
  File "/home/airflow/.local/lib/python3.12/site-packages/airflow/utils/helpers.py", line 57, in validate_key
    raise AirflowException(
airflow.exceptions.AirflowException: The key 'ML 1' has to be made of alphanumeric characters, dashes, dots and underscores exclusively
[2025-04-23T21:04:37.972+0000] {processor.py:927} WARNING - No viable dags retrieved from /opt/airflow/dags/ML/ML1.py
[2025-04-23T21:04:38.051+0000] {processor.py:208} INFO - Processing /opt/airflow/dags/ML/ML1.py took 0.412 seconds
[2025-04-23T21:05:08.247+0000] {processor.py:186} INFO - Started process (PID=3107) to work on /opt/airflow/dags/ML/ML1.py
[2025-04-23T21:05:08.249+0000] {processor.py:914} INFO - Processing file /opt/airflow/dags/ML/ML1.py for tasks to queue
[2025-04-23T21:05:08.251+0000] {logging_mixin.py:190} INFO - [2025-04-23T21:05:08.250+0000] {dagbag.py:588} INFO - Filling up the DagBag from /opt/airflow/dags/ML/ML1.py
[2025-04-23T21:05:08.526+0000] {logging_mixin.py:190} INFO - [2025-04-23T21:05:08.518+0000] {dagbag.py:387} ERROR - Failed to import: /opt/airflow/dags/ML/ML1.py
Traceback (most recent call last):
  File "/home/airflow/.local/lib/python3.12/site-packages/airflow/models/dagbag.py", line 383, in parse
    loader.exec_module(new_module)
  File "<frozen importlib._bootstrap_external>", line 999, in exec_module
  File "<frozen importlib._bootstrap>", line 488, in _call_with_frames_removed
  File "/opt/airflow/dags/ML/ML1.py", line 17, in <module>
    with DAG(
         ^^^^
  File "/home/airflow/.local/lib/python3.12/site-packages/airflow/models/dag.py", line 593, in __init__
    validate_key(dag_id)
  File "/home/airflow/.local/lib/python3.12/site-packages/airflow/utils/helpers.py", line 57, in validate_key
    raise AirflowException(
airflow.exceptions.AirflowException: The key 'ML 1' has to be made of alphanumeric characters, dashes, dots and underscores exclusively
[2025-04-23T21:05:08.527+0000] {processor.py:927} WARNING - No viable dags retrieved from /opt/airflow/dags/ML/ML1.py
[2025-04-23T21:05:08.593+0000] {processor.py:208} INFO - Processing /opt/airflow/dags/ML/ML1.py took 0.352 seconds
[2025-04-23T21:05:39.299+0000] {processor.py:186} INFO - Started process (PID=3136) to work on /opt/airflow/dags/ML/ML1.py
[2025-04-23T21:05:39.301+0000] {processor.py:914} INFO - Processing file /opt/airflow/dags/ML/ML1.py for tasks to queue
[2025-04-23T21:05:39.304+0000] {logging_mixin.py:190} INFO - [2025-04-23T21:05:39.303+0000] {dagbag.py:588} INFO - Filling up the DagBag from /opt/airflow/dags/ML/ML1.py
[2025-04-23T21:05:39.578+0000] {logging_mixin.py:190} INFO - [2025-04-23T21:05:39.568+0000] {dagbag.py:387} ERROR - Failed to import: /opt/airflow/dags/ML/ML1.py
Traceback (most recent call last):
  File "/home/airflow/.local/lib/python3.12/site-packages/airflow/models/dagbag.py", line 383, in parse
    loader.exec_module(new_module)
  File "<frozen importlib._bootstrap_external>", line 999, in exec_module
  File "<frozen importlib._bootstrap>", line 488, in _call_with_frames_removed
  File "/opt/airflow/dags/ML/ML1.py", line 17, in <module>
    with DAG(
         ^^^^
  File "/home/airflow/.local/lib/python3.12/site-packages/airflow/models/dag.py", line 593, in __init__
    validate_key(dag_id)
  File "/home/airflow/.local/lib/python3.12/site-packages/airflow/utils/helpers.py", line 57, in validate_key
    raise AirflowException(
airflow.exceptions.AirflowException: The key 'ML 1' has to be made of alphanumeric characters, dashes, dots and underscores exclusively
[2025-04-23T21:05:39.579+0000] {processor.py:927} WARNING - No viable dags retrieved from /opt/airflow/dags/ML/ML1.py
[2025-04-23T21:05:39.669+0000] {processor.py:208} INFO - Processing /opt/airflow/dags/ML/ML1.py took 0.376 seconds
[2025-04-23T21:06:10.135+0000] {processor.py:186} INFO - Started process (PID=3165) to work on /opt/airflow/dags/ML/ML1.py
[2025-04-23T21:06:10.138+0000] {processor.py:914} INFO - Processing file /opt/airflow/dags/ML/ML1.py for tasks to queue
[2025-04-23T21:06:10.143+0000] {logging_mixin.py:190} INFO - [2025-04-23T21:06:10.143+0000] {dagbag.py:588} INFO - Filling up the DagBag from /opt/airflow/dags/ML/ML1.py
[2025-04-23T21:06:10.414+0000] {logging_mixin.py:190} INFO - [2025-04-23T21:06:10.406+0000] {dagbag.py:387} ERROR - Failed to import: /opt/airflow/dags/ML/ML1.py
Traceback (most recent call last):
  File "/home/airflow/.local/lib/python3.12/site-packages/airflow/models/dagbag.py", line 383, in parse
    loader.exec_module(new_module)
  File "<frozen importlib._bootstrap_external>", line 999, in exec_module
  File "<frozen importlib._bootstrap>", line 488, in _call_with_frames_removed
  File "/opt/airflow/dags/ML/ML1.py", line 17, in <module>
    with DAG(
         ^^^^
  File "/home/airflow/.local/lib/python3.12/site-packages/airflow/models/dag.py", line 593, in __init__
    validate_key(dag_id)
  File "/home/airflow/.local/lib/python3.12/site-packages/airflow/utils/helpers.py", line 57, in validate_key
    raise AirflowException(
airflow.exceptions.AirflowException: The key 'ML 1' has to be made of alphanumeric characters, dashes, dots and underscores exclusively
[2025-04-23T21:06:10.415+0000] {processor.py:927} WARNING - No viable dags retrieved from /opt/airflow/dags/ML/ML1.py
[2025-04-23T21:06:10.497+0000] {processor.py:208} INFO - Processing /opt/airflow/dags/ML/ML1.py took 0.369 seconds
[2025-04-23T21:06:41.097+0000] {processor.py:186} INFO - Started process (PID=3194) to work on /opt/airflow/dags/ML/ML1.py
[2025-04-23T21:06:41.098+0000] {processor.py:914} INFO - Processing file /opt/airflow/dags/ML/ML1.py for tasks to queue
[2025-04-23T21:06:41.100+0000] {logging_mixin.py:190} INFO - [2025-04-23T21:06:41.100+0000] {dagbag.py:588} INFO - Filling up the DagBag from /opt/airflow/dags/ML/ML1.py
[2025-04-23T21:06:41.380+0000] {logging_mixin.py:190} INFO - [2025-04-23T21:06:41.371+0000] {dagbag.py:387} ERROR - Failed to import: /opt/airflow/dags/ML/ML1.py
Traceback (most recent call last):
  File "/home/airflow/.local/lib/python3.12/site-packages/airflow/models/dagbag.py", line 383, in parse
    loader.exec_module(new_module)
  File "<frozen importlib._bootstrap_external>", line 999, in exec_module
  File "<frozen importlib._bootstrap>", line 488, in _call_with_frames_removed
  File "/opt/airflow/dags/ML/ML1.py", line 17, in <module>
    with DAG(
         ^^^^
  File "/home/airflow/.local/lib/python3.12/site-packages/airflow/models/dag.py", line 593, in __init__
    validate_key(dag_id)
  File "/home/airflow/.local/lib/python3.12/site-packages/airflow/utils/helpers.py", line 57, in validate_key
    raise AirflowException(
airflow.exceptions.AirflowException: The key 'ML 1' has to be made of alphanumeric characters, dashes, dots and underscores exclusively
[2025-04-23T21:06:41.381+0000] {processor.py:927} WARNING - No viable dags retrieved from /opt/airflow/dags/ML/ML1.py
[2025-04-23T21:06:41.451+0000] {processor.py:208} INFO - Processing /opt/airflow/dags/ML/ML1.py took 0.359 seconds
[2025-04-23T21:07:11.747+0000] {processor.py:186} INFO - Started process (PID=3222) to work on /opt/airflow/dags/ML/ML1.py
[2025-04-23T21:07:11.749+0000] {processor.py:914} INFO - Processing file /opt/airflow/dags/ML/ML1.py for tasks to queue
[2025-04-23T21:07:11.754+0000] {logging_mixin.py:190} INFO - [2025-04-23T21:07:11.753+0000] {dagbag.py:588} INFO - Filling up the DagBag from /opt/airflow/dags/ML/ML1.py
[2025-04-23T21:07:12.095+0000] {logging_mixin.py:190} INFO - [2025-04-23T21:07:12.087+0000] {dagbag.py:387} ERROR - Failed to import: /opt/airflow/dags/ML/ML1.py
Traceback (most recent call last):
  File "/home/airflow/.local/lib/python3.12/site-packages/airflow/models/dagbag.py", line 383, in parse
    loader.exec_module(new_module)
  File "<frozen importlib._bootstrap_external>", line 999, in exec_module
  File "<frozen importlib._bootstrap>", line 488, in _call_with_frames_removed
  File "/opt/airflow/dags/ML/ML1.py", line 17, in <module>
    with DAG(
         ^^^^
  File "/home/airflow/.local/lib/python3.12/site-packages/airflow/models/dag.py", line 593, in __init__
    validate_key(dag_id)
  File "/home/airflow/.local/lib/python3.12/site-packages/airflow/utils/helpers.py", line 57, in validate_key
    raise AirflowException(
airflow.exceptions.AirflowException: The key 'ML 1' has to be made of alphanumeric characters, dashes, dots and underscores exclusively
[2025-04-23T21:07:12.096+0000] {processor.py:927} WARNING - No viable dags retrieved from /opt/airflow/dags/ML/ML1.py
[2025-04-23T21:07:12.182+0000] {processor.py:208} INFO - Processing /opt/airflow/dags/ML/ML1.py took 0.442 seconds
[2025-04-23T21:07:42.563+0000] {processor.py:186} INFO - Started process (PID=3252) to work on /opt/airflow/dags/ML/ML1.py
[2025-04-23T21:07:42.564+0000] {processor.py:914} INFO - Processing file /opt/airflow/dags/ML/ML1.py for tasks to queue
[2025-04-23T21:07:42.568+0000] {logging_mixin.py:190} INFO - [2025-04-23T21:07:42.567+0000] {dagbag.py:588} INFO - Filling up the DagBag from /opt/airflow/dags/ML/ML1.py
[2025-04-23T21:07:42.856+0000] {logging_mixin.py:190} INFO - [2025-04-23T21:07:42.848+0000] {dagbag.py:387} ERROR - Failed to import: /opt/airflow/dags/ML/ML1.py
Traceback (most recent call last):
  File "/home/airflow/.local/lib/python3.12/site-packages/airflow/models/dagbag.py", line 383, in parse
    loader.exec_module(new_module)
  File "<frozen importlib._bootstrap_external>", line 999, in exec_module
  File "<frozen importlib._bootstrap>", line 488, in _call_with_frames_removed
  File "/opt/airflow/dags/ML/ML1.py", line 17, in <module>
    with DAG(
         ^^^^
  File "/home/airflow/.local/lib/python3.12/site-packages/airflow/models/dag.py", line 593, in __init__
    validate_key(dag_id)
  File "/home/airflow/.local/lib/python3.12/site-packages/airflow/utils/helpers.py", line 57, in validate_key
    raise AirflowException(
airflow.exceptions.AirflowException: The key 'ML 1' has to be made of alphanumeric characters, dashes, dots and underscores exclusively
[2025-04-23T21:07:42.857+0000] {processor.py:927} WARNING - No viable dags retrieved from /opt/airflow/dags/ML/ML1.py
[2025-04-23T21:07:42.929+0000] {processor.py:208} INFO - Processing /opt/airflow/dags/ML/ML1.py took 0.383 seconds
[2025-04-23T21:08:13.008+0000] {processor.py:186} INFO - Started process (PID=3281) to work on /opt/airflow/dags/ML/ML1.py
[2025-04-23T21:08:13.009+0000] {processor.py:914} INFO - Processing file /opt/airflow/dags/ML/ML1.py for tasks to queue
[2025-04-23T21:08:13.012+0000] {logging_mixin.py:190} INFO - [2025-04-23T21:08:13.011+0000] {dagbag.py:588} INFO - Filling up the DagBag from /opt/airflow/dags/ML/ML1.py
[2025-04-23T21:08:13.276+0000] {logging_mixin.py:190} INFO - [2025-04-23T21:08:13.266+0000] {dagbag.py:387} ERROR - Failed to import: /opt/airflow/dags/ML/ML1.py
Traceback (most recent call last):
  File "/home/airflow/.local/lib/python3.12/site-packages/airflow/models/dagbag.py", line 383, in parse
    loader.exec_module(new_module)
  File "<frozen importlib._bootstrap_external>", line 999, in exec_module
  File "<frozen importlib._bootstrap>", line 488, in _call_with_frames_removed
  File "/opt/airflow/dags/ML/ML1.py", line 17, in <module>
    with DAG(
         ^^^^
  File "/home/airflow/.local/lib/python3.12/site-packages/airflow/models/dag.py", line 593, in __init__
    validate_key(dag_id)
  File "/home/airflow/.local/lib/python3.12/site-packages/airflow/utils/helpers.py", line 57, in validate_key
    raise AirflowException(
airflow.exceptions.AirflowException: The key 'ML 1' has to be made of alphanumeric characters, dashes, dots and underscores exclusively
[2025-04-23T21:08:13.277+0000] {processor.py:927} WARNING - No viable dags retrieved from /opt/airflow/dags/ML/ML1.py
[2025-04-23T21:08:13.353+0000] {processor.py:208} INFO - Processing /opt/airflow/dags/ML/ML1.py took 0.350 seconds
[2025-04-23T21:08:43.671+0000] {processor.py:186} INFO - Started process (PID=3311) to work on /opt/airflow/dags/ML/ML1.py
[2025-04-23T21:08:43.672+0000] {processor.py:914} INFO - Processing file /opt/airflow/dags/ML/ML1.py for tasks to queue
[2025-04-23T21:08:43.675+0000] {logging_mixin.py:190} INFO - [2025-04-23T21:08:43.674+0000] {dagbag.py:588} INFO - Filling up the DagBag from /opt/airflow/dags/ML/ML1.py
[2025-04-23T21:08:43.940+0000] {logging_mixin.py:190} INFO - [2025-04-23T21:08:43.931+0000] {dagbag.py:387} ERROR - Failed to import: /opt/airflow/dags/ML/ML1.py
Traceback (most recent call last):
  File "/home/airflow/.local/lib/python3.12/site-packages/airflow/models/dagbag.py", line 383, in parse
    loader.exec_module(new_module)
  File "<frozen importlib._bootstrap_external>", line 999, in exec_module
  File "<frozen importlib._bootstrap>", line 488, in _call_with_frames_removed
  File "/opt/airflow/dags/ML/ML1.py", line 17, in <module>
    with DAG(
         ^^^^
  File "/home/airflow/.local/lib/python3.12/site-packages/airflow/models/dag.py", line 593, in __init__
    validate_key(dag_id)
  File "/home/airflow/.local/lib/python3.12/site-packages/airflow/utils/helpers.py", line 57, in validate_key
    raise AirflowException(
airflow.exceptions.AirflowException: The key 'ML 1' has to be made of alphanumeric characters, dashes, dots and underscores exclusively
[2025-04-23T21:08:43.941+0000] {processor.py:927} WARNING - No viable dags retrieved from /opt/airflow/dags/ML/ML1.py
[2025-04-23T21:08:44.009+0000] {processor.py:208} INFO - Processing /opt/airflow/dags/ML/ML1.py took 0.344 seconds
[2025-04-23T21:09:14.307+0000] {processor.py:186} INFO - Started process (PID=3340) to work on /opt/airflow/dags/ML/ML1.py
[2025-04-23T21:09:14.311+0000] {processor.py:914} INFO - Processing file /opt/airflow/dags/ML/ML1.py for tasks to queue
[2025-04-23T21:09:14.314+0000] {logging_mixin.py:190} INFO - [2025-04-23T21:09:14.313+0000] {dagbag.py:588} INFO - Filling up the DagBag from /opt/airflow/dags/ML/ML1.py
[2025-04-23T21:09:14.612+0000] {logging_mixin.py:190} INFO - [2025-04-23T21:09:14.601+0000] {dagbag.py:387} ERROR - Failed to import: /opt/airflow/dags/ML/ML1.py
Traceback (most recent call last):
  File "/home/airflow/.local/lib/python3.12/site-packages/airflow/models/dagbag.py", line 383, in parse
    loader.exec_module(new_module)
  File "<frozen importlib._bootstrap_external>", line 999, in exec_module
  File "<frozen importlib._bootstrap>", line 488, in _call_with_frames_removed
  File "/opt/airflow/dags/ML/ML1.py", line 17, in <module>
    with DAG(
         ^^^^
  File "/home/airflow/.local/lib/python3.12/site-packages/airflow/models/dag.py", line 593, in __init__
    validate_key(dag_id)
  File "/home/airflow/.local/lib/python3.12/site-packages/airflow/utils/helpers.py", line 57, in validate_key
    raise AirflowException(
airflow.exceptions.AirflowException: The key 'ML 1' has to be made of alphanumeric characters, dashes, dots and underscores exclusively
[2025-04-23T21:09:14.613+0000] {processor.py:927} WARNING - No viable dags retrieved from /opt/airflow/dags/ML/ML1.py
[2025-04-23T21:09:14.695+0000] {processor.py:208} INFO - Processing /opt/airflow/dags/ML/ML1.py took 0.393 seconds
[2025-04-23T21:09:45.656+0000] {processor.py:186} INFO - Started process (PID=3369) to work on /opt/airflow/dags/ML/ML1.py
[2025-04-23T21:09:45.657+0000] {processor.py:914} INFO - Processing file /opt/airflow/dags/ML/ML1.py for tasks to queue
[2025-04-23T21:09:45.660+0000] {logging_mixin.py:190} INFO - [2025-04-23T21:09:45.659+0000] {dagbag.py:588} INFO - Filling up the DagBag from /opt/airflow/dags/ML/ML1.py
[2025-04-23T21:09:45.940+0000] {logging_mixin.py:190} INFO - [2025-04-23T21:09:45.930+0000] {dagbag.py:387} ERROR - Failed to import: /opt/airflow/dags/ML/ML1.py
Traceback (most recent call last):
  File "/home/airflow/.local/lib/python3.12/site-packages/airflow/models/dagbag.py", line 383, in parse
    loader.exec_module(new_module)
  File "<frozen importlib._bootstrap_external>", line 999, in exec_module
  File "<frozen importlib._bootstrap>", line 488, in _call_with_frames_removed
  File "/opt/airflow/dags/ML/ML1.py", line 17, in <module>
    with DAG(
         ^^^^
  File "/home/airflow/.local/lib/python3.12/site-packages/airflow/models/dag.py", line 593, in __init__
    validate_key(dag_id)
  File "/home/airflow/.local/lib/python3.12/site-packages/airflow/utils/helpers.py", line 57, in validate_key
    raise AirflowException(
airflow.exceptions.AirflowException: The key 'ML 1' has to be made of alphanumeric characters, dashes, dots and underscores exclusively
[2025-04-23T21:09:45.941+0000] {processor.py:927} WARNING - No viable dags retrieved from /opt/airflow/dags/ML/ML1.py
[2025-04-23T21:09:46.027+0000] {processor.py:208} INFO - Processing /opt/airflow/dags/ML/ML1.py took 0.378 seconds
[2025-04-23T21:10:16.185+0000] {processor.py:186} INFO - Started process (PID=3398) to work on /opt/airflow/dags/ML/ML1.py
[2025-04-23T21:10:16.187+0000] {processor.py:914} INFO - Processing file /opt/airflow/dags/ML/ML1.py for tasks to queue
[2025-04-23T21:10:16.191+0000] {logging_mixin.py:190} INFO - [2025-04-23T21:10:16.191+0000] {dagbag.py:588} INFO - Filling up the DagBag from /opt/airflow/dags/ML/ML1.py
[2025-04-23T21:10:16.484+0000] {logging_mixin.py:190} INFO - [2025-04-23T21:10:16.476+0000] {dagbag.py:387} ERROR - Failed to import: /opt/airflow/dags/ML/ML1.py
Traceback (most recent call last):
  File "/home/airflow/.local/lib/python3.12/site-packages/airflow/models/dagbag.py", line 383, in parse
    loader.exec_module(new_module)
  File "<frozen importlib._bootstrap_external>", line 999, in exec_module
  File "<frozen importlib._bootstrap>", line 488, in _call_with_frames_removed
  File "/opt/airflow/dags/ML/ML1.py", line 17, in <module>
    with DAG(
         ^^^^
  File "/home/airflow/.local/lib/python3.12/site-packages/airflow/models/dag.py", line 593, in __init__
    validate_key(dag_id)
  File "/home/airflow/.local/lib/python3.12/site-packages/airflow/utils/helpers.py", line 57, in validate_key
    raise AirflowException(
airflow.exceptions.AirflowException: The key 'ML 1' has to be made of alphanumeric characters, dashes, dots and underscores exclusively
[2025-04-23T21:10:16.485+0000] {processor.py:927} WARNING - No viable dags retrieved from /opt/airflow/dags/ML/ML1.py
[2025-04-23T21:10:16.561+0000] {processor.py:208} INFO - Processing /opt/airflow/dags/ML/ML1.py took 0.382 seconds
[2025-04-23T21:10:46.944+0000] {processor.py:186} INFO - Started process (PID=3427) to work on /opt/airflow/dags/ML/ML1.py
[2025-04-23T21:10:46.946+0000] {processor.py:914} INFO - Processing file /opt/airflow/dags/ML/ML1.py for tasks to queue
[2025-04-23T21:10:46.949+0000] {logging_mixin.py:190} INFO - [2025-04-23T21:10:46.949+0000] {dagbag.py:588} INFO - Filling up the DagBag from /opt/airflow/dags/ML/ML1.py
[2025-04-23T21:10:47.236+0000] {logging_mixin.py:190} INFO - [2025-04-23T21:10:47.225+0000] {dagbag.py:387} ERROR - Failed to import: /opt/airflow/dags/ML/ML1.py
Traceback (most recent call last):
  File "/home/airflow/.local/lib/python3.12/site-packages/airflow/models/dagbag.py", line 383, in parse
    loader.exec_module(new_module)
  File "<frozen importlib._bootstrap_external>", line 999, in exec_module
  File "<frozen importlib._bootstrap>", line 488, in _call_with_frames_removed
  File "/opt/airflow/dags/ML/ML1.py", line 17, in <module>
    with DAG(
         ^^^^
  File "/home/airflow/.local/lib/python3.12/site-packages/airflow/models/dag.py", line 593, in __init__
    validate_key(dag_id)
  File "/home/airflow/.local/lib/python3.12/site-packages/airflow/utils/helpers.py", line 57, in validate_key
    raise AirflowException(
airflow.exceptions.AirflowException: The key 'ML 1' has to be made of alphanumeric characters, dashes, dots and underscores exclusively
[2025-04-23T21:10:47.237+0000] {processor.py:927} WARNING - No viable dags retrieved from /opt/airflow/dags/ML/ML1.py
[2025-04-23T21:10:47.313+0000] {processor.py:208} INFO - Processing /opt/airflow/dags/ML/ML1.py took 0.374 seconds
[2025-04-23T21:11:17.593+0000] {processor.py:186} INFO - Started process (PID=3456) to work on /opt/airflow/dags/ML/ML1.py
[2025-04-23T21:11:17.594+0000] {processor.py:914} INFO - Processing file /opt/airflow/dags/ML/ML1.py for tasks to queue
[2025-04-23T21:11:17.596+0000] {logging_mixin.py:190} INFO - [2025-04-23T21:11:17.596+0000] {dagbag.py:588} INFO - Filling up the DagBag from /opt/airflow/dags/ML/ML1.py
[2025-04-23T21:11:17.879+0000] {logging_mixin.py:190} INFO - [2025-04-23T21:11:17.872+0000] {dagbag.py:387} ERROR - Failed to import: /opt/airflow/dags/ML/ML1.py
Traceback (most recent call last):
  File "/home/airflow/.local/lib/python3.12/site-packages/airflow/models/dagbag.py", line 383, in parse
    loader.exec_module(new_module)
  File "<frozen importlib._bootstrap_external>", line 999, in exec_module
  File "<frozen importlib._bootstrap>", line 488, in _call_with_frames_removed
  File "/opt/airflow/dags/ML/ML1.py", line 17, in <module>
    with DAG(
         ^^^^
  File "/home/airflow/.local/lib/python3.12/site-packages/airflow/models/dag.py", line 593, in __init__
    validate_key(dag_id)
  File "/home/airflow/.local/lib/python3.12/site-packages/airflow/utils/helpers.py", line 57, in validate_key
    raise AirflowException(
airflow.exceptions.AirflowException: The key 'ML 1' has to be made of alphanumeric characters, dashes, dots and underscores exclusively
[2025-04-23T21:11:17.880+0000] {processor.py:927} WARNING - No viable dags retrieved from /opt/airflow/dags/ML/ML1.py
[2025-04-23T21:11:17.999+0000] {processor.py:208} INFO - Processing /opt/airflow/dags/ML/ML1.py took 0.412 seconds
[2025-04-23T21:11:48.452+0000] {processor.py:186} INFO - Started process (PID=3485) to work on /opt/airflow/dags/ML/ML1.py
[2025-04-23T21:11:48.453+0000] {processor.py:914} INFO - Processing file /opt/airflow/dags/ML/ML1.py for tasks to queue
[2025-04-23T21:11:48.459+0000] {logging_mixin.py:190} INFO - [2025-04-23T21:11:48.458+0000] {dagbag.py:588} INFO - Filling up the DagBag from /opt/airflow/dags/ML/ML1.py
[2025-04-23T21:11:48.767+0000] {logging_mixin.py:190} INFO - [2025-04-23T21:11:48.759+0000] {dagbag.py:387} ERROR - Failed to import: /opt/airflow/dags/ML/ML1.py
Traceback (most recent call last):
  File "/home/airflow/.local/lib/python3.12/site-packages/airflow/models/dagbag.py", line 383, in parse
    loader.exec_module(new_module)
  File "<frozen importlib._bootstrap_external>", line 999, in exec_module
  File "<frozen importlib._bootstrap>", line 488, in _call_with_frames_removed
  File "/opt/airflow/dags/ML/ML1.py", line 17, in <module>
    with DAG(
         ^^^^
  File "/home/airflow/.local/lib/python3.12/site-packages/airflow/models/dag.py", line 593, in __init__
    validate_key(dag_id)
  File "/home/airflow/.local/lib/python3.12/site-packages/airflow/utils/helpers.py", line 57, in validate_key
    raise AirflowException(
airflow.exceptions.AirflowException: The key 'ML 1' has to be made of alphanumeric characters, dashes, dots and underscores exclusively
[2025-04-23T21:11:48.769+0000] {processor.py:927} WARNING - No viable dags retrieved from /opt/airflow/dags/ML/ML1.py
[2025-04-23T21:11:48.830+0000] {processor.py:208} INFO - Processing /opt/airflow/dags/ML/ML1.py took 0.385 seconds
[2025-04-23T21:12:19.104+0000] {processor.py:186} INFO - Started process (PID=3514) to work on /opt/airflow/dags/ML/ML1.py
[2025-04-23T21:12:19.106+0000] {processor.py:914} INFO - Processing file /opt/airflow/dags/ML/ML1.py for tasks to queue
[2025-04-23T21:12:19.108+0000] {logging_mixin.py:190} INFO - [2025-04-23T21:12:19.108+0000] {dagbag.py:588} INFO - Filling up the DagBag from /opt/airflow/dags/ML/ML1.py
[2025-04-23T21:12:19.436+0000] {logging_mixin.py:190} INFO - [2025-04-23T21:12:19.427+0000] {dagbag.py:387} ERROR - Failed to import: /opt/airflow/dags/ML/ML1.py
Traceback (most recent call last):
  File "/home/airflow/.local/lib/python3.12/site-packages/airflow/models/dagbag.py", line 383, in parse
    loader.exec_module(new_module)
  File "<frozen importlib._bootstrap_external>", line 999, in exec_module
  File "<frozen importlib._bootstrap>", line 488, in _call_with_frames_removed
  File "/opt/airflow/dags/ML/ML1.py", line 17, in <module>
    with DAG(
         ^^^^
  File "/home/airflow/.local/lib/python3.12/site-packages/airflow/models/dag.py", line 593, in __init__
    validate_key(dag_id)
  File "/home/airflow/.local/lib/python3.12/site-packages/airflow/utils/helpers.py", line 57, in validate_key
    raise AirflowException(
airflow.exceptions.AirflowException: The key 'ML 1' has to be made of alphanumeric characters, dashes, dots and underscores exclusively
[2025-04-23T21:12:19.437+0000] {processor.py:927} WARNING - No viable dags retrieved from /opt/airflow/dags/ML/ML1.py
[2025-04-23T21:12:19.514+0000] {processor.py:208} INFO - Processing /opt/airflow/dags/ML/ML1.py took 0.417 seconds
[2025-04-23T21:12:50.283+0000] {processor.py:186} INFO - Started process (PID=3543) to work on /opt/airflow/dags/ML/ML1.py
[2025-04-23T21:12:50.285+0000] {processor.py:914} INFO - Processing file /opt/airflow/dags/ML/ML1.py for tasks to queue
[2025-04-23T21:12:50.287+0000] {logging_mixin.py:190} INFO - [2025-04-23T21:12:50.287+0000] {dagbag.py:588} INFO - Filling up the DagBag from /opt/airflow/dags/ML/ML1.py
[2025-04-23T21:12:50.553+0000] {logging_mixin.py:190} INFO - [2025-04-23T21:12:50.546+0000] {dagbag.py:387} ERROR - Failed to import: /opt/airflow/dags/ML/ML1.py
Traceback (most recent call last):
  File "/home/airflow/.local/lib/python3.12/site-packages/airflow/models/dagbag.py", line 383, in parse
    loader.exec_module(new_module)
  File "<frozen importlib._bootstrap_external>", line 999, in exec_module
  File "<frozen importlib._bootstrap>", line 488, in _call_with_frames_removed
  File "/opt/airflow/dags/ML/ML1.py", line 17, in <module>
    with DAG(
         ^^^^
  File "/home/airflow/.local/lib/python3.12/site-packages/airflow/models/dag.py", line 593, in __init__
    validate_key(dag_id)
  File "/home/airflow/.local/lib/python3.12/site-packages/airflow/utils/helpers.py", line 57, in validate_key
    raise AirflowException(
airflow.exceptions.AirflowException: The key 'ML 1' has to be made of alphanumeric characters, dashes, dots and underscores exclusively
[2025-04-23T21:12:50.554+0000] {processor.py:927} WARNING - No viable dags retrieved from /opt/airflow/dags/ML/ML1.py
[2025-04-23T21:12:50.626+0000] {processor.py:208} INFO - Processing /opt/airflow/dags/ML/ML1.py took 0.348 seconds
[2025-04-23T21:13:21.097+0000] {processor.py:186} INFO - Started process (PID=3572) to work on /opt/airflow/dags/ML/ML1.py
[2025-04-23T21:13:21.098+0000] {processor.py:914} INFO - Processing file /opt/airflow/dags/ML/ML1.py for tasks to queue
[2025-04-23T21:13:21.100+0000] {logging_mixin.py:190} INFO - [2025-04-23T21:13:21.100+0000] {dagbag.py:588} INFO - Filling up the DagBag from /opt/airflow/dags/ML/ML1.py
[2025-04-23T21:13:21.339+0000] {logging_mixin.py:190} INFO - [2025-04-23T21:13:21.331+0000] {dagbag.py:387} ERROR - Failed to import: /opt/airflow/dags/ML/ML1.py
Traceback (most recent call last):
  File "/home/airflow/.local/lib/python3.12/site-packages/airflow/models/dagbag.py", line 383, in parse
    loader.exec_module(new_module)
  File "<frozen importlib._bootstrap_external>", line 999, in exec_module
  File "<frozen importlib._bootstrap>", line 488, in _call_with_frames_removed
  File "/opt/airflow/dags/ML/ML1.py", line 17, in <module>
    with DAG(
         ^^^^
  File "/home/airflow/.local/lib/python3.12/site-packages/airflow/models/dag.py", line 593, in __init__
    validate_key(dag_id)
  File "/home/airflow/.local/lib/python3.12/site-packages/airflow/utils/helpers.py", line 57, in validate_key
    raise AirflowException(
airflow.exceptions.AirflowException: The key 'ML 1' has to be made of alphanumeric characters, dashes, dots and underscores exclusively
[2025-04-23T21:13:21.339+0000] {processor.py:927} WARNING - No viable dags retrieved from /opt/airflow/dags/ML/ML1.py
[2025-04-23T21:13:21.401+0000] {processor.py:208} INFO - Processing /opt/airflow/dags/ML/ML1.py took 0.309 seconds
[2025-04-23T21:13:52.067+0000] {processor.py:186} INFO - Started process (PID=3601) to work on /opt/airflow/dags/ML/ML1.py
[2025-04-23T21:13:52.069+0000] {processor.py:914} INFO - Processing file /opt/airflow/dags/ML/ML1.py for tasks to queue
[2025-04-23T21:13:52.072+0000] {logging_mixin.py:190} INFO - [2025-04-23T21:13:52.071+0000] {dagbag.py:588} INFO - Filling up the DagBag from /opt/airflow/dags/ML/ML1.py
[2025-04-23T21:13:52.400+0000] {logging_mixin.py:190} INFO - [2025-04-23T21:13:52.390+0000] {dagbag.py:387} ERROR - Failed to import: /opt/airflow/dags/ML/ML1.py
Traceback (most recent call last):
  File "/home/airflow/.local/lib/python3.12/site-packages/airflow/models/dagbag.py", line 383, in parse
    loader.exec_module(new_module)
  File "<frozen importlib._bootstrap_external>", line 999, in exec_module
  File "<frozen importlib._bootstrap>", line 488, in _call_with_frames_removed
  File "/opt/airflow/dags/ML/ML1.py", line 17, in <module>
    with DAG(
         ^^^^
  File "/home/airflow/.local/lib/python3.12/site-packages/airflow/models/dag.py", line 593, in __init__
    validate_key(dag_id)
  File "/home/airflow/.local/lib/python3.12/site-packages/airflow/utils/helpers.py", line 57, in validate_key
    raise AirflowException(
airflow.exceptions.AirflowException: The key 'ML 1' has to be made of alphanumeric characters, dashes, dots and underscores exclusively
[2025-04-23T21:13:52.401+0000] {processor.py:927} WARNING - No viable dags retrieved from /opt/airflow/dags/ML/ML1.py
[2025-04-23T21:13:52.523+0000] {processor.py:208} INFO - Processing /opt/airflow/dags/ML/ML1.py took 0.466 seconds
[2025-04-23T21:14:22.935+0000] {processor.py:186} INFO - Started process (PID=3630) to work on /opt/airflow/dags/ML/ML1.py
[2025-04-23T21:14:22.936+0000] {processor.py:914} INFO - Processing file /opt/airflow/dags/ML/ML1.py for tasks to queue
[2025-04-23T21:14:22.939+0000] {logging_mixin.py:190} INFO - [2025-04-23T21:14:22.939+0000] {dagbag.py:588} INFO - Filling up the DagBag from /opt/airflow/dags/ML/ML1.py
[2025-04-23T21:14:23.211+0000] {logging_mixin.py:190} INFO - [2025-04-23T21:14:23.203+0000] {dagbag.py:387} ERROR - Failed to import: /opt/airflow/dags/ML/ML1.py
Traceback (most recent call last):
  File "/home/airflow/.local/lib/python3.12/site-packages/airflow/models/dagbag.py", line 383, in parse
    loader.exec_module(new_module)
  File "<frozen importlib._bootstrap_external>", line 999, in exec_module
  File "<frozen importlib._bootstrap>", line 488, in _call_with_frames_removed
  File "/opt/airflow/dags/ML/ML1.py", line 17, in <module>
    with DAG(
         ^^^^
  File "/home/airflow/.local/lib/python3.12/site-packages/airflow/models/dag.py", line 593, in __init__
    validate_key(dag_id)
  File "/home/airflow/.local/lib/python3.12/site-packages/airflow/utils/helpers.py", line 57, in validate_key
    raise AirflowException(
airflow.exceptions.AirflowException: The key 'ML 1' has to be made of alphanumeric characters, dashes, dots and underscores exclusively
[2025-04-23T21:14:23.212+0000] {processor.py:927} WARNING - No viable dags retrieved from /opt/airflow/dags/ML/ML1.py
[2025-04-23T21:14:23.278+0000] {processor.py:208} INFO - Processing /opt/airflow/dags/ML/ML1.py took 0.350 seconds
[2025-04-23T21:14:53.922+0000] {processor.py:186} INFO - Started process (PID=3665) to work on /opt/airflow/dags/ML/ML1.py
[2025-04-23T21:14:53.924+0000] {processor.py:914} INFO - Processing file /opt/airflow/dags/ML/ML1.py for tasks to queue
[2025-04-23T21:14:53.927+0000] {logging_mixin.py:190} INFO - [2025-04-23T21:14:53.926+0000] {dagbag.py:588} INFO - Filling up the DagBag from /opt/airflow/dags/ML/ML1.py
[2025-04-23T21:14:54.265+0000] {logging_mixin.py:190} INFO - [2025-04-23T21:14:54.257+0000] {dagbag.py:387} ERROR - Failed to import: /opt/airflow/dags/ML/ML1.py
Traceback (most recent call last):
  File "/home/airflow/.local/lib/python3.12/site-packages/airflow/models/dagbag.py", line 383, in parse
    loader.exec_module(new_module)
  File "<frozen importlib._bootstrap_external>", line 999, in exec_module
  File "<frozen importlib._bootstrap>", line 488, in _call_with_frames_removed
  File "/opt/airflow/dags/ML/ML1.py", line 17, in <module>
    with DAG(
         ^^^^
  File "/home/airflow/.local/lib/python3.12/site-packages/airflow/models/dag.py", line 593, in __init__
    validate_key(dag_id)
  File "/home/airflow/.local/lib/python3.12/site-packages/airflow/utils/helpers.py", line 57, in validate_key
    raise AirflowException(
airflow.exceptions.AirflowException: The key 'ML 1' has to be made of alphanumeric characters, dashes, dots and underscores exclusively
[2025-04-23T21:14:54.266+0000] {processor.py:927} WARNING - No viable dags retrieved from /opt/airflow/dags/ML/ML1.py
[2025-04-23T21:14:54.351+0000] {processor.py:208} INFO - Processing /opt/airflow/dags/ML/ML1.py took 0.436 seconds
[2025-04-23T21:15:24.800+0000] {processor.py:186} INFO - Started process (PID=3693) to work on /opt/airflow/dags/ML/ML1.py
[2025-04-23T21:15:24.802+0000] {processor.py:914} INFO - Processing file /opt/airflow/dags/ML/ML1.py for tasks to queue
[2025-04-23T21:15:24.805+0000] {logging_mixin.py:190} INFO - [2025-04-23T21:15:24.805+0000] {dagbag.py:588} INFO - Filling up the DagBag from /opt/airflow/dags/ML/ML1.py
[2025-04-23T21:15:25.088+0000] {logging_mixin.py:190} INFO - [2025-04-23T21:15:25.081+0000] {dagbag.py:387} ERROR - Failed to import: /opt/airflow/dags/ML/ML1.py
Traceback (most recent call last):
  File "/home/airflow/.local/lib/python3.12/site-packages/airflow/models/dagbag.py", line 383, in parse
    loader.exec_module(new_module)
  File "<frozen importlib._bootstrap_external>", line 999, in exec_module
  File "<frozen importlib._bootstrap>", line 488, in _call_with_frames_removed
  File "/opt/airflow/dags/ML/ML1.py", line 17, in <module>
    with DAG(
         ^^^^
  File "/home/airflow/.local/lib/python3.12/site-packages/airflow/models/dag.py", line 593, in __init__
    validate_key(dag_id)
  File "/home/airflow/.local/lib/python3.12/site-packages/airflow/utils/helpers.py", line 57, in validate_key
    raise AirflowException(
airflow.exceptions.AirflowException: The key 'ML 1' has to be made of alphanumeric characters, dashes, dots and underscores exclusively
[2025-04-23T21:15:25.089+0000] {processor.py:927} WARNING - No viable dags retrieved from /opt/airflow/dags/ML/ML1.py
[2025-04-23T21:15:25.166+0000] {processor.py:208} INFO - Processing /opt/airflow/dags/ML/ML1.py took 0.373 seconds
[2025-04-23T21:15:55.544+0000] {processor.py:186} INFO - Started process (PID=3722) to work on /opt/airflow/dags/ML/ML1.py
[2025-04-23T21:15:55.546+0000] {processor.py:914} INFO - Processing file /opt/airflow/dags/ML/ML1.py for tasks to queue
[2025-04-23T21:15:55.553+0000] {logging_mixin.py:190} INFO - [2025-04-23T21:15:55.551+0000] {dagbag.py:588} INFO - Filling up the DagBag from /opt/airflow/dags/ML/ML1.py
[2025-04-23T21:15:55.908+0000] {logging_mixin.py:190} INFO - [2025-04-23T21:15:55.900+0000] {dagbag.py:387} ERROR - Failed to import: /opt/airflow/dags/ML/ML1.py
Traceback (most recent call last):
  File "/home/airflow/.local/lib/python3.12/site-packages/airflow/models/dagbag.py", line 383, in parse
    loader.exec_module(new_module)
  File "<frozen importlib._bootstrap_external>", line 999, in exec_module
  File "<frozen importlib._bootstrap>", line 488, in _call_with_frames_removed
  File "/opt/airflow/dags/ML/ML1.py", line 17, in <module>
    with DAG(
         ^^^^
  File "/home/airflow/.local/lib/python3.12/site-packages/airflow/models/dag.py", line 593, in __init__
    validate_key(dag_id)
  File "/home/airflow/.local/lib/python3.12/site-packages/airflow/utils/helpers.py", line 57, in validate_key
    raise AirflowException(
airflow.exceptions.AirflowException: The key 'ML 1' has to be made of alphanumeric characters, dashes, dots and underscores exclusively
[2025-04-23T21:15:55.909+0000] {processor.py:927} WARNING - No viable dags retrieved from /opt/airflow/dags/ML/ML1.py
[2025-04-23T21:15:55.980+0000] {processor.py:208} INFO - Processing /opt/airflow/dags/ML/ML1.py took 0.445 seconds
[2025-04-23T21:16:26.105+0000] {processor.py:186} INFO - Started process (PID=3752) to work on /opt/airflow/dags/ML/ML1.py
[2025-04-23T21:16:26.106+0000] {processor.py:914} INFO - Processing file /opt/airflow/dags/ML/ML1.py for tasks to queue
[2025-04-23T21:16:26.108+0000] {logging_mixin.py:190} INFO - [2025-04-23T21:16:26.108+0000] {dagbag.py:588} INFO - Filling up the DagBag from /opt/airflow/dags/ML/ML1.py
[2025-04-23T21:16:26.372+0000] {logging_mixin.py:190} INFO - [2025-04-23T21:16:26.365+0000] {dagbag.py:387} ERROR - Failed to import: /opt/airflow/dags/ML/ML1.py
Traceback (most recent call last):
  File "/home/airflow/.local/lib/python3.12/site-packages/airflow/models/dagbag.py", line 383, in parse
    loader.exec_module(new_module)
  File "<frozen importlib._bootstrap_external>", line 999, in exec_module
  File "<frozen importlib._bootstrap>", line 488, in _call_with_frames_removed
  File "/opt/airflow/dags/ML/ML1.py", line 17, in <module>
    with DAG(
         ^^^^
  File "/home/airflow/.local/lib/python3.12/site-packages/airflow/models/dag.py", line 593, in __init__
    validate_key(dag_id)
  File "/home/airflow/.local/lib/python3.12/site-packages/airflow/utils/helpers.py", line 57, in validate_key
    raise AirflowException(
airflow.exceptions.AirflowException: The key 'ML 1' has to be made of alphanumeric characters, dashes, dots and underscores exclusively
[2025-04-23T21:16:26.373+0000] {processor.py:927} WARNING - No viable dags retrieved from /opt/airflow/dags/ML/ML1.py
[2025-04-23T21:16:26.427+0000] {processor.py:208} INFO - Processing /opt/airflow/dags/ML/ML1.py took 0.328 seconds
