[2025-04-24T18:14:51.554+0000] {processor.py:186} INFO - Started process (PID=82) to work on /opt/airflow/dags/ML/ML1.py
[2025-04-24T18:14:51.559+0000] {processor.py:914} INFO - Processing file /opt/airflow/dags/ML/ML1.py for tasks to queue
[2025-04-24T18:14:51.586+0000] {logging_mixin.py:190} INFO - [2025-04-24T18:14:51.585+0000] {dagbag.py:588} INFO - Filling up the DagBag from /opt/airflow/dags/ML/ML1.py
[2025-04-24T18:14:58.795+0000] {logging_mixin.py:190} INFO - [2025-04-24T18:14:58.773+0000] {dagbag.py:387} ERROR - Failed to import: /opt/airflow/dags/ML/ML1.py
Traceback (most recent call last):
  File "/home/airflow/.local/lib/python3.12/site-packages/airflow/models/dagbag.py", line 383, in parse
    loader.exec_module(new_module)
  File "<frozen importlib._bootstrap_external>", line 999, in exec_module
  File "<frozen importlib._bootstrap>", line 488, in _call_with_frames_removed
  File "/opt/airflow/dags/ML/ML1.py", line 17, in <module>
    with DAG(
         ^^^^
  File "/home/airflow/.local/lib/python3.12/site-packages/airflow/models/dag.py", line 593, in __init__
    validate_key(dag_id)
  File "/home/airflow/.local/lib/python3.12/site-packages/airflow/utils/helpers.py", line 57, in validate_key
    raise AirflowException(
airflow.exceptions.AirflowException: The key 'ML 1' has to be made of alphanumeric characters, dashes, dots and underscores exclusively
[2025-04-24T18:14:58.797+0000] {processor.py:927} WARNING - No viable dags retrieved from /opt/airflow/dags/ML/ML1.py
[2025-04-24T18:14:58.938+0000] {processor.py:208} INFO - Processing /opt/airflow/dags/ML/ML1.py took 7.438 seconds
[2025-04-24T18:15:29.118+0000] {processor.py:186} INFO - Started process (PID=111) to work on /opt/airflow/dags/ML/ML1.py
[2025-04-24T18:15:29.121+0000] {processor.py:914} INFO - Processing file /opt/airflow/dags/ML/ML1.py for tasks to queue
[2025-04-24T18:15:29.127+0000] {logging_mixin.py:190} INFO - [2025-04-24T18:15:29.126+0000] {dagbag.py:588} INFO - Filling up the DagBag from /opt/airflow/dags/ML/ML1.py
[2025-04-24T18:15:30.258+0000] {logging_mixin.py:190} INFO - [2025-04-24T18:15:30.237+0000] {dagbag.py:387} ERROR - Failed to import: /opt/airflow/dags/ML/ML1.py
Traceback (most recent call last):
  File "/home/airflow/.local/lib/python3.12/site-packages/airflow/models/dagbag.py", line 383, in parse
    loader.exec_module(new_module)
  File "<frozen importlib._bootstrap_external>", line 999, in exec_module
  File "<frozen importlib._bootstrap>", line 488, in _call_with_frames_removed
  File "/opt/airflow/dags/ML/ML1.py", line 17, in <module>
    with DAG(
         ^^^^
  File "/home/airflow/.local/lib/python3.12/site-packages/airflow/models/dag.py", line 593, in __init__
    validate_key(dag_id)
  File "/home/airflow/.local/lib/python3.12/site-packages/airflow/utils/helpers.py", line 57, in validate_key
    raise AirflowException(
airflow.exceptions.AirflowException: The key 'ML 1' has to be made of alphanumeric characters, dashes, dots and underscores exclusively
[2025-04-24T18:15:30.261+0000] {processor.py:927} WARNING - No viable dags retrieved from /opt/airflow/dags/ML/ML1.py
[2025-04-24T18:15:30.407+0000] {processor.py:208} INFO - Processing /opt/airflow/dags/ML/ML1.py took 1.306 seconds
[2025-04-24T18:16:01.032+0000] {processor.py:186} INFO - Started process (PID=140) to work on /opt/airflow/dags/ML/ML1.py
[2025-04-24T18:16:01.036+0000] {processor.py:914} INFO - Processing file /opt/airflow/dags/ML/ML1.py for tasks to queue
[2025-04-24T18:16:01.045+0000] {logging_mixin.py:190} INFO - [2025-04-24T18:16:01.043+0000] {dagbag.py:588} INFO - Filling up the DagBag from /opt/airflow/dags/ML/ML1.py
[2025-04-24T18:16:02.537+0000] {logging_mixin.py:190} INFO - [2025-04-24T18:16:02.521+0000] {dagbag.py:387} ERROR - Failed to import: /opt/airflow/dags/ML/ML1.py
Traceback (most recent call last):
  File "/home/airflow/.local/lib/python3.12/site-packages/airflow/models/dagbag.py", line 383, in parse
    loader.exec_module(new_module)
  File "<frozen importlib._bootstrap_external>", line 999, in exec_module
  File "<frozen importlib._bootstrap>", line 488, in _call_with_frames_removed
  File "/opt/airflow/dags/ML/ML1.py", line 17, in <module>
    with DAG(
         ^^^^
  File "/home/airflow/.local/lib/python3.12/site-packages/airflow/models/dag.py", line 593, in __init__
    validate_key(dag_id)
  File "/home/airflow/.local/lib/python3.12/site-packages/airflow/utils/helpers.py", line 57, in validate_key
    raise AirflowException(
airflow.exceptions.AirflowException: The key 'ML 1' has to be made of alphanumeric characters, dashes, dots and underscores exclusively
[2025-04-24T18:16:02.539+0000] {processor.py:927} WARNING - No viable dags retrieved from /opt/airflow/dags/ML/ML1.py
[2025-04-24T18:16:02.672+0000] {processor.py:208} INFO - Processing /opt/airflow/dags/ML/ML1.py took 1.663 seconds
[2025-04-24T18:16:33.032+0000] {processor.py:186} INFO - Started process (PID=169) to work on /opt/airflow/dags/ML/ML1.py
[2025-04-24T18:16:33.034+0000] {processor.py:914} INFO - Processing file /opt/airflow/dags/ML/ML1.py for tasks to queue
[2025-04-24T18:16:33.036+0000] {logging_mixin.py:190} INFO - [2025-04-24T18:16:33.036+0000] {dagbag.py:588} INFO - Filling up the DagBag from /opt/airflow/dags/ML/ML1.py
[2025-04-24T18:16:33.675+0000] {logging_mixin.py:190} INFO - [2025-04-24T18:16:33.667+0000] {dagbag.py:387} ERROR - Failed to import: /opt/airflow/dags/ML/ML1.py
Traceback (most recent call last):
  File "/home/airflow/.local/lib/python3.12/site-packages/airflow/models/dagbag.py", line 383, in parse
    loader.exec_module(new_module)
  File "<frozen importlib._bootstrap_external>", line 999, in exec_module
  File "<frozen importlib._bootstrap>", line 488, in _call_with_frames_removed
  File "/opt/airflow/dags/ML/ML1.py", line 17, in <module>
    with DAG(
         ^^^^
  File "/home/airflow/.local/lib/python3.12/site-packages/airflow/models/dag.py", line 593, in __init__
    validate_key(dag_id)
  File "/home/airflow/.local/lib/python3.12/site-packages/airflow/utils/helpers.py", line 57, in validate_key
    raise AirflowException(
airflow.exceptions.AirflowException: The key 'ML 1' has to be made of alphanumeric characters, dashes, dots and underscores exclusively
[2025-04-24T18:16:33.676+0000] {processor.py:927} WARNING - No viable dags retrieved from /opt/airflow/dags/ML/ML1.py
[2025-04-24T18:16:33.742+0000] {processor.py:208} INFO - Processing /opt/airflow/dags/ML/ML1.py took 0.715 seconds
[2025-04-24T18:17:04.097+0000] {processor.py:186} INFO - Started process (PID=197) to work on /opt/airflow/dags/ML/ML1.py
[2025-04-24T18:17:04.100+0000] {processor.py:914} INFO - Processing file /opt/airflow/dags/ML/ML1.py for tasks to queue
[2025-04-24T18:17:04.104+0000] {logging_mixin.py:190} INFO - [2025-04-24T18:17:04.103+0000] {dagbag.py:588} INFO - Filling up the DagBag from /opt/airflow/dags/ML/ML1.py
[2025-04-24T18:17:04.615+0000] {logging_mixin.py:190} INFO - [2025-04-24T18:17:04.607+0000] {dagbag.py:387} ERROR - Failed to import: /opt/airflow/dags/ML/ML1.py
Traceback (most recent call last):
  File "/home/airflow/.local/lib/python3.12/site-packages/airflow/models/dagbag.py", line 383, in parse
    loader.exec_module(new_module)
  File "<frozen importlib._bootstrap_external>", line 999, in exec_module
  File "<frozen importlib._bootstrap>", line 488, in _call_with_frames_removed
  File "/opt/airflow/dags/ML/ML1.py", line 17, in <module>
    with DAG(
         ^^^^
  File "/home/airflow/.local/lib/python3.12/site-packages/airflow/models/dag.py", line 593, in __init__
    validate_key(dag_id)
  File "/home/airflow/.local/lib/python3.12/site-packages/airflow/utils/helpers.py", line 57, in validate_key
    raise AirflowException(
airflow.exceptions.AirflowException: The key 'ML 1' has to be made of alphanumeric characters, dashes, dots and underscores exclusively
[2025-04-24T18:17:04.616+0000] {processor.py:927} WARNING - No viable dags retrieved from /opt/airflow/dags/ML/ML1.py
[2025-04-24T18:17:04.686+0000] {processor.py:208} INFO - Processing /opt/airflow/dags/ML/ML1.py took 0.599 seconds
[2025-04-24T18:17:35.008+0000] {processor.py:186} INFO - Started process (PID=226) to work on /opt/airflow/dags/ML/ML1.py
[2025-04-24T18:17:35.010+0000] {processor.py:914} INFO - Processing file /opt/airflow/dags/ML/ML1.py for tasks to queue
[2025-04-24T18:17:35.012+0000] {logging_mixin.py:190} INFO - [2025-04-24T18:17:35.011+0000] {dagbag.py:588} INFO - Filling up the DagBag from /opt/airflow/dags/ML/ML1.py
[2025-04-24T18:17:35.476+0000] {logging_mixin.py:190} INFO - [2025-04-24T18:17:35.467+0000] {dagbag.py:387} ERROR - Failed to import: /opt/airflow/dags/ML/ML1.py
Traceback (most recent call last):
  File "/home/airflow/.local/lib/python3.12/site-packages/airflow/models/dagbag.py", line 383, in parse
    loader.exec_module(new_module)
  File "<frozen importlib._bootstrap_external>", line 999, in exec_module
  File "<frozen importlib._bootstrap>", line 488, in _call_with_frames_removed
  File "/opt/airflow/dags/ML/ML1.py", line 17, in <module>
    with DAG(
         ^^^^
  File "/home/airflow/.local/lib/python3.12/site-packages/airflow/models/dag.py", line 593, in __init__
    validate_key(dag_id)
  File "/home/airflow/.local/lib/python3.12/site-packages/airflow/utils/helpers.py", line 57, in validate_key
    raise AirflowException(
airflow.exceptions.AirflowException: The key 'ML 1' has to be made of alphanumeric characters, dashes, dots and underscores exclusively
[2025-04-24T18:17:35.477+0000] {processor.py:927} WARNING - No viable dags retrieved from /opt/airflow/dags/ML/ML1.py
[2025-04-24T18:17:35.563+0000] {processor.py:208} INFO - Processing /opt/airflow/dags/ML/ML1.py took 0.562 seconds
[2025-04-24T18:18:05.926+0000] {processor.py:186} INFO - Started process (PID=255) to work on /opt/airflow/dags/ML/ML1.py
[2025-04-24T18:18:05.927+0000] {processor.py:914} INFO - Processing file /opt/airflow/dags/ML/ML1.py for tasks to queue
[2025-04-24T18:18:05.929+0000] {logging_mixin.py:190} INFO - [2025-04-24T18:18:05.929+0000] {dagbag.py:588} INFO - Filling up the DagBag from /opt/airflow/dags/ML/ML1.py
[2025-04-24T18:18:06.376+0000] {logging_mixin.py:190} INFO - [2025-04-24T18:18:06.370+0000] {dagbag.py:387} ERROR - Failed to import: /opt/airflow/dags/ML/ML1.py
Traceback (most recent call last):
  File "/home/airflow/.local/lib/python3.12/site-packages/airflow/models/dagbag.py", line 383, in parse
    loader.exec_module(new_module)
  File "<frozen importlib._bootstrap_external>", line 999, in exec_module
  File "<frozen importlib._bootstrap>", line 488, in _call_with_frames_removed
  File "/opt/airflow/dags/ML/ML1.py", line 17, in <module>
    with DAG(
         ^^^^
  File "/home/airflow/.local/lib/python3.12/site-packages/airflow/models/dag.py", line 593, in __init__
    validate_key(dag_id)
  File "/home/airflow/.local/lib/python3.12/site-packages/airflow/utils/helpers.py", line 57, in validate_key
    raise AirflowException(
airflow.exceptions.AirflowException: The key 'ML 1' has to be made of alphanumeric characters, dashes, dots and underscores exclusively
[2025-04-24T18:18:06.377+0000] {processor.py:927} WARNING - No viable dags retrieved from /opt/airflow/dags/ML/ML1.py
[2025-04-24T18:18:06.439+0000] {processor.py:208} INFO - Processing /opt/airflow/dags/ML/ML1.py took 0.518 seconds
[2025-04-24T18:18:36.990+0000] {processor.py:186} INFO - Started process (PID=284) to work on /opt/airflow/dags/ML/ML1.py
[2025-04-24T18:18:36.991+0000] {processor.py:914} INFO - Processing file /opt/airflow/dags/ML/ML1.py for tasks to queue
[2025-04-24T18:18:36.993+0000] {logging_mixin.py:190} INFO - [2025-04-24T18:18:36.993+0000] {dagbag.py:588} INFO - Filling up the DagBag from /opt/airflow/dags/ML/ML1.py
[2025-04-24T18:18:37.413+0000] {logging_mixin.py:190} INFO - [2025-04-24T18:18:37.406+0000] {dagbag.py:387} ERROR - Failed to import: /opt/airflow/dags/ML/ML1.py
Traceback (most recent call last):
  File "/home/airflow/.local/lib/python3.12/site-packages/airflow/models/dagbag.py", line 383, in parse
    loader.exec_module(new_module)
  File "<frozen importlib._bootstrap_external>", line 999, in exec_module
  File "<frozen importlib._bootstrap>", line 488, in _call_with_frames_removed
  File "/opt/airflow/dags/ML/ML1.py", line 17, in <module>
    with DAG(
         ^^^^
  File "/home/airflow/.local/lib/python3.12/site-packages/airflow/models/dag.py", line 593, in __init__
    validate_key(dag_id)
  File "/home/airflow/.local/lib/python3.12/site-packages/airflow/utils/helpers.py", line 57, in validate_key
    raise AirflowException(
airflow.exceptions.AirflowException: The key 'ML 1' has to be made of alphanumeric characters, dashes, dots and underscores exclusively
[2025-04-24T18:18:37.414+0000] {processor.py:927} WARNING - No viable dags retrieved from /opt/airflow/dags/ML/ML1.py
[2025-04-24T18:18:37.472+0000] {processor.py:208} INFO - Processing /opt/airflow/dags/ML/ML1.py took 0.487 seconds
[2025-04-24T18:19:07.657+0000] {processor.py:186} INFO - Started process (PID=313) to work on /opt/airflow/dags/ML/ML1.py
[2025-04-24T18:19:07.658+0000] {processor.py:914} INFO - Processing file /opt/airflow/dags/ML/ML1.py for tasks to queue
[2025-04-24T18:19:07.660+0000] {logging_mixin.py:190} INFO - [2025-04-24T18:19:07.660+0000] {dagbag.py:588} INFO - Filling up the DagBag from /opt/airflow/dags/ML/ML1.py
[2025-04-24T18:19:08.051+0000] {logging_mixin.py:190} INFO - [2025-04-24T18:19:08.044+0000] {dagbag.py:387} ERROR - Failed to import: /opt/airflow/dags/ML/ML1.py
Traceback (most recent call last):
  File "/home/airflow/.local/lib/python3.12/site-packages/airflow/models/dagbag.py", line 383, in parse
    loader.exec_module(new_module)
  File "<frozen importlib._bootstrap_external>", line 999, in exec_module
  File "<frozen importlib._bootstrap>", line 488, in _call_with_frames_removed
  File "/opt/airflow/dags/ML/ML1.py", line 17, in <module>
    with DAG(
         ^^^^
  File "/home/airflow/.local/lib/python3.12/site-packages/airflow/models/dag.py", line 593, in __init__
    validate_key(dag_id)
  File "/home/airflow/.local/lib/python3.12/site-packages/airflow/utils/helpers.py", line 57, in validate_key
    raise AirflowException(
airflow.exceptions.AirflowException: The key 'ML 1' has to be made of alphanumeric characters, dashes, dots and underscores exclusively
[2025-04-24T18:19:08.051+0000] {processor.py:927} WARNING - No viable dags retrieved from /opt/airflow/dags/ML/ML1.py
[2025-04-24T18:19:08.111+0000] {processor.py:208} INFO - Processing /opt/airflow/dags/ML/ML1.py took 0.459 seconds
[2025-04-24T18:19:38.468+0000] {processor.py:186} INFO - Started process (PID=342) to work on /opt/airflow/dags/ML/ML1.py
[2025-04-24T18:19:38.469+0000] {processor.py:914} INFO - Processing file /opt/airflow/dags/ML/ML1.py for tasks to queue
[2025-04-24T18:19:38.471+0000] {logging_mixin.py:190} INFO - [2025-04-24T18:19:38.471+0000] {dagbag.py:588} INFO - Filling up the DagBag from /opt/airflow/dags/ML/ML1.py
[2025-04-24T18:19:38.841+0000] {logging_mixin.py:190} INFO - [2025-04-24T18:19:38.833+0000] {dagbag.py:387} ERROR - Failed to import: /opt/airflow/dags/ML/ML1.py
Traceback (most recent call last):
  File "/home/airflow/.local/lib/python3.12/site-packages/airflow/models/dagbag.py", line 383, in parse
    loader.exec_module(new_module)
  File "<frozen importlib._bootstrap_external>", line 999, in exec_module
  File "<frozen importlib._bootstrap>", line 488, in _call_with_frames_removed
  File "/opt/airflow/dags/ML/ML1.py", line 17, in <module>
    with DAG(
         ^^^^
  File "/home/airflow/.local/lib/python3.12/site-packages/airflow/models/dag.py", line 593, in __init__
    validate_key(dag_id)
  File "/home/airflow/.local/lib/python3.12/site-packages/airflow/utils/helpers.py", line 57, in validate_key
    raise AirflowException(
airflow.exceptions.AirflowException: The key 'ML 1' has to be made of alphanumeric characters, dashes, dots and underscores exclusively
[2025-04-24T18:19:38.842+0000] {processor.py:927} WARNING - No viable dags retrieved from /opt/airflow/dags/ML/ML1.py
[2025-04-24T18:19:38.905+0000] {processor.py:208} INFO - Processing /opt/airflow/dags/ML/ML1.py took 0.441 seconds
[2025-04-24T18:20:09.063+0000] {processor.py:186} INFO - Started process (PID=371) to work on /opt/airflow/dags/ML/ML1.py
[2025-04-24T18:20:09.064+0000] {processor.py:914} INFO - Processing file /opt/airflow/dags/ML/ML1.py for tasks to queue
[2025-04-24T18:20:09.066+0000] {logging_mixin.py:190} INFO - [2025-04-24T18:20:09.066+0000] {dagbag.py:588} INFO - Filling up the DagBag from /opt/airflow/dags/ML/ML1.py
[2025-04-24T18:20:09.432+0000] {logging_mixin.py:190} INFO - [2025-04-24T18:20:09.424+0000] {dagbag.py:387} ERROR - Failed to import: /opt/airflow/dags/ML/ML1.py
Traceback (most recent call last):
  File "/home/airflow/.local/lib/python3.12/site-packages/airflow/models/dagbag.py", line 383, in parse
    loader.exec_module(new_module)
  File "<frozen importlib._bootstrap_external>", line 999, in exec_module
  File "<frozen importlib._bootstrap>", line 488, in _call_with_frames_removed
  File "/opt/airflow/dags/ML/ML1.py", line 17, in <module>
    with DAG(
         ^^^^
  File "/home/airflow/.local/lib/python3.12/site-packages/airflow/models/dag.py", line 593, in __init__
    validate_key(dag_id)
  File "/home/airflow/.local/lib/python3.12/site-packages/airflow/utils/helpers.py", line 57, in validate_key
    raise AirflowException(
airflow.exceptions.AirflowException: The key 'ML 1' has to be made of alphanumeric characters, dashes, dots and underscores exclusively
[2025-04-24T18:20:09.433+0000] {processor.py:927} WARNING - No viable dags retrieved from /opt/airflow/dags/ML/ML1.py
[2025-04-24T18:20:09.492+0000] {processor.py:208} INFO - Processing /opt/airflow/dags/ML/ML1.py took 0.434 seconds
[2025-04-24T18:20:39.572+0000] {processor.py:186} INFO - Started process (PID=401) to work on /opt/airflow/dags/ML/ML1.py
[2025-04-24T18:20:39.573+0000] {processor.py:914} INFO - Processing file /opt/airflow/dags/ML/ML1.py for tasks to queue
[2025-04-24T18:20:39.576+0000] {logging_mixin.py:190} INFO - [2025-04-24T18:20:39.576+0000] {dagbag.py:588} INFO - Filling up the DagBag from /opt/airflow/dags/ML/ML1.py
[2025-04-24T18:20:39.938+0000] {logging_mixin.py:190} INFO - [2025-04-24T18:20:39.924+0000] {dagbag.py:387} ERROR - Failed to import: /opt/airflow/dags/ML/ML1.py
Traceback (most recent call last):
  File "/home/airflow/.local/lib/python3.12/site-packages/airflow/models/dagbag.py", line 383, in parse
    loader.exec_module(new_module)
  File "<frozen importlib._bootstrap_external>", line 999, in exec_module
  File "<frozen importlib._bootstrap>", line 488, in _call_with_frames_removed
  File "/opt/airflow/dags/ML/ML1.py", line 17, in <module>
    with DAG(
         ^^^^
  File "/home/airflow/.local/lib/python3.12/site-packages/airflow/models/dag.py", line 593, in __init__
    validate_key(dag_id)
  File "/home/airflow/.local/lib/python3.12/site-packages/airflow/utils/helpers.py", line 57, in validate_key
    raise AirflowException(
airflow.exceptions.AirflowException: The key 'ML 1' has to be made of alphanumeric characters, dashes, dots and underscores exclusively
[2025-04-24T18:20:39.939+0000] {processor.py:927} WARNING - No viable dags retrieved from /opt/airflow/dags/ML/ML1.py
[2025-04-24T18:20:40.005+0000] {processor.py:208} INFO - Processing /opt/airflow/dags/ML/ML1.py took 0.439 seconds
[2025-04-24T18:21:10.694+0000] {processor.py:186} INFO - Started process (PID=429) to work on /opt/airflow/dags/ML/ML1.py
[2025-04-24T18:21:10.695+0000] {processor.py:914} INFO - Processing file /opt/airflow/dags/ML/ML1.py for tasks to queue
[2025-04-24T18:21:10.698+0000] {logging_mixin.py:190} INFO - [2025-04-24T18:21:10.697+0000] {dagbag.py:588} INFO - Filling up the DagBag from /opt/airflow/dags/ML/ML1.py
[2025-04-24T18:21:11.100+0000] {logging_mixin.py:190} INFO - [2025-04-24T18:21:11.090+0000] {dagbag.py:387} ERROR - Failed to import: /opt/airflow/dags/ML/ML1.py
Traceback (most recent call last):
  File "/home/airflow/.local/lib/python3.12/site-packages/airflow/models/dagbag.py", line 383, in parse
    loader.exec_module(new_module)
  File "<frozen importlib._bootstrap_external>", line 999, in exec_module
  File "<frozen importlib._bootstrap>", line 488, in _call_with_frames_removed
  File "/opt/airflow/dags/ML/ML1.py", line 17, in <module>
    with DAG(
         ^^^^
  File "/home/airflow/.local/lib/python3.12/site-packages/airflow/models/dag.py", line 593, in __init__
    validate_key(dag_id)
  File "/home/airflow/.local/lib/python3.12/site-packages/airflow/utils/helpers.py", line 57, in validate_key
    raise AirflowException(
airflow.exceptions.AirflowException: The key 'ML 1' has to be made of alphanumeric characters, dashes, dots and underscores exclusively
[2025-04-24T18:21:11.101+0000] {processor.py:927} WARNING - No viable dags retrieved from /opt/airflow/dags/ML/ML1.py
[2025-04-24T18:21:11.166+0000] {processor.py:208} INFO - Processing /opt/airflow/dags/ML/ML1.py took 0.478 seconds
[2025-04-24T18:21:41.434+0000] {processor.py:186} INFO - Started process (PID=458) to work on /opt/airflow/dags/ML/ML1.py
[2025-04-24T18:21:41.435+0000] {processor.py:914} INFO - Processing file /opt/airflow/dags/ML/ML1.py for tasks to queue
[2025-04-24T18:21:41.437+0000] {logging_mixin.py:190} INFO - [2025-04-24T18:21:41.437+0000] {dagbag.py:588} INFO - Filling up the DagBag from /opt/airflow/dags/ML/ML1.py
[2025-04-24T18:21:41.831+0000] {logging_mixin.py:190} INFO - [2025-04-24T18:21:41.822+0000] {dagbag.py:387} ERROR - Failed to import: /opt/airflow/dags/ML/ML1.py
Traceback (most recent call last):
  File "/home/airflow/.local/lib/python3.12/site-packages/airflow/models/dagbag.py", line 383, in parse
    loader.exec_module(new_module)
  File "<frozen importlib._bootstrap_external>", line 999, in exec_module
  File "<frozen importlib._bootstrap>", line 488, in _call_with_frames_removed
  File "/opt/airflow/dags/ML/ML1.py", line 17, in <module>
    with DAG(
         ^^^^
  File "/home/airflow/.local/lib/python3.12/site-packages/airflow/models/dag.py", line 593, in __init__
    validate_key(dag_id)
  File "/home/airflow/.local/lib/python3.12/site-packages/airflow/utils/helpers.py", line 57, in validate_key
    raise AirflowException(
airflow.exceptions.AirflowException: The key 'ML 1' has to be made of alphanumeric characters, dashes, dots and underscores exclusively
[2025-04-24T18:21:41.832+0000] {processor.py:927} WARNING - No viable dags retrieved from /opt/airflow/dags/ML/ML1.py
[2025-04-24T18:21:41.890+0000] {processor.py:208} INFO - Processing /opt/airflow/dags/ML/ML1.py took 0.463 seconds
[2025-04-24T18:22:12.590+0000] {processor.py:186} INFO - Started process (PID=487) to work on /opt/airflow/dags/ML/ML1.py
[2025-04-24T18:22:12.591+0000] {processor.py:914} INFO - Processing file /opt/airflow/dags/ML/ML1.py for tasks to queue
[2025-04-24T18:22:12.593+0000] {logging_mixin.py:190} INFO - [2025-04-24T18:22:12.593+0000] {dagbag.py:588} INFO - Filling up the DagBag from /opt/airflow/dags/ML/ML1.py
[2025-04-24T18:22:12.984+0000] {logging_mixin.py:190} INFO - [2025-04-24T18:22:12.976+0000] {dagbag.py:387} ERROR - Failed to import: /opt/airflow/dags/ML/ML1.py
Traceback (most recent call last):
  File "/home/airflow/.local/lib/python3.12/site-packages/airflow/models/dagbag.py", line 383, in parse
    loader.exec_module(new_module)
  File "<frozen importlib._bootstrap_external>", line 999, in exec_module
  File "<frozen importlib._bootstrap>", line 488, in _call_with_frames_removed
  File "/opt/airflow/dags/ML/ML1.py", line 17, in <module>
    with DAG(
         ^^^^
  File "/home/airflow/.local/lib/python3.12/site-packages/airflow/models/dag.py", line 593, in __init__
    validate_key(dag_id)
  File "/home/airflow/.local/lib/python3.12/site-packages/airflow/utils/helpers.py", line 57, in validate_key
    raise AirflowException(
airflow.exceptions.AirflowException: The key 'ML 1' has to be made of alphanumeric characters, dashes, dots and underscores exclusively
[2025-04-24T18:22:12.985+0000] {processor.py:927} WARNING - No viable dags retrieved from /opt/airflow/dags/ML/ML1.py
[2025-04-24T18:22:13.057+0000] {processor.py:208} INFO - Processing /opt/airflow/dags/ML/ML1.py took 0.472 seconds
[2025-04-24T18:22:43.257+0000] {processor.py:186} INFO - Started process (PID=516) to work on /opt/airflow/dags/ML/ML1.py
[2025-04-24T18:22:43.258+0000] {processor.py:914} INFO - Processing file /opt/airflow/dags/ML/ML1.py for tasks to queue
[2025-04-24T18:22:43.260+0000] {logging_mixin.py:190} INFO - [2025-04-24T18:22:43.260+0000] {dagbag.py:588} INFO - Filling up the DagBag from /opt/airflow/dags/ML/ML1.py
[2025-04-24T18:22:43.659+0000] {logging_mixin.py:190} INFO - [2025-04-24T18:22:43.649+0000] {dagbag.py:387} ERROR - Failed to import: /opt/airflow/dags/ML/ML1.py
Traceback (most recent call last):
  File "/home/airflow/.local/lib/python3.12/site-packages/airflow/models/dagbag.py", line 383, in parse
    loader.exec_module(new_module)
  File "<frozen importlib._bootstrap_external>", line 999, in exec_module
  File "<frozen importlib._bootstrap>", line 488, in _call_with_frames_removed
  File "/opt/airflow/dags/ML/ML1.py", line 17, in <module>
    with DAG(
         ^^^^
  File "/home/airflow/.local/lib/python3.12/site-packages/airflow/models/dag.py", line 593, in __init__
    validate_key(dag_id)
  File "/home/airflow/.local/lib/python3.12/site-packages/airflow/utils/helpers.py", line 57, in validate_key
    raise AirflowException(
airflow.exceptions.AirflowException: The key 'ML 1' has to be made of alphanumeric characters, dashes, dots and underscores exclusively
[2025-04-24T18:22:43.660+0000] {processor.py:927} WARNING - No viable dags retrieved from /opt/airflow/dags/ML/ML1.py
[2025-04-24T18:22:43.734+0000] {processor.py:208} INFO - Processing /opt/airflow/dags/ML/ML1.py took 0.482 seconds
[2025-04-24T18:23:14.371+0000] {processor.py:186} INFO - Started process (PID=545) to work on /opt/airflow/dags/ML/ML1.py
[2025-04-24T18:23:14.373+0000] {processor.py:914} INFO - Processing file /opt/airflow/dags/ML/ML1.py for tasks to queue
[2025-04-24T18:23:14.377+0000] {logging_mixin.py:190} INFO - [2025-04-24T18:23:14.376+0000] {dagbag.py:588} INFO - Filling up the DagBag from /opt/airflow/dags/ML/ML1.py
[2025-04-24T18:23:14.843+0000] {logging_mixin.py:190} INFO - [2025-04-24T18:23:14.835+0000] {dagbag.py:387} ERROR - Failed to import: /opt/airflow/dags/ML/ML1.py
Traceback (most recent call last):
  File "/home/airflow/.local/lib/python3.12/site-packages/airflow/models/dagbag.py", line 383, in parse
    loader.exec_module(new_module)
  File "<frozen importlib._bootstrap_external>", line 999, in exec_module
  File "<frozen importlib._bootstrap>", line 488, in _call_with_frames_removed
  File "/opt/airflow/dags/ML/ML1.py", line 17, in <module>
    with DAG(
         ^^^^
  File "/home/airflow/.local/lib/python3.12/site-packages/airflow/models/dag.py", line 593, in __init__
    validate_key(dag_id)
  File "/home/airflow/.local/lib/python3.12/site-packages/airflow/utils/helpers.py", line 57, in validate_key
    raise AirflowException(
airflow.exceptions.AirflowException: The key 'ML 1' has to be made of alphanumeric characters, dashes, dots and underscores exclusively
[2025-04-24T18:23:14.844+0000] {processor.py:927} WARNING - No viable dags retrieved from /opt/airflow/dags/ML/ML1.py
[2025-04-24T18:23:14.919+0000] {processor.py:208} INFO - Processing /opt/airflow/dags/ML/ML1.py took 0.563 seconds
[2025-04-24T18:23:45.235+0000] {processor.py:186} INFO - Started process (PID=574) to work on /opt/airflow/dags/ML/ML1.py
[2025-04-24T18:23:45.237+0000] {processor.py:914} INFO - Processing file /opt/airflow/dags/ML/ML1.py for tasks to queue
[2025-04-24T18:23:45.239+0000] {logging_mixin.py:190} INFO - [2025-04-24T18:23:45.239+0000] {dagbag.py:588} INFO - Filling up the DagBag from /opt/airflow/dags/ML/ML1.py
[2025-04-24T18:23:45.689+0000] {logging_mixin.py:190} INFO - [2025-04-24T18:23:45.679+0000] {dagbag.py:387} ERROR - Failed to import: /opt/airflow/dags/ML/ML1.py
Traceback (most recent call last):
  File "/home/airflow/.local/lib/python3.12/site-packages/airflow/models/dagbag.py", line 383, in parse
    loader.exec_module(new_module)
  File "<frozen importlib._bootstrap_external>", line 999, in exec_module
  File "<frozen importlib._bootstrap>", line 488, in _call_with_frames_removed
  File "/opt/airflow/dags/ML/ML1.py", line 17, in <module>
    with DAG(
         ^^^^
  File "/home/airflow/.local/lib/python3.12/site-packages/airflow/models/dag.py", line 593, in __init__
    validate_key(dag_id)
  File "/home/airflow/.local/lib/python3.12/site-packages/airflow/utils/helpers.py", line 57, in validate_key
    raise AirflowException(
airflow.exceptions.AirflowException: The key 'ML 1' has to be made of alphanumeric characters, dashes, dots and underscores exclusively
[2025-04-24T18:23:45.690+0000] {processor.py:927} WARNING - No viable dags retrieved from /opt/airflow/dags/ML/ML1.py
[2025-04-24T18:23:45.765+0000] {processor.py:208} INFO - Processing /opt/airflow/dags/ML/ML1.py took 0.535 seconds
[2025-04-24T18:24:16.276+0000] {processor.py:186} INFO - Started process (PID=603) to work on /opt/airflow/dags/ML/ML1.py
[2025-04-24T18:24:16.279+0000] {processor.py:914} INFO - Processing file /opt/airflow/dags/ML/ML1.py for tasks to queue
[2025-04-24T18:24:16.286+0000] {logging_mixin.py:190} INFO - [2025-04-24T18:24:16.285+0000] {dagbag.py:588} INFO - Filling up the DagBag from /opt/airflow/dags/ML/ML1.py
[2025-04-24T18:24:16.758+0000] {logging_mixin.py:190} INFO - [2025-04-24T18:24:16.750+0000] {dagbag.py:387} ERROR - Failed to import: /opt/airflow/dags/ML/ML1.py
Traceback (most recent call last):
  File "/home/airflow/.local/lib/python3.12/site-packages/airflow/models/dagbag.py", line 383, in parse
    loader.exec_module(new_module)
  File "<frozen importlib._bootstrap_external>", line 999, in exec_module
  File "<frozen importlib._bootstrap>", line 488, in _call_with_frames_removed
  File "/opt/airflow/dags/ML/ML1.py", line 17, in <module>
    with DAG(
         ^^^^
  File "/home/airflow/.local/lib/python3.12/site-packages/airflow/models/dag.py", line 593, in __init__
    validate_key(dag_id)
  File "/home/airflow/.local/lib/python3.12/site-packages/airflow/utils/helpers.py", line 57, in validate_key
    raise AirflowException(
airflow.exceptions.AirflowException: The key 'ML 1' has to be made of alphanumeric characters, dashes, dots and underscores exclusively
[2025-04-24T18:24:16.759+0000] {processor.py:927} WARNING - No viable dags retrieved from /opt/airflow/dags/ML/ML1.py
[2025-04-24T18:24:16.833+0000] {processor.py:208} INFO - Processing /opt/airflow/dags/ML/ML1.py took 0.568 seconds
[2025-04-24T18:24:48.647+0000] {processor.py:186} INFO - Started process (PID=632) to work on /opt/airflow/dags/ML/ML1.py
[2025-04-24T18:24:48.648+0000] {processor.py:914} INFO - Processing file /opt/airflow/dags/ML/ML1.py for tasks to queue
[2025-04-24T18:24:48.651+0000] {logging_mixin.py:190} INFO - [2025-04-24T18:24:48.650+0000] {dagbag.py:588} INFO - Filling up the DagBag from /opt/airflow/dags/ML/ML1.py
[2025-04-24T18:24:49.305+0000] {logging_mixin.py:190} INFO - [2025-04-24T18:24:49.293+0000] {dagbag.py:387} ERROR - Failed to import: /opt/airflow/dags/ML/ML1.py
Traceback (most recent call last):
  File "/home/airflow/.local/lib/python3.12/site-packages/airflow/models/dagbag.py", line 383, in parse
    loader.exec_module(new_module)
  File "<frozen importlib._bootstrap_external>", line 999, in exec_module
  File "<frozen importlib._bootstrap>", line 488, in _call_with_frames_removed
  File "/opt/airflow/dags/ML/ML1.py", line 17, in <module>
    with DAG(
         ^^^^
  File "/home/airflow/.local/lib/python3.12/site-packages/airflow/models/dag.py", line 593, in __init__
    validate_key(dag_id)
  File "/home/airflow/.local/lib/python3.12/site-packages/airflow/utils/helpers.py", line 57, in validate_key
    raise AirflowException(
airflow.exceptions.AirflowException: The key 'ML 1' has to be made of alphanumeric characters, dashes, dots and underscores exclusively
[2025-04-24T18:24:49.306+0000] {processor.py:927} WARNING - No viable dags retrieved from /opt/airflow/dags/ML/ML1.py
[2025-04-24T18:24:49.408+0000] {processor.py:208} INFO - Processing /opt/airflow/dags/ML/ML1.py took 0.768 seconds
[2025-04-24T18:25:19.599+0000] {processor.py:186} INFO - Started process (PID=661) to work on /opt/airflow/dags/ML/ML1.py
[2025-04-24T18:25:19.601+0000] {processor.py:914} INFO - Processing file /opt/airflow/dags/ML/ML1.py for tasks to queue
[2025-04-24T18:25:19.607+0000] {logging_mixin.py:190} INFO - [2025-04-24T18:25:19.606+0000] {dagbag.py:588} INFO - Filling up the DagBag from /opt/airflow/dags/ML/ML1.py
[2025-04-24T18:25:20.203+0000] {logging_mixin.py:190} INFO - [2025-04-24T18:25:20.190+0000] {dagbag.py:387} ERROR - Failed to import: /opt/airflow/dags/ML/ML1.py
Traceback (most recent call last):
  File "/home/airflow/.local/lib/python3.12/site-packages/airflow/models/dagbag.py", line 383, in parse
    loader.exec_module(new_module)
  File "<frozen importlib._bootstrap_external>", line 999, in exec_module
  File "<frozen importlib._bootstrap>", line 488, in _call_with_frames_removed
  File "/opt/airflow/dags/ML/ML1.py", line 17, in <module>
    with DAG(
         ^^^^
  File "/home/airflow/.local/lib/python3.12/site-packages/airflow/models/dag.py", line 593, in __init__
    validate_key(dag_id)
  File "/home/airflow/.local/lib/python3.12/site-packages/airflow/utils/helpers.py", line 57, in validate_key
    raise AirflowException(
airflow.exceptions.AirflowException: The key 'ML 1' has to be made of alphanumeric characters, dashes, dots and underscores exclusively
[2025-04-24T18:25:20.204+0000] {processor.py:927} WARNING - No viable dags retrieved from /opt/airflow/dags/ML/ML1.py
[2025-04-24T18:25:20.335+0000] {processor.py:208} INFO - Processing /opt/airflow/dags/ML/ML1.py took 0.750 seconds
[2025-04-24T18:25:51.139+0000] {processor.py:186} INFO - Started process (PID=697) to work on /opt/airflow/dags/ML/ML1.py
[2025-04-24T18:25:51.141+0000] {processor.py:914} INFO - Processing file /opt/airflow/dags/ML/ML1.py for tasks to queue
[2025-04-24T18:25:51.145+0000] {logging_mixin.py:190} INFO - [2025-04-24T18:25:51.144+0000] {dagbag.py:588} INFO - Filling up the DagBag from /opt/airflow/dags/ML/ML1.py
[2025-04-24T18:25:51.522+0000] {logging_mixin.py:190} INFO - [2025-04-24T18:25:51.514+0000] {dagbag.py:387} ERROR - Failed to import: /opt/airflow/dags/ML/ML1.py
Traceback (most recent call last):
  File "/home/airflow/.local/lib/python3.12/site-packages/airflow/models/dagbag.py", line 383, in parse
    loader.exec_module(new_module)
  File "<frozen importlib._bootstrap_external>", line 999, in exec_module
  File "<frozen importlib._bootstrap>", line 488, in _call_with_frames_removed
  File "/opt/airflow/dags/ML/ML1.py", line 17, in <module>
    with DAG(
         ^^^^
  File "/home/airflow/.local/lib/python3.12/site-packages/airflow/models/dag.py", line 593, in __init__
    validate_key(dag_id)
  File "/home/airflow/.local/lib/python3.12/site-packages/airflow/utils/helpers.py", line 57, in validate_key
    raise AirflowException(
airflow.exceptions.AirflowException: The key 'ML 1' has to be made of alphanumeric characters, dashes, dots and underscores exclusively
[2025-04-24T18:25:51.522+0000] {processor.py:927} WARNING - No viable dags retrieved from /opt/airflow/dags/ML/ML1.py
[2025-04-24T18:25:51.601+0000] {processor.py:208} INFO - Processing /opt/airflow/dags/ML/ML1.py took 0.468 seconds
[2025-04-24T18:26:22.309+0000] {processor.py:186} INFO - Started process (PID=726) to work on /opt/airflow/dags/ML/ML1.py
[2025-04-24T18:26:22.311+0000] {processor.py:914} INFO - Processing file /opt/airflow/dags/ML/ML1.py for tasks to queue
[2025-04-24T18:26:22.313+0000] {logging_mixin.py:190} INFO - [2025-04-24T18:26:22.312+0000] {dagbag.py:588} INFO - Filling up the DagBag from /opt/airflow/dags/ML/ML1.py
[2025-04-24T18:26:22.754+0000] {logging_mixin.py:190} INFO - [2025-04-24T18:26:22.745+0000] {dagbag.py:387} ERROR - Failed to import: /opt/airflow/dags/ML/ML1.py
Traceback (most recent call last):
  File "/home/airflow/.local/lib/python3.12/site-packages/airflow/models/dagbag.py", line 383, in parse
    loader.exec_module(new_module)
  File "<frozen importlib._bootstrap_external>", line 999, in exec_module
  File "<frozen importlib._bootstrap>", line 488, in _call_with_frames_removed
  File "/opt/airflow/dags/ML/ML1.py", line 17, in <module>
    with DAG(
         ^^^^
  File "/home/airflow/.local/lib/python3.12/site-packages/airflow/models/dag.py", line 593, in __init__
    validate_key(dag_id)
  File "/home/airflow/.local/lib/python3.12/site-packages/airflow/utils/helpers.py", line 57, in validate_key
    raise AirflowException(
airflow.exceptions.AirflowException: The key 'ML 1' has to be made of alphanumeric characters, dashes, dots and underscores exclusively
[2025-04-24T18:26:22.756+0000] {processor.py:927} WARNING - No viable dags retrieved from /opt/airflow/dags/ML/ML1.py
[2025-04-24T18:26:22.852+0000] {processor.py:208} INFO - Processing /opt/airflow/dags/ML/ML1.py took 0.550 seconds
[2025-04-24T18:26:53.353+0000] {processor.py:186} INFO - Started process (PID=755) to work on /opt/airflow/dags/ML/ML1.py
[2025-04-24T18:26:53.354+0000] {processor.py:914} INFO - Processing file /opt/airflow/dags/ML/ML1.py for tasks to queue
[2025-04-24T18:26:53.356+0000] {logging_mixin.py:190} INFO - [2025-04-24T18:26:53.356+0000] {dagbag.py:588} INFO - Filling up the DagBag from /opt/airflow/dags/ML/ML1.py
[2025-04-24T18:26:53.781+0000] {logging_mixin.py:190} INFO - [2025-04-24T18:26:53.774+0000] {dagbag.py:387} ERROR - Failed to import: /opt/airflow/dags/ML/ML1.py
Traceback (most recent call last):
  File "/home/airflow/.local/lib/python3.12/site-packages/airflow/models/dagbag.py", line 383, in parse
    loader.exec_module(new_module)
  File "<frozen importlib._bootstrap_external>", line 999, in exec_module
  File "<frozen importlib._bootstrap>", line 488, in _call_with_frames_removed
  File "/opt/airflow/dags/ML/ML1.py", line 17, in <module>
    with DAG(
         ^^^^
  File "/home/airflow/.local/lib/python3.12/site-packages/airflow/models/dag.py", line 593, in __init__
    validate_key(dag_id)
  File "/home/airflow/.local/lib/python3.12/site-packages/airflow/utils/helpers.py", line 57, in validate_key
    raise AirflowException(
airflow.exceptions.AirflowException: The key 'ML 1' has to be made of alphanumeric characters, dashes, dots and underscores exclusively
[2025-04-24T18:26:53.782+0000] {processor.py:927} WARNING - No viable dags retrieved from /opt/airflow/dags/ML/ML1.py
[2025-04-24T18:26:53.842+0000] {processor.py:208} INFO - Processing /opt/airflow/dags/ML/ML1.py took 0.495 seconds
[2025-04-24T18:27:24.251+0000] {processor.py:186} INFO - Started process (PID=784) to work on /opt/airflow/dags/ML/ML1.py
[2025-04-24T18:27:24.252+0000] {processor.py:914} INFO - Processing file /opt/airflow/dags/ML/ML1.py for tasks to queue
[2025-04-24T18:27:24.254+0000] {logging_mixin.py:190} INFO - [2025-04-24T18:27:24.254+0000] {dagbag.py:588} INFO - Filling up the DagBag from /opt/airflow/dags/ML/ML1.py
[2025-04-24T18:27:24.785+0000] {logging_mixin.py:190} INFO - [2025-04-24T18:27:24.778+0000] {dagbag.py:387} ERROR - Failed to import: /opt/airflow/dags/ML/ML1.py
Traceback (most recent call last):
  File "/home/airflow/.local/lib/python3.12/site-packages/airflow/models/dagbag.py", line 383, in parse
    loader.exec_module(new_module)
  File "<frozen importlib._bootstrap_external>", line 999, in exec_module
  File "<frozen importlib._bootstrap>", line 488, in _call_with_frames_removed
  File "/opt/airflow/dags/ML/ML1.py", line 17, in <module>
    with DAG(
         ^^^^
  File "/home/airflow/.local/lib/python3.12/site-packages/airflow/models/dag.py", line 593, in __init__
    validate_key(dag_id)
  File "/home/airflow/.local/lib/python3.12/site-packages/airflow/utils/helpers.py", line 57, in validate_key
    raise AirflowException(
airflow.exceptions.AirflowException: The key 'ML 1' has to be made of alphanumeric characters, dashes, dots and underscores exclusively
[2025-04-24T18:27:24.786+0000] {processor.py:927} WARNING - No viable dags retrieved from /opt/airflow/dags/ML/ML1.py
[2025-04-24T18:27:24.849+0000] {processor.py:208} INFO - Processing /opt/airflow/dags/ML/ML1.py took 0.603 seconds
[2025-04-24T18:27:55.021+0000] {processor.py:186} INFO - Started process (PID=813) to work on /opt/airflow/dags/ML/ML1.py
[2025-04-24T18:27:55.023+0000] {processor.py:914} INFO - Processing file /opt/airflow/dags/ML/ML1.py for tasks to queue
[2025-04-24T18:27:55.025+0000] {logging_mixin.py:190} INFO - [2025-04-24T18:27:55.025+0000] {dagbag.py:588} INFO - Filling up the DagBag from /opt/airflow/dags/ML/ML1.py
[2025-04-24T18:27:55.424+0000] {logging_mixin.py:190} INFO - [2025-04-24T18:27:55.416+0000] {dagbag.py:387} ERROR - Failed to import: /opt/airflow/dags/ML/ML1.py
Traceback (most recent call last):
  File "/home/airflow/.local/lib/python3.12/site-packages/airflow/models/dagbag.py", line 383, in parse
    loader.exec_module(new_module)
  File "<frozen importlib._bootstrap_external>", line 999, in exec_module
  File "<frozen importlib._bootstrap>", line 488, in _call_with_frames_removed
  File "/opt/airflow/dags/ML/ML1.py", line 17, in <module>
    with DAG(
         ^^^^
  File "/home/airflow/.local/lib/python3.12/site-packages/airflow/models/dag.py", line 593, in __init__
    validate_key(dag_id)
  File "/home/airflow/.local/lib/python3.12/site-packages/airflow/utils/helpers.py", line 57, in validate_key
    raise AirflowException(
airflow.exceptions.AirflowException: The key 'ML 1' has to be made of alphanumeric characters, dashes, dots and underscores exclusively
[2025-04-24T18:27:55.425+0000] {processor.py:927} WARNING - No viable dags retrieved from /opt/airflow/dags/ML/ML1.py
[2025-04-24T18:27:55.483+0000] {processor.py:208} INFO - Processing /opt/airflow/dags/ML/ML1.py took 0.467 seconds
[2025-04-24T18:28:26.067+0000] {processor.py:186} INFO - Started process (PID=842) to work on /opt/airflow/dags/ML/ML1.py
[2025-04-24T18:28:26.069+0000] {processor.py:914} INFO - Processing file /opt/airflow/dags/ML/ML1.py for tasks to queue
[2025-04-24T18:28:26.072+0000] {logging_mixin.py:190} INFO - [2025-04-24T18:28:26.072+0000] {dagbag.py:588} INFO - Filling up the DagBag from /opt/airflow/dags/ML/ML1.py
[2025-04-24T18:28:26.611+0000] {logging_mixin.py:190} INFO - [2025-04-24T18:28:26.601+0000] {dagbag.py:387} ERROR - Failed to import: /opt/airflow/dags/ML/ML1.py
Traceback (most recent call last):
  File "/home/airflow/.local/lib/python3.12/site-packages/airflow/models/dagbag.py", line 383, in parse
    loader.exec_module(new_module)
  File "<frozen importlib._bootstrap_external>", line 999, in exec_module
  File "<frozen importlib._bootstrap>", line 488, in _call_with_frames_removed
  File "/opt/airflow/dags/ML/ML1.py", line 17, in <module>
    with DAG(
         ^^^^
  File "/home/airflow/.local/lib/python3.12/site-packages/airflow/models/dag.py", line 593, in __init__
    validate_key(dag_id)
  File "/home/airflow/.local/lib/python3.12/site-packages/airflow/utils/helpers.py", line 57, in validate_key
    raise AirflowException(
airflow.exceptions.AirflowException: The key 'ML 1' has to be made of alphanumeric characters, dashes, dots and underscores exclusively
[2025-04-24T18:28:26.613+0000] {processor.py:927} WARNING - No viable dags retrieved from /opt/airflow/dags/ML/ML1.py
[2025-04-24T18:28:26.773+0000] {processor.py:208} INFO - Processing /opt/airflow/dags/ML/ML1.py took 0.715 seconds
[2025-04-24T18:28:57.186+0000] {processor.py:186} INFO - Started process (PID=871) to work on /opt/airflow/dags/ML/ML1.py
[2025-04-24T18:28:57.187+0000] {processor.py:914} INFO - Processing file /opt/airflow/dags/ML/ML1.py for tasks to queue
[2025-04-24T18:28:57.189+0000] {logging_mixin.py:190} INFO - [2025-04-24T18:28:57.189+0000] {dagbag.py:588} INFO - Filling up the DagBag from /opt/airflow/dags/ML/ML1.py
[2025-04-24T18:28:57.633+0000] {logging_mixin.py:190} INFO - [2025-04-24T18:28:57.624+0000] {dagbag.py:387} ERROR - Failed to import: /opt/airflow/dags/ML/ML1.py
Traceback (most recent call last):
  File "/home/airflow/.local/lib/python3.12/site-packages/airflow/models/dagbag.py", line 383, in parse
    loader.exec_module(new_module)
  File "<frozen importlib._bootstrap_external>", line 999, in exec_module
  File "<frozen importlib._bootstrap>", line 488, in _call_with_frames_removed
  File "/opt/airflow/dags/ML/ML1.py", line 17, in <module>
    with DAG(
         ^^^^
  File "/home/airflow/.local/lib/python3.12/site-packages/airflow/models/dag.py", line 593, in __init__
    validate_key(dag_id)
  File "/home/airflow/.local/lib/python3.12/site-packages/airflow/utils/helpers.py", line 57, in validate_key
    raise AirflowException(
airflow.exceptions.AirflowException: The key 'ML 1' has to be made of alphanumeric characters, dashes, dots and underscores exclusively
[2025-04-24T18:28:57.634+0000] {processor.py:927} WARNING - No viable dags retrieved from /opt/airflow/dags/ML/ML1.py
[2025-04-24T18:28:57.712+0000] {processor.py:208} INFO - Processing /opt/airflow/dags/ML/ML1.py took 0.533 seconds
[2025-04-24T18:29:27.913+0000] {processor.py:186} INFO - Started process (PID=901) to work on /opt/airflow/dags/ML/ML1.py
[2025-04-24T18:29:27.914+0000] {processor.py:914} INFO - Processing file /opt/airflow/dags/ML/ML1.py for tasks to queue
[2025-04-24T18:29:27.916+0000] {logging_mixin.py:190} INFO - [2025-04-24T18:29:27.916+0000] {dagbag.py:588} INFO - Filling up the DagBag from /opt/airflow/dags/ML/ML1.py
[2025-04-24T18:29:28.311+0000] {logging_mixin.py:190} INFO - [2025-04-24T18:29:28.302+0000] {dagbag.py:387} ERROR - Failed to import: /opt/airflow/dags/ML/ML1.py
Traceback (most recent call last):
  File "/home/airflow/.local/lib/python3.12/site-packages/airflow/models/dagbag.py", line 383, in parse
    loader.exec_module(new_module)
  File "<frozen importlib._bootstrap_external>", line 999, in exec_module
  File "<frozen importlib._bootstrap>", line 488, in _call_with_frames_removed
  File "/opt/airflow/dags/ML/ML1.py", line 17, in <module>
    with DAG(
         ^^^^
  File "/home/airflow/.local/lib/python3.12/site-packages/airflow/models/dag.py", line 593, in __init__
    validate_key(dag_id)
  File "/home/airflow/.local/lib/python3.12/site-packages/airflow/utils/helpers.py", line 57, in validate_key
    raise AirflowException(
airflow.exceptions.AirflowException: The key 'ML 1' has to be made of alphanumeric characters, dashes, dots and underscores exclusively
[2025-04-24T18:29:28.313+0000] {processor.py:927} WARNING - No viable dags retrieved from /opt/airflow/dags/ML/ML1.py
[2025-04-24T18:29:28.384+0000] {processor.py:208} INFO - Processing /opt/airflow/dags/ML/ML1.py took 0.476 seconds
[2025-04-24T18:29:59.076+0000] {processor.py:186} INFO - Started process (PID=930) to work on /opt/airflow/dags/ML/ML1.py
[2025-04-24T18:29:59.077+0000] {processor.py:914} INFO - Processing file /opt/airflow/dags/ML/ML1.py for tasks to queue
[2025-04-24T18:29:59.079+0000] {logging_mixin.py:190} INFO - [2025-04-24T18:29:59.079+0000] {dagbag.py:588} INFO - Filling up the DagBag from /opt/airflow/dags/ML/ML1.py
[2025-04-24T18:29:59.490+0000] {logging_mixin.py:190} INFO - [2025-04-24T18:29:59.481+0000] {dagbag.py:387} ERROR - Failed to import: /opt/airflow/dags/ML/ML1.py
Traceback (most recent call last):
  File "/home/airflow/.local/lib/python3.12/site-packages/airflow/models/dagbag.py", line 383, in parse
    loader.exec_module(new_module)
  File "<frozen importlib._bootstrap_external>", line 999, in exec_module
  File "<frozen importlib._bootstrap>", line 488, in _call_with_frames_removed
  File "/opt/airflow/dags/ML/ML1.py", line 17, in <module>
    with DAG(
         ^^^^
  File "/home/airflow/.local/lib/python3.12/site-packages/airflow/models/dag.py", line 593, in __init__
    validate_key(dag_id)
  File "/home/airflow/.local/lib/python3.12/site-packages/airflow/utils/helpers.py", line 57, in validate_key
    raise AirflowException(
airflow.exceptions.AirflowException: The key 'ML 1' has to be made of alphanumeric characters, dashes, dots and underscores exclusively
[2025-04-24T18:29:59.491+0000] {processor.py:927} WARNING - No viable dags retrieved from /opt/airflow/dags/ML/ML1.py
[2025-04-24T18:29:59.553+0000] {processor.py:208} INFO - Processing /opt/airflow/dags/ML/ML1.py took 0.482 seconds
[2025-04-24T18:30:29.664+0000] {processor.py:186} INFO - Started process (PID=959) to work on /opt/airflow/dags/ML/ML1.py
[2025-04-24T18:30:29.665+0000] {processor.py:914} INFO - Processing file /opt/airflow/dags/ML/ML1.py for tasks to queue
[2025-04-24T18:30:29.668+0000] {logging_mixin.py:190} INFO - [2025-04-24T18:30:29.668+0000] {dagbag.py:588} INFO - Filling up the DagBag from /opt/airflow/dags/ML/ML1.py
[2025-04-24T18:30:30.072+0000] {logging_mixin.py:190} INFO - [2025-04-24T18:30:30.066+0000] {dagbag.py:387} ERROR - Failed to import: /opt/airflow/dags/ML/ML1.py
Traceback (most recent call last):
  File "/home/airflow/.local/lib/python3.12/site-packages/airflow/models/dagbag.py", line 383, in parse
    loader.exec_module(new_module)
  File "<frozen importlib._bootstrap_external>", line 999, in exec_module
  File "<frozen importlib._bootstrap>", line 488, in _call_with_frames_removed
  File "/opt/airflow/dags/ML/ML1.py", line 17, in <module>
    with DAG(
         ^^^^
  File "/home/airflow/.local/lib/python3.12/site-packages/airflow/models/dag.py", line 593, in __init__
    validate_key(dag_id)
  File "/home/airflow/.local/lib/python3.12/site-packages/airflow/utils/helpers.py", line 57, in validate_key
    raise AirflowException(
airflow.exceptions.AirflowException: The key 'ML 1' has to be made of alphanumeric characters, dashes, dots and underscores exclusively
[2025-04-24T18:30:30.073+0000] {processor.py:927} WARNING - No viable dags retrieved from /opt/airflow/dags/ML/ML1.py
[2025-04-24T18:30:30.140+0000] {processor.py:208} INFO - Processing /opt/airflow/dags/ML/ML1.py took 0.482 seconds
[2025-04-24T18:31:00.456+0000] {processor.py:186} INFO - Started process (PID=988) to work on /opt/airflow/dags/ML/ML1.py
[2025-04-24T18:31:00.457+0000] {processor.py:914} INFO - Processing file /opt/airflow/dags/ML/ML1.py for tasks to queue
[2025-04-24T18:31:00.460+0000] {logging_mixin.py:190} INFO - [2025-04-24T18:31:00.459+0000] {dagbag.py:588} INFO - Filling up the DagBag from /opt/airflow/dags/ML/ML1.py
[2025-04-24T18:31:00.720+0000] {logging_mixin.py:190} INFO - [2025-04-24T18:31:00.711+0000] {dagbag.py:387} ERROR - Failed to import: /opt/airflow/dags/ML/ML1.py
Traceback (most recent call last):
  File "/home/airflow/.local/lib/python3.12/site-packages/airflow/models/dagbag.py", line 383, in parse
    loader.exec_module(new_module)
  File "<frozen importlib._bootstrap_external>", line 999, in exec_module
  File "<frozen importlib._bootstrap>", line 488, in _call_with_frames_removed
  File "/opt/airflow/dags/ML/ML1.py", line 17, in <module>
    with DAG(
         ^^^^
  File "/home/airflow/.local/lib/python3.12/site-packages/airflow/models/dag.py", line 593, in __init__
    validate_key(dag_id)
  File "/home/airflow/.local/lib/python3.12/site-packages/airflow/utils/helpers.py", line 57, in validate_key
    raise AirflowException(
airflow.exceptions.AirflowException: The key 'ML 1' has to be made of alphanumeric characters, dashes, dots and underscores exclusively
[2025-04-24T18:31:00.721+0000] {processor.py:927} WARNING - No viable dags retrieved from /opt/airflow/dags/ML/ML1.py
[2025-04-24T18:31:00.783+0000] {processor.py:208} INFO - Processing /opt/airflow/dags/ML/ML1.py took 0.332 seconds
[2025-04-24T18:31:31.208+0000] {processor.py:186} INFO - Started process (PID=1017) to work on /opt/airflow/dags/ML/ML1.py
[2025-04-24T18:31:31.209+0000] {processor.py:914} INFO - Processing file /opt/airflow/dags/ML/ML1.py for tasks to queue
[2025-04-24T18:31:31.211+0000] {logging_mixin.py:190} INFO - [2025-04-24T18:31:31.211+0000] {dagbag.py:588} INFO - Filling up the DagBag from /opt/airflow/dags/ML/ML1.py
[2025-04-24T18:31:31.465+0000] {logging_mixin.py:190} INFO - [2025-04-24T18:31:31.458+0000] {dagbag.py:387} ERROR - Failed to import: /opt/airflow/dags/ML/ML1.py
Traceback (most recent call last):
  File "/home/airflow/.local/lib/python3.12/site-packages/airflow/models/dagbag.py", line 383, in parse
    loader.exec_module(new_module)
  File "<frozen importlib._bootstrap_external>", line 999, in exec_module
  File "<frozen importlib._bootstrap>", line 488, in _call_with_frames_removed
  File "/opt/airflow/dags/ML/ML1.py", line 17, in <module>
    with DAG(
         ^^^^
  File "/home/airflow/.local/lib/python3.12/site-packages/airflow/models/dag.py", line 593, in __init__
    validate_key(dag_id)
  File "/home/airflow/.local/lib/python3.12/site-packages/airflow/utils/helpers.py", line 57, in validate_key
    raise AirflowException(
airflow.exceptions.AirflowException: The key 'ML 1' has to be made of alphanumeric characters, dashes, dots and underscores exclusively
[2025-04-24T18:31:31.466+0000] {processor.py:927} WARNING - No viable dags retrieved from /opt/airflow/dags/ML/ML1.py
[2025-04-24T18:31:31.525+0000] {processor.py:208} INFO - Processing /opt/airflow/dags/ML/ML1.py took 0.322 seconds
[2025-04-24T18:32:01.946+0000] {processor.py:186} INFO - Started process (PID=1046) to work on /opt/airflow/dags/ML/ML1.py
[2025-04-24T18:32:01.947+0000] {processor.py:914} INFO - Processing file /opt/airflow/dags/ML/ML1.py for tasks to queue
[2025-04-24T18:32:01.949+0000] {logging_mixin.py:190} INFO - [2025-04-24T18:32:01.949+0000] {dagbag.py:588} INFO - Filling up the DagBag from /opt/airflow/dags/ML/ML1.py
[2025-04-24T18:32:02.199+0000] {logging_mixin.py:190} INFO - [2025-04-24T18:32:02.193+0000] {dagbag.py:387} ERROR - Failed to import: /opt/airflow/dags/ML/ML1.py
Traceback (most recent call last):
  File "/home/airflow/.local/lib/python3.12/site-packages/airflow/models/dagbag.py", line 383, in parse
    loader.exec_module(new_module)
  File "<frozen importlib._bootstrap_external>", line 999, in exec_module
  File "<frozen importlib._bootstrap>", line 488, in _call_with_frames_removed
  File "/opt/airflow/dags/ML/ML1.py", line 17, in <module>
    with DAG(
         ^^^^
  File "/home/airflow/.local/lib/python3.12/site-packages/airflow/models/dag.py", line 593, in __init__
    validate_key(dag_id)
  File "/home/airflow/.local/lib/python3.12/site-packages/airflow/utils/helpers.py", line 57, in validate_key
    raise AirflowException(
airflow.exceptions.AirflowException: The key 'ML 1' has to be made of alphanumeric characters, dashes, dots and underscores exclusively
[2025-04-24T18:32:02.200+0000] {processor.py:927} WARNING - No viable dags retrieved from /opt/airflow/dags/ML/ML1.py
[2025-04-24T18:32:02.267+0000] {processor.py:208} INFO - Processing /opt/airflow/dags/ML/ML1.py took 0.327 seconds
[2025-04-24T18:32:32.593+0000] {processor.py:186} INFO - Started process (PID=1075) to work on /opt/airflow/dags/ML/ML1.py
[2025-04-24T18:32:32.594+0000] {processor.py:914} INFO - Processing file /opt/airflow/dags/ML/ML1.py for tasks to queue
[2025-04-24T18:32:32.596+0000] {logging_mixin.py:190} INFO - [2025-04-24T18:32:32.596+0000] {dagbag.py:588} INFO - Filling up the DagBag from /opt/airflow/dags/ML/ML1.py
[2025-04-24T18:32:32.877+0000] {logging_mixin.py:190} INFO - [2025-04-24T18:32:32.871+0000] {dagbag.py:387} ERROR - Failed to import: /opt/airflow/dags/ML/ML1.py
Traceback (most recent call last):
  File "/home/airflow/.local/lib/python3.12/site-packages/airflow/models/dagbag.py", line 383, in parse
    loader.exec_module(new_module)
  File "<frozen importlib._bootstrap_external>", line 999, in exec_module
  File "<frozen importlib._bootstrap>", line 488, in _call_with_frames_removed
  File "/opt/airflow/dags/ML/ML1.py", line 17, in <module>
    with DAG(
         ^^^^
  File "/home/airflow/.local/lib/python3.12/site-packages/airflow/models/dag.py", line 593, in __init__
    validate_key(dag_id)
  File "/home/airflow/.local/lib/python3.12/site-packages/airflow/utils/helpers.py", line 57, in validate_key
    raise AirflowException(
airflow.exceptions.AirflowException: The key 'ML 1' has to be made of alphanumeric characters, dashes, dots and underscores exclusively
[2025-04-24T18:32:32.878+0000] {processor.py:927} WARNING - No viable dags retrieved from /opt/airflow/dags/ML/ML1.py
[2025-04-24T18:32:32.937+0000] {processor.py:208} INFO - Processing /opt/airflow/dags/ML/ML1.py took 0.349 seconds
[2025-04-24T18:33:03.522+0000] {processor.py:186} INFO - Started process (PID=1105) to work on /opt/airflow/dags/ML/ML1.py
[2025-04-24T18:33:03.523+0000] {processor.py:914} INFO - Processing file /opt/airflow/dags/ML/ML1.py for tasks to queue
[2025-04-24T18:33:03.527+0000] {logging_mixin.py:190} INFO - [2025-04-24T18:33:03.526+0000] {dagbag.py:588} INFO - Filling up the DagBag from /opt/airflow/dags/ML/ML1.py
[2025-04-24T18:33:03.837+0000] {logging_mixin.py:190} INFO - [2025-04-24T18:33:03.829+0000] {dagbag.py:387} ERROR - Failed to import: /opt/airflow/dags/ML/ML1.py
Traceback (most recent call last):
  File "/home/airflow/.local/lib/python3.12/site-packages/airflow/models/dagbag.py", line 383, in parse
    loader.exec_module(new_module)
  File "<frozen importlib._bootstrap_external>", line 999, in exec_module
  File "<frozen importlib._bootstrap>", line 488, in _call_with_frames_removed
  File "/opt/airflow/dags/ML/ML1.py", line 17, in <module>
    with DAG(
         ^^^^
  File "/home/airflow/.local/lib/python3.12/site-packages/airflow/models/dag.py", line 593, in __init__
    validate_key(dag_id)
  File "/home/airflow/.local/lib/python3.12/site-packages/airflow/utils/helpers.py", line 57, in validate_key
    raise AirflowException(
airflow.exceptions.AirflowException: The key 'ML 1' has to be made of alphanumeric characters, dashes, dots and underscores exclusively
[2025-04-24T18:33:03.837+0000] {processor.py:927} WARNING - No viable dags retrieved from /opt/airflow/dags/ML/ML1.py
[2025-04-24T18:33:03.928+0000] {processor.py:208} INFO - Processing /opt/airflow/dags/ML/ML1.py took 0.412 seconds
[2025-04-24T18:33:34.150+0000] {processor.py:186} INFO - Started process (PID=1134) to work on /opt/airflow/dags/ML/ML1.py
[2025-04-24T18:33:34.151+0000] {processor.py:914} INFO - Processing file /opt/airflow/dags/ML/ML1.py for tasks to queue
[2025-04-24T18:33:34.155+0000] {logging_mixin.py:190} INFO - [2025-04-24T18:33:34.154+0000] {dagbag.py:588} INFO - Filling up the DagBag from /opt/airflow/dags/ML/ML1.py
[2025-04-24T18:33:34.417+0000] {logging_mixin.py:190} INFO - [2025-04-24T18:33:34.403+0000] {dagbag.py:387} ERROR - Failed to import: /opt/airflow/dags/ML/ML1.py
Traceback (most recent call last):
  File "/home/airflow/.local/lib/python3.12/site-packages/airflow/models/dagbag.py", line 383, in parse
    loader.exec_module(new_module)
  File "<frozen importlib._bootstrap_external>", line 999, in exec_module
  File "<frozen importlib._bootstrap>", line 488, in _call_with_frames_removed
  File "/opt/airflow/dags/ML/ML1.py", line 17, in <module>
    with DAG(
         ^^^^
  File "/home/airflow/.local/lib/python3.12/site-packages/airflow/models/dag.py", line 593, in __init__
    validate_key(dag_id)
  File "/home/airflow/.local/lib/python3.12/site-packages/airflow/utils/helpers.py", line 57, in validate_key
    raise AirflowException(
airflow.exceptions.AirflowException: The key 'ML 1' has to be made of alphanumeric characters, dashes, dots and underscores exclusively
[2025-04-24T18:33:34.418+0000] {processor.py:927} WARNING - No viable dags retrieved from /opt/airflow/dags/ML/ML1.py
[2025-04-24T18:33:34.498+0000] {processor.py:208} INFO - Processing /opt/airflow/dags/ML/ML1.py took 0.353 seconds
[2025-04-24T18:34:04.666+0000] {processor.py:186} INFO - Started process (PID=1162) to work on /opt/airflow/dags/ML/ML1.py
[2025-04-24T18:34:04.668+0000] {processor.py:914} INFO - Processing file /opt/airflow/dags/ML/ML1.py for tasks to queue
[2025-04-24T18:34:04.673+0000] {logging_mixin.py:190} INFO - [2025-04-24T18:34:04.672+0000] {dagbag.py:588} INFO - Filling up the DagBag from /opt/airflow/dags/ML/ML1.py
[2025-04-24T18:34:05.076+0000] {logging_mixin.py:190} INFO - [2025-04-24T18:34:05.067+0000] {dagbag.py:387} ERROR - Failed to import: /opt/airflow/dags/ML/ML1.py
Traceback (most recent call last):
  File "/home/airflow/.local/lib/python3.12/site-packages/airflow/models/dagbag.py", line 383, in parse
    loader.exec_module(new_module)
  File "<frozen importlib._bootstrap_external>", line 999, in exec_module
  File "<frozen importlib._bootstrap>", line 488, in _call_with_frames_removed
  File "/opt/airflow/dags/ML/ML1.py", line 17, in <module>
    with DAG(
         ^^^^
  File "/home/airflow/.local/lib/python3.12/site-packages/airflow/models/dag.py", line 593, in __init__
    validate_key(dag_id)
  File "/home/airflow/.local/lib/python3.12/site-packages/airflow/utils/helpers.py", line 57, in validate_key
    raise AirflowException(
airflow.exceptions.AirflowException: The key 'ML 1' has to be made of alphanumeric characters, dashes, dots and underscores exclusively
[2025-04-24T18:34:05.077+0000] {processor.py:927} WARNING - No viable dags retrieved from /opt/airflow/dags/ML/ML1.py
[2025-04-24T18:34:05.176+0000] {processor.py:208} INFO - Processing /opt/airflow/dags/ML/ML1.py took 0.517 seconds
[2025-04-24T18:34:36.105+0000] {processor.py:186} INFO - Started process (PID=1191) to work on /opt/airflow/dags/ML/ML1.py
[2025-04-24T18:34:36.107+0000] {processor.py:914} INFO - Processing file /opt/airflow/dags/ML/ML1.py for tasks to queue
[2025-04-24T18:34:36.110+0000] {logging_mixin.py:190} INFO - [2025-04-24T18:34:36.109+0000] {dagbag.py:588} INFO - Filling up the DagBag from /opt/airflow/dags/ML/ML1.py
[2025-04-24T18:34:36.386+0000] {logging_mixin.py:190} INFO - [2025-04-24T18:34:36.376+0000] {dagbag.py:387} ERROR - Failed to import: /opt/airflow/dags/ML/ML1.py
Traceback (most recent call last):
  File "/home/airflow/.local/lib/python3.12/site-packages/airflow/models/dagbag.py", line 383, in parse
    loader.exec_module(new_module)
  File "<frozen importlib._bootstrap_external>", line 999, in exec_module
  File "<frozen importlib._bootstrap>", line 488, in _call_with_frames_removed
  File "/opt/airflow/dags/ML/ML1.py", line 17, in <module>
    with DAG(
         ^^^^
  File "/home/airflow/.local/lib/python3.12/site-packages/airflow/models/dag.py", line 593, in __init__
    validate_key(dag_id)
  File "/home/airflow/.local/lib/python3.12/site-packages/airflow/utils/helpers.py", line 57, in validate_key
    raise AirflowException(
airflow.exceptions.AirflowException: The key 'ML 1' has to be made of alphanumeric characters, dashes, dots and underscores exclusively
[2025-04-24T18:34:36.387+0000] {processor.py:927} WARNING - No viable dags retrieved from /opt/airflow/dags/ML/ML1.py
[2025-04-24T18:34:36.461+0000] {processor.py:208} INFO - Processing /opt/airflow/dags/ML/ML1.py took 0.361 seconds
[2025-04-24T18:35:06.719+0000] {processor.py:186} INFO - Started process (PID=1221) to work on /opt/airflow/dags/ML/ML1.py
[2025-04-24T18:35:06.720+0000] {processor.py:914} INFO - Processing file /opt/airflow/dags/ML/ML1.py for tasks to queue
[2025-04-24T18:35:06.722+0000] {logging_mixin.py:190} INFO - [2025-04-24T18:35:06.722+0000] {dagbag.py:588} INFO - Filling up the DagBag from /opt/airflow/dags/ML/ML1.py
[2025-04-24T18:35:06.979+0000] {logging_mixin.py:190} INFO - [2025-04-24T18:35:06.970+0000] {dagbag.py:387} ERROR - Failed to import: /opt/airflow/dags/ML/ML1.py
Traceback (most recent call last):
  File "/home/airflow/.local/lib/python3.12/site-packages/airflow/models/dagbag.py", line 383, in parse
    loader.exec_module(new_module)
  File "<frozen importlib._bootstrap_external>", line 999, in exec_module
  File "<frozen importlib._bootstrap>", line 488, in _call_with_frames_removed
  File "/opt/airflow/dags/ML/ML1.py", line 17, in <module>
    with DAG(
         ^^^^
  File "/home/airflow/.local/lib/python3.12/site-packages/airflow/models/dag.py", line 593, in __init__
    validate_key(dag_id)
  File "/home/airflow/.local/lib/python3.12/site-packages/airflow/utils/helpers.py", line 57, in validate_key
    raise AirflowException(
airflow.exceptions.AirflowException: The key 'ML 1' has to be made of alphanumeric characters, dashes, dots and underscores exclusively
[2025-04-24T18:35:06.979+0000] {processor.py:927} WARNING - No viable dags retrieved from /opt/airflow/dags/ML/ML1.py
[2025-04-24T18:35:07.045+0000] {processor.py:208} INFO - Processing /opt/airflow/dags/ML/ML1.py took 0.331 seconds
[2025-04-24T18:35:37.349+0000] {processor.py:186} INFO - Started process (PID=1250) to work on /opt/airflow/dags/ML/ML1.py
[2025-04-24T18:35:37.351+0000] {processor.py:914} INFO - Processing file /opt/airflow/dags/ML/ML1.py for tasks to queue
[2025-04-24T18:35:37.353+0000] {logging_mixin.py:190} INFO - [2025-04-24T18:35:37.353+0000] {dagbag.py:588} INFO - Filling up the DagBag from /opt/airflow/dags/ML/ML1.py
[2025-04-24T18:35:37.610+0000] {logging_mixin.py:190} INFO - [2025-04-24T18:35:37.602+0000] {dagbag.py:387} ERROR - Failed to import: /opt/airflow/dags/ML/ML1.py
Traceback (most recent call last):
  File "/home/airflow/.local/lib/python3.12/site-packages/airflow/models/dagbag.py", line 383, in parse
    loader.exec_module(new_module)
  File "<frozen importlib._bootstrap_external>", line 999, in exec_module
  File "<frozen importlib._bootstrap>", line 488, in _call_with_frames_removed
  File "/opt/airflow/dags/ML/ML1.py", line 17, in <module>
    with DAG(
         ^^^^
  File "/home/airflow/.local/lib/python3.12/site-packages/airflow/models/dag.py", line 593, in __init__
    validate_key(dag_id)
  File "/home/airflow/.local/lib/python3.12/site-packages/airflow/utils/helpers.py", line 57, in validate_key
    raise AirflowException(
airflow.exceptions.AirflowException: The key 'ML 1' has to be made of alphanumeric characters, dashes, dots and underscores exclusively
[2025-04-24T18:35:37.610+0000] {processor.py:927} WARNING - No viable dags retrieved from /opt/airflow/dags/ML/ML1.py
[2025-04-24T18:35:37.701+0000] {processor.py:208} INFO - Processing /opt/airflow/dags/ML/ML1.py took 0.357 seconds
[2025-04-24T18:36:07.794+0000] {processor.py:186} INFO - Started process (PID=1279) to work on /opt/airflow/dags/ML/ML1.py
[2025-04-24T18:36:07.795+0000] {processor.py:914} INFO - Processing file /opt/airflow/dags/ML/ML1.py for tasks to queue
[2025-04-24T18:36:07.797+0000] {logging_mixin.py:190} INFO - [2025-04-24T18:36:07.797+0000] {dagbag.py:588} INFO - Filling up the DagBag from /opt/airflow/dags/ML/ML1.py
[2025-04-24T18:36:08.059+0000] {logging_mixin.py:190} INFO - [2025-04-24T18:36:08.051+0000] {dagbag.py:387} ERROR - Failed to import: /opt/airflow/dags/ML/ML1.py
Traceback (most recent call last):
  File "/home/airflow/.local/lib/python3.12/site-packages/airflow/models/dagbag.py", line 383, in parse
    loader.exec_module(new_module)
  File "<frozen importlib._bootstrap_external>", line 999, in exec_module
  File "<frozen importlib._bootstrap>", line 488, in _call_with_frames_removed
  File "/opt/airflow/dags/ML/ML1.py", line 17, in <module>
    with DAG(
         ^^^^
  File "/home/airflow/.local/lib/python3.12/site-packages/airflow/models/dag.py", line 593, in __init__
    validate_key(dag_id)
  File "/home/airflow/.local/lib/python3.12/site-packages/airflow/utils/helpers.py", line 57, in validate_key
    raise AirflowException(
airflow.exceptions.AirflowException: The key 'ML 1' has to be made of alphanumeric characters, dashes, dots and underscores exclusively
[2025-04-24T18:36:08.060+0000] {processor.py:927} WARNING - No viable dags retrieved from /opt/airflow/dags/ML/ML1.py
[2025-04-24T18:36:08.137+0000] {processor.py:208} INFO - Processing /opt/airflow/dags/ML/ML1.py took 0.349 seconds
[2025-04-24T18:36:38.447+0000] {processor.py:186} INFO - Started process (PID=1308) to work on /opt/airflow/dags/ML/ML1.py
[2025-04-24T18:36:38.449+0000] {processor.py:914} INFO - Processing file /opt/airflow/dags/ML/ML1.py for tasks to queue
[2025-04-24T18:36:38.451+0000] {logging_mixin.py:190} INFO - [2025-04-24T18:36:38.451+0000] {dagbag.py:588} INFO - Filling up the DagBag from /opt/airflow/dags/ML/ML1.py
[2025-04-24T18:36:38.722+0000] {logging_mixin.py:190} INFO - [2025-04-24T18:36:38.715+0000] {dagbag.py:387} ERROR - Failed to import: /opt/airflow/dags/ML/ML1.py
Traceback (most recent call last):
  File "/home/airflow/.local/lib/python3.12/site-packages/airflow/models/dagbag.py", line 383, in parse
    loader.exec_module(new_module)
  File "<frozen importlib._bootstrap_external>", line 999, in exec_module
  File "<frozen importlib._bootstrap>", line 488, in _call_with_frames_removed
  File "/opt/airflow/dags/ML/ML1.py", line 17, in <module>
    with DAG(
         ^^^^
  File "/home/airflow/.local/lib/python3.12/site-packages/airflow/models/dag.py", line 593, in __init__
    validate_key(dag_id)
  File "/home/airflow/.local/lib/python3.12/site-packages/airflow/utils/helpers.py", line 57, in validate_key
    raise AirflowException(
airflow.exceptions.AirflowException: The key 'ML 1' has to be made of alphanumeric characters, dashes, dots and underscores exclusively
[2025-04-24T18:36:38.723+0000] {processor.py:927} WARNING - No viable dags retrieved from /opt/airflow/dags/ML/ML1.py
[2025-04-24T18:36:38.775+0000] {processor.py:208} INFO - Processing /opt/airflow/dags/ML/ML1.py took 0.333 seconds
[2025-04-24T18:37:09.052+0000] {processor.py:186} INFO - Started process (PID=1337) to work on /opt/airflow/dags/ML/ML1.py
[2025-04-24T18:37:09.053+0000] {processor.py:914} INFO - Processing file /opt/airflow/dags/ML/ML1.py for tasks to queue
[2025-04-24T18:37:09.055+0000] {logging_mixin.py:190} INFO - [2025-04-24T18:37:09.055+0000] {dagbag.py:588} INFO - Filling up the DagBag from /opt/airflow/dags/ML/ML1.py
[2025-04-24T18:37:09.322+0000] {logging_mixin.py:190} INFO - [2025-04-24T18:37:09.313+0000] {dagbag.py:387} ERROR - Failed to import: /opt/airflow/dags/ML/ML1.py
Traceback (most recent call last):
  File "/home/airflow/.local/lib/python3.12/site-packages/airflow/models/dagbag.py", line 383, in parse
    loader.exec_module(new_module)
  File "<frozen importlib._bootstrap_external>", line 999, in exec_module
  File "<frozen importlib._bootstrap>", line 488, in _call_with_frames_removed
  File "/opt/airflow/dags/ML/ML1.py", line 17, in <module>
    with DAG(
         ^^^^
  File "/home/airflow/.local/lib/python3.12/site-packages/airflow/models/dag.py", line 593, in __init__
    validate_key(dag_id)
  File "/home/airflow/.local/lib/python3.12/site-packages/airflow/utils/helpers.py", line 57, in validate_key
    raise AirflowException(
airflow.exceptions.AirflowException: The key 'ML 1' has to be made of alphanumeric characters, dashes, dots and underscores exclusively
[2025-04-24T18:37:09.323+0000] {processor.py:927} WARNING - No viable dags retrieved from /opt/airflow/dags/ML/ML1.py
[2025-04-24T18:37:09.387+0000] {processor.py:208} INFO - Processing /opt/airflow/dags/ML/ML1.py took 0.340 seconds
[2025-04-24T18:37:39.713+0000] {processor.py:186} INFO - Started process (PID=1366) to work on /opt/airflow/dags/ML/ML1.py
[2025-04-24T18:37:39.714+0000] {processor.py:914} INFO - Processing file /opt/airflow/dags/ML/ML1.py for tasks to queue
[2025-04-24T18:37:39.716+0000] {logging_mixin.py:190} INFO - [2025-04-24T18:37:39.716+0000] {dagbag.py:588} INFO - Filling up the DagBag from /opt/airflow/dags/ML/ML1.py
[2025-04-24T18:37:39.971+0000] {logging_mixin.py:190} INFO - [2025-04-24T18:37:39.964+0000] {dagbag.py:387} ERROR - Failed to import: /opt/airflow/dags/ML/ML1.py
Traceback (most recent call last):
  File "/home/airflow/.local/lib/python3.12/site-packages/airflow/models/dagbag.py", line 383, in parse
    loader.exec_module(new_module)
  File "<frozen importlib._bootstrap_external>", line 999, in exec_module
  File "<frozen importlib._bootstrap>", line 488, in _call_with_frames_removed
  File "/opt/airflow/dags/ML/ML1.py", line 17, in <module>
    with DAG(
         ^^^^
  File "/home/airflow/.local/lib/python3.12/site-packages/airflow/models/dag.py", line 593, in __init__
    validate_key(dag_id)
  File "/home/airflow/.local/lib/python3.12/site-packages/airflow/utils/helpers.py", line 57, in validate_key
    raise AirflowException(
airflow.exceptions.AirflowException: The key 'ML 1' has to be made of alphanumeric characters, dashes, dots and underscores exclusively
[2025-04-24T18:37:39.972+0000] {processor.py:927} WARNING - No viable dags retrieved from /opt/airflow/dags/ML/ML1.py
[2025-04-24T18:37:40.039+0000] {processor.py:208} INFO - Processing /opt/airflow/dags/ML/ML1.py took 0.331 seconds
[2025-04-24T18:38:10.351+0000] {processor.py:186} INFO - Started process (PID=1395) to work on /opt/airflow/dags/ML/ML1.py
[2025-04-24T18:38:10.352+0000] {processor.py:914} INFO - Processing file /opt/airflow/dags/ML/ML1.py for tasks to queue
[2025-04-24T18:38:10.357+0000] {logging_mixin.py:190} INFO - [2025-04-24T18:38:10.356+0000] {dagbag.py:588} INFO - Filling up the DagBag from /opt/airflow/dags/ML/ML1.py
[2025-04-24T18:38:10.974+0000] {logging_mixin.py:190} INFO - [2025-04-24T18:38:10.957+0000] {dagbag.py:387} ERROR - Failed to import: /opt/airflow/dags/ML/ML1.py
Traceback (most recent call last):
  File "/home/airflow/.local/lib/python3.12/site-packages/airflow/models/dagbag.py", line 383, in parse
    loader.exec_module(new_module)
  File "<frozen importlib._bootstrap_external>", line 999, in exec_module
  File "<frozen importlib._bootstrap>", line 488, in _call_with_frames_removed
  File "/opt/airflow/dags/ML/ML1.py", line 17, in <module>
    with DAG(
         ^^^^
  File "/home/airflow/.local/lib/python3.12/site-packages/airflow/models/dag.py", line 593, in __init__
    validate_key(dag_id)
  File "/home/airflow/.local/lib/python3.12/site-packages/airflow/utils/helpers.py", line 57, in validate_key
    raise AirflowException(
airflow.exceptions.AirflowException: The key 'ML 1' has to be made of alphanumeric characters, dashes, dots and underscores exclusively
[2025-04-24T18:38:10.976+0000] {processor.py:927} WARNING - No viable dags retrieved from /opt/airflow/dags/ML/ML1.py
[2025-04-24T18:38:11.101+0000] {processor.py:208} INFO - Processing /opt/airflow/dags/ML/ML1.py took 0.763 seconds
[2025-04-24T18:38:41.264+0000] {processor.py:186} INFO - Started process (PID=1424) to work on /opt/airflow/dags/ML/ML1.py
[2025-04-24T18:38:41.265+0000] {processor.py:914} INFO - Processing file /opt/airflow/dags/ML/ML1.py for tasks to queue
[2025-04-24T18:38:41.268+0000] {logging_mixin.py:190} INFO - [2025-04-24T18:38:41.267+0000] {dagbag.py:588} INFO - Filling up the DagBag from /opt/airflow/dags/ML/ML1.py
[2025-04-24T18:38:41.614+0000] {logging_mixin.py:190} INFO - [2025-04-24T18:38:41.593+0000] {dagbag.py:387} ERROR - Failed to import: /opt/airflow/dags/ML/ML1.py
Traceback (most recent call last):
  File "/home/airflow/.local/lib/python3.12/site-packages/airflow/models/dagbag.py", line 383, in parse
    loader.exec_module(new_module)
  File "<frozen importlib._bootstrap_external>", line 999, in exec_module
  File "<frozen importlib._bootstrap>", line 488, in _call_with_frames_removed
  File "/opt/airflow/dags/ML/ML1.py", line 17, in <module>
    with DAG(
         ^^^^
  File "/home/airflow/.local/lib/python3.12/site-packages/airflow/models/dag.py", line 593, in __init__
    validate_key(dag_id)
  File "/home/airflow/.local/lib/python3.12/site-packages/airflow/utils/helpers.py", line 57, in validate_key
    raise AirflowException(
airflow.exceptions.AirflowException: The key 'ML 1' has to be made of alphanumeric characters, dashes, dots and underscores exclusively
[2025-04-24T18:38:41.616+0000] {processor.py:927} WARNING - No viable dags retrieved from /opt/airflow/dags/ML/ML1.py
[2025-04-24T18:38:41.710+0000] {processor.py:208} INFO - Processing /opt/airflow/dags/ML/ML1.py took 0.453 seconds
[2025-04-24T18:39:11.986+0000] {processor.py:186} INFO - Started process (PID=1453) to work on /opt/airflow/dags/ML/ML1.py
[2025-04-24T18:39:11.988+0000] {processor.py:914} INFO - Processing file /opt/airflow/dags/ML/ML1.py for tasks to queue
[2025-04-24T18:39:11.991+0000] {logging_mixin.py:190} INFO - [2025-04-24T18:39:11.990+0000] {dagbag.py:588} INFO - Filling up the DagBag from /opt/airflow/dags/ML/ML1.py
[2025-04-24T18:39:12.519+0000] {logging_mixin.py:190} INFO - [2025-04-24T18:39:12.507+0000] {dagbag.py:387} ERROR - Failed to import: /opt/airflow/dags/ML/ML1.py
Traceback (most recent call last):
  File "/home/airflow/.local/lib/python3.12/site-packages/airflow/models/dagbag.py", line 383, in parse
    loader.exec_module(new_module)
  File "<frozen importlib._bootstrap_external>", line 999, in exec_module
  File "<frozen importlib._bootstrap>", line 488, in _call_with_frames_removed
  File "/opt/airflow/dags/ML/ML1.py", line 17, in <module>
    with DAG(
         ^^^^
  File "/home/airflow/.local/lib/python3.12/site-packages/airflow/models/dag.py", line 593, in __init__
    validate_key(dag_id)
  File "/home/airflow/.local/lib/python3.12/site-packages/airflow/utils/helpers.py", line 57, in validate_key
    raise AirflowException(
airflow.exceptions.AirflowException: The key 'ML 1' has to be made of alphanumeric characters, dashes, dots and underscores exclusively
[2025-04-24T18:39:12.521+0000] {processor.py:927} WARNING - No viable dags retrieved from /opt/airflow/dags/ML/ML1.py
[2025-04-24T18:39:12.613+0000] {processor.py:208} INFO - Processing /opt/airflow/dags/ML/ML1.py took 0.638 seconds
[2025-04-24T18:39:42.782+0000] {processor.py:186} INFO - Started process (PID=1482) to work on /opt/airflow/dags/ML/ML1.py
[2025-04-24T18:39:42.784+0000] {processor.py:914} INFO - Processing file /opt/airflow/dags/ML/ML1.py for tasks to queue
[2025-04-24T18:39:42.786+0000] {logging_mixin.py:190} INFO - [2025-04-24T18:39:42.786+0000] {dagbag.py:588} INFO - Filling up the DagBag from /opt/airflow/dags/ML/ML1.py
[2025-04-24T18:39:43.061+0000] {logging_mixin.py:190} INFO - [2025-04-24T18:39:43.053+0000] {dagbag.py:387} ERROR - Failed to import: /opt/airflow/dags/ML/ML1.py
Traceback (most recent call last):
  File "/home/airflow/.local/lib/python3.12/site-packages/airflow/models/dagbag.py", line 383, in parse
    loader.exec_module(new_module)
  File "<frozen importlib._bootstrap_external>", line 999, in exec_module
  File "<frozen importlib._bootstrap>", line 488, in _call_with_frames_removed
  File "/opt/airflow/dags/ML/ML1.py", line 17, in <module>
    with DAG(
         ^^^^
  File "/home/airflow/.local/lib/python3.12/site-packages/airflow/models/dag.py", line 593, in __init__
    validate_key(dag_id)
  File "/home/airflow/.local/lib/python3.12/site-packages/airflow/utils/helpers.py", line 57, in validate_key
    raise AirflowException(
airflow.exceptions.AirflowException: The key 'ML 1' has to be made of alphanumeric characters, dashes, dots and underscores exclusively
[2025-04-24T18:39:43.062+0000] {processor.py:927} WARNING - No viable dags retrieved from /opt/airflow/dags/ML/ML1.py
[2025-04-24T18:39:43.147+0000] {processor.py:208} INFO - Processing /opt/airflow/dags/ML/ML1.py took 0.369 seconds
[2025-04-24T18:40:13.517+0000] {processor.py:186} INFO - Started process (PID=1511) to work on /opt/airflow/dags/ML/ML1.py
[2025-04-24T18:40:13.518+0000] {processor.py:914} INFO - Processing file /opt/airflow/dags/ML/ML1.py for tasks to queue
[2025-04-24T18:40:13.520+0000] {logging_mixin.py:190} INFO - [2025-04-24T18:40:13.519+0000] {dagbag.py:588} INFO - Filling up the DagBag from /opt/airflow/dags/ML/ML1.py
[2025-04-24T18:40:13.793+0000] {logging_mixin.py:190} INFO - [2025-04-24T18:40:13.786+0000] {dagbag.py:387} ERROR - Failed to import: /opt/airflow/dags/ML/ML1.py
Traceback (most recent call last):
  File "/home/airflow/.local/lib/python3.12/site-packages/airflow/models/dagbag.py", line 383, in parse
    loader.exec_module(new_module)
  File "<frozen importlib._bootstrap_external>", line 999, in exec_module
  File "<frozen importlib._bootstrap>", line 488, in _call_with_frames_removed
  File "/opt/airflow/dags/ML/ML1.py", line 17, in <module>
    with DAG(
         ^^^^
  File "/home/airflow/.local/lib/python3.12/site-packages/airflow/models/dag.py", line 593, in __init__
    validate_key(dag_id)
  File "/home/airflow/.local/lib/python3.12/site-packages/airflow/utils/helpers.py", line 57, in validate_key
    raise AirflowException(
airflow.exceptions.AirflowException: The key 'ML 1' has to be made of alphanumeric characters, dashes, dots and underscores exclusively
[2025-04-24T18:40:13.794+0000] {processor.py:927} WARNING - No viable dags retrieved from /opt/airflow/dags/ML/ML1.py
[2025-04-24T18:40:13.851+0000] {processor.py:208} INFO - Processing /opt/airflow/dags/ML/ML1.py took 0.340 seconds
[2025-04-24T18:40:44.613+0000] {processor.py:186} INFO - Started process (PID=1540) to work on /opt/airflow/dags/ML/ML1.py
[2025-04-24T18:40:44.614+0000] {processor.py:914} INFO - Processing file /opt/airflow/dags/ML/ML1.py for tasks to queue
[2025-04-24T18:40:44.617+0000] {logging_mixin.py:190} INFO - [2025-04-24T18:40:44.617+0000] {dagbag.py:588} INFO - Filling up the DagBag from /opt/airflow/dags/ML/ML1.py
[2025-04-24T18:40:44.947+0000] {logging_mixin.py:190} INFO - [2025-04-24T18:40:44.937+0000] {dagbag.py:387} ERROR - Failed to import: /opt/airflow/dags/ML/ML1.py
Traceback (most recent call last):
  File "/home/airflow/.local/lib/python3.12/site-packages/airflow/models/dagbag.py", line 383, in parse
    loader.exec_module(new_module)
  File "<frozen importlib._bootstrap_external>", line 999, in exec_module
  File "<frozen importlib._bootstrap>", line 488, in _call_with_frames_removed
  File "/opt/airflow/dags/ML/ML1.py", line 17, in <module>
    with DAG(
         ^^^^
  File "/home/airflow/.local/lib/python3.12/site-packages/airflow/models/dag.py", line 593, in __init__
    validate_key(dag_id)
  File "/home/airflow/.local/lib/python3.12/site-packages/airflow/utils/helpers.py", line 57, in validate_key
    raise AirflowException(
airflow.exceptions.AirflowException: The key 'ML 1' has to be made of alphanumeric characters, dashes, dots and underscores exclusively
[2025-04-24T18:40:44.948+0000] {processor.py:927} WARNING - No viable dags retrieved from /opt/airflow/dags/ML/ML1.py
[2025-04-24T18:40:45.044+0000] {processor.py:208} INFO - Processing /opt/airflow/dags/ML/ML1.py took 0.439 seconds
[2025-04-24T18:41:15.750+0000] {processor.py:186} INFO - Started process (PID=1569) to work on /opt/airflow/dags/ML/ML1.py
[2025-04-24T18:41:15.752+0000] {processor.py:914} INFO - Processing file /opt/airflow/dags/ML/ML1.py for tasks to queue
[2025-04-24T18:41:15.754+0000] {logging_mixin.py:190} INFO - [2025-04-24T18:41:15.754+0000] {dagbag.py:588} INFO - Filling up the DagBag from /opt/airflow/dags/ML/ML1.py
[2025-04-24T18:41:16.030+0000] {logging_mixin.py:190} INFO - [2025-04-24T18:41:16.005+0000] {dagbag.py:387} ERROR - Failed to import: /opt/airflow/dags/ML/ML1.py
Traceback (most recent call last):
  File "/home/airflow/.local/lib/python3.12/site-packages/airflow/models/dagbag.py", line 383, in parse
    loader.exec_module(new_module)
  File "<frozen importlib._bootstrap_external>", line 999, in exec_module
  File "<frozen importlib._bootstrap>", line 488, in _call_with_frames_removed
  File "/opt/airflow/dags/ML/ML1.py", line 17, in <module>
    with DAG(
         ^^^^
  File "/home/airflow/.local/lib/python3.12/site-packages/airflow/models/dag.py", line 593, in __init__
    validate_key(dag_id)
  File "/home/airflow/.local/lib/python3.12/site-packages/airflow/utils/helpers.py", line 57, in validate_key
    raise AirflowException(
airflow.exceptions.AirflowException: The key 'ML 1' has to be made of alphanumeric characters, dashes, dots and underscores exclusively
[2025-04-24T18:41:16.033+0000] {processor.py:927} WARNING - No viable dags retrieved from /opt/airflow/dags/ML/ML1.py
[2025-04-24T18:41:16.227+0000] {processor.py:208} INFO - Processing /opt/airflow/dags/ML/ML1.py took 0.483 seconds
[2025-04-24T18:41:46.475+0000] {processor.py:186} INFO - Started process (PID=1599) to work on /opt/airflow/dags/ML/ML1.py
[2025-04-24T18:41:46.479+0000] {processor.py:914} INFO - Processing file /opt/airflow/dags/ML/ML1.py for tasks to queue
[2025-04-24T18:41:46.481+0000] {logging_mixin.py:190} INFO - [2025-04-24T18:41:46.481+0000] {dagbag.py:588} INFO - Filling up the DagBag from /opt/airflow/dags/ML/ML1.py
[2025-04-24T18:41:46.802+0000] {logging_mixin.py:190} INFO - [2025-04-24T18:41:46.783+0000] {dagbag.py:387} ERROR - Failed to import: /opt/airflow/dags/ML/ML1.py
Traceback (most recent call last):
  File "/home/airflow/.local/lib/python3.12/site-packages/airflow/models/dagbag.py", line 383, in parse
    loader.exec_module(new_module)
  File "<frozen importlib._bootstrap_external>", line 999, in exec_module
  File "<frozen importlib._bootstrap>", line 488, in _call_with_frames_removed
  File "/opt/airflow/dags/ML/ML1.py", line 17, in <module>
    with DAG(
         ^^^^
  File "/home/airflow/.local/lib/python3.12/site-packages/airflow/models/dag.py", line 593, in __init__
    validate_key(dag_id)
  File "/home/airflow/.local/lib/python3.12/site-packages/airflow/utils/helpers.py", line 57, in validate_key
    raise AirflowException(
airflow.exceptions.AirflowException: The key 'ML 1' has to be made of alphanumeric characters, dashes, dots and underscores exclusively
[2025-04-24T18:41:46.803+0000] {processor.py:927} WARNING - No viable dags retrieved from /opt/airflow/dags/ML/ML1.py
[2025-04-24T18:41:46.871+0000] {processor.py:208} INFO - Processing /opt/airflow/dags/ML/ML1.py took 0.400 seconds
[2025-04-24T18:42:17.343+0000] {processor.py:186} INFO - Started process (PID=1628) to work on /opt/airflow/dags/ML/ML1.py
[2025-04-24T18:42:17.345+0000] {processor.py:914} INFO - Processing file /opt/airflow/dags/ML/ML1.py for tasks to queue
[2025-04-24T18:42:17.348+0000] {logging_mixin.py:190} INFO - [2025-04-24T18:42:17.348+0000] {dagbag.py:588} INFO - Filling up the DagBag from /opt/airflow/dags/ML/ML1.py
[2025-04-24T18:42:17.639+0000] {logging_mixin.py:190} INFO - [2025-04-24T18:42:17.630+0000] {dagbag.py:387} ERROR - Failed to import: /opt/airflow/dags/ML/ML1.py
Traceback (most recent call last):
  File "/home/airflow/.local/lib/python3.12/site-packages/airflow/models/dagbag.py", line 383, in parse
    loader.exec_module(new_module)
  File "<frozen importlib._bootstrap_external>", line 999, in exec_module
  File "<frozen importlib._bootstrap>", line 488, in _call_with_frames_removed
  File "/opt/airflow/dags/ML/ML1.py", line 17, in <module>
    with DAG(
         ^^^^
  File "/home/airflow/.local/lib/python3.12/site-packages/airflow/models/dag.py", line 593, in __init__
    validate_key(dag_id)
  File "/home/airflow/.local/lib/python3.12/site-packages/airflow/utils/helpers.py", line 57, in validate_key
    raise AirflowException(
airflow.exceptions.AirflowException: The key 'ML 1' has to be made of alphanumeric characters, dashes, dots and underscores exclusively
[2025-04-24T18:42:17.640+0000] {processor.py:927} WARNING - No viable dags retrieved from /opt/airflow/dags/ML/ML1.py
[2025-04-24T18:42:17.715+0000] {processor.py:208} INFO - Processing /opt/airflow/dags/ML/ML1.py took 0.378 seconds
[2025-04-24T18:42:48.135+0000] {processor.py:186} INFO - Started process (PID=1657) to work on /opt/airflow/dags/ML/ML1.py
[2025-04-24T18:42:48.136+0000] {processor.py:914} INFO - Processing file /opt/airflow/dags/ML/ML1.py for tasks to queue
[2025-04-24T18:42:48.139+0000] {logging_mixin.py:190} INFO - [2025-04-24T18:42:48.139+0000] {dagbag.py:588} INFO - Filling up the DagBag from /opt/airflow/dags/ML/ML1.py
[2025-04-24T18:42:48.394+0000] {logging_mixin.py:190} INFO - [2025-04-24T18:42:48.389+0000] {dagbag.py:387} ERROR - Failed to import: /opt/airflow/dags/ML/ML1.py
Traceback (most recent call last):
  File "/home/airflow/.local/lib/python3.12/site-packages/airflow/models/dagbag.py", line 383, in parse
    loader.exec_module(new_module)
  File "<frozen importlib._bootstrap_external>", line 999, in exec_module
  File "<frozen importlib._bootstrap>", line 488, in _call_with_frames_removed
  File "/opt/airflow/dags/ML/ML1.py", line 17, in <module>
    with DAG(
         ^^^^
  File "/home/airflow/.local/lib/python3.12/site-packages/airflow/models/dag.py", line 593, in __init__
    validate_key(dag_id)
  File "/home/airflow/.local/lib/python3.12/site-packages/airflow/utils/helpers.py", line 57, in validate_key
    raise AirflowException(
airflow.exceptions.AirflowException: The key 'ML 1' has to be made of alphanumeric characters, dashes, dots and underscores exclusively
[2025-04-24T18:42:48.395+0000] {processor.py:927} WARNING - No viable dags retrieved from /opt/airflow/dags/ML/ML1.py
[2025-04-24T18:42:48.445+0000] {processor.py:208} INFO - Processing /opt/airflow/dags/ML/ML1.py took 0.315 seconds
[2025-04-24T18:43:18.692+0000] {processor.py:186} INFO - Started process (PID=1686) to work on /opt/airflow/dags/ML/ML1.py
[2025-04-24T18:43:18.693+0000] {processor.py:914} INFO - Processing file /opt/airflow/dags/ML/ML1.py for tasks to queue
[2025-04-24T18:43:18.695+0000] {logging_mixin.py:190} INFO - [2025-04-24T18:43:18.695+0000] {dagbag.py:588} INFO - Filling up the DagBag from /opt/airflow/dags/ML/ML1.py
[2025-04-24T18:43:18.949+0000] {logging_mixin.py:190} INFO - [2025-04-24T18:43:18.942+0000] {dagbag.py:387} ERROR - Failed to import: /opt/airflow/dags/ML/ML1.py
Traceback (most recent call last):
  File "/home/airflow/.local/lib/python3.12/site-packages/airflow/models/dagbag.py", line 383, in parse
    loader.exec_module(new_module)
  File "<frozen importlib._bootstrap_external>", line 999, in exec_module
  File "<frozen importlib._bootstrap>", line 488, in _call_with_frames_removed
  File "/opt/airflow/dags/ML/ML1.py", line 17, in <module>
    with DAG(
         ^^^^
  File "/home/airflow/.local/lib/python3.12/site-packages/airflow/models/dag.py", line 593, in __init__
    validate_key(dag_id)
  File "/home/airflow/.local/lib/python3.12/site-packages/airflow/utils/helpers.py", line 57, in validate_key
    raise AirflowException(
airflow.exceptions.AirflowException: The key 'ML 1' has to be made of alphanumeric characters, dashes, dots and underscores exclusively
[2025-04-24T18:43:18.950+0000] {processor.py:927} WARNING - No viable dags retrieved from /opt/airflow/dags/ML/ML1.py
[2025-04-24T18:43:19.010+0000] {processor.py:208} INFO - Processing /opt/airflow/dags/ML/ML1.py took 0.325 seconds
[2025-04-24T18:43:49.502+0000] {processor.py:186} INFO - Started process (PID=1715) to work on /opt/airflow/dags/ML/ML1.py
[2025-04-24T18:43:49.503+0000] {processor.py:914} INFO - Processing file /opt/airflow/dags/ML/ML1.py for tasks to queue
[2025-04-24T18:43:49.505+0000] {logging_mixin.py:190} INFO - [2025-04-24T18:43:49.505+0000] {dagbag.py:588} INFO - Filling up the DagBag from /opt/airflow/dags/ML/ML1.py
[2025-04-24T18:43:49.756+0000] {logging_mixin.py:190} INFO - [2025-04-24T18:43:49.747+0000] {dagbag.py:387} ERROR - Failed to import: /opt/airflow/dags/ML/ML1.py
Traceback (most recent call last):
  File "/home/airflow/.local/lib/python3.12/site-packages/airflow/models/dagbag.py", line 383, in parse
    loader.exec_module(new_module)
  File "<frozen importlib._bootstrap_external>", line 999, in exec_module
  File "<frozen importlib._bootstrap>", line 488, in _call_with_frames_removed
  File "/opt/airflow/dags/ML/ML1.py", line 17, in <module>
    with DAG(
         ^^^^
  File "/home/airflow/.local/lib/python3.12/site-packages/airflow/models/dag.py", line 593, in __init__
    validate_key(dag_id)
  File "/home/airflow/.local/lib/python3.12/site-packages/airflow/utils/helpers.py", line 57, in validate_key
    raise AirflowException(
airflow.exceptions.AirflowException: The key 'ML 1' has to be made of alphanumeric characters, dashes, dots and underscores exclusively
[2025-04-24T18:43:49.756+0000] {processor.py:927} WARNING - No viable dags retrieved from /opt/airflow/dags/ML/ML1.py
[2025-04-24T18:43:49.834+0000] {processor.py:208} INFO - Processing /opt/airflow/dags/ML/ML1.py took 0.336 seconds
[2025-04-24T18:44:20.155+0000] {processor.py:186} INFO - Started process (PID=1744) to work on /opt/airflow/dags/ML/ML1.py
[2025-04-24T18:44:20.156+0000] {processor.py:914} INFO - Processing file /opt/airflow/dags/ML/ML1.py for tasks to queue
[2025-04-24T18:44:20.158+0000] {logging_mixin.py:190} INFO - [2025-04-24T18:44:20.158+0000] {dagbag.py:588} INFO - Filling up the DagBag from /opt/airflow/dags/ML/ML1.py
[2025-04-24T18:44:20.428+0000] {logging_mixin.py:190} INFO - [2025-04-24T18:44:20.419+0000] {dagbag.py:387} ERROR - Failed to import: /opt/airflow/dags/ML/ML1.py
Traceback (most recent call last):
  File "/home/airflow/.local/lib/python3.12/site-packages/airflow/models/dagbag.py", line 383, in parse
    loader.exec_module(new_module)
  File "<frozen importlib._bootstrap_external>", line 999, in exec_module
  File "<frozen importlib._bootstrap>", line 488, in _call_with_frames_removed
  File "/opt/airflow/dags/ML/ML1.py", line 17, in <module>
    with DAG(
         ^^^^
  File "/home/airflow/.local/lib/python3.12/site-packages/airflow/models/dag.py", line 593, in __init__
    validate_key(dag_id)
  File "/home/airflow/.local/lib/python3.12/site-packages/airflow/utils/helpers.py", line 57, in validate_key
    raise AirflowException(
airflow.exceptions.AirflowException: The key 'ML 1' has to be made of alphanumeric characters, dashes, dots and underscores exclusively
[2025-04-24T18:44:20.429+0000] {processor.py:927} WARNING - No viable dags retrieved from /opt/airflow/dags/ML/ML1.py
[2025-04-24T18:44:20.487+0000] {processor.py:208} INFO - Processing /opt/airflow/dags/ML/ML1.py took 0.337 seconds
[2025-04-24T18:44:51.016+0000] {processor.py:186} INFO - Started process (PID=1773) to work on /opt/airflow/dags/ML/ML1.py
[2025-04-24T18:44:51.017+0000] {processor.py:914} INFO - Processing file /opt/airflow/dags/ML/ML1.py for tasks to queue
[2025-04-24T18:44:51.022+0000] {logging_mixin.py:190} INFO - [2025-04-24T18:44:51.021+0000] {dagbag.py:588} INFO - Filling up the DagBag from /opt/airflow/dags/ML/ML1.py
[2025-04-24T18:44:51.498+0000] {logging_mixin.py:190} INFO - [2025-04-24T18:44:51.486+0000] {dagbag.py:387} ERROR - Failed to import: /opt/airflow/dags/ML/ML1.py
Traceback (most recent call last):
  File "/home/airflow/.local/lib/python3.12/site-packages/airflow/models/dagbag.py", line 383, in parse
    loader.exec_module(new_module)
  File "<frozen importlib._bootstrap_external>", line 999, in exec_module
  File "<frozen importlib._bootstrap>", line 488, in _call_with_frames_removed
  File "/opt/airflow/dags/ML/ML1.py", line 17, in <module>
    with DAG(
         ^^^^
  File "/home/airflow/.local/lib/python3.12/site-packages/airflow/models/dag.py", line 593, in __init__
    validate_key(dag_id)
  File "/home/airflow/.local/lib/python3.12/site-packages/airflow/utils/helpers.py", line 57, in validate_key
    raise AirflowException(
airflow.exceptions.AirflowException: The key 'ML 1' has to be made of alphanumeric characters, dashes, dots and underscores exclusively
[2025-04-24T18:44:51.499+0000] {processor.py:927} WARNING - No viable dags retrieved from /opt/airflow/dags/ML/ML1.py
[2025-04-24T18:44:51.595+0000] {processor.py:208} INFO - Processing /opt/airflow/dags/ML/ML1.py took 0.589 seconds
[2025-04-24T18:45:21.755+0000] {processor.py:186} INFO - Started process (PID=1802) to work on /opt/airflow/dags/ML/ML1.py
[2025-04-24T18:45:21.756+0000] {processor.py:914} INFO - Processing file /opt/airflow/dags/ML/ML1.py for tasks to queue
[2025-04-24T18:45:21.759+0000] {logging_mixin.py:190} INFO - [2025-04-24T18:45:21.759+0000] {dagbag.py:588} INFO - Filling up the DagBag from /opt/airflow/dags/ML/ML1.py
[2025-04-24T18:45:22.014+0000] {logging_mixin.py:190} INFO - [2025-04-24T18:45:22.009+0000] {dagbag.py:387} ERROR - Failed to import: /opt/airflow/dags/ML/ML1.py
Traceback (most recent call last):
  File "/home/airflow/.local/lib/python3.12/site-packages/airflow/models/dagbag.py", line 383, in parse
    loader.exec_module(new_module)
  File "<frozen importlib._bootstrap_external>", line 999, in exec_module
  File "<frozen importlib._bootstrap>", line 488, in _call_with_frames_removed
  File "/opt/airflow/dags/ML/ML1.py", line 17, in <module>
    with DAG(
         ^^^^
  File "/home/airflow/.local/lib/python3.12/site-packages/airflow/models/dag.py", line 593, in __init__
    validate_key(dag_id)
  File "/home/airflow/.local/lib/python3.12/site-packages/airflow/utils/helpers.py", line 57, in validate_key
    raise AirflowException(
airflow.exceptions.AirflowException: The key 'ML 1' has to be made of alphanumeric characters, dashes, dots and underscores exclusively
[2025-04-24T18:45:22.015+0000] {processor.py:927} WARNING - No viable dags retrieved from /opt/airflow/dags/ML/ML1.py
[2025-04-24T18:45:22.072+0000] {processor.py:208} INFO - Processing /opt/airflow/dags/ML/ML1.py took 0.321 seconds
[2025-04-24T18:45:52.486+0000] {processor.py:186} INFO - Started process (PID=1831) to work on /opt/airflow/dags/ML/ML1.py
[2025-04-24T18:45:52.487+0000] {processor.py:914} INFO - Processing file /opt/airflow/dags/ML/ML1.py for tasks to queue
[2025-04-24T18:45:52.490+0000] {logging_mixin.py:190} INFO - [2025-04-24T18:45:52.490+0000] {dagbag.py:588} INFO - Filling up the DagBag from /opt/airflow/dags/ML/ML1.py
[2025-04-24T18:45:52.737+0000] {logging_mixin.py:190} INFO - [2025-04-24T18:45:52.730+0000] {dagbag.py:387} ERROR - Failed to import: /opt/airflow/dags/ML/ML1.py
Traceback (most recent call last):
  File "/home/airflow/.local/lib/python3.12/site-packages/airflow/models/dagbag.py", line 383, in parse
    loader.exec_module(new_module)
  File "<frozen importlib._bootstrap_external>", line 999, in exec_module
  File "<frozen importlib._bootstrap>", line 488, in _call_with_frames_removed
  File "/opt/airflow/dags/ML/ML1.py", line 17, in <module>
    with DAG(
         ^^^^
  File "/home/airflow/.local/lib/python3.12/site-packages/airflow/models/dag.py", line 593, in __init__
    validate_key(dag_id)
  File "/home/airflow/.local/lib/python3.12/site-packages/airflow/utils/helpers.py", line 57, in validate_key
    raise AirflowException(
airflow.exceptions.AirflowException: The key 'ML 1' has to be made of alphanumeric characters, dashes, dots and underscores exclusively
[2025-04-24T18:45:52.738+0000] {processor.py:927} WARNING - No viable dags retrieved from /opt/airflow/dags/ML/ML1.py
[2025-04-24T18:45:52.784+0000] {processor.py:208} INFO - Processing /opt/airflow/dags/ML/ML1.py took 0.303 seconds
[2025-04-24T18:46:23.263+0000] {processor.py:186} INFO - Started process (PID=1866) to work on /opt/airflow/dags/ML/ML1.py
[2025-04-24T18:46:23.264+0000] {processor.py:914} INFO - Processing file /opt/airflow/dags/ML/ML1.py for tasks to queue
[2025-04-24T18:46:23.266+0000] {logging_mixin.py:190} INFO - [2025-04-24T18:46:23.266+0000] {dagbag.py:588} INFO - Filling up the DagBag from /opt/airflow/dags/ML/ML1.py
[2025-04-24T18:46:23.517+0000] {logging_mixin.py:190} INFO - [2025-04-24T18:46:23.511+0000] {dagbag.py:387} ERROR - Failed to import: /opt/airflow/dags/ML/ML1.py
Traceback (most recent call last):
  File "/home/airflow/.local/lib/python3.12/site-packages/airflow/models/dagbag.py", line 383, in parse
    loader.exec_module(new_module)
  File "<frozen importlib._bootstrap_external>", line 999, in exec_module
  File "<frozen importlib._bootstrap>", line 488, in _call_with_frames_removed
  File "/opt/airflow/dags/ML/ML1.py", line 17, in <module>
    with DAG(
         ^^^^
  File "/home/airflow/.local/lib/python3.12/site-packages/airflow/models/dag.py", line 593, in __init__
    validate_key(dag_id)
  File "/home/airflow/.local/lib/python3.12/site-packages/airflow/utils/helpers.py", line 57, in validate_key
    raise AirflowException(
airflow.exceptions.AirflowException: The key 'ML 1' has to be made of alphanumeric characters, dashes, dots and underscores exclusively
[2025-04-24T18:46:23.518+0000] {processor.py:927} WARNING - No viable dags retrieved from /opt/airflow/dags/ML/ML1.py
[2025-04-24T18:46:23.556+0000] {processor.py:208} INFO - Processing /opt/airflow/dags/ML/ML1.py took 0.298 seconds
[2025-04-24T18:46:53.983+0000] {processor.py:186} INFO - Started process (PID=1896) to work on /opt/airflow/dags/ML/ML1.py
[2025-04-24T18:46:53.984+0000] {processor.py:914} INFO - Processing file /opt/airflow/dags/ML/ML1.py for tasks to queue
[2025-04-24T18:46:53.986+0000] {logging_mixin.py:190} INFO - [2025-04-24T18:46:53.986+0000] {dagbag.py:588} INFO - Filling up the DagBag from /opt/airflow/dags/ML/ML1.py
[2025-04-24T18:46:54.292+0000] {logging_mixin.py:190} INFO - [2025-04-24T18:46:54.285+0000] {dagbag.py:387} ERROR - Failed to import: /opt/airflow/dags/ML/ML1.py
Traceback (most recent call last):
  File "/home/airflow/.local/lib/python3.12/site-packages/airflow/models/dagbag.py", line 383, in parse
    loader.exec_module(new_module)
  File "<frozen importlib._bootstrap_external>", line 999, in exec_module
  File "<frozen importlib._bootstrap>", line 488, in _call_with_frames_removed
  File "/opt/airflow/dags/ML/ML1.py", line 17, in <module>
    with DAG(
         ^^^^
  File "/home/airflow/.local/lib/python3.12/site-packages/airflow/models/dag.py", line 593, in __init__
    validate_key(dag_id)
  File "/home/airflow/.local/lib/python3.12/site-packages/airflow/utils/helpers.py", line 57, in validate_key
    raise AirflowException(
airflow.exceptions.AirflowException: The key 'ML 1' has to be made of alphanumeric characters, dashes, dots and underscores exclusively
[2025-04-24T18:46:54.293+0000] {processor.py:927} WARNING - No viable dags retrieved from /opt/airflow/dags/ML/ML1.py
[2025-04-24T18:46:54.362+0000] {processor.py:208} INFO - Processing /opt/airflow/dags/ML/ML1.py took 0.385 seconds
[2025-04-24T18:47:24.528+0000] {processor.py:186} INFO - Started process (PID=1926) to work on /opt/airflow/dags/ML/ML1.py
[2025-04-24T18:47:24.530+0000] {processor.py:914} INFO - Processing file /opt/airflow/dags/ML/ML1.py for tasks to queue
[2025-04-24T18:47:24.532+0000] {logging_mixin.py:190} INFO - [2025-04-24T18:47:24.532+0000] {dagbag.py:588} INFO - Filling up the DagBag from /opt/airflow/dags/ML/ML1.py
[2025-04-24T18:47:24.799+0000] {logging_mixin.py:190} INFO - [2025-04-24T18:47:24.792+0000] {dagbag.py:387} ERROR - Failed to import: /opt/airflow/dags/ML/ML1.py
Traceback (most recent call last):
  File "/home/airflow/.local/lib/python3.12/site-packages/airflow/models/dagbag.py", line 383, in parse
    loader.exec_module(new_module)
  File "<frozen importlib._bootstrap_external>", line 999, in exec_module
  File "<frozen importlib._bootstrap>", line 488, in _call_with_frames_removed
  File "/opt/airflow/dags/ML/ML1.py", line 17, in <module>
    with DAG(
         ^^^^
  File "/home/airflow/.local/lib/python3.12/site-packages/airflow/models/dag.py", line 593, in __init__
    validate_key(dag_id)
  File "/home/airflow/.local/lib/python3.12/site-packages/airflow/utils/helpers.py", line 57, in validate_key
    raise AirflowException(
airflow.exceptions.AirflowException: The key 'ML 1' has to be made of alphanumeric characters, dashes, dots and underscores exclusively
[2025-04-24T18:47:24.800+0000] {processor.py:927} WARNING - No viable dags retrieved from /opt/airflow/dags/ML/ML1.py
[2025-04-24T18:47:24.859+0000] {processor.py:208} INFO - Processing /opt/airflow/dags/ML/ML1.py took 0.338 seconds
[2025-04-24T18:47:54.955+0000] {processor.py:186} INFO - Started process (PID=1955) to work on /opt/airflow/dags/ML/ML1.py
[2025-04-24T18:47:54.957+0000] {processor.py:914} INFO - Processing file /opt/airflow/dags/ML/ML1.py for tasks to queue
[2025-04-24T18:47:54.963+0000] {logging_mixin.py:190} INFO - [2025-04-24T18:47:54.962+0000] {dagbag.py:588} INFO - Filling up the DagBag from /opt/airflow/dags/ML/ML1.py
[2025-04-24T18:47:55.285+0000] {logging_mixin.py:190} INFO - [2025-04-24T18:47:55.277+0000] {dagbag.py:387} ERROR - Failed to import: /opt/airflow/dags/ML/ML1.py
Traceback (most recent call last):
  File "/home/airflow/.local/lib/python3.12/site-packages/airflow/models/dagbag.py", line 383, in parse
    loader.exec_module(new_module)
  File "<frozen importlib._bootstrap_external>", line 999, in exec_module
  File "<frozen importlib._bootstrap>", line 488, in _call_with_frames_removed
  File "/opt/airflow/dags/ML/ML1.py", line 17, in <module>
    with DAG(
         ^^^^
  File "/home/airflow/.local/lib/python3.12/site-packages/airflow/models/dag.py", line 593, in __init__
    validate_key(dag_id)
  File "/home/airflow/.local/lib/python3.12/site-packages/airflow/utils/helpers.py", line 57, in validate_key
    raise AirflowException(
airflow.exceptions.AirflowException: The key 'ML 1' has to be made of alphanumeric characters, dashes, dots and underscores exclusively
[2025-04-24T18:47:55.286+0000] {processor.py:927} WARNING - No viable dags retrieved from /opt/airflow/dags/ML/ML1.py
[2025-04-24T18:47:55.344+0000] {processor.py:208} INFO - Processing /opt/airflow/dags/ML/ML1.py took 0.398 seconds
[2025-04-24T18:48:25.437+0000] {processor.py:186} INFO - Started process (PID=1984) to work on /opt/airflow/dags/ML/ML1.py
[2025-04-24T18:48:25.438+0000] {processor.py:914} INFO - Processing file /opt/airflow/dags/ML/ML1.py for tasks to queue
[2025-04-24T18:48:25.442+0000] {logging_mixin.py:190} INFO - [2025-04-24T18:48:25.442+0000] {dagbag.py:588} INFO - Filling up the DagBag from /opt/airflow/dags/ML/ML1.py
[2025-04-24T18:48:25.777+0000] {logging_mixin.py:190} INFO - [2025-04-24T18:48:25.770+0000] {dagbag.py:387} ERROR - Failed to import: /opt/airflow/dags/ML/ML1.py
Traceback (most recent call last):
  File "/home/airflow/.local/lib/python3.12/site-packages/airflow/models/dagbag.py", line 383, in parse
    loader.exec_module(new_module)
  File "<frozen importlib._bootstrap_external>", line 999, in exec_module
  File "<frozen importlib._bootstrap>", line 488, in _call_with_frames_removed
  File "/opt/airflow/dags/ML/ML1.py", line 17, in <module>
    with DAG(
         ^^^^
  File "/home/airflow/.local/lib/python3.12/site-packages/airflow/models/dag.py", line 593, in __init__
    validate_key(dag_id)
  File "/home/airflow/.local/lib/python3.12/site-packages/airflow/utils/helpers.py", line 57, in validate_key
    raise AirflowException(
airflow.exceptions.AirflowException: The key 'ML 1' has to be made of alphanumeric characters, dashes, dots and underscores exclusively
[2025-04-24T18:48:25.778+0000] {processor.py:927} WARNING - No viable dags retrieved from /opt/airflow/dags/ML/ML1.py
[2025-04-24T18:48:25.842+0000] {processor.py:208} INFO - Processing /opt/airflow/dags/ML/ML1.py took 0.412 seconds
[2025-04-24T18:48:55.912+0000] {processor.py:186} INFO - Started process (PID=2013) to work on /opt/airflow/dags/ML/ML1.py
[2025-04-24T18:48:55.913+0000] {processor.py:914} INFO - Processing file /opt/airflow/dags/ML/ML1.py for tasks to queue
[2025-04-24T18:48:55.915+0000] {logging_mixin.py:190} INFO - [2025-04-24T18:48:55.915+0000] {dagbag.py:588} INFO - Filling up the DagBag from /opt/airflow/dags/ML/ML1.py
[2025-04-24T18:48:56.195+0000] {logging_mixin.py:190} INFO - [2025-04-24T18:48:56.184+0000] {dagbag.py:387} ERROR - Failed to import: /opt/airflow/dags/ML/ML1.py
Traceback (most recent call last):
  File "/home/airflow/.local/lib/python3.12/site-packages/airflow/models/dagbag.py", line 383, in parse
    loader.exec_module(new_module)
  File "<frozen importlib._bootstrap_external>", line 999, in exec_module
  File "<frozen importlib._bootstrap>", line 488, in _call_with_frames_removed
  File "/opt/airflow/dags/ML/ML1.py", line 17, in <module>
    with DAG(
         ^^^^
  File "/home/airflow/.local/lib/python3.12/site-packages/airflow/models/dag.py", line 593, in __init__
    validate_key(dag_id)
  File "/home/airflow/.local/lib/python3.12/site-packages/airflow/utils/helpers.py", line 57, in validate_key
    raise AirflowException(
airflow.exceptions.AirflowException: The key 'ML 1' has to be made of alphanumeric characters, dashes, dots and underscores exclusively
[2025-04-24T18:48:56.196+0000] {processor.py:927} WARNING - No viable dags retrieved from /opt/airflow/dags/ML/ML1.py
[2025-04-24T18:48:56.248+0000] {processor.py:208} INFO - Processing /opt/airflow/dags/ML/ML1.py took 0.341 seconds
[2025-04-24T18:49:26.378+0000] {processor.py:186} INFO - Started process (PID=2042) to work on /opt/airflow/dags/ML/ML1.py
[2025-04-24T18:49:26.379+0000] {processor.py:914} INFO - Processing file /opt/airflow/dags/ML/ML1.py for tasks to queue
[2025-04-24T18:49:26.382+0000] {logging_mixin.py:190} INFO - [2025-04-24T18:49:26.381+0000] {dagbag.py:588} INFO - Filling up the DagBag from /opt/airflow/dags/ML/ML1.py
[2025-04-24T18:49:26.662+0000] {logging_mixin.py:190} INFO - [2025-04-24T18:49:26.654+0000] {dagbag.py:387} ERROR - Failed to import: /opt/airflow/dags/ML/ML1.py
Traceback (most recent call last):
  File "/home/airflow/.local/lib/python3.12/site-packages/airflow/models/dagbag.py", line 383, in parse
    loader.exec_module(new_module)
  File "<frozen importlib._bootstrap_external>", line 999, in exec_module
  File "<frozen importlib._bootstrap>", line 488, in _call_with_frames_removed
  File "/opt/airflow/dags/ML/ML1.py", line 17, in <module>
    with DAG(
         ^^^^
  File "/home/airflow/.local/lib/python3.12/site-packages/airflow/models/dag.py", line 593, in __init__
    validate_key(dag_id)
  File "/home/airflow/.local/lib/python3.12/site-packages/airflow/utils/helpers.py", line 57, in validate_key
    raise AirflowException(
airflow.exceptions.AirflowException: The key 'ML 1' has to be made of alphanumeric characters, dashes, dots and underscores exclusively
[2025-04-24T18:49:26.663+0000] {processor.py:927} WARNING - No viable dags retrieved from /opt/airflow/dags/ML/ML1.py
[2025-04-24T18:49:26.701+0000] {processor.py:208} INFO - Processing /opt/airflow/dags/ML/ML1.py took 0.328 seconds
[2025-04-24T18:49:57.325+0000] {processor.py:186} INFO - Started process (PID=2070) to work on /opt/airflow/dags/ML/ML1.py
[2025-04-24T18:49:57.327+0000] {processor.py:914} INFO - Processing file /opt/airflow/dags/ML/ML1.py for tasks to queue
[2025-04-24T18:49:57.330+0000] {logging_mixin.py:190} INFO - [2025-04-24T18:49:57.329+0000] {dagbag.py:588} INFO - Filling up the DagBag from /opt/airflow/dags/ML/ML1.py
[2025-04-24T18:49:57.621+0000] {logging_mixin.py:190} INFO - [2025-04-24T18:49:57.613+0000] {dagbag.py:387} ERROR - Failed to import: /opt/airflow/dags/ML/ML1.py
Traceback (most recent call last):
  File "/home/airflow/.local/lib/python3.12/site-packages/airflow/models/dagbag.py", line 383, in parse
    loader.exec_module(new_module)
  File "<frozen importlib._bootstrap_external>", line 999, in exec_module
  File "<frozen importlib._bootstrap>", line 488, in _call_with_frames_removed
  File "/opt/airflow/dags/ML/ML1.py", line 17, in <module>
    with DAG(
         ^^^^
  File "/home/airflow/.local/lib/python3.12/site-packages/airflow/models/dag.py", line 593, in __init__
    validate_key(dag_id)
  File "/home/airflow/.local/lib/python3.12/site-packages/airflow/utils/helpers.py", line 57, in validate_key
    raise AirflowException(
airflow.exceptions.AirflowException: The key 'ML 1' has to be made of alphanumeric characters, dashes, dots and underscores exclusively
[2025-04-24T18:49:57.622+0000] {processor.py:927} WARNING - No viable dags retrieved from /opt/airflow/dags/ML/ML1.py
[2025-04-24T18:49:57.675+0000] {processor.py:208} INFO - Processing /opt/airflow/dags/ML/ML1.py took 0.355 seconds
[2025-04-24T18:50:28.344+0000] {processor.py:186} INFO - Started process (PID=2099) to work on /opt/airflow/dags/ML/ML1.py
[2025-04-24T18:50:28.345+0000] {processor.py:914} INFO - Processing file /opt/airflow/dags/ML/ML1.py for tasks to queue
[2025-04-24T18:50:28.347+0000] {logging_mixin.py:190} INFO - [2025-04-24T18:50:28.347+0000] {dagbag.py:588} INFO - Filling up the DagBag from /opt/airflow/dags/ML/ML1.py
[2025-04-24T18:50:28.671+0000] {logging_mixin.py:190} INFO - [2025-04-24T18:50:28.660+0000] {dagbag.py:387} ERROR - Failed to import: /opt/airflow/dags/ML/ML1.py
Traceback (most recent call last):
  File "/home/airflow/.local/lib/python3.12/site-packages/airflow/models/dagbag.py", line 383, in parse
    loader.exec_module(new_module)
  File "<frozen importlib._bootstrap_external>", line 999, in exec_module
  File "<frozen importlib._bootstrap>", line 488, in _call_with_frames_removed
  File "/opt/airflow/dags/ML/ML1.py", line 17, in <module>
    with DAG(
         ^^^^
  File "/home/airflow/.local/lib/python3.12/site-packages/airflow/models/dag.py", line 593, in __init__
    validate_key(dag_id)
  File "/home/airflow/.local/lib/python3.12/site-packages/airflow/utils/helpers.py", line 57, in validate_key
    raise AirflowException(
airflow.exceptions.AirflowException: The key 'ML 1' has to be made of alphanumeric characters, dashes, dots and underscores exclusively
[2025-04-24T18:50:28.674+0000] {processor.py:927} WARNING - No viable dags retrieved from /opt/airflow/dags/ML/ML1.py
[2025-04-24T18:50:28.779+0000] {processor.py:208} INFO - Processing /opt/airflow/dags/ML/ML1.py took 0.440 seconds
[2025-04-24T18:50:58.915+0000] {processor.py:186} INFO - Started process (PID=2129) to work on /opt/airflow/dags/ML/ML1.py
[2025-04-24T18:50:58.916+0000] {processor.py:914} INFO - Processing file /opt/airflow/dags/ML/ML1.py for tasks to queue
[2025-04-24T18:50:58.919+0000] {logging_mixin.py:190} INFO - [2025-04-24T18:50:58.919+0000] {dagbag.py:588} INFO - Filling up the DagBag from /opt/airflow/dags/ML/ML1.py
[2025-04-24T18:50:59.190+0000] {logging_mixin.py:190} INFO - [2025-04-24T18:50:59.183+0000] {dagbag.py:387} ERROR - Failed to import: /opt/airflow/dags/ML/ML1.py
Traceback (most recent call last):
  File "/home/airflow/.local/lib/python3.12/site-packages/airflow/models/dagbag.py", line 383, in parse
    loader.exec_module(new_module)
  File "<frozen importlib._bootstrap_external>", line 999, in exec_module
  File "<frozen importlib._bootstrap>", line 488, in _call_with_frames_removed
  File "/opt/airflow/dags/ML/ML1.py", line 17, in <module>
    with DAG(
         ^^^^
  File "/home/airflow/.local/lib/python3.12/site-packages/airflow/models/dag.py", line 593, in __init__
    validate_key(dag_id)
  File "/home/airflow/.local/lib/python3.12/site-packages/airflow/utils/helpers.py", line 57, in validate_key
    raise AirflowException(
airflow.exceptions.AirflowException: The key 'ML 1' has to be made of alphanumeric characters, dashes, dots and underscores exclusively
[2025-04-24T18:50:59.191+0000] {processor.py:927} WARNING - No viable dags retrieved from /opt/airflow/dags/ML/ML1.py
[2025-04-24T18:50:59.257+0000] {processor.py:208} INFO - Processing /opt/airflow/dags/ML/ML1.py took 0.348 seconds
[2025-04-24T18:51:29.543+0000] {processor.py:186} INFO - Started process (PID=2158) to work on /opt/airflow/dags/ML/ML1.py
[2025-04-24T18:51:29.545+0000] {processor.py:914} INFO - Processing file /opt/airflow/dags/ML/ML1.py for tasks to queue
[2025-04-24T18:51:29.547+0000] {logging_mixin.py:190} INFO - [2025-04-24T18:51:29.547+0000] {dagbag.py:588} INFO - Filling up the DagBag from /opt/airflow/dags/ML/ML1.py
[2025-04-24T18:51:29.807+0000] {logging_mixin.py:190} INFO - [2025-04-24T18:51:29.800+0000] {dagbag.py:387} ERROR - Failed to import: /opt/airflow/dags/ML/ML1.py
Traceback (most recent call last):
  File "/home/airflow/.local/lib/python3.12/site-packages/airflow/models/dagbag.py", line 383, in parse
    loader.exec_module(new_module)
  File "<frozen importlib._bootstrap_external>", line 999, in exec_module
  File "<frozen importlib._bootstrap>", line 488, in _call_with_frames_removed
  File "/opt/airflow/dags/ML/ML1.py", line 17, in <module>
    with DAG(
         ^^^^
  File "/home/airflow/.local/lib/python3.12/site-packages/airflow/models/dag.py", line 593, in __init__
    validate_key(dag_id)
  File "/home/airflow/.local/lib/python3.12/site-packages/airflow/utils/helpers.py", line 57, in validate_key
    raise AirflowException(
airflow.exceptions.AirflowException: The key 'ML 1' has to be made of alphanumeric characters, dashes, dots and underscores exclusively
[2025-04-24T18:51:29.808+0000] {processor.py:927} WARNING - No viable dags retrieved from /opt/airflow/dags/ML/ML1.py
[2025-04-24T18:51:29.851+0000] {processor.py:208} INFO - Processing /opt/airflow/dags/ML/ML1.py took 0.313 seconds
[2025-04-24T18:52:00.168+0000] {processor.py:186} INFO - Started process (PID=2187) to work on /opt/airflow/dags/ML/ML1.py
[2025-04-24T18:52:00.170+0000] {processor.py:914} INFO - Processing file /opt/airflow/dags/ML/ML1.py for tasks to queue
[2025-04-24T18:52:00.172+0000] {logging_mixin.py:190} INFO - [2025-04-24T18:52:00.172+0000] {dagbag.py:588} INFO - Filling up the DagBag from /opt/airflow/dags/ML/ML1.py
[2025-04-24T18:52:00.477+0000] {logging_mixin.py:190} INFO - [2025-04-24T18:52:00.467+0000] {dagbag.py:387} ERROR - Failed to import: /opt/airflow/dags/ML/ML1.py
Traceback (most recent call last):
  File "/home/airflow/.local/lib/python3.12/site-packages/airflow/models/dagbag.py", line 383, in parse
    loader.exec_module(new_module)
  File "<frozen importlib._bootstrap_external>", line 999, in exec_module
  File "<frozen importlib._bootstrap>", line 488, in _call_with_frames_removed
  File "/opt/airflow/dags/ML/ML1.py", line 17, in <module>
    with DAG(
         ^^^^
  File "/home/airflow/.local/lib/python3.12/site-packages/airflow/models/dag.py", line 593, in __init__
    validate_key(dag_id)
  File "/home/airflow/.local/lib/python3.12/site-packages/airflow/utils/helpers.py", line 57, in validate_key
    raise AirflowException(
airflow.exceptions.AirflowException: The key 'ML 1' has to be made of alphanumeric characters, dashes, dots and underscores exclusively
[2025-04-24T18:52:00.479+0000] {processor.py:927} WARNING - No viable dags retrieved from /opt/airflow/dags/ML/ML1.py
[2025-04-24T18:52:00.546+0000] {processor.py:208} INFO - Processing /opt/airflow/dags/ML/ML1.py took 0.385 seconds
[2025-04-24T18:52:30.843+0000] {processor.py:186} INFO - Started process (PID=2216) to work on /opt/airflow/dags/ML/ML1.py
[2025-04-24T18:52:30.845+0000] {processor.py:914} INFO - Processing file /opt/airflow/dags/ML/ML1.py for tasks to queue
[2025-04-24T18:52:30.847+0000] {logging_mixin.py:190} INFO - [2025-04-24T18:52:30.847+0000] {dagbag.py:588} INFO - Filling up the DagBag from /opt/airflow/dags/ML/ML1.py
[2025-04-24T18:52:31.146+0000] {logging_mixin.py:190} INFO - [2025-04-24T18:52:31.138+0000] {dagbag.py:387} ERROR - Failed to import: /opt/airflow/dags/ML/ML1.py
Traceback (most recent call last):
  File "/home/airflow/.local/lib/python3.12/site-packages/airflow/models/dagbag.py", line 383, in parse
    loader.exec_module(new_module)
  File "<frozen importlib._bootstrap_external>", line 999, in exec_module
  File "<frozen importlib._bootstrap>", line 488, in _call_with_frames_removed
  File "/opt/airflow/dags/ML/ML1.py", line 17, in <module>
    with DAG(
         ^^^^
  File "/home/airflow/.local/lib/python3.12/site-packages/airflow/models/dag.py", line 593, in __init__
    validate_key(dag_id)
  File "/home/airflow/.local/lib/python3.12/site-packages/airflow/utils/helpers.py", line 57, in validate_key
    raise AirflowException(
airflow.exceptions.AirflowException: The key 'ML 1' has to be made of alphanumeric characters, dashes, dots and underscores exclusively
[2025-04-24T18:52:31.147+0000] {processor.py:927} WARNING - No viable dags retrieved from /opt/airflow/dags/ML/ML1.py
[2025-04-24T18:52:31.221+0000] {processor.py:208} INFO - Processing /opt/airflow/dags/ML/ML1.py took 0.387 seconds
[2025-04-24T18:53:01.898+0000] {processor.py:186} INFO - Started process (PID=2246) to work on /opt/airflow/dags/ML/ML1.py
[2025-04-24T18:53:01.899+0000] {processor.py:914} INFO - Processing file /opt/airflow/dags/ML/ML1.py for tasks to queue
[2025-04-24T18:53:01.902+0000] {logging_mixin.py:190} INFO - [2025-04-24T18:53:01.901+0000] {dagbag.py:588} INFO - Filling up the DagBag from /opt/airflow/dags/ML/ML1.py
[2025-04-24T18:53:02.181+0000] {logging_mixin.py:190} INFO - [2025-04-24T18:53:02.173+0000] {dagbag.py:387} ERROR - Failed to import: /opt/airflow/dags/ML/ML1.py
Traceback (most recent call last):
  File "/home/airflow/.local/lib/python3.12/site-packages/airflow/models/dagbag.py", line 383, in parse
    loader.exec_module(new_module)
  File "<frozen importlib._bootstrap_external>", line 999, in exec_module
  File "<frozen importlib._bootstrap>", line 488, in _call_with_frames_removed
  File "/opt/airflow/dags/ML/ML1.py", line 17, in <module>
    with DAG(
         ^^^^
  File "/home/airflow/.local/lib/python3.12/site-packages/airflow/models/dag.py", line 593, in __init__
    validate_key(dag_id)
  File "/home/airflow/.local/lib/python3.12/site-packages/airflow/utils/helpers.py", line 57, in validate_key
    raise AirflowException(
airflow.exceptions.AirflowException: The key 'ML 1' has to be made of alphanumeric characters, dashes, dots and underscores exclusively
[2025-04-24T18:53:02.182+0000] {processor.py:927} WARNING - No viable dags retrieved from /opt/airflow/dags/ML/ML1.py
[2025-04-24T18:53:02.257+0000] {processor.py:208} INFO - Processing /opt/airflow/dags/ML/ML1.py took 0.365 seconds
[2025-04-24T18:53:32.642+0000] {processor.py:186} INFO - Started process (PID=2275) to work on /opt/airflow/dags/ML/ML1.py
[2025-04-24T18:53:32.644+0000] {processor.py:914} INFO - Processing file /opt/airflow/dags/ML/ML1.py for tasks to queue
[2025-04-24T18:53:32.647+0000] {logging_mixin.py:190} INFO - [2025-04-24T18:53:32.646+0000] {dagbag.py:588} INFO - Filling up the DagBag from /opt/airflow/dags/ML/ML1.py
[2025-04-24T18:53:32.933+0000] {logging_mixin.py:190} INFO - [2025-04-24T18:53:32.923+0000] {dagbag.py:387} ERROR - Failed to import: /opt/airflow/dags/ML/ML1.py
Traceback (most recent call last):
  File "/home/airflow/.local/lib/python3.12/site-packages/airflow/models/dagbag.py", line 383, in parse
    loader.exec_module(new_module)
  File "<frozen importlib._bootstrap_external>", line 999, in exec_module
  File "<frozen importlib._bootstrap>", line 488, in _call_with_frames_removed
  File "/opt/airflow/dags/ML/ML1.py", line 17, in <module>
    with DAG(
         ^^^^
  File "/home/airflow/.local/lib/python3.12/site-packages/airflow/models/dag.py", line 593, in __init__
    validate_key(dag_id)
  File "/home/airflow/.local/lib/python3.12/site-packages/airflow/utils/helpers.py", line 57, in validate_key
    raise AirflowException(
airflow.exceptions.AirflowException: The key 'ML 1' has to be made of alphanumeric characters, dashes, dots and underscores exclusively
[2025-04-24T18:53:32.935+0000] {processor.py:927} WARNING - No viable dags retrieved from /opt/airflow/dags/ML/ML1.py
[2025-04-24T18:53:33.020+0000] {processor.py:208} INFO - Processing /opt/airflow/dags/ML/ML1.py took 0.384 seconds
[2025-04-24T18:54:03.349+0000] {processor.py:186} INFO - Started process (PID=2304) to work on /opt/airflow/dags/ML/ML1.py
[2025-04-24T18:54:03.350+0000] {processor.py:914} INFO - Processing file /opt/airflow/dags/ML/ML1.py for tasks to queue
[2025-04-24T18:54:03.352+0000] {logging_mixin.py:190} INFO - [2025-04-24T18:54:03.352+0000] {dagbag.py:588} INFO - Filling up the DagBag from /opt/airflow/dags/ML/ML1.py
[2025-04-24T18:54:03.622+0000] {logging_mixin.py:190} INFO - [2025-04-24T18:54:03.594+0000] {dagbag.py:387} ERROR - Failed to import: /opt/airflow/dags/ML/ML1.py
Traceback (most recent call last):
  File "/home/airflow/.local/lib/python3.12/site-packages/airflow/models/dagbag.py", line 383, in parse
    loader.exec_module(new_module)
  File "<frozen importlib._bootstrap_external>", line 999, in exec_module
  File "<frozen importlib._bootstrap>", line 488, in _call_with_frames_removed
  File "/opt/airflow/dags/ML/ML1.py", line 17, in <module>
    with DAG(
         ^^^^
  File "/home/airflow/.local/lib/python3.12/site-packages/airflow/models/dag.py", line 593, in __init__
    validate_key(dag_id)
  File "/home/airflow/.local/lib/python3.12/site-packages/airflow/utils/helpers.py", line 57, in validate_key
    raise AirflowException(
airflow.exceptions.AirflowException: The key 'ML 1' has to be made of alphanumeric characters, dashes, dots and underscores exclusively
[2025-04-24T18:54:03.623+0000] {processor.py:927} WARNING - No viable dags retrieved from /opt/airflow/dags/ML/ML1.py
[2025-04-24T18:54:03.694+0000] {processor.py:208} INFO - Processing /opt/airflow/dags/ML/ML1.py took 0.351 seconds
[2025-04-24T18:54:33.994+0000] {processor.py:186} INFO - Started process (PID=2333) to work on /opt/airflow/dags/ML/ML1.py
[2025-04-24T18:54:33.996+0000] {processor.py:914} INFO - Processing file /opt/airflow/dags/ML/ML1.py for tasks to queue
[2025-04-24T18:54:33.998+0000] {logging_mixin.py:190} INFO - [2025-04-24T18:54:33.998+0000] {dagbag.py:588} INFO - Filling up the DagBag from /opt/airflow/dags/ML/ML1.py
[2025-04-24T18:54:34.299+0000] {logging_mixin.py:190} INFO - [2025-04-24T18:54:34.290+0000] {dagbag.py:387} ERROR - Failed to import: /opt/airflow/dags/ML/ML1.py
Traceback (most recent call last):
  File "/home/airflow/.local/lib/python3.12/site-packages/airflow/models/dagbag.py", line 383, in parse
    loader.exec_module(new_module)
  File "<frozen importlib._bootstrap_external>", line 999, in exec_module
  File "<frozen importlib._bootstrap>", line 488, in _call_with_frames_removed
  File "/opt/airflow/dags/ML/ML1.py", line 17, in <module>
    with DAG(
         ^^^^
  File "/home/airflow/.local/lib/python3.12/site-packages/airflow/models/dag.py", line 593, in __init__
    validate_key(dag_id)
  File "/home/airflow/.local/lib/python3.12/site-packages/airflow/utils/helpers.py", line 57, in validate_key
    raise AirflowException(
airflow.exceptions.AirflowException: The key 'ML 1' has to be made of alphanumeric characters, dashes, dots and underscores exclusively
[2025-04-24T18:54:34.300+0000] {processor.py:927} WARNING - No viable dags retrieved from /opt/airflow/dags/ML/ML1.py
[2025-04-24T18:54:34.388+0000] {processor.py:208} INFO - Processing /opt/airflow/dags/ML/ML1.py took 0.402 seconds
[2025-04-24T18:55:05.034+0000] {processor.py:186} INFO - Started process (PID=2362) to work on /opt/airflow/dags/ML/ML1.py
[2025-04-24T18:55:05.035+0000] {processor.py:914} INFO - Processing file /opt/airflow/dags/ML/ML1.py for tasks to queue
[2025-04-24T18:55:05.038+0000] {logging_mixin.py:190} INFO - [2025-04-24T18:55:05.038+0000] {dagbag.py:588} INFO - Filling up the DagBag from /opt/airflow/dags/ML/ML1.py
[2025-04-24T18:55:05.321+0000] {logging_mixin.py:190} INFO - [2025-04-24T18:55:05.310+0000] {dagbag.py:387} ERROR - Failed to import: /opt/airflow/dags/ML/ML1.py
Traceback (most recent call last):
  File "/home/airflow/.local/lib/python3.12/site-packages/airflow/models/dagbag.py", line 383, in parse
    loader.exec_module(new_module)
  File "<frozen importlib._bootstrap_external>", line 999, in exec_module
  File "<frozen importlib._bootstrap>", line 488, in _call_with_frames_removed
  File "/opt/airflow/dags/ML/ML1.py", line 17, in <module>
    with DAG(
         ^^^^
  File "/home/airflow/.local/lib/python3.12/site-packages/airflow/models/dag.py", line 593, in __init__
    validate_key(dag_id)
  File "/home/airflow/.local/lib/python3.12/site-packages/airflow/utils/helpers.py", line 57, in validate_key
    raise AirflowException(
airflow.exceptions.AirflowException: The key 'ML 1' has to be made of alphanumeric characters, dashes, dots and underscores exclusively
[2025-04-24T18:55:05.323+0000] {processor.py:927} WARNING - No viable dags retrieved from /opt/airflow/dags/ML/ML1.py
[2025-04-24T18:55:05.419+0000] {processor.py:208} INFO - Processing /opt/airflow/dags/ML/ML1.py took 0.391 seconds
[2025-04-24T18:55:35.600+0000] {processor.py:186} INFO - Started process (PID=2391) to work on /opt/airflow/dags/ML/ML1.py
[2025-04-24T18:55:35.601+0000] {processor.py:914} INFO - Processing file /opt/airflow/dags/ML/ML1.py for tasks to queue
[2025-04-24T18:55:35.604+0000] {logging_mixin.py:190} INFO - [2025-04-24T18:55:35.603+0000] {dagbag.py:588} INFO - Filling up the DagBag from /opt/airflow/dags/ML/ML1.py
[2025-04-24T18:55:35.908+0000] {logging_mixin.py:190} INFO - [2025-04-24T18:55:35.893+0000] {dagbag.py:387} ERROR - Failed to import: /opt/airflow/dags/ML/ML1.py
Traceback (most recent call last):
  File "/home/airflow/.local/lib/python3.12/site-packages/airflow/models/dagbag.py", line 383, in parse
    loader.exec_module(new_module)
  File "<frozen importlib._bootstrap_external>", line 999, in exec_module
  File "<frozen importlib._bootstrap>", line 488, in _call_with_frames_removed
  File "/opt/airflow/dags/ML/ML1.py", line 17, in <module>
    with DAG(
         ^^^^
  File "/home/airflow/.local/lib/python3.12/site-packages/airflow/models/dag.py", line 593, in __init__
    validate_key(dag_id)
  File "/home/airflow/.local/lib/python3.12/site-packages/airflow/utils/helpers.py", line 57, in validate_key
    raise AirflowException(
airflow.exceptions.AirflowException: The key 'ML 1' has to be made of alphanumeric characters, dashes, dots and underscores exclusively
[2025-04-24T18:55:35.909+0000] {processor.py:927} WARNING - No viable dags retrieved from /opt/airflow/dags/ML/ML1.py
[2025-04-24T18:55:36.074+0000] {processor.py:208} INFO - Processing /opt/airflow/dags/ML/ML1.py took 0.481 seconds
[2025-04-24T18:56:06.257+0000] {processor.py:186} INFO - Started process (PID=2420) to work on /opt/airflow/dags/ML/ML1.py
[2025-04-24T18:56:06.258+0000] {processor.py:914} INFO - Processing file /opt/airflow/dags/ML/ML1.py for tasks to queue
[2025-04-24T18:56:06.260+0000] {logging_mixin.py:190} INFO - [2025-04-24T18:56:06.260+0000] {dagbag.py:588} INFO - Filling up the DagBag from /opt/airflow/dags/ML/ML1.py
[2025-04-24T18:56:06.510+0000] {logging_mixin.py:190} INFO - [2025-04-24T18:56:06.503+0000] {dagbag.py:387} ERROR - Failed to import: /opt/airflow/dags/ML/ML1.py
Traceback (most recent call last):
  File "/home/airflow/.local/lib/python3.12/site-packages/airflow/models/dagbag.py", line 383, in parse
    loader.exec_module(new_module)
  File "<frozen importlib._bootstrap_external>", line 999, in exec_module
  File "<frozen importlib._bootstrap>", line 488, in _call_with_frames_removed
  File "/opt/airflow/dags/ML/ML1.py", line 17, in <module>
    with DAG(
         ^^^^
  File "/home/airflow/.local/lib/python3.12/site-packages/airflow/models/dag.py", line 593, in __init__
    validate_key(dag_id)
  File "/home/airflow/.local/lib/python3.12/site-packages/airflow/utils/helpers.py", line 57, in validate_key
    raise AirflowException(
airflow.exceptions.AirflowException: The key 'ML 1' has to be made of alphanumeric characters, dashes, dots and underscores exclusively
[2025-04-24T18:56:06.511+0000] {processor.py:927} WARNING - No viable dags retrieved from /opt/airflow/dags/ML/ML1.py
[2025-04-24T18:56:06.576+0000] {processor.py:208} INFO - Processing /opt/airflow/dags/ML/ML1.py took 0.325 seconds
[2025-04-24T18:56:36.657+0000] {processor.py:186} INFO - Started process (PID=2450) to work on /opt/airflow/dags/ML/ML1.py
[2025-04-24T18:56:36.658+0000] {processor.py:914} INFO - Processing file /opt/airflow/dags/ML/ML1.py for tasks to queue
[2025-04-24T18:56:36.660+0000] {logging_mixin.py:190} INFO - [2025-04-24T18:56:36.660+0000] {dagbag.py:588} INFO - Filling up the DagBag from /opt/airflow/dags/ML/ML1.py
[2025-04-24T18:56:36.904+0000] {logging_mixin.py:190} INFO - [2025-04-24T18:56:36.894+0000] {dagbag.py:387} ERROR - Failed to import: /opt/airflow/dags/ML/ML1.py
Traceback (most recent call last):
  File "/home/airflow/.local/lib/python3.12/site-packages/airflow/models/dagbag.py", line 383, in parse
    loader.exec_module(new_module)
  File "<frozen importlib._bootstrap_external>", line 999, in exec_module
  File "<frozen importlib._bootstrap>", line 488, in _call_with_frames_removed
  File "/opt/airflow/dags/ML/ML1.py", line 17, in <module>
    with DAG(
         ^^^^
  File "/home/airflow/.local/lib/python3.12/site-packages/airflow/models/dag.py", line 593, in __init__
    validate_key(dag_id)
  File "/home/airflow/.local/lib/python3.12/site-packages/airflow/utils/helpers.py", line 57, in validate_key
    raise AirflowException(
airflow.exceptions.AirflowException: The key 'ML 1' has to be made of alphanumeric characters, dashes, dots and underscores exclusively
[2025-04-24T18:56:36.905+0000] {processor.py:927} WARNING - No viable dags retrieved from /opt/airflow/dags/ML/ML1.py
[2025-04-24T18:56:37.093+0000] {processor.py:208} INFO - Processing /opt/airflow/dags/ML/ML1.py took 0.442 seconds
[2025-04-24T18:57:07.376+0000] {processor.py:186} INFO - Started process (PID=2479) to work on /opt/airflow/dags/ML/ML1.py
[2025-04-24T18:57:07.377+0000] {processor.py:914} INFO - Processing file /opt/airflow/dags/ML/ML1.py for tasks to queue
[2025-04-24T18:57:07.380+0000] {logging_mixin.py:190} INFO - [2025-04-24T18:57:07.379+0000] {dagbag.py:588} INFO - Filling up the DagBag from /opt/airflow/dags/ML/ML1.py
[2025-04-24T18:57:07.639+0000] {logging_mixin.py:190} INFO - [2025-04-24T18:57:07.636+0000] {dagbag.py:387} ERROR - Failed to import: /opt/airflow/dags/ML/ML1.py
Traceback (most recent call last):
  File "/home/airflow/.local/lib/python3.12/site-packages/airflow/models/dagbag.py", line 383, in parse
    loader.exec_module(new_module)
  File "<frozen importlib._bootstrap_external>", line 999, in exec_module
  File "<frozen importlib._bootstrap>", line 488, in _call_with_frames_removed
  File "/opt/airflow/dags/ML/ML1.py", line 17, in <module>
    with DAG(
         ^^^^
  File "/home/airflow/.local/lib/python3.12/site-packages/airflow/models/dag.py", line 593, in __init__
    validate_key(dag_id)
  File "/home/airflow/.local/lib/python3.12/site-packages/airflow/utils/helpers.py", line 57, in validate_key
    raise AirflowException(
airflow.exceptions.AirflowException: The key 'ML 1' has to be made of alphanumeric characters, dashes, dots and underscores exclusively
[2025-04-24T18:57:07.640+0000] {processor.py:927} WARNING - No viable dags retrieved from /opt/airflow/dags/ML/ML1.py
[2025-04-24T18:57:07.684+0000] {processor.py:208} INFO - Processing /opt/airflow/dags/ML/ML1.py took 0.314 seconds
[2025-04-24T18:57:38.067+0000] {processor.py:186} INFO - Started process (PID=2508) to work on /opt/airflow/dags/ML/ML1.py
[2025-04-24T18:57:38.068+0000] {processor.py:914} INFO - Processing file /opt/airflow/dags/ML/ML1.py for tasks to queue
[2025-04-24T18:57:38.070+0000] {logging_mixin.py:190} INFO - [2025-04-24T18:57:38.070+0000] {dagbag.py:588} INFO - Filling up the DagBag from /opt/airflow/dags/ML/ML1.py
[2025-04-24T18:57:38.324+0000] {logging_mixin.py:190} INFO - [2025-04-24T18:57:38.314+0000] {dagbag.py:387} ERROR - Failed to import: /opt/airflow/dags/ML/ML1.py
Traceback (most recent call last):
  File "/home/airflow/.local/lib/python3.12/site-packages/airflow/models/dagbag.py", line 383, in parse
    loader.exec_module(new_module)
  File "<frozen importlib._bootstrap_external>", line 999, in exec_module
  File "<frozen importlib._bootstrap>", line 488, in _call_with_frames_removed
  File "/opt/airflow/dags/ML/ML1.py", line 17, in <module>
    with DAG(
         ^^^^
  File "/home/airflow/.local/lib/python3.12/site-packages/airflow/models/dag.py", line 593, in __init__
    validate_key(dag_id)
  File "/home/airflow/.local/lib/python3.12/site-packages/airflow/utils/helpers.py", line 57, in validate_key
    raise AirflowException(
airflow.exceptions.AirflowException: The key 'ML 1' has to be made of alphanumeric characters, dashes, dots and underscores exclusively
[2025-04-24T18:57:38.325+0000] {processor.py:927} WARNING - No viable dags retrieved from /opt/airflow/dags/ML/ML1.py
[2025-04-24T18:57:38.387+0000] {processor.py:208} INFO - Processing /opt/airflow/dags/ML/ML1.py took 0.324 seconds
[2025-04-24T18:58:08.676+0000] {processor.py:186} INFO - Started process (PID=2537) to work on /opt/airflow/dags/ML/ML1.py
[2025-04-24T18:58:08.677+0000] {processor.py:914} INFO - Processing file /opt/airflow/dags/ML/ML1.py for tasks to queue
[2025-04-24T18:58:08.679+0000] {logging_mixin.py:190} INFO - [2025-04-24T18:58:08.679+0000] {dagbag.py:588} INFO - Filling up the DagBag from /opt/airflow/dags/ML/ML1.py
[2025-04-24T18:58:08.981+0000] {logging_mixin.py:190} INFO - [2025-04-24T18:58:08.971+0000] {dagbag.py:387} ERROR - Failed to import: /opt/airflow/dags/ML/ML1.py
Traceback (most recent call last):
  File "/home/airflow/.local/lib/python3.12/site-packages/airflow/models/dagbag.py", line 383, in parse
    loader.exec_module(new_module)
  File "<frozen importlib._bootstrap_external>", line 999, in exec_module
  File "<frozen importlib._bootstrap>", line 488, in _call_with_frames_removed
  File "/opt/airflow/dags/ML/ML1.py", line 17, in <module>
    with DAG(
         ^^^^
  File "/home/airflow/.local/lib/python3.12/site-packages/airflow/models/dag.py", line 593, in __init__
    validate_key(dag_id)
  File "/home/airflow/.local/lib/python3.12/site-packages/airflow/utils/helpers.py", line 57, in validate_key
    raise AirflowException(
airflow.exceptions.AirflowException: The key 'ML 1' has to be made of alphanumeric characters, dashes, dots and underscores exclusively
[2025-04-24T18:58:08.982+0000] {processor.py:927} WARNING - No viable dags retrieved from /opt/airflow/dags/ML/ML1.py
[2025-04-24T18:58:09.053+0000] {processor.py:208} INFO - Processing /opt/airflow/dags/ML/ML1.py took 0.382 seconds
[2025-04-24T18:58:39.675+0000] {processor.py:186} INFO - Started process (PID=2566) to work on /opt/airflow/dags/ML/ML1.py
[2025-04-24T18:58:39.676+0000] {processor.py:914} INFO - Processing file /opt/airflow/dags/ML/ML1.py for tasks to queue
[2025-04-24T18:58:39.678+0000] {logging_mixin.py:190} INFO - [2025-04-24T18:58:39.677+0000] {dagbag.py:588} INFO - Filling up the DagBag from /opt/airflow/dags/ML/ML1.py
[2025-04-24T18:58:39.930+0000] {logging_mixin.py:190} INFO - [2025-04-24T18:58:39.922+0000] {dagbag.py:387} ERROR - Failed to import: /opt/airflow/dags/ML/ML1.py
Traceback (most recent call last):
  File "/home/airflow/.local/lib/python3.12/site-packages/airflow/models/dagbag.py", line 383, in parse
    loader.exec_module(new_module)
  File "<frozen importlib._bootstrap_external>", line 999, in exec_module
  File "<frozen importlib._bootstrap>", line 488, in _call_with_frames_removed
  File "/opt/airflow/dags/ML/ML1.py", line 17, in <module>
    with DAG(
         ^^^^
  File "/home/airflow/.local/lib/python3.12/site-packages/airflow/models/dag.py", line 593, in __init__
    validate_key(dag_id)
  File "/home/airflow/.local/lib/python3.12/site-packages/airflow/utils/helpers.py", line 57, in validate_key
    raise AirflowException(
airflow.exceptions.AirflowException: The key 'ML 1' has to be made of alphanumeric characters, dashes, dots and underscores exclusively
[2025-04-24T18:58:39.931+0000] {processor.py:927} WARNING - No viable dags retrieved from /opt/airflow/dags/ML/ML1.py
[2025-04-24T18:58:39.991+0000] {processor.py:208} INFO - Processing /opt/airflow/dags/ML/ML1.py took 0.323 seconds
[2025-04-24T18:59:10.509+0000] {processor.py:186} INFO - Started process (PID=2595) to work on /opt/airflow/dags/ML/ML1.py
[2025-04-24T18:59:10.511+0000] {processor.py:914} INFO - Processing file /opt/airflow/dags/ML/ML1.py for tasks to queue
[2025-04-24T18:59:10.513+0000] {logging_mixin.py:190} INFO - [2025-04-24T18:59:10.513+0000] {dagbag.py:588} INFO - Filling up the DagBag from /opt/airflow/dags/ML/ML1.py
[2025-04-24T18:59:10.842+0000] {logging_mixin.py:190} INFO - [2025-04-24T18:59:10.833+0000] {dagbag.py:387} ERROR - Failed to import: /opt/airflow/dags/ML/ML1.py
Traceback (most recent call last):
  File "/home/airflow/.local/lib/python3.12/site-packages/airflow/models/dagbag.py", line 383, in parse
    loader.exec_module(new_module)
  File "<frozen importlib._bootstrap_external>", line 999, in exec_module
  File "<frozen importlib._bootstrap>", line 488, in _call_with_frames_removed
  File "/opt/airflow/dags/ML/ML1.py", line 17, in <module>
    with DAG(
         ^^^^
  File "/home/airflow/.local/lib/python3.12/site-packages/airflow/models/dag.py", line 593, in __init__
    validate_key(dag_id)
  File "/home/airflow/.local/lib/python3.12/site-packages/airflow/utils/helpers.py", line 57, in validate_key
    raise AirflowException(
airflow.exceptions.AirflowException: The key 'ML 1' has to be made of alphanumeric characters, dashes, dots and underscores exclusively
[2025-04-24T18:59:10.843+0000] {processor.py:927} WARNING - No viable dags retrieved from /opt/airflow/dags/ML/ML1.py
[2025-04-24T18:59:10.909+0000] {processor.py:208} INFO - Processing /opt/airflow/dags/ML/ML1.py took 0.406 seconds
[2025-04-24T18:59:41.050+0000] {processor.py:186} INFO - Started process (PID=2623) to work on /opt/airflow/dags/ML/ML1.py
[2025-04-24T18:59:41.051+0000] {processor.py:914} INFO - Processing file /opt/airflow/dags/ML/ML1.py for tasks to queue
[2025-04-24T18:59:41.054+0000] {logging_mixin.py:190} INFO - [2025-04-24T18:59:41.053+0000] {dagbag.py:588} INFO - Filling up the DagBag from /opt/airflow/dags/ML/ML1.py
[2025-04-24T18:59:41.358+0000] {logging_mixin.py:190} INFO - [2025-04-24T18:59:41.344+0000] {dagbag.py:387} ERROR - Failed to import: /opt/airflow/dags/ML/ML1.py
Traceback (most recent call last):
  File "/home/airflow/.local/lib/python3.12/site-packages/airflow/models/dagbag.py", line 383, in parse
    loader.exec_module(new_module)
  File "<frozen importlib._bootstrap_external>", line 999, in exec_module
  File "<frozen importlib._bootstrap>", line 488, in _call_with_frames_removed
  File "/opt/airflow/dags/ML/ML1.py", line 17, in <module>
    with DAG(
         ^^^^
  File "/home/airflow/.local/lib/python3.12/site-packages/airflow/models/dag.py", line 593, in __init__
    validate_key(dag_id)
  File "/home/airflow/.local/lib/python3.12/site-packages/airflow/utils/helpers.py", line 57, in validate_key
    raise AirflowException(
airflow.exceptions.AirflowException: The key 'ML 1' has to be made of alphanumeric characters, dashes, dots and underscores exclusively
[2025-04-24T18:59:41.360+0000] {processor.py:927} WARNING - No viable dags retrieved from /opt/airflow/dags/ML/ML1.py
[2025-04-24T18:59:41.443+0000] {processor.py:208} INFO - Processing /opt/airflow/dags/ML/ML1.py took 0.400 seconds
[2025-04-24T19:00:11.987+0000] {processor.py:186} INFO - Started process (PID=2652) to work on /opt/airflow/dags/ML/ML1.py
[2025-04-24T19:00:11.989+0000] {processor.py:914} INFO - Processing file /opt/airflow/dags/ML/ML1.py for tasks to queue
[2025-04-24T19:00:11.990+0000] {logging_mixin.py:190} INFO - [2025-04-24T19:00:11.990+0000] {dagbag.py:588} INFO - Filling up the DagBag from /opt/airflow/dags/ML/ML1.py
[2025-04-24T19:00:12.239+0000] {logging_mixin.py:190} INFO - [2025-04-24T19:00:12.233+0000] {dagbag.py:387} ERROR - Failed to import: /opt/airflow/dags/ML/ML1.py
Traceback (most recent call last):
  File "/home/airflow/.local/lib/python3.12/site-packages/airflow/models/dagbag.py", line 383, in parse
    loader.exec_module(new_module)
  File "<frozen importlib._bootstrap_external>", line 999, in exec_module
  File "<frozen importlib._bootstrap>", line 488, in _call_with_frames_removed
  File "/opt/airflow/dags/ML/ML1.py", line 17, in <module>
    with DAG(
         ^^^^
  File "/home/airflow/.local/lib/python3.12/site-packages/airflow/models/dag.py", line 593, in __init__
    validate_key(dag_id)
  File "/home/airflow/.local/lib/python3.12/site-packages/airflow/utils/helpers.py", line 57, in validate_key
    raise AirflowException(
airflow.exceptions.AirflowException: The key 'ML 1' has to be made of alphanumeric characters, dashes, dots and underscores exclusively
[2025-04-24T19:00:12.240+0000] {processor.py:927} WARNING - No viable dags retrieved from /opt/airflow/dags/ML/ML1.py
[2025-04-24T19:00:12.316+0000] {processor.py:208} INFO - Processing /opt/airflow/dags/ML/ML1.py took 0.334 seconds
[2025-04-24T19:00:42.434+0000] {processor.py:186} INFO - Started process (PID=2681) to work on /opt/airflow/dags/ML/ML1.py
[2025-04-24T19:00:42.435+0000] {processor.py:914} INFO - Processing file /opt/airflow/dags/ML/ML1.py for tasks to queue
[2025-04-24T19:00:42.439+0000] {logging_mixin.py:190} INFO - [2025-04-24T19:00:42.439+0000] {dagbag.py:588} INFO - Filling up the DagBag from /opt/airflow/dags/ML/ML1.py
[2025-04-24T19:00:42.718+0000] {logging_mixin.py:190} INFO - [2025-04-24T19:00:42.711+0000] {dagbag.py:387} ERROR - Failed to import: /opt/airflow/dags/ML/ML1.py
Traceback (most recent call last):
  File "/home/airflow/.local/lib/python3.12/site-packages/airflow/models/dagbag.py", line 383, in parse
    loader.exec_module(new_module)
  File "<frozen importlib._bootstrap_external>", line 999, in exec_module
  File "<frozen importlib._bootstrap>", line 488, in _call_with_frames_removed
  File "/opt/airflow/dags/ML/ML1.py", line 17, in <module>
    with DAG(
         ^^^^
  File "/home/airflow/.local/lib/python3.12/site-packages/airflow/models/dag.py", line 593, in __init__
    validate_key(dag_id)
  File "/home/airflow/.local/lib/python3.12/site-packages/airflow/utils/helpers.py", line 57, in validate_key
    raise AirflowException(
airflow.exceptions.AirflowException: The key 'ML 1' has to be made of alphanumeric characters, dashes, dots and underscores exclusively
[2025-04-24T19:00:42.719+0000] {processor.py:927} WARNING - No viable dags retrieved from /opt/airflow/dags/ML/ML1.py
[2025-04-24T19:00:42.779+0000] {processor.py:208} INFO - Processing /opt/airflow/dags/ML/ML1.py took 0.351 seconds
[2025-04-24T19:01:13.604+0000] {processor.py:186} INFO - Started process (PID=2710) to work on /opt/airflow/dags/ML/ML1.py
[2025-04-24T19:01:13.605+0000] {processor.py:914} INFO - Processing file /opt/airflow/dags/ML/ML1.py for tasks to queue
[2025-04-24T19:01:13.607+0000] {logging_mixin.py:190} INFO - [2025-04-24T19:01:13.607+0000] {dagbag.py:588} INFO - Filling up the DagBag from /opt/airflow/dags/ML/ML1.py
[2025-04-24T19:01:13.901+0000] {logging_mixin.py:190} INFO - [2025-04-24T19:01:13.889+0000] {dagbag.py:387} ERROR - Failed to import: /opt/airflow/dags/ML/ML1.py
Traceback (most recent call last):
  File "/home/airflow/.local/lib/python3.12/site-packages/airflow/models/dagbag.py", line 383, in parse
    loader.exec_module(new_module)
  File "<frozen importlib._bootstrap_external>", line 999, in exec_module
  File "<frozen importlib._bootstrap>", line 488, in _call_with_frames_removed
  File "/opt/airflow/dags/ML/ML1.py", line 17, in <module>
    with DAG(
         ^^^^
  File "/home/airflow/.local/lib/python3.12/site-packages/airflow/models/dag.py", line 593, in __init__
    validate_key(dag_id)
  File "/home/airflow/.local/lib/python3.12/site-packages/airflow/utils/helpers.py", line 57, in validate_key
    raise AirflowException(
airflow.exceptions.AirflowException: The key 'ML 1' has to be made of alphanumeric characters, dashes, dots and underscores exclusively
[2025-04-24T19:01:13.902+0000] {processor.py:927} WARNING - No viable dags retrieved from /opt/airflow/dags/ML/ML1.py
[2025-04-24T19:01:13.980+0000] {processor.py:208} INFO - Processing /opt/airflow/dags/ML/ML1.py took 0.382 seconds
[2025-04-24T19:01:44.273+0000] {processor.py:186} INFO - Started process (PID=2739) to work on /opt/airflow/dags/ML/ML1.py
[2025-04-24T19:01:44.274+0000] {processor.py:914} INFO - Processing file /opt/airflow/dags/ML/ML1.py for tasks to queue
[2025-04-24T19:01:44.276+0000] {logging_mixin.py:190} INFO - [2025-04-24T19:01:44.276+0000] {dagbag.py:588} INFO - Filling up the DagBag from /opt/airflow/dags/ML/ML1.py
[2025-04-24T19:01:44.542+0000] {logging_mixin.py:190} INFO - [2025-04-24T19:01:44.530+0000] {dagbag.py:387} ERROR - Failed to import: /opt/airflow/dags/ML/ML1.py
Traceback (most recent call last):
  File "/home/airflow/.local/lib/python3.12/site-packages/airflow/models/dagbag.py", line 383, in parse
    loader.exec_module(new_module)
  File "<frozen importlib._bootstrap_external>", line 999, in exec_module
  File "<frozen importlib._bootstrap>", line 488, in _call_with_frames_removed
  File "/opt/airflow/dags/ML/ML1.py", line 17, in <module>
    with DAG(
         ^^^^
  File "/home/airflow/.local/lib/python3.12/site-packages/airflow/models/dag.py", line 593, in __init__
    validate_key(dag_id)
  File "/home/airflow/.local/lib/python3.12/site-packages/airflow/utils/helpers.py", line 57, in validate_key
    raise AirflowException(
airflow.exceptions.AirflowException: The key 'ML 1' has to be made of alphanumeric characters, dashes, dots and underscores exclusively
[2025-04-24T19:01:44.543+0000] {processor.py:927} WARNING - No viable dags retrieved from /opt/airflow/dags/ML/ML1.py
[2025-04-24T19:01:44.595+0000] {processor.py:208} INFO - Processing /opt/airflow/dags/ML/ML1.py took 0.327 seconds
[2025-04-24T19:02:14.869+0000] {processor.py:186} INFO - Started process (PID=2768) to work on /opt/airflow/dags/ML/ML1.py
[2025-04-24T19:02:14.870+0000] {processor.py:914} INFO - Processing file /opt/airflow/dags/ML/ML1.py for tasks to queue
[2025-04-24T19:02:14.872+0000] {logging_mixin.py:190} INFO - [2025-04-24T19:02:14.872+0000] {dagbag.py:588} INFO - Filling up the DagBag from /opt/airflow/dags/ML/ML1.py
[2025-04-24T19:02:15.138+0000] {logging_mixin.py:190} INFO - [2025-04-24T19:02:15.125+0000] {dagbag.py:387} ERROR - Failed to import: /opt/airflow/dags/ML/ML1.py
Traceback (most recent call last):
  File "/home/airflow/.local/lib/python3.12/site-packages/airflow/models/dagbag.py", line 383, in parse
    loader.exec_module(new_module)
  File "<frozen importlib._bootstrap_external>", line 999, in exec_module
  File "<frozen importlib._bootstrap>", line 488, in _call_with_frames_removed
  File "/opt/airflow/dags/ML/ML1.py", line 17, in <module>
    with DAG(
         ^^^^
  File "/home/airflow/.local/lib/python3.12/site-packages/airflow/models/dag.py", line 593, in __init__
    validate_key(dag_id)
  File "/home/airflow/.local/lib/python3.12/site-packages/airflow/utils/helpers.py", line 57, in validate_key
    raise AirflowException(
airflow.exceptions.AirflowException: The key 'ML 1' has to be made of alphanumeric characters, dashes, dots and underscores exclusively
[2025-04-24T19:02:15.138+0000] {processor.py:927} WARNING - No viable dags retrieved from /opt/airflow/dags/ML/ML1.py
[2025-04-24T19:02:15.188+0000] {processor.py:208} INFO - Processing /opt/airflow/dags/ML/ML1.py took 0.325 seconds
[2025-04-24T19:02:45.397+0000] {processor.py:186} INFO - Started process (PID=2797) to work on /opt/airflow/dags/ML/ML1.py
[2025-04-24T19:02:45.398+0000] {processor.py:914} INFO - Processing file /opt/airflow/dags/ML/ML1.py for tasks to queue
[2025-04-24T19:02:45.401+0000] {logging_mixin.py:190} INFO - [2025-04-24T19:02:45.401+0000] {dagbag.py:588} INFO - Filling up the DagBag from /opt/airflow/dags/ML/ML1.py
[2025-04-24T19:02:45.657+0000] {logging_mixin.py:190} INFO - [2025-04-24T19:02:45.648+0000] {dagbag.py:387} ERROR - Failed to import: /opt/airflow/dags/ML/ML1.py
Traceback (most recent call last):
  File "/home/airflow/.local/lib/python3.12/site-packages/airflow/models/dagbag.py", line 383, in parse
    loader.exec_module(new_module)
  File "<frozen importlib._bootstrap_external>", line 999, in exec_module
  File "<frozen importlib._bootstrap>", line 488, in _call_with_frames_removed
  File "/opt/airflow/dags/ML/ML1.py", line 17, in <module>
    with DAG(
         ^^^^
  File "/home/airflow/.local/lib/python3.12/site-packages/airflow/models/dag.py", line 593, in __init__
    validate_key(dag_id)
  File "/home/airflow/.local/lib/python3.12/site-packages/airflow/utils/helpers.py", line 57, in validate_key
    raise AirflowException(
airflow.exceptions.AirflowException: The key 'ML 1' has to be made of alphanumeric characters, dashes, dots and underscores exclusively
[2025-04-24T19:02:45.658+0000] {processor.py:927} WARNING - No viable dags retrieved from /opt/airflow/dags/ML/ML1.py
[2025-04-24T19:02:45.778+0000] {processor.py:208} INFO - Processing /opt/airflow/dags/ML/ML1.py took 0.385 seconds
[2025-04-24T19:03:16.053+0000] {processor.py:186} INFO - Started process (PID=2826) to work on /opt/airflow/dags/ML/ML1.py
[2025-04-24T19:03:16.054+0000] {processor.py:914} INFO - Processing file /opt/airflow/dags/ML/ML1.py for tasks to queue
[2025-04-24T19:03:16.057+0000] {logging_mixin.py:190} INFO - [2025-04-24T19:03:16.056+0000] {dagbag.py:588} INFO - Filling up the DagBag from /opt/airflow/dags/ML/ML1.py
[2025-04-24T19:03:16.313+0000] {logging_mixin.py:190} INFO - [2025-04-24T19:03:16.306+0000] {dagbag.py:387} ERROR - Failed to import: /opt/airflow/dags/ML/ML1.py
Traceback (most recent call last):
  File "/home/airflow/.local/lib/python3.12/site-packages/airflow/models/dagbag.py", line 383, in parse
    loader.exec_module(new_module)
  File "<frozen importlib._bootstrap_external>", line 999, in exec_module
  File "<frozen importlib._bootstrap>", line 488, in _call_with_frames_removed
  File "/opt/airflow/dags/ML/ML1.py", line 17, in <module>
    with DAG(
         ^^^^
  File "/home/airflow/.local/lib/python3.12/site-packages/airflow/models/dag.py", line 593, in __init__
    validate_key(dag_id)
  File "/home/airflow/.local/lib/python3.12/site-packages/airflow/utils/helpers.py", line 57, in validate_key
    raise AirflowException(
airflow.exceptions.AirflowException: The key 'ML 1' has to be made of alphanumeric characters, dashes, dots and underscores exclusively
[2025-04-24T19:03:16.315+0000] {processor.py:927} WARNING - No viable dags retrieved from /opt/airflow/dags/ML/ML1.py
[2025-04-24T19:03:16.394+0000] {processor.py:208} INFO - Processing /opt/airflow/dags/ML/ML1.py took 0.346 seconds
[2025-04-24T19:03:46.707+0000] {processor.py:186} INFO - Started process (PID=2855) to work on /opt/airflow/dags/ML/ML1.py
[2025-04-24T19:03:46.708+0000] {processor.py:914} INFO - Processing file /opt/airflow/dags/ML/ML1.py for tasks to queue
[2025-04-24T19:03:46.710+0000] {logging_mixin.py:190} INFO - [2025-04-24T19:03:46.710+0000] {dagbag.py:588} INFO - Filling up the DagBag from /opt/airflow/dags/ML/ML1.py
[2025-04-24T19:03:46.947+0000] {logging_mixin.py:190} INFO - [2025-04-24T19:03:46.939+0000] {dagbag.py:387} ERROR - Failed to import: /opt/airflow/dags/ML/ML1.py
Traceback (most recent call last):
  File "/home/airflow/.local/lib/python3.12/site-packages/airflow/models/dagbag.py", line 383, in parse
    loader.exec_module(new_module)
  File "<frozen importlib._bootstrap_external>", line 999, in exec_module
  File "<frozen importlib._bootstrap>", line 488, in _call_with_frames_removed
  File "/opt/airflow/dags/ML/ML1.py", line 17, in <module>
    with DAG(
         ^^^^
  File "/home/airflow/.local/lib/python3.12/site-packages/airflow/models/dag.py", line 593, in __init__
    validate_key(dag_id)
  File "/home/airflow/.local/lib/python3.12/site-packages/airflow/utils/helpers.py", line 57, in validate_key
    raise AirflowException(
airflow.exceptions.AirflowException: The key 'ML 1' has to be made of alphanumeric characters, dashes, dots and underscores exclusively
[2025-04-24T19:03:46.949+0000] {processor.py:927} WARNING - No viable dags retrieved from /opt/airflow/dags/ML/ML1.py
[2025-04-24T19:03:47.023+0000] {processor.py:208} INFO - Processing /opt/airflow/dags/ML/ML1.py took 0.322 seconds
[2025-04-24T19:04:17.187+0000] {processor.py:186} INFO - Started process (PID=2884) to work on /opt/airflow/dags/ML/ML1.py
[2025-04-24T19:04:17.189+0000] {processor.py:914} INFO - Processing file /opt/airflow/dags/ML/ML1.py for tasks to queue
[2025-04-24T19:04:17.192+0000] {logging_mixin.py:190} INFO - [2025-04-24T19:04:17.191+0000] {dagbag.py:588} INFO - Filling up the DagBag from /opt/airflow/dags/ML/ML1.py
[2025-04-24T19:04:17.459+0000] {logging_mixin.py:190} INFO - [2025-04-24T19:04:17.449+0000] {dagbag.py:387} ERROR - Failed to import: /opt/airflow/dags/ML/ML1.py
Traceback (most recent call last):
  File "/home/airflow/.local/lib/python3.12/site-packages/airflow/models/dagbag.py", line 383, in parse
    loader.exec_module(new_module)
  File "<frozen importlib._bootstrap_external>", line 999, in exec_module
  File "<frozen importlib._bootstrap>", line 488, in _call_with_frames_removed
  File "/opt/airflow/dags/ML/ML1.py", line 17, in <module>
    with DAG(
         ^^^^
  File "/home/airflow/.local/lib/python3.12/site-packages/airflow/models/dag.py", line 593, in __init__
    validate_key(dag_id)
  File "/home/airflow/.local/lib/python3.12/site-packages/airflow/utils/helpers.py", line 57, in validate_key
    raise AirflowException(
airflow.exceptions.AirflowException: The key 'ML 1' has to be made of alphanumeric characters, dashes, dots and underscores exclusively
[2025-04-24T19:04:17.460+0000] {processor.py:927} WARNING - No viable dags retrieved from /opt/airflow/dags/ML/ML1.py
[2025-04-24T19:04:17.532+0000] {processor.py:208} INFO - Processing /opt/airflow/dags/ML/ML1.py took 0.353 seconds
[2025-04-24T19:04:47.955+0000] {processor.py:186} INFO - Started process (PID=2914) to work on /opt/airflow/dags/ML/ML1.py
[2025-04-24T19:04:47.956+0000] {processor.py:914} INFO - Processing file /opt/airflow/dags/ML/ML1.py for tasks to queue
[2025-04-24T19:04:47.958+0000] {logging_mixin.py:190} INFO - [2025-04-24T19:04:47.958+0000] {dagbag.py:588} INFO - Filling up the DagBag from /opt/airflow/dags/ML/ML1.py
[2025-04-24T19:04:48.206+0000] {logging_mixin.py:190} INFO - [2025-04-24T19:04:48.199+0000] {dagbag.py:387} ERROR - Failed to import: /opt/airflow/dags/ML/ML1.py
Traceback (most recent call last):
  File "/home/airflow/.local/lib/python3.12/site-packages/airflow/models/dagbag.py", line 383, in parse
    loader.exec_module(new_module)
  File "<frozen importlib._bootstrap_external>", line 999, in exec_module
  File "<frozen importlib._bootstrap>", line 488, in _call_with_frames_removed
  File "/opt/airflow/dags/ML/ML1.py", line 17, in <module>
    with DAG(
         ^^^^
  File "/home/airflow/.local/lib/python3.12/site-packages/airflow/models/dag.py", line 593, in __init__
    validate_key(dag_id)
  File "/home/airflow/.local/lib/python3.12/site-packages/airflow/utils/helpers.py", line 57, in validate_key
    raise AirflowException(
airflow.exceptions.AirflowException: The key 'ML 1' has to be made of alphanumeric characters, dashes, dots and underscores exclusively
[2025-04-24T19:04:48.207+0000] {processor.py:927} WARNING - No viable dags retrieved from /opt/airflow/dags/ML/ML1.py
[2025-04-24T19:04:48.272+0000] {processor.py:208} INFO - Processing /opt/airflow/dags/ML/ML1.py took 0.324 seconds
[2025-04-24T19:05:18.908+0000] {processor.py:186} INFO - Started process (PID=2942) to work on /opt/airflow/dags/ML/ML1.py
[2025-04-24T19:05:18.909+0000] {processor.py:914} INFO - Processing file /opt/airflow/dags/ML/ML1.py for tasks to queue
[2025-04-24T19:05:18.911+0000] {logging_mixin.py:190} INFO - [2025-04-24T19:05:18.911+0000] {dagbag.py:588} INFO - Filling up the DagBag from /opt/airflow/dags/ML/ML1.py
[2025-04-24T19:05:19.150+0000] {logging_mixin.py:190} INFO - [2025-04-24T19:05:19.143+0000] {dagbag.py:387} ERROR - Failed to import: /opt/airflow/dags/ML/ML1.py
Traceback (most recent call last):
  File "/home/airflow/.local/lib/python3.12/site-packages/airflow/models/dagbag.py", line 383, in parse
    loader.exec_module(new_module)
  File "<frozen importlib._bootstrap_external>", line 999, in exec_module
  File "<frozen importlib._bootstrap>", line 488, in _call_with_frames_removed
  File "/opt/airflow/dags/ML/ML1.py", line 17, in <module>
    with DAG(
         ^^^^
  File "/home/airflow/.local/lib/python3.12/site-packages/airflow/models/dag.py", line 593, in __init__
    validate_key(dag_id)
  File "/home/airflow/.local/lib/python3.12/site-packages/airflow/utils/helpers.py", line 57, in validate_key
    raise AirflowException(
airflow.exceptions.AirflowException: The key 'ML 1' has to be made of alphanumeric characters, dashes, dots and underscores exclusively
[2025-04-24T19:05:19.151+0000] {processor.py:927} WARNING - No viable dags retrieved from /opt/airflow/dags/ML/ML1.py
[2025-04-24T19:05:19.212+0000] {processor.py:208} INFO - Processing /opt/airflow/dags/ML/ML1.py took 0.309 seconds
[2025-04-24T19:05:50.059+0000] {processor.py:186} INFO - Started process (PID=2972) to work on /opt/airflow/dags/ML/ML1.py
[2025-04-24T19:05:50.060+0000] {processor.py:914} INFO - Processing file /opt/airflow/dags/ML/ML1.py for tasks to queue
[2025-04-24T19:05:50.062+0000] {logging_mixin.py:190} INFO - [2025-04-24T19:05:50.062+0000] {dagbag.py:588} INFO - Filling up the DagBag from /opt/airflow/dags/ML/ML1.py
[2025-04-24T19:05:50.319+0000] {logging_mixin.py:190} INFO - [2025-04-24T19:05:50.293+0000] {dagbag.py:387} ERROR - Failed to import: /opt/airflow/dags/ML/ML1.py
Traceback (most recent call last):
  File "/home/airflow/.local/lib/python3.12/site-packages/airflow/models/dagbag.py", line 383, in parse
    loader.exec_module(new_module)
  File "<frozen importlib._bootstrap_external>", line 999, in exec_module
  File "<frozen importlib._bootstrap>", line 488, in _call_with_frames_removed
  File "/opt/airflow/dags/ML/ML1.py", line 17, in <module>
    with DAG(
         ^^^^
  File "/home/airflow/.local/lib/python3.12/site-packages/airflow/models/dag.py", line 593, in __init__
    validate_key(dag_id)
  File "/home/airflow/.local/lib/python3.12/site-packages/airflow/utils/helpers.py", line 57, in validate_key
    raise AirflowException(
airflow.exceptions.AirflowException: The key 'ML 1' has to be made of alphanumeric characters, dashes, dots and underscores exclusively
[2025-04-24T19:05:50.320+0000] {processor.py:927} WARNING - No viable dags retrieved from /opt/airflow/dags/ML/ML1.py
[2025-04-24T19:05:50.384+0000] {processor.py:208} INFO - Processing /opt/airflow/dags/ML/ML1.py took 0.329 seconds
[2025-04-24T19:06:20.494+0000] {processor.py:186} INFO - Started process (PID=3001) to work on /opt/airflow/dags/ML/ML1.py
[2025-04-24T19:06:20.496+0000] {processor.py:914} INFO - Processing file /opt/airflow/dags/ML/ML1.py for tasks to queue
[2025-04-24T19:06:20.498+0000] {logging_mixin.py:190} INFO - [2025-04-24T19:06:20.498+0000] {dagbag.py:588} INFO - Filling up the DagBag from /opt/airflow/dags/ML/ML1.py
[2025-04-24T19:06:20.742+0000] {logging_mixin.py:190} INFO - [2025-04-24T19:06:20.734+0000] {dagbag.py:387} ERROR - Failed to import: /opt/airflow/dags/ML/ML1.py
Traceback (most recent call last):
  File "/home/airflow/.local/lib/python3.12/site-packages/airflow/models/dagbag.py", line 383, in parse
    loader.exec_module(new_module)
  File "<frozen importlib._bootstrap_external>", line 999, in exec_module
  File "<frozen importlib._bootstrap>", line 488, in _call_with_frames_removed
  File "/opt/airflow/dags/ML/ML1.py", line 17, in <module>
    with DAG(
         ^^^^
  File "/home/airflow/.local/lib/python3.12/site-packages/airflow/models/dag.py", line 593, in __init__
    validate_key(dag_id)
  File "/home/airflow/.local/lib/python3.12/site-packages/airflow/utils/helpers.py", line 57, in validate_key
    raise AirflowException(
airflow.exceptions.AirflowException: The key 'ML 1' has to be made of alphanumeric characters, dashes, dots and underscores exclusively
[2025-04-24T19:06:20.743+0000] {processor.py:927} WARNING - No viable dags retrieved from /opt/airflow/dags/ML/ML1.py
[2025-04-24T19:06:20.804+0000] {processor.py:208} INFO - Processing /opt/airflow/dags/ML/ML1.py took 0.317 seconds
[2025-04-24T19:06:51.519+0000] {processor.py:186} INFO - Started process (PID=3030) to work on /opt/airflow/dags/ML/ML1.py
[2025-04-24T19:06:51.520+0000] {processor.py:914} INFO - Processing file /opt/airflow/dags/ML/ML1.py for tasks to queue
[2025-04-24T19:06:51.522+0000] {logging_mixin.py:190} INFO - [2025-04-24T19:06:51.522+0000] {dagbag.py:588} INFO - Filling up the DagBag from /opt/airflow/dags/ML/ML1.py
[2025-04-24T19:06:51.778+0000] {logging_mixin.py:190} INFO - [2025-04-24T19:06:51.772+0000] {dagbag.py:387} ERROR - Failed to import: /opt/airflow/dags/ML/ML1.py
Traceback (most recent call last):
  File "/home/airflow/.local/lib/python3.12/site-packages/airflow/models/dagbag.py", line 383, in parse
    loader.exec_module(new_module)
  File "<frozen importlib._bootstrap_external>", line 999, in exec_module
  File "<frozen importlib._bootstrap>", line 488, in _call_with_frames_removed
  File "/opt/airflow/dags/ML/ML1.py", line 17, in <module>
    with DAG(
         ^^^^
  File "/home/airflow/.local/lib/python3.12/site-packages/airflow/models/dag.py", line 593, in __init__
    validate_key(dag_id)
  File "/home/airflow/.local/lib/python3.12/site-packages/airflow/utils/helpers.py", line 57, in validate_key
    raise AirflowException(
airflow.exceptions.AirflowException: The key 'ML 1' has to be made of alphanumeric characters, dashes, dots and underscores exclusively
[2025-04-24T19:06:51.779+0000] {processor.py:927} WARNING - No viable dags retrieved from /opt/airflow/dags/ML/ML1.py
[2025-04-24T19:06:51.828+0000] {processor.py:208} INFO - Processing /opt/airflow/dags/ML/ML1.py took 0.314 seconds
[2025-04-24T19:07:22.403+0000] {processor.py:186} INFO - Started process (PID=3059) to work on /opt/airflow/dags/ML/ML1.py
[2025-04-24T19:07:22.405+0000] {processor.py:914} INFO - Processing file /opt/airflow/dags/ML/ML1.py for tasks to queue
[2025-04-24T19:07:22.407+0000] {logging_mixin.py:190} INFO - [2025-04-24T19:07:22.407+0000] {dagbag.py:588} INFO - Filling up the DagBag from /opt/airflow/dags/ML/ML1.py
[2025-04-24T19:07:22.662+0000] {logging_mixin.py:190} INFO - [2025-04-24T19:07:22.651+0000] {dagbag.py:387} ERROR - Failed to import: /opt/airflow/dags/ML/ML1.py
Traceback (most recent call last):
  File "/home/airflow/.local/lib/python3.12/site-packages/airflow/models/dagbag.py", line 383, in parse
    loader.exec_module(new_module)
  File "<frozen importlib._bootstrap_external>", line 999, in exec_module
  File "<frozen importlib._bootstrap>", line 488, in _call_with_frames_removed
  File "/opt/airflow/dags/ML/ML1.py", line 17, in <module>
    with DAG(
         ^^^^
  File "/home/airflow/.local/lib/python3.12/site-packages/airflow/models/dag.py", line 593, in __init__
    validate_key(dag_id)
  File "/home/airflow/.local/lib/python3.12/site-packages/airflow/utils/helpers.py", line 57, in validate_key
    raise AirflowException(
airflow.exceptions.AirflowException: The key 'ML 1' has to be made of alphanumeric characters, dashes, dots and underscores exclusively
[2025-04-24T19:07:22.663+0000] {processor.py:927} WARNING - No viable dags retrieved from /opt/airflow/dags/ML/ML1.py
[2025-04-24T19:07:22.726+0000] {processor.py:208} INFO - Processing /opt/airflow/dags/ML/ML1.py took 0.328 seconds
[2025-04-24T19:07:53.028+0000] {processor.py:186} INFO - Started process (PID=3088) to work on /opt/airflow/dags/ML/ML1.py
[2025-04-24T19:07:53.029+0000] {processor.py:914} INFO - Processing file /opt/airflow/dags/ML/ML1.py for tasks to queue
[2025-04-24T19:07:53.031+0000] {logging_mixin.py:190} INFO - [2025-04-24T19:07:53.031+0000] {dagbag.py:588} INFO - Filling up the DagBag from /opt/airflow/dags/ML/ML1.py
[2025-04-24T19:07:53.324+0000] {logging_mixin.py:190} INFO - [2025-04-24T19:07:53.316+0000] {dagbag.py:387} ERROR - Failed to import: /opt/airflow/dags/ML/ML1.py
Traceback (most recent call last):
  File "/home/airflow/.local/lib/python3.12/site-packages/airflow/models/dagbag.py", line 383, in parse
    loader.exec_module(new_module)
  File "<frozen importlib._bootstrap_external>", line 999, in exec_module
  File "<frozen importlib._bootstrap>", line 488, in _call_with_frames_removed
  File "/opt/airflow/dags/ML/ML1.py", line 17, in <module>
    with DAG(
         ^^^^
  File "/home/airflow/.local/lib/python3.12/site-packages/airflow/models/dag.py", line 593, in __init__
    validate_key(dag_id)
  File "/home/airflow/.local/lib/python3.12/site-packages/airflow/utils/helpers.py", line 57, in validate_key
    raise AirflowException(
airflow.exceptions.AirflowException: The key 'ML 1' has to be made of alphanumeric characters, dashes, dots and underscores exclusively
[2025-04-24T19:07:53.325+0000] {processor.py:927} WARNING - No viable dags retrieved from /opt/airflow/dags/ML/ML1.py
[2025-04-24T19:07:53.399+0000] {processor.py:208} INFO - Processing /opt/airflow/dags/ML/ML1.py took 0.378 seconds
[2025-04-24T19:08:23.604+0000] {processor.py:186} INFO - Started process (PID=3118) to work on /opt/airflow/dags/ML/ML1.py
[2025-04-24T19:08:23.606+0000] {processor.py:914} INFO - Processing file /opt/airflow/dags/ML/ML1.py for tasks to queue
[2025-04-24T19:08:23.608+0000] {logging_mixin.py:190} INFO - [2025-04-24T19:08:23.608+0000] {dagbag.py:588} INFO - Filling up the DagBag from /opt/airflow/dags/ML/ML1.py
[2025-04-24T19:08:23.858+0000] {logging_mixin.py:190} INFO - [2025-04-24T19:08:23.845+0000] {dagbag.py:387} ERROR - Failed to import: /opt/airflow/dags/ML/ML1.py
Traceback (most recent call last):
  File "/home/airflow/.local/lib/python3.12/site-packages/airflow/models/dagbag.py", line 383, in parse
    loader.exec_module(new_module)
  File "<frozen importlib._bootstrap_external>", line 999, in exec_module
  File "<frozen importlib._bootstrap>", line 488, in _call_with_frames_removed
  File "/opt/airflow/dags/ML/ML1.py", line 17, in <module>
    with DAG(
         ^^^^
  File "/home/airflow/.local/lib/python3.12/site-packages/airflow/models/dag.py", line 593, in __init__
    validate_key(dag_id)
  File "/home/airflow/.local/lib/python3.12/site-packages/airflow/utils/helpers.py", line 57, in validate_key
    raise AirflowException(
airflow.exceptions.AirflowException: The key 'ML 1' has to be made of alphanumeric characters, dashes, dots and underscores exclusively
[2025-04-24T19:08:23.858+0000] {processor.py:927} WARNING - No viable dags retrieved from /opt/airflow/dags/ML/ML1.py
[2025-04-24T19:08:23.924+0000] {processor.py:208} INFO - Processing /opt/airflow/dags/ML/ML1.py took 0.324 seconds
[2025-04-24T19:08:54.028+0000] {processor.py:186} INFO - Started process (PID=3147) to work on /opt/airflow/dags/ML/ML1.py
[2025-04-24T19:08:54.030+0000] {processor.py:914} INFO - Processing file /opt/airflow/dags/ML/ML1.py for tasks to queue
[2025-04-24T19:08:54.032+0000] {logging_mixin.py:190} INFO - [2025-04-24T19:08:54.032+0000] {dagbag.py:588} INFO - Filling up the DagBag from /opt/airflow/dags/ML/ML1.py
[2025-04-24T19:08:54.284+0000] {logging_mixin.py:190} INFO - [2025-04-24T19:08:54.275+0000] {dagbag.py:387} ERROR - Failed to import: /opt/airflow/dags/ML/ML1.py
Traceback (most recent call last):
  File "/home/airflow/.local/lib/python3.12/site-packages/airflow/models/dagbag.py", line 383, in parse
    loader.exec_module(new_module)
  File "<frozen importlib._bootstrap_external>", line 999, in exec_module
  File "<frozen importlib._bootstrap>", line 488, in _call_with_frames_removed
  File "/opt/airflow/dags/ML/ML1.py", line 17, in <module>
    with DAG(
         ^^^^
  File "/home/airflow/.local/lib/python3.12/site-packages/airflow/models/dag.py", line 593, in __init__
    validate_key(dag_id)
  File "/home/airflow/.local/lib/python3.12/site-packages/airflow/utils/helpers.py", line 57, in validate_key
    raise AirflowException(
airflow.exceptions.AirflowException: The key 'ML 1' has to be made of alphanumeric characters, dashes, dots and underscores exclusively
[2025-04-24T19:08:54.285+0000] {processor.py:927} WARNING - No viable dags retrieved from /opt/airflow/dags/ML/ML1.py
[2025-04-24T19:08:54.353+0000] {processor.py:208} INFO - Processing /opt/airflow/dags/ML/ML1.py took 0.329 seconds
[2025-04-24T19:09:24.704+0000] {processor.py:186} INFO - Started process (PID=3175) to work on /opt/airflow/dags/ML/ML1.py
[2025-04-24T19:09:24.706+0000] {processor.py:914} INFO - Processing file /opt/airflow/dags/ML/ML1.py for tasks to queue
[2025-04-24T19:09:24.708+0000] {logging_mixin.py:190} INFO - [2025-04-24T19:09:24.707+0000] {dagbag.py:588} INFO - Filling up the DagBag from /opt/airflow/dags/ML/ML1.py
[2025-04-24T19:09:24.982+0000] {logging_mixin.py:190} INFO - [2025-04-24T19:09:24.975+0000] {dagbag.py:387} ERROR - Failed to import: /opt/airflow/dags/ML/ML1.py
Traceback (most recent call last):
  File "/home/airflow/.local/lib/python3.12/site-packages/airflow/models/dagbag.py", line 383, in parse
    loader.exec_module(new_module)
  File "<frozen importlib._bootstrap_external>", line 999, in exec_module
  File "<frozen importlib._bootstrap>", line 488, in _call_with_frames_removed
  File "/opt/airflow/dags/ML/ML1.py", line 17, in <module>
    with DAG(
         ^^^^
  File "/home/airflow/.local/lib/python3.12/site-packages/airflow/models/dag.py", line 593, in __init__
    validate_key(dag_id)
  File "/home/airflow/.local/lib/python3.12/site-packages/airflow/utils/helpers.py", line 57, in validate_key
    raise AirflowException(
airflow.exceptions.AirflowException: The key 'ML 1' has to be made of alphanumeric characters, dashes, dots and underscores exclusively
[2025-04-24T19:09:24.983+0000] {processor.py:927} WARNING - No viable dags retrieved from /opt/airflow/dags/ML/ML1.py
[2025-04-24T19:09:25.040+0000] {processor.py:208} INFO - Processing /opt/airflow/dags/ML/ML1.py took 0.341 seconds
[2025-04-24T19:09:55.338+0000] {processor.py:186} INFO - Started process (PID=3210) to work on /opt/airflow/dags/ML/ML1.py
[2025-04-24T19:09:55.340+0000] {processor.py:914} INFO - Processing file /opt/airflow/dags/ML/ML1.py for tasks to queue
[2025-04-24T19:09:55.342+0000] {logging_mixin.py:190} INFO - [2025-04-24T19:09:55.341+0000] {dagbag.py:588} INFO - Filling up the DagBag from /opt/airflow/dags/ML/ML1.py
[2025-04-24T19:09:55.578+0000] {logging_mixin.py:190} INFO - [2025-04-24T19:09:55.569+0000] {dagbag.py:387} ERROR - Failed to import: /opt/airflow/dags/ML/ML1.py
Traceback (most recent call last):
  File "/home/airflow/.local/lib/python3.12/site-packages/airflow/models/dagbag.py", line 383, in parse
    loader.exec_module(new_module)
  File "<frozen importlib._bootstrap_external>", line 999, in exec_module
  File "<frozen importlib._bootstrap>", line 488, in _call_with_frames_removed
  File "/opt/airflow/dags/ML/ML1.py", line 17, in <module>
    with DAG(
         ^^^^
  File "/home/airflow/.local/lib/python3.12/site-packages/airflow/models/dag.py", line 593, in __init__
    validate_key(dag_id)
  File "/home/airflow/.local/lib/python3.12/site-packages/airflow/utils/helpers.py", line 57, in validate_key
    raise AirflowException(
airflow.exceptions.AirflowException: The key 'ML 1' has to be made of alphanumeric characters, dashes, dots and underscores exclusively
[2025-04-24T19:09:55.579+0000] {processor.py:927} WARNING - No viable dags retrieved from /opt/airflow/dags/ML/ML1.py
[2025-04-24T19:09:55.641+0000] {processor.py:208} INFO - Processing /opt/airflow/dags/ML/ML1.py took 0.307 seconds
[2025-04-24T19:10:26.054+0000] {processor.py:186} INFO - Started process (PID=3238) to work on /opt/airflow/dags/ML/ML1.py
[2025-04-24T19:10:26.057+0000] {processor.py:914} INFO - Processing file /opt/airflow/dags/ML/ML1.py for tasks to queue
[2025-04-24T19:10:26.061+0000] {logging_mixin.py:190} INFO - [2025-04-24T19:10:26.061+0000] {dagbag.py:588} INFO - Filling up the DagBag from /opt/airflow/dags/ML/ML1.py
[2025-04-24T19:10:26.334+0000] {logging_mixin.py:190} INFO - [2025-04-24T19:10:26.323+0000] {dagbag.py:387} ERROR - Failed to import: /opt/airflow/dags/ML/ML1.py
Traceback (most recent call last):
  File "/home/airflow/.local/lib/python3.12/site-packages/airflow/models/dagbag.py", line 383, in parse
    loader.exec_module(new_module)
  File "<frozen importlib._bootstrap_external>", line 999, in exec_module
  File "<frozen importlib._bootstrap>", line 488, in _call_with_frames_removed
  File "/opt/airflow/dags/ML/ML1.py", line 17, in <module>
    with DAG(
         ^^^^
  File "/home/airflow/.local/lib/python3.12/site-packages/airflow/models/dag.py", line 593, in __init__
    validate_key(dag_id)
  File "/home/airflow/.local/lib/python3.12/site-packages/airflow/utils/helpers.py", line 57, in validate_key
    raise AirflowException(
airflow.exceptions.AirflowException: The key 'ML 1' has to be made of alphanumeric characters, dashes, dots and underscores exclusively
[2025-04-24T19:10:26.335+0000] {processor.py:927} WARNING - No viable dags retrieved from /opt/airflow/dags/ML/ML1.py
[2025-04-24T19:10:26.391+0000] {processor.py:208} INFO - Processing /opt/airflow/dags/ML/ML1.py took 0.346 seconds
[2025-04-24T19:10:56.719+0000] {processor.py:186} INFO - Started process (PID=3267) to work on /opt/airflow/dags/ML/ML1.py
[2025-04-24T19:10:56.722+0000] {processor.py:914} INFO - Processing file /opt/airflow/dags/ML/ML1.py for tasks to queue
[2025-04-24T19:10:56.726+0000] {logging_mixin.py:190} INFO - [2025-04-24T19:10:56.726+0000] {dagbag.py:588} INFO - Filling up the DagBag from /opt/airflow/dags/ML/ML1.py
[2025-04-24T19:10:56.964+0000] {logging_mixin.py:190} INFO - [2025-04-24T19:10:56.955+0000] {dagbag.py:387} ERROR - Failed to import: /opt/airflow/dags/ML/ML1.py
Traceback (most recent call last):
  File "/home/airflow/.local/lib/python3.12/site-packages/airflow/models/dagbag.py", line 383, in parse
    loader.exec_module(new_module)
  File "<frozen importlib._bootstrap_external>", line 999, in exec_module
  File "<frozen importlib._bootstrap>", line 488, in _call_with_frames_removed
  File "/opt/airflow/dags/ML/ML1.py", line 17, in <module>
    with DAG(
         ^^^^
  File "/home/airflow/.local/lib/python3.12/site-packages/airflow/models/dag.py", line 593, in __init__
    validate_key(dag_id)
  File "/home/airflow/.local/lib/python3.12/site-packages/airflow/utils/helpers.py", line 57, in validate_key
    raise AirflowException(
airflow.exceptions.AirflowException: The key 'ML 1' has to be made of alphanumeric characters, dashes, dots and underscores exclusively
[2025-04-24T19:10:56.965+0000] {processor.py:927} WARNING - No viable dags retrieved from /opt/airflow/dags/ML/ML1.py
[2025-04-24T19:10:57.021+0000] {processor.py:208} INFO - Processing /opt/airflow/dags/ML/ML1.py took 0.310 seconds
[2025-04-24T19:11:27.190+0000] {processor.py:186} INFO - Started process (PID=3297) to work on /opt/airflow/dags/ML/ML1.py
[2025-04-24T19:11:27.190+0000] {processor.py:914} INFO - Processing file /opt/airflow/dags/ML/ML1.py for tasks to queue
[2025-04-24T19:11:27.192+0000] {logging_mixin.py:190} INFO - [2025-04-24T19:11:27.192+0000] {dagbag.py:588} INFO - Filling up the DagBag from /opt/airflow/dags/ML/ML1.py
[2025-04-24T19:11:27.440+0000] {logging_mixin.py:190} INFO - [2025-04-24T19:11:27.431+0000] {dagbag.py:387} ERROR - Failed to import: /opt/airflow/dags/ML/ML1.py
Traceback (most recent call last):
  File "/home/airflow/.local/lib/python3.12/site-packages/airflow/models/dagbag.py", line 383, in parse
    loader.exec_module(new_module)
  File "<frozen importlib._bootstrap_external>", line 999, in exec_module
  File "<frozen importlib._bootstrap>", line 488, in _call_with_frames_removed
  File "/opt/airflow/dags/ML/ML1.py", line 17, in <module>
    with DAG(
         ^^^^
  File "/home/airflow/.local/lib/python3.12/site-packages/airflow/models/dag.py", line 593, in __init__
    validate_key(dag_id)
  File "/home/airflow/.local/lib/python3.12/site-packages/airflow/utils/helpers.py", line 57, in validate_key
    raise AirflowException(
airflow.exceptions.AirflowException: The key 'ML 1' has to be made of alphanumeric characters, dashes, dots and underscores exclusively
[2025-04-24T19:11:27.441+0000] {processor.py:927} WARNING - No viable dags retrieved from /opt/airflow/dags/ML/ML1.py
[2025-04-24T19:11:27.506+0000] {processor.py:208} INFO - Processing /opt/airflow/dags/ML/ML1.py took 0.322 seconds
[2025-04-24T19:11:58.011+0000] {processor.py:186} INFO - Started process (PID=3326) to work on /opt/airflow/dags/ML/ML1.py
[2025-04-24T19:11:58.012+0000] {processor.py:914} INFO - Processing file /opt/airflow/dags/ML/ML1.py for tasks to queue
[2025-04-24T19:11:58.015+0000] {logging_mixin.py:190} INFO - [2025-04-24T19:11:58.014+0000] {dagbag.py:588} INFO - Filling up the DagBag from /opt/airflow/dags/ML/ML1.py
[2025-04-24T19:11:58.282+0000] {logging_mixin.py:190} INFO - [2025-04-24T19:11:58.275+0000] {dagbag.py:387} ERROR - Failed to import: /opt/airflow/dags/ML/ML1.py
Traceback (most recent call last):
  File "/home/airflow/.local/lib/python3.12/site-packages/airflow/models/dagbag.py", line 383, in parse
    loader.exec_module(new_module)
  File "<frozen importlib._bootstrap_external>", line 999, in exec_module
  File "<frozen importlib._bootstrap>", line 488, in _call_with_frames_removed
  File "/opt/airflow/dags/ML/ML1.py", line 17, in <module>
    with DAG(
         ^^^^
  File "/home/airflow/.local/lib/python3.12/site-packages/airflow/models/dag.py", line 593, in __init__
    validate_key(dag_id)
  File "/home/airflow/.local/lib/python3.12/site-packages/airflow/utils/helpers.py", line 57, in validate_key
    raise AirflowException(
airflow.exceptions.AirflowException: The key 'ML 1' has to be made of alphanumeric characters, dashes, dots and underscores exclusively
[2025-04-24T19:11:58.282+0000] {processor.py:927} WARNING - No viable dags retrieved from /opt/airflow/dags/ML/ML1.py
[2025-04-24T19:11:58.358+0000] {processor.py:208} INFO - Processing /opt/airflow/dags/ML/ML1.py took 0.351 seconds
[2025-04-24T19:12:28.541+0000] {processor.py:186} INFO - Started process (PID=3355) to work on /opt/airflow/dags/ML/ML1.py
[2025-04-24T19:12:28.543+0000] {processor.py:914} INFO - Processing file /opt/airflow/dags/ML/ML1.py for tasks to queue
[2025-04-24T19:12:28.545+0000] {logging_mixin.py:190} INFO - [2025-04-24T19:12:28.544+0000] {dagbag.py:588} INFO - Filling up the DagBag from /opt/airflow/dags/ML/ML1.py
[2025-04-24T19:12:28.789+0000] {logging_mixin.py:190} INFO - [2025-04-24T19:12:28.781+0000] {dagbag.py:387} ERROR - Failed to import: /opt/airflow/dags/ML/ML1.py
Traceback (most recent call last):
  File "/home/airflow/.local/lib/python3.12/site-packages/airflow/models/dagbag.py", line 383, in parse
    loader.exec_module(new_module)
  File "<frozen importlib._bootstrap_external>", line 999, in exec_module
  File "<frozen importlib._bootstrap>", line 488, in _call_with_frames_removed
  File "/opt/airflow/dags/ML/ML1.py", line 17, in <module>
    with DAG(
         ^^^^
  File "/home/airflow/.local/lib/python3.12/site-packages/airflow/models/dag.py", line 593, in __init__
    validate_key(dag_id)
  File "/home/airflow/.local/lib/python3.12/site-packages/airflow/utils/helpers.py", line 57, in validate_key
    raise AirflowException(
airflow.exceptions.AirflowException: The key 'ML 1' has to be made of alphanumeric characters, dashes, dots and underscores exclusively
[2025-04-24T19:12:28.790+0000] {processor.py:927} WARNING - No viable dags retrieved from /opt/airflow/dags/ML/ML1.py
[2025-04-24T19:12:28.857+0000] {processor.py:208} INFO - Processing /opt/airflow/dags/ML/ML1.py took 0.323 seconds
[2025-04-24T19:12:59.027+0000] {processor.py:186} INFO - Started process (PID=3384) to work on /opt/airflow/dags/ML/ML1.py
[2025-04-24T19:12:59.028+0000] {processor.py:914} INFO - Processing file /opt/airflow/dags/ML/ML1.py for tasks to queue
[2025-04-24T19:12:59.031+0000] {logging_mixin.py:190} INFO - [2025-04-24T19:12:59.030+0000] {dagbag.py:588} INFO - Filling up the DagBag from /opt/airflow/dags/ML/ML1.py
[2025-04-24T19:12:59.273+0000] {logging_mixin.py:190} INFO - [2025-04-24T19:12:59.267+0000] {dagbag.py:387} ERROR - Failed to import: /opt/airflow/dags/ML/ML1.py
Traceback (most recent call last):
  File "/home/airflow/.local/lib/python3.12/site-packages/airflow/models/dagbag.py", line 383, in parse
    loader.exec_module(new_module)
  File "<frozen importlib._bootstrap_external>", line 999, in exec_module
  File "<frozen importlib._bootstrap>", line 488, in _call_with_frames_removed
  File "/opt/airflow/dags/ML/ML1.py", line 17, in <module>
    with DAG(
         ^^^^
  File "/home/airflow/.local/lib/python3.12/site-packages/airflow/models/dag.py", line 593, in __init__
    validate_key(dag_id)
  File "/home/airflow/.local/lib/python3.12/site-packages/airflow/utils/helpers.py", line 57, in validate_key
    raise AirflowException(
airflow.exceptions.AirflowException: The key 'ML 1' has to be made of alphanumeric characters, dashes, dots and underscores exclusively
[2025-04-24T19:12:59.273+0000] {processor.py:927} WARNING - No viable dags retrieved from /opt/airflow/dags/ML/ML1.py
[2025-04-24T19:12:59.314+0000] {processor.py:208} INFO - Processing /opt/airflow/dags/ML/ML1.py took 0.292 seconds
[2025-04-24T20:27:47.840+0000] {processor.py:186} INFO - Started process (PID=3386) to work on /opt/airflow/dags/ML/ML1.py
[2025-04-24T20:27:47.841+0000] {processor.py:914} INFO - Processing file /opt/airflow/dags/ML/ML1.py for tasks to queue
[2025-04-24T20:27:47.846+0000] {logging_mixin.py:190} INFO - [2025-04-24T20:27:47.846+0000] {dagbag.py:588} INFO - Filling up the DagBag from /opt/airflow/dags/ML/ML1.py
[2025-04-24T20:27:48.271+0000] {logging_mixin.py:190} INFO - [2025-04-24T20:27:48.260+0000] {dagbag.py:387} ERROR - Failed to import: /opt/airflow/dags/ML/ML1.py
Traceback (most recent call last):
  File "/home/airflow/.local/lib/python3.12/site-packages/airflow/models/dagbag.py", line 383, in parse
    loader.exec_module(new_module)
  File "<frozen importlib._bootstrap_external>", line 999, in exec_module
  File "<frozen importlib._bootstrap>", line 488, in _call_with_frames_removed
  File "/opt/airflow/dags/ML/ML1.py", line 17, in <module>
    with DAG(
         ^^^^
  File "/home/airflow/.local/lib/python3.12/site-packages/airflow/models/dag.py", line 593, in __init__
    validate_key(dag_id)
  File "/home/airflow/.local/lib/python3.12/site-packages/airflow/utils/helpers.py", line 57, in validate_key
    raise AirflowException(
airflow.exceptions.AirflowException: The key 'ML 1' has to be made of alphanumeric characters, dashes, dots and underscores exclusively
[2025-04-24T20:27:48.272+0000] {processor.py:927} WARNING - No viable dags retrieved from /opt/airflow/dags/ML/ML1.py
[2025-04-24T20:27:48.477+0000] {processor.py:208} INFO - Processing /opt/airflow/dags/ML/ML1.py took 0.644 seconds
[2025-04-24T20:28:19.398+0000] {processor.py:186} INFO - Started process (PID=3415) to work on /opt/airflow/dags/ML/ML1.py
[2025-04-24T20:28:19.400+0000] {processor.py:914} INFO - Processing file /opt/airflow/dags/ML/ML1.py for tasks to queue
[2025-04-24T20:28:19.402+0000] {logging_mixin.py:190} INFO - [2025-04-24T20:28:19.401+0000] {dagbag.py:588} INFO - Filling up the DagBag from /opt/airflow/dags/ML/ML1.py
[2025-04-24T20:28:19.659+0000] {logging_mixin.py:190} INFO - [2025-04-24T20:28:19.652+0000] {dagbag.py:387} ERROR - Failed to import: /opt/airflow/dags/ML/ML1.py
Traceback (most recent call last):
  File "/home/airflow/.local/lib/python3.12/site-packages/airflow/models/dagbag.py", line 383, in parse
    loader.exec_module(new_module)
  File "<frozen importlib._bootstrap_external>", line 999, in exec_module
  File "<frozen importlib._bootstrap>", line 488, in _call_with_frames_removed
  File "/opt/airflow/dags/ML/ML1.py", line 17, in <module>
    with DAG(
         ^^^^
  File "/home/airflow/.local/lib/python3.12/site-packages/airflow/models/dag.py", line 593, in __init__
    validate_key(dag_id)
  File "/home/airflow/.local/lib/python3.12/site-packages/airflow/utils/helpers.py", line 57, in validate_key
    raise AirflowException(
airflow.exceptions.AirflowException: The key 'ML 1' has to be made of alphanumeric characters, dashes, dots and underscores exclusively
[2025-04-24T20:28:19.660+0000] {processor.py:927} WARNING - No viable dags retrieved from /opt/airflow/dags/ML/ML1.py
[2025-04-24T20:28:19.730+0000] {processor.py:208} INFO - Processing /opt/airflow/dags/ML/ML1.py took 0.338 seconds
[2025-04-24T23:25:42.981+0000] {processor.py:186} INFO - Started process (PID=3444) to work on /opt/airflow/dags/ML/ML1.py
[2025-04-24T23:25:42.984+0000] {processor.py:914} INFO - Processing file /opt/airflow/dags/ML/ML1.py for tasks to queue
[2025-04-24T23:25:43.007+0000] {logging_mixin.py:190} INFO - [2025-04-24T23:25:43.006+0000] {dagbag.py:588} INFO - Filling up the DagBag from /opt/airflow/dags/ML/ML1.py
[2025-04-24T23:25:44.392+0000] {logging_mixin.py:190} INFO - [2025-04-24T23:25:44.265+0000] {dagbag.py:387} ERROR - Failed to import: /opt/airflow/dags/ML/ML1.py
Traceback (most recent call last):
  File "/home/airflow/.local/lib/python3.12/site-packages/airflow/models/dagbag.py", line 383, in parse
    loader.exec_module(new_module)
  File "<frozen importlib._bootstrap_external>", line 999, in exec_module
  File "<frozen importlib._bootstrap>", line 488, in _call_with_frames_removed
  File "/opt/airflow/dags/ML/ML1.py", line 17, in <module>
    with DAG(
         ^^^^
  File "/home/airflow/.local/lib/python3.12/site-packages/airflow/models/dag.py", line 593, in __init__
    validate_key(dag_id)
  File "/home/airflow/.local/lib/python3.12/site-packages/airflow/utils/helpers.py", line 57, in validate_key
    raise AirflowException(
airflow.exceptions.AirflowException: The key 'ML 1' has to be made of alphanumeric characters, dashes, dots and underscores exclusively
[2025-04-24T23:25:44.402+0000] {processor.py:927} WARNING - No viable dags retrieved from /opt/airflow/dags/ML/ML1.py
[2025-04-24T23:25:45.085+0000] {processor.py:208} INFO - Processing /opt/airflow/dags/ML/ML1.py took 2.115 seconds
[2025-04-24T23:26:00.050+0000] {processor.py:186} INFO - Started process (PID=3473) to work on /opt/airflow/dags/ML/ML1.py
[2025-04-24T23:26:00.055+0000] {processor.py:914} INFO - Processing file /opt/airflow/dags/ML/ML1.py for tasks to queue
[2025-04-24T23:26:00.061+0000] {logging_mixin.py:190} INFO - [2025-04-24T23:26:00.060+0000] {dagbag.py:588} INFO - Filling up the DagBag from /opt/airflow/dags/ML/ML1.py
[2025-04-24T23:26:01.158+0000] {logging_mixin.py:190} INFO - [2025-04-24T23:26:01.143+0000] {dagbag.py:387} ERROR - Failed to import: /opt/airflow/dags/ML/ML1.py
Traceback (most recent call last):
  File "/home/airflow/.local/lib/python3.12/site-packages/airflow/models/dagbag.py", line 383, in parse
    loader.exec_module(new_module)
  File "<frozen importlib._bootstrap_external>", line 999, in exec_module
  File "<frozen importlib._bootstrap>", line 488, in _call_with_frames_removed
  File "/opt/airflow/dags/ML/ML1.py", line 17, in <module>
    with DAG(
         ^^^^
  File "/home/airflow/.local/lib/python3.12/site-packages/airflow/models/dag.py", line 593, in __init__
    validate_key(dag_id)
  File "/home/airflow/.local/lib/python3.12/site-packages/airflow/utils/helpers.py", line 57, in validate_key
    raise AirflowException(
airflow.exceptions.AirflowException: The key 'ML 1' has to be made of alphanumeric characters, dashes, dots and underscores exclusively
[2025-04-24T23:26:01.161+0000] {processor.py:927} WARNING - No viable dags retrieved from /opt/airflow/dags/ML/ML1.py
[2025-04-24T23:26:01.287+0000] {processor.py:208} INFO - Processing /opt/airflow/dags/ML/ML1.py took 1.252 seconds
